Workbook

Sheet Diseño
A2: =VALUE(LEFT(C4,FIND(" - ",C4)-1)) -> 964 | B2: Diseño de Contenido Curricular
B4: Curso | C4: 964 - Organización Computacional
B5: Periodo al que aplica | C5: Primer Semestre 2026
B8: No. | C8: Competencia | D8: Nombre de la Unidad | E8: Tema | F8: Subtema | G8: Mes | H8: Semana
B9: 1 | C9: Diseña Circuitos digitales combinacionales para operaciones aritméticas y lógicas mediante el uso de Proteus, Logisim y Arduino IDE para construir una Unidad Aritmética Lógica (ALU) funcional que ejecute suma, resta, multiplicación y potencias | D9: Conceptos básicos de la Electrónica | E9: Representación de datos en una computadora digital | F9: Sistemas numéricos posicionales. | G9: Enero | H9: 2
B10: 2 | C10: Diseña Circuitos digitales combinacionales para operaciones aritméticas y lógicas mediante el uso de Proteus, Logisim y Arduino IDE para construir una Unidad Aritmética Lógica (ALU) funcional que ejecute suma, resta, multiplicación y potencias | D10: Conceptos básicos de la Electrónica | E10: Representación de datos en una computadora digital | F10: Sistemas numéricos base 2, 8 y 16. | G10: Enero | H10: 3
B11: 3 | C11: Diseña Circuitos digitales combinacionales para operaciones aritméticas y lógicas mediante el uso de Proteus, Logisim y Arduino IDE para construir una Unidad Aritmética Lógica (ALU) funcional que ejecute suma, resta, multiplicación y potencias | D11: Conceptos básicos de la Electrónica | E11: Representación de datos en una computadora digital | F11: Sistemas numéricos base 2, 8 y 16. | G11: Enero | H11: 3
B12: 4 | C12: Diseña Circuitos digitales combinacionales para operaciones aritméticas y lógicas mediante el uso de Proteus, Logisim y Arduino IDE para construir una Unidad Aritmética Lógica (ALU) funcional que ejecute suma, resta, multiplicación y potencias | D12: Conceptos básicos de la Electrónica | E12: Representación de datos en una computadora digital | F12: Sistemas numéricos base 2, 8 y 16. | G12: Enero | H12: 4
B13: 5 | C13: Define los sistemas numéricos posicionales (binario, octal y decimal) y los componentes básicos de la electrónica digital (puertas lógicas, transistores, LEDs) ofreciendo explicaciones sobre su función y relación en la representación de la información en dispositivos digitales con precisión | D13: Lógica Binaria y Operaciones Básicas | E13: Lógica Binaria y Operaciones Básicas | F13: Formas de Minimización de funciones booleanas | G13: Enero | H13: 3
B14: 6 | C14: Define los sistemas numéricos posicionales (binario, octal y decimal) y los componentes básicos de la electrónica digital (puertas lógicas, transistores, LEDs) ofreciendo explicaciones sobre su función y relación en la representación de la información en dispositivos digitales con precisión | D14: Lógica Binaria y Operaciones Básicas | E14: Lógica Binaria y Operaciones Básicas | F14: Mapas de Karnaugh | G14: Enero | H14: 3
B15: 7 | C15: Define los sistemas numéricos posicionales (binario, octal y decimal) y los componentes básicos de la electrónica digital (puertas lógicas, transistores, LEDs) ofreciendo explicaciones sobre su función y relación en la representación de la información en dispositivos digitales con precisión | D15: Lógica Binaria y Operaciones Básicas | E15: Lógica Binaria y Operaciones Básicas | F15: Circuitos Lógicos Binarios | G15: Enero | H15: 3
B16: 8 | C16: Define los sistemas numéricos posicionales (binario, octal y decimal) y los componentes básicos de la electrónica digital (puertas lógicas, transistores, LEDs) ofreciendo explicaciones sobre su función y relación en la representación de la información en dispositivos digitales con precisión | D16: Lógica Binaria y Operaciones Básicas | E16: Lógica Binaria y Operaciones Básicas | F16: Operaciones combinadas (Xor, Xnor, Nand, Nor) | G16: Enero | H16: 3
B17: 9 | C17: Define los sistemas numéricos posicionales (binario, octal y decimal) y los componentes básicos de la electrónica digital (puertas lógicas, transistores, LEDs) ofreciendo explicaciones sobre su función y relación en la representación de la información en dispositivos digitales con precisión | D17: Lógica Combinacional | E17: Diseño de Lógica Combinacional | F17: Comparadores | G17: Febrero | H17: 4
B18: 10 | C18: Define los sistemas numéricos posicionales (binario, octal y decimal) y los componentes básicos de la electrónica digital (puertas lógicas, transistores, LEDs) ofreciendo explicaciones sobre su función y relación en la representación de la información en dispositivos digitales con precisión | D18: Lógica Combinacional | E18: Diseño de Lógica Combinacional | F18: Multiplexador | G18: Febrero | H18: 4
B19: 11 | C19: Define los sistemas numéricos posicionales (binario, octal y decimal) y los componentes básicos de la electrónica digital (puertas lógicas, transistores, LEDs) ofreciendo explicaciones sobre su función y relación en la representación de la información en dispositivos digitales con precisión | D19: Lógica Combinacional | E19: Diseño de Lógica Combinacional | F19: Demultiplexador | G19: Febrero | H19: 4
B20: 12 | C20: Define los sistemas numéricos posicionales (binario, octal y decimal) y los componentes básicos de la electrónica digital (puertas lógicas, transistores, LEDs) ofreciendo explicaciones sobre su función y relación en la representación de la información en dispositivos digitales con precisión | D20: Lógica Combinacional | E20: Diseño de Lógica Combinacional | F20: De binario a BCD | G20: Febrero | H20: 4
... B24: 16 | C24: Implementa Circuitos digitales secuenciales utilizando flip-flops SR, D, JK y T mediante simulación en Proteus y montaje en protoboard aplicando técnicas de diseño lógico para crear y comprobar aplicaciones de almacenamiento, conteo y control de estados en sistemas electrónicos digitales | D24: Bloques Digitales y Lógica Secuencial | E24: Introduccion a la logica secuencial | F24: Latches | G24: Febrero | H24: 6
B25: 17
B26: 18
B27: 19 | C27: Implementa Circuitos digitales secuenciales utilizando flip-flops SR, D, JK y T mediante simulación en Proteus y montaje en protoboard aplicando técnicas de diseño lógico para crear y comprobar aplicaciones de almacenamiento, conteo y control de estados en sistemas electrónicos digitales | D27: Bloques Digitales y Logica Secuencial | E27: Introduccion a la logica secuencial | F27: Flip-flop tipo SR | G27: Febrero | H27: 7
B28: 20 | C28: Implementa Circuitos digitales secuenciales utilizando flip-flops SR, D, JK y T mediante simulación en Proteus y montaje en protoboard aplicando técnicas de diseño lógico para crear y comprobar aplicaciones de almacenamiento, conteo y control de estados en sistemas electrónicos digitales | D28: Bloques Digitales y Logica Secuencial | E28: Introduccion a la logica secuencial | F28: Flip-flop tipo D | G28: Febrero | H28: 7
B29: 21 | C29: Implementa Circuitos digitales secuenciales utilizando flip-flops SR, D, JK y T mediante simulación en Proteus y montaje en protoboard aplicando técnicas de diseño lógico para crear y comprobar aplicaciones de almacenamiento, conteo y control de estados en sistemas electrónicos digitales | D29: Bloques Digitales y Logica Secuencial | E29: Introduccion a la logica secuencial | F29: Flip-flop tipo JK | G29: Febrero | H29: 7
B30: 22 | C30: Implementa Circuitos digitales secuenciales utilizando flip-flops SR, D, JK y T mediante simulación en Proteus y montaje en protoboard aplicando técnicas de diseño lógico para crear y comprobar aplicaciones de almacenamiento, conteo y control de estados en sistemas electrónicos digitales | D30: Bloques Digitales y Logica Secuencial | E30: Introduccion a la logica secuencial | F30: Flip-flop tipo T | G30: Febrero | H30: 7
B31: 23 | C31: Implementa Circuitos digitales secuenciales utilizando flip-flops SR, D, JK y T mediante simulación en Proteus y montaje en protoboard aplicando técnicas de diseño lógico para crear y comprobar aplicaciones de almacenamiento, conteo y control de estados en sistemas electrónicos digitales | D31: Bloques Digitales y Logica Secuencial | E31: Flip-Flops | F31: Aplicaciones de flip-flops en circuitos digitales | H31: 7
B32: 24 | C32: Integra circuitos digitales y sistemas embebidos mediante el uso de bases numéricas, transistores, compuertas lógicas, bloques combinacionales y secuenciales, registros, memoria RAM, Arduino, actuadores, controladores y sensores para la resolución de problemas prácticos de automatización y control en contextos académicos y tecnológicos | D32: Bloques Digitales y Logica Secuencial | E32: Contadores | F32: Contadorres | G32: Marzo | H32: 8
B33: 25 | C33: Integra circuitos digitales y sistemas embebidos mediante el uso de bases numéricas, transistores, compuertas lógicas, bloques combinacionales y secuenciales, registros, memoria RAM, Arduino, actuadores, controladores y sensores para la resolución de problemas prácticos de automatización y control en contextos académicos y tecnológicos | D33: Bloques Digitales y Logica Secuencial | E33: Contadores | F33: Contadorres | G33: Marzo | H33: 8
B34: 26
B35: 27
B36: 28
B37: 29
B38: 30 | C38: Implementa soluciones de almacenamiento y conteo digital utilizando registros y contadores apoyándose en simuladores de circuitos digitales como Proteus para optimizar el manejo de datos y eventos secuenciales en sistemas electrónicos | D38: Registros Digitales, Actuadores y Controladores Avanzados | E38: Registros digitales | F38: Registro en paralelo | G38: Marzo | H38: 9
B39: 31 | C39: Implementa soluciones de almacenamiento y conteo digital utilizando registros y contadores apoyándose en simuladores de circuitos digitales como Proteus para optimizar el manejo de datos y eventos secuenciales en sistemas electrónicos | D39: Registros Digitales, Actuadores y Controladores Avanzados | E39: Registros digitales | F39: Registro en serie | G39: Marzo | H39: 9
B40: 32 | C40: Implementa soluciones de almacenamiento y conteo digital utilizando registros y contadores apoyándose en simuladores de circuitos digitales como Proteus para optimizar el manejo de datos y eventos secuenciales en sistemas electrónicos | D40: Registros Digitales, Actuadores y Controladores Avanzados | E40: Registros digitales | F40: Registros en almacenamiento | G40: Marzo | H40: 9
B41: 33 | C41: Implementa soluciones de almacenamiento y conteo digital utilizando registros y contadores apoyándose en simuladores de circuitos digitales como Proteus para optimizar el manejo de datos y eventos secuenciales en sistemas electrónicos | D41: Registros Digitales, Actuadores y Controladores Avanzados | E41: Registros digitales | F41: Transferencia de datos | G41: Marzo | H41: 9
B42: 34 | C42: Implementa soluciones de almacenamiento y conteo digital utilizando registros y contadores apoyándose en simuladores de circuitos digitales como Proteus para optimizar el manejo de datos y eventos secuenciales en sistemas electrónicos | D42: Registros Digitales, Actuadores y Controladores Avanzados | E42: Registros digitales | F42: Memoria RAM | G42: Marzo | H42: 9
B43: 35 | C43: Diseña sistemas de control interactivos con microcontroladores y sensores mediante el uso de Arduino IDE y librerías de comunicación (Serial, I2C, SPI) para automatizar procesos de monitoreo y control en tiempo real en dispositivos electrónicos | D43: Arduino | E43: Introduccion a Arduino | F43: Funcionamiento y partes de un Arduino | G43: Marzo | H43: 10
B44: 36 | C44: Diseña sistemas de control interactivos con microcontroladores y sensores mediante el uso de Arduino IDE y librerías de comunicación (Serial, I2C, SPI) para automatizar procesos de monitoreo y control en tiempo real en dispositivos electrónicos | D44: Arduino | E44: Introduccion a Arduino | F44: Codigo de Arduino y su implementación | G44: Marzo | H44: 10
B45: 37 | C45: Diseña sistemas de control interactivos con microcontroladores y sensores mediante el uso de Arduino IDE y librerías de comunicación (Serial, I2C, SPI) para automatizar procesos de monitoreo y control en tiempo real en dispositivos electrónicos | D45: Arduino | E45: Introduccion a Arduino | F45: Protocolos de Comunicación (Serial, I2C, SPI) | G45: Marzo | H45: 10
B46: 38 | C46: Diseña sistemas de control interactivos con microcontroladores y sensores mediante el uso de Arduino IDE y librerías de comunicación (Serial, I2C, SPI) para automatizar procesos de monitoreo y control en tiempo real en dispositivos electrónicos | D46: Arduino | E46: Introduccion a Arduino | F46: Actuadores | G46: Marzo | H46: 10
B47: 39
...

Sheet Semana Diagnostico
B2: Diseño de Contenido Curricular
B4: Curso | C4: ='Diseño'!C4 -> 964 - Organización Computacional
B5: Semana | C5: 1
B6: Tiempo | C6: =B15+B22+B29+B41+B47+C48 -> 100
A9: 1. Bienvenida y Presentación | G9: Tiempo Aproximado | H9: 15
G10: No puedes excederte mas de 15 minutos
A11: Nombre y Formacion Academica | B11: Me presentaré diciendo mi nombre completo. Compartiré mi formación académica, la carrera que estudié y resaltaré la experiencia que tengo en el área de sistemas y organización computacional. Mencionaré que mi preparación me da las bases necesarias para acompañarlos en el aprendizaje de la materia.
A12: Experiencia docente y profecional | B12: Hablaré de mi experiencia dando clases en el área de computación e informática. Mencionaré los cursos o asignaturas en los que he trabajado previamente. Compartiré también mi experiencia profesional fuera de la docencia, como proyectos, trabajos en empresas o colaboraciones relacionadas con sistemas y computación. Resaltaré cómo esta experiencia me permite vincular la teoría con la práctica y enriquecer la clase. | K12: Estos puntos son recomendaciones de los puntos a tratar durante tu presentacion, si no usaras estos eres libre de agregar mas filas para indicar que haras. En los recuadros de la derecha colocar breve resumen de lo que planeas decir. No debes ser muy especifico seran pequeñas anotaciones que te ayudaran a recordar lo que planeaste
A13: Rol del auxiliar dentro del curso (funciones, actividades y apoyo a los estudiantes). | B13: Explicaré que como auxiliar mi función principal es acompañar y apoyar tanto al docente como a los estudiantes. Mencionaré que estaré disponible para resolver dudas, orientar en el uso de materiales, guiar en actividades prácticas y reforzar los temas vistos en clase. Aclararé que mi objetivo es facilitar el aprendizaje y servir como un puente entre el profesor y los alumnos.
A14: Expectativas sobre la dinámica del curso | B14: Compartiré que espero que el curso sea participativo y dinámico. Mencionaré que deseo que los estudiantes se involucren activamente en clase, planteen preguntas y aporten ideas. Resaltaré que la práctica y la colaboración serán claves para el aprendizaje. Explicaré que mi expectativa es que trabajemos en un ambiente de respeto, compromiso y motivación mutua.
A15: Tiempo que emplearas | B15: 15
A18: 2. Evaluación de Conocimientos Previos | G18: Tiempo Aproximado | H18: 25
G19: No puedes excederte mas de 45 minutos
A20: Redactaras de 15 a 20 preguntas con sus respectivas respuestas , por lo que debes escoge los temas que evaluaras | B20: ¿Qué es el sistema binario y por qué se usa en computación digital? → Es el sistema que usa dos símbolos (0 y 1). Se utiliza porque los circuitos electrónicos trabajan con dos estados: encendido y apagado. ¿Cuál es la diferencia entre un nivel lógico alto (1) y un nivel lógico bajo (0)? → El 1 representa presencia de voltaje y el 0 ausencia de voltaje. ¿Qué es una compuerta lógica? Menciona tres tipos. → Son circuitos básicos que realizan operaciones lógicas; ejemplos: AND, OR, NOT. ¿Cuál es la tabla de verdad de una compuerta AND? → Solo da 1 si ambas entradas son 1. ¿Qué función realiza una compuerta OR? → Da 1 si al menos una entrada es 1. ¿Qué es una compuerta NOT y qué hace? → Invierte el valor de entrada; de 1 a 0 y de 0 a 1. ¿Qué diferencia hay entre combinacional y secuencial en circuitos digitales? → Los combinacionales dependen solo de entradas actuales; los secuenciales también dependen de estados previos. ¿Qué es un flip-flop y para qué se usa? → Es un circuito secuencial que almacena un bit de información. ¿Qué es un multiplexor (MUX) y cuál es su utilidad? → Selecciona una de varias entradas y la dirige a la salida. ¿Qué es un sumador binario y cómo se utiliza en la ALU? → Es un circuito que realiza sumas binarias; en la ALU sirve para operaciones aritméticas. ¿Qué es la memoria RAM y para qué sirve? → Es una memoria de acceso rápido y temporal que almacena datos e instrucciones mientras el equipo está en uso. ¿Cuál es la diferencia entre hardware y software? → El hardware son los componentes físicos, mientras que el software son los programas e instrucciones que los hacen funcionar. ¿Qué es un bus en arquitectura computacional? → Es un sistema de comunicación que transporta datos, direcciones y señales de control entre los componentes del computador. ¿Qué es la unidad de control (UC) en la CPU? → Es la parte que coordina y dirige las operaciones, interpretando instrucciones y controlando el flujo de datos. ¿Cuál es la diferencia entre memoria caché y memoria principal? → La caché es más rápida y almacena datos de uso frecuente; la principal (RAM) es más grande pero más lenta en comparación. | K20: En los recuadors de la derecha deberas colocar las preguntas que planeas realizar con sus respectivas respuestas. En el segundo recuadro deberas colocar un breve resumne de lo que tines planificado para la parte practica del curso previo al que estas impartiendo.
A21: Redactaras una parte practica | B21: Planifico un repaso práctico de conceptos básicos de circuitos digitales: - Identificación de valores binarios en ejemplos sencillos. - Resolución de tablas de verdad para AND, OR y NOT. - Ejercicios de simulación con compuertas lógicas. - Ejemplo breve de sumador binario de 1 bit. - Actividad en parejas para diferenciar circuitos combinacionales y secuenciales.
A22: Tiempo que emplearas | B22: 25
A25: 3. Presentación de los Estudiantes | G25: Tiempo Aproximado | H25: 30
G26: No puedes excederte mas de 30 minutos
A27: Seleccion al Azar de 5 Estudiantes | B27: Explicaré que la dinámica será mediante selección al azar. Los estudiantes serán elegidos al final de la actividad inicial para garantizar imparcialidad y fomentar la participación. Se usarán números asignados a cada estudiante o una aplicación sencilla de sorteo en línea. Serán seleccionados 5 estudiantes al azar, quienes responderán preguntas específicas frente al grupo. | K27: En el primer recuadro colocaras la metodollogia que adoptaras para la eleccion de los estudiantes. En el segundo recuadro colocaras la redaccion de las preguntas que comprendan los siguientes puntos respecto al estudiante: Nombre. Intereses y expectativas sobre el curso. Experiencia previa relacionada con el curso (si aplica). Un dato curioso sobre sí mismo. Consideras que la prueba de conociminetos previos esta acorde al conocimiento que se te brindo en su momento Que tan comodo se sintio con la prueba anterior.
A28: Preguntas que responderan los estudiantes afortunados | B28: 1. ¿Cuál es tu nombre? 2. ¿Cuáles son tus intereses y expectativas sobre el curso? 3. ¿Tienes experiencia previa relacionada con este curso? (si aplica) 4. Cuéntanos un dato curioso sobre ti. 5. ¿Consideras que la prueba de conocimientos previos estuvo acorde con lo que habías aprendido antes? 6. ¿Qué tan cómodo(a) te sentiste con la prueba anterior?
A29: Tiempo que emplearas | B29: 30
A32: 4. Senso de Horarios de Calificación | G32: Tiempo Aproximado | H32: 5
A33: Deberas estar recordando que deben contestar el formulario asi mismo dejar el link fijado en la llamada | G33: Esta actividad quedara abierta hasta el fin de la clase. pero emplearas 5 min especificos para la actividad
A34: Link de google forms donde este el cuestionario | B34: Compartiré un Google Form con mis estudiantes. Configuraré el formulario para que solo puedan responder con su correo institucional, así garantizaré que cada estudiante envíe únicamente una respuesta. El cuestionario pedirá su nombre, grupo, día y horario preferido para la calificación. | K34: Esta actividad te ayudara a realizar un senso de posibles horarios de calificacion y que tus estudiantes esten enterados y puedan preveer los dias de calificacion y asi mismo el horario. Deberas colocar en los reacuadros de la derecha link de Google form libre para correos intitucionales, esto para garantizar una sola respuesta por estudiante. TAmbien deberas colocar los posibles horarios y dias que tentativamente tendrias disponibles. para colocarlos en el google form.
A35: Dias y posibles Horarios de calificacion | B35: Tendré disponibles los siguientes horarios tentativos: - Sábado: 9:00 – 10:30 h, 11:00 – 12:30 h, 13:00 – 14:30 h Explicaré que estos horarios serán tentativos y que podré ajustarlos según la disponibilidad del grupo.
A36: Tiempo que emplearas | B36: 5
A39: 4. Mostrar Programa del Curso | G39: Tiempo Aproximado | H39: 20
G40: No puedes excederte mas de 30 minutos
A41: Tiempo que emplearas | B41: 20
A44: 2. Evaluación de Conocimientos del Curso Actual | G44: Tiempo Aproximado | H44: 10
G45: No puedes excederte mas de 15 minutos
A46: Redactaras 20 preguntas con sus respectivas respuestas | B46: Pregunta: ¿Cuál es el objetivo principal del laboratorio? Respuesta: Aplicar principios de electrónica digital en el diseño y análisis de circuitos combinacionales y secuenciales. Pregunta: Menciona dos sistemas numéricos posicionales utilizados en el curso. Respuesta: Binario y octal. Pregunta: ¿Qué software se utiliza para simular circuitos digitales? Respuesta: Proteus, Logisim o Multisim. Pregunta: ¿Qué es el álgebra booleana? Respuesta: Un sistema matemático para representar y simplificar operaciones lógicas. Pregunta: ¿Qué herramienta se usa para minimizar funciones booleanas? Respuesta: Mapas de Karnaugh. Pregunta: Nombra dos compuertas lógicas básicas. Respuesta: AND y OR. Pregunta: ¿Cuál es la diferencia principal entre lógica combinacional y lógica secuencial? Respuesta: La combinacional depende solo de las entradas actuales, la secuencial depende de entradas y estados previos. Pregunta: Menciona un ejemplo de circuito combinacional estudiado en el curso. Respuesta: Sumador. Pregunta: ¿Qué componente es fundamental para almacenar estados en lógica secuencial? Respuesta: Flip-flop. Pregunta: Escribe un tipo de flip-flop visto en el laboratorio. Respuesta: Flip-flop tipo JK. Pregunta: ¿Qué es un contador síncrono? Respuesta: Un contador en el que todos los flip-flops cambian de estado al mismo tiempo. Pregunta: Menciona un tipo de registro digital. Respuesta: Registro en paralelo. Pregunta: ¿Qué plataforma se utiliza para programar y controlar sensores en Arduino? Respuesta: Arduino IDE. Pregunta: Nombra un actuador utilizado en las prácticas de Arduino. Respuesta: Servomotor. Pregunta: ¿Cuál es el porcentaje mínimo de asistencia requerido para aprobar el laboratorio? Respuesta: 80%.
A47: Tiempo que emplearas | B47: 10

Sheet S.2
B2: Diseño de la Sesión de Laboratorio
B4: Curso | C4: ='Diseño'!C4 -> 964 - Organización Computacional
B5: Semana | C5: 2
B6: Tiempo | C6: =H10+H21+H44+H68 -> 100
B7: Ponderación | C7: =B49+B60 -> 0
B8: Validación de Tiempo | C8: =IF(H44<=0, "❌ ERROR: La Actividad 1 debe tener un tiempo mayor a 0.", IF(H21>60, "❌ ERROR: El 'Área de Conocimiento' no puede exceder los 60 min.", IF(C6<100, "❌ ERROR: El tiempo total debe ser de al menos 100 min.", "✅ VALIDACIÓN CORRECTA"))) -> ✅ VALIDACIÓN CORRECTA
A10: 1. Área Actitudinal (Saber Ser) | G10: Tiempo Aproximado | H10: 5
G11: Tiene que estar en un rango de 3 a 5 minutos
A12: Nombre del Valor | B12: Reponsabilidad
A13: Tiempo Aproximado | B13: 5
A14: Descripcion
A15: La responsabilidad se manifiesta en el compromiso del estudiante con sus entregables, su participación activa en la clase y el cumplimiento de las actividades propuestas. Es fundamental para el desarrollo exitoso de proyectos prácticos como el diseño de circuitos digitales.
A17: Como se relaciona con los conocimientos de la sesion y se aplicaria
A18: La responsabilidad se aplica al momento de entregar los diseños de circuitos a tiempo, revisar simulaciones, y participar en la construcción del ALU. El estudiante debe comprometerse con su aprendizaje y con el uso correcto de las herramientas como Proteus, Logisim y Arduino IDE.
A21: 2. Área Conocimiento (Saber) | G21: Tiempo Aproximado | H21: 50
G22: No puede exceder los 60 minutos
A23: Competencia a desarrollar | B23: Diseña Circuitos digitales combinacionales para operaciones aritméticas y lógicas mediante el uso de Proteus, Logisim y Arduino IDE para construir una Unidad Aritmética Lógica (ALU) funcional que ejecute suma, resta, multiplicación y potencias
A24: Competencia a desarrollar
A26: 2.1 Contenido
A27: No. | B27: Unidad | D27: Tema | F27: Sub Tema
A28: 1 | B28: =IFERROR(__xludf.DUMMYFUNCTION("FILTER('Diseño'!D:D,'Diseño'!H:H=$C$5)"),"Conceptos básicos de la Electrónica") -> Conceptos básicos de la Electrónica | D28: =IFERROR(__xludf.DUMMYFUNCTION("FILTER('Diseño'!E:E,'Diseño'!H:H=$C$5)"),"Representación de datos en una computadora digital") -> Representación de datos en una computadora digital | F28: =IFERROR(__xludf.DUMMYFUNCTION("FILTER('Diseño'!F:F,'Diseño'!H:H=$C$5)"),"Sistemas numéricos posicionales.") -> Sistemas numéricos posicionales.
A29: 2 | B29: =IFERROR(__xludf.DUMMYFUNCTION("FILTER('Diseño'!D:D,'Diseño'!H:H=$C$5)"),"Conceptos básicos de la Electrónica") -> Conceptos básicos de la Electrónica | D29: =IFERROR(__xludf.DUMMYFUNCTION("FILTER('Diseño'!E:E,'Diseño'!H:H=$C$5)"),"Representación de datos en una computadora digital") -> Representación de datos en una computadora digital | F29: Sistemas numéricos base 2, 8 y 16.
A30: 3
A31: 4
A32: 5
A33: 6
A34: 7
A36: 2.2 Recursos Educativos
A38: Tipo de Recurso a utilizar | B38: Tipo | C38: Rango Aproximando | D38: Tiempo Aproximado
A39: Presentacion | B39: Obligatorio | D39: 40
A40: Video | B40: Obligatorio | C40: 3 a 6 minutos | D40: 10
A41: Lectura | B41: Optativo | D41: 10
A42: Ejercicio Demostrativo | B42: Obligatorio
A44: 3. Área de Habilidades (Saber Hacer) | G44: Tiempo Aproximado | H44: =B50 -> 40
G45: Tiene que estar en un rango de 30 a 50 minutos
A46: Actividad 1 (Obligatoria)
A47: Competencia que predomina en la actividad | B47: Diseña Circuitos digitales combinacionales para operaciones aritméticas y lógicas mediante el uso de Proteus, Logisim y Arduino IDE para construir una Unidad Aritmética Lógica (ALU) funcional que ejecute suma, resta, multiplicación y potencias
A48: Tipo de Actividad | B48: Ejercicio practico
A49: Ponderación | B49: 0
A50: Tiempo Aproximado | B50: 40
...

Sheet S.3
B2: Diseño de la Sesión de Laboratorio
B4: Curso | C4: ='Diseño'!C4 -> 964 - Organización Computacional
B5: Semana | C5: 3
B6: Tiempo | C6: =H10+H21+H44+H68 -> 110
B7: Ponderación | C7: =B49+B60 -> 0
B8: Validación de Tiempo | C8: =IF(H44<=0, "❌ ERROR: La Actividad 1 debe tener un tiempo mayor a 0.", IF(H21>60, "❌ ERROR: El 'Área de Conocimiento' no puede exceder los 60 min.", IF((H10+H21+H44)<100, "❌ ERROR: El tiempo total debe ser de al menos 100 min.", "✅ VALIDACIÓN CORRECTA"))) -> ✅ VALIDACIÓN CORRECTA
A10: 1. Área Actitudinal (Saber Ser) | G10: Tiempo Aproximado | H10: 5
G11: Tiene que estar en un rango de 3 a 5 minutos
A12: Nombre del Valor | B12: Trabajo en equipo
A13: Tiempo Aproximado | B13: 5
A14: Descripcion
A15: Fomentar la colaboración y comunicación efectiva entre los miembros del equipo para lograr objetivos comunes en el diseño y desarrollo de circuitos combinacionales y sistemas electrónicos.
A17: Como se relaciona con los conocimientos de la sesion y se aplicaria
A18: El trabajo en equipo se relaciona con los conocimientos de la sesión al permitir a los estudiantes colaborar para analizar, diseñar y simular circuitos combinacionales, asegurando que cada integrante aporte y comprenda la función y requerimientos del sistema, mejorando así la calidad y efectividad del proyecto.
A21: 2. Área Conocimiento (Saber) | G21: Tiempo Aproximado | H21: 50
G22: No puede exceder los 60 minutos
A23: Competencia a desarrollar | B23: Define los sistemas numéricos posicionales (binario, octal y decimal) y los componentes básicos de la electrónica digital (puertas lógicas, transistores, LEDs) ofreciendo explicaciones sobre su función y relación en la representación de la información en dispositivos digitales con precisión
A24: Competencia a desarrollar
A26: 2.1 Contenido
A27: No. | B27: Unidad | D27: Tema | F27: Sub Tema
A28: 1 | B28: Lógica Binaria y Operaciones Básicas | D28: Lógica Binaria y Operaciones Básicas | F28: Formas de Minimización de funciones booleanas
A29: 2 | B29: Lógica Binaria y Operaciones Básicas | D29: Lógica Binaria y Operaciones Básicas | F29: Mapas de Karnaugh
A30: 3 | B30: Lógica Binaria y Operaciones Básicas | D30: Lógica Binaria y Operaciones Básicas | F30: Circuitos Lógicos Binarios
A31: 4 | B31: Lógica Binaria y Operaciones Básicas | D31: Lógica Binaria y Operaciones Básicas | F31: Operaciones combinadas (Xor, Xnor, Nand, Nor)
A32: 5
A33: 6
A34: 7
A36: 2.2 Recursos Educativos
A38: Tipo de Recurso a utilizar | B38: Tipo | C38: Rango Aproximando | D38: Tiempo Aproximado
A39: Presentacion | B39: Obligatorio
A40: Video | B40: Obligatorio | C40: 3 a 6 minutos
A41: Lectura | B41: Optativo
A42: Ejercicio Demostrativo | B42: Obligatorio
A44: 3. Área de Habilidades (Saber Hacer) | G44: Tiempo Aproximado | H44: 45
G45: Tiene que estar en un rango de 30 a 50 minutos
A46: Actividad 1 (Obligatoria)
A47: Competencia que predomina en la actividad | B47: Define los sistemas numéricos posicionales (binario, octal y decimal) y los componentes básicos de la electrónica digital (puertas lógicas, transistores, LEDs) ofreciendo explicaciones sobre su función y relación en la representación de la información en dispositivos digitales con precisión
A48: Tipo de Actividad | B48: Ejercicio practico
A49: Ponderación | B49: 0
A50: Tiempo Aproximado | B50: 10
...

Sheet S.4
B2: Diseño de la Sesión de Laboratorio
B4: Curso | C4: ='Diseño'!C4 -> 964 - Organización Computacional
B5: Semana | C5: 4
B6: Tiempo | C6: 100
B7: Ponderación | C7: 1
B8: Validación de Tiempo | C8: =IF(H44<=0, "❌ ERROR: La Actividad 1 debe tener un tiempo mayor a 0.", IF(H21>60, "❌ ERROR: El 'Área de Conocimiento' no puede exceder los 60 min.", IF((H10+H21+H44)<100, "❌ ERROR: El tiempo total debe ser de al menos 100 min.", "✅ VALIDACIÓN CORRECTA"))) -> ✅ VALIDACIÓN CORRECTA
A10: 1. Área Actitudinal (Saber Ser) | G10: Tiempo Aproximado | H10: 5
G11: Tiene que estar en un rango de 3 a 5 minutos
A12: Nombre del Valor | B12: Pensamiento lógico
A13: Tiempo Aproximado | B13: 5
A14: Descripcion
A15: Utilizar el pensamiento lógico para analizar y estructurar el diseño de circuitos combinacionales, como comparadores, multiplexores, demultiplexores y conversores binario–BCD, asegurando soluciones claras y funcionales.
A17: Como se relaciona con los conocimientos de la sesion y se aplicaria
A18: El pensamiento lógico se relaciona con los conocimientos de la sesión al permitir al estudiante analizar y estructurar el funcionamiento de comparadores, multiplexores, demultiplexores y conversores binario–BCD. Se aplica al diseñar y simular circuitos combinacionales, asegurando que la implementación cumpla con los requerimientos y funcione correctamente.
A21: 2. Área Conocimiento (Saber) | G21: Tiempo Aproximado | H21: 50
G22: No puede exceder los 60 minutos
A23: Competencia a desarrollar | B23: Define los sistemas numéricos posicionales (binario, octal y decimal) y los componentes básicos de la electrónica digital (puertas lógicas, transistores, LEDs) ofreciendo explicaciones sobre su función y relación en la representación de la información en dispositivos digitales con precisión
A24: Competencia a desarrollar
A26: 2.1 Contenido
A27: No. | B27: Unidad | D27: Tema | F27: Sub Tema
A28: 1 | B28: =IFERROR(__xludf.DUMMYFUNCTION("FILTER('Diseño'!D:D,'Diseño'!H:H=$C$5)"),"Conceptos básicos de la Electrónica") -> Conceptos básicos de la Electrónica | D28: =IFERROR(__xludf.DUMMYFUNCTION("FILTER('Diseño'!E:E,'Diseño'!H:H=$C$5)"),"Representación de datos en una computadora digital") -> Representación de datos en una computadora digital | F28: =IFERROR(__xludf.DUMMYFUNCTION("FILTER('Diseño'!F:F,'Diseño'!H:H=$C$5)"),"Sistemas numéricos base 2, 8 y 16.") -> Sistemas numéricos base 2, 8 y 16.
A29: 2 | B29: =IFERROR(__xludf.DUMMYFUNCTION("""COMPUTED_VALUE"""),"Lógica Combinacional") -> Lógica Combinacional | D29: =IFERROR(__xludf.DUMMYFUNCTION("""COMPUTED_VALUE"""),"Diseño de Lógica Combinacional") -> Diseño de Lógica Combinacional | F29: =IFERROR(__xludf.DUMMYFUNCTION("""COMPUTED_VALUE"""),"Comparadores") -> Comparadores
A30: 3 | B30: =IFERROR(__xludf.DUMMYFUNCTION("""COMPUTED_VALUE"""),"Lógica Combinacional") -> Lógica Combinacional | D30: =IFERROR(__xludf.DUMMYFUNCTION("""COMPUTED_VALUE"""),"Diseño de Lógica Combinacional") -> Diseño de Lógica Combinacional | F30: =IFERROR(__xludf.DUMMYFUNCTION("""COMPUTED_VALUE"""),"Multiplexador") -> Multiplexador
A31: 4 | B31: =IFERROR(__xludf.DUMMYFUNCTION("""COMPUTED_VALUE"""),"Lógica Combinacional") -> Lógica Combinacional | D31: =IFERROR(__xludf.DUMMYFUNCTION("""COMPUTED_VALUE"""),"Diseño de Lógica Combinacional") -> Diseño de Lógica Combinacional | F31: =IFERROR(__xludf.DUMMYFUNCTION("""COMPUTED_VALUE"""),"Demultiplexador") -> Demultiplexador
A32: 5 | B32: =IFERROR(__xludf.DUMMYFUNCTION("""COMPUTED_VALUE"""),"Lógica Combinacional") -> Lógica Combinacional | D32: =IFERROR(__xludf.DUMMYFUNCTION("""COMPUTED_VALUE"""),"Diseño de Lógica Combinacional") -> Diseño de Lógica Combinacional | F32: =IFERROR(__xludf.DUMMYFUNCTION("""COMPUTED_VALUE"""),"De binario a BCD") -> De binario a BCD
A33: 6
A34: 7
A36: 2.2 Recursos Educativos
A38: Tipo de Recurso a utilizar | B38: Tipo | C38: Rango Aproximando | D38: Tiempo Aproximado
A39: Presentacion | B39: Obligatorio | D39: 35
A40: Video | B40: Obligatorio | C40: 3 a 6 minutos | D40: 5
A41: Lectura | B41: Optativo
A42: Ejercicio Demostrativo | B42: Obligatorio | D42: 10
A44: 3. Área de Habilidades (Saber Hacer) | G44: Tiempo Aproximado | H44: 45
G45: Tiene que estar en un rango de 30 a 50 minutos
A46: Actividad 1 (Obligatoria)
A47: Competencia que predomina en la actividad | B47: Define los sistemas numéricos posicionales (binario, octal y decimal) y los componentes básicos de la electrónica digital (puertas lógicas, transistores, LEDs) ofreciendo explicaciones sobre su función y relación en la representación de la información en dispositivos digitales con precisión
A48: Tipo de Actividad | B48: Analisis
A49: Ponderación | B49: 0
A50: Tiempo Aproximado | B50: 35
...

Sheet S.5
B2: Diseño de la Sesión de Laboratorio
B4: Curso | C4: ='Diseño'!C4 -> 964 - Organización Computacional
B5: Semana | C5: 5
B6: Tiempo | C6: 100
B7: Ponderación | C7: 1
B8: Validación de Tiempo | C8: =IF(H44<=0, "❌ ERROR: La Actividad 1 debe tener un tiempo mayor a 0.", IF(H21>60, "❌ ERROR: El 'Área de Conocimiento' no puede exceder los 60 min.", IF((H10+H21+H44)<100, "❌ ERROR: El tiempo total debe ser de al menos 100 min.", "✅ VALIDACIÓN CORRECTA"))) -> ✅ VALIDACIÓN CORRECTA
A10: 1. Área Actitudinal (Saber Ser) | G10: Tiempo Aproximado | H10: 5
G11: Tiene que estar en un rango de 3 a 5 minutos
A12: Nombre del Valor | B12: Pensamiento crítico
A13: Tiempo Aproximado | B13: 5
A14: Descripcion
A15: El pensamiento crítico permite al estudiante analizar el funcionamiento de los circuitos combinacionales de manera objetiva, cuestionando resultados y validando el diseño de sumadores, restadores y multiplicadores mediante herramientas de simulación digital. Fomenta la precisión y la honestidad al momento de interpretar los resultados obtenidos.
A17: Como se relaciona con los conocimientos de la sesion y se aplicaria
A18: Se aplica en la evaluación de los bloques combinacionales estudiados (sumador, restador, multiplicador y circuitos de control), ya que el estudiante debe comparar los resultados de la simulación con el diseño teórico, identificar posibles errores y proponer mejoras fundamentadas en un análisis lógico.
A21: 2. Área Conocimiento (Saber) | G21: Tiempo Aproximado | H21: 50
G22: No puede exceder los 60 minutos
A23: Competencia a desarrollar | B23: Diseña Circuitos digitales combinacionales para operaciones aritméticas y lógicas mediante el uso de Proteus, Logisim y Arduino IDE para construir una Unidad Aritmética Lógica (ALU) funcional que ejecute suma, resta, multiplicación y potencias
A24: Competencia a desarrollar
A26: 2.1 Contenido
A27: No. | B27: Unidad | D27: Tema | F27: Sub Tema
A28: 1 | B28: =IFERROR(__xludf.DUMMYFUNCTION("FILTER('Diseño'!D:D,'Diseño'!H:H=$C$5)"),"Bloques Digitales y Lógica Secuencial") -> Bloques Digitales y Lógica Secuencial | D28: =IFERROR(__xludf.DUMMYFUNCTION("FILTER('Diseño'!E:E,'Diseño'!H:H=$C$5)"),"Bloques Combinacionales") -> Bloques Combinacionales | F28: =IFERROR(__xludf.DUMMYFUNCTION("FILTER('Diseño'!F:F,'Diseño'!H:H=$C$5)"),"Circuitos de Control") -> Circuitos de Control
A29: 2 | B29: =IFERROR(__xludf.DUMMYFUNCTION("""COMPUTED_VALUE"""),"Bloques Digitales y Lógica Secuencial") -> Bloques Digitales y Lógica Secuencial | D29: =IFERROR(__xludf.DUMMYFUNCTION("""COMPUTED_VALUE"""),"Bloques Combinacionales") -> Bloques Combinacionales | F29: =IFERROR(__xludf.DUMMYFUNCTION("""COMPUTED_VALUE"""),"Sumador") -> Sumador
A30: 3 | B30: =IFERROR(__xludf.DUMMYFUNCTION("""COMPUTED_VALUE"""),"Bloques Digitales y Lógica Secuencial") -> Bloques Digitales y Lógica Secuencial | D30: =IFERROR(__xludf.DUMMYFUNCTION("""COMPUTED_VALUE"""),"Bloques Combinacionales") -> Bloques Combinacionales | F30: =IFERROR(__xludf.DUMMYFUNCTION("""COMPUTED_VALUE"""),"Restador") -> Restador
A31: 4 | B31: =IFERROR(__xludf.DUMMYFUNCTION("""COMPUTED_VALUE"""),"Bloques Digitales y Lógica Secuencial") -> Bloques Digitales y Lógica Secuencial | D31: =IFERROR(__xludf.DUMMYFUNCTION("""COMPUTED_VALUE"""),"Bloques Combinacionales") -> Bloques Combinacionales | F31: =IFERROR(__xludf.DUMMYFUNCTION("""COMPUTED_VALUE"""),"Multiplicador") -> Multiplicador
A32: 5
A33: 6
A34: 7
A36: 2.2 Recursos Educativos
A38: Tipo de Recurso a utilizar | B38: Tipo | C38: Rango Aproximando | D38: Tiempo Aproximado
A39: Presentacion | B39: Obligatorio | D39: 35
A40: Video | B40: Obligatorio | C40: 3 a 6 minutos | D40: 5
A41: Lectura | B41: Optativo
A42: Ejercicio Demostrativo | B42: Obligatorio | D42: 10
A44: 3. Área de Habilidades (Saber Hacer) | G44: Tiempo Aproximado | H44: 45
G45: Tiene que estar en un rango de 30 a 50 minutos
A46: Actividad 1 (Obligatoria)
A47: Competencia que predomina en la actividad | B47: Diseña Circuitos digitales combinacionales para operaciones aritméticas y lógicas mediante el uso de Proteus, Logisim y Arduino IDE para construir una Unidad Aritmética Lógica (ALU) funcional que ejecute suma, resta, multiplicación y potencias
A48: Tipo de Actividad | B48: Analisis
A49: Ponderación | B49: 0
A50: Tiempo Aproximado | B50: 35
...

Sheet S.6
B2: Diseño de la Sesión de Laboratorio
B4: Curso | C4: ='Diseño'!C4 -> 964 - Organización Computacional
B5: Semana | C5: 6
B6: Tiempo | C6: =H10+H21+H44+H68 -> 110
B7: Ponderación | C7: =B49+B60 -> 0
B8: Validación de Tiempo | C8: =IF(H44<=0, "❌ ERROR: La Actividad 1 debe tener un tiempo mayor a 0.", IF(H21>60, "❌ ERROR: El 'Área de Conocimiento' no puede exceder los 60 min.", IF((H10+H21+H44)<100, "❌ ERROR: El tiempo total debe ser de al menos 100 min.", "✅ VALIDACIÓN CORRECTA"))) -> ✅ VALIDACIÓN CORRECTA
A10: 1. Área Actitudinal (Saber Ser) | G10: Tiempo Aproximado | H10: 5
G11: Tiene que estar en un rango de 3 a 5 minutos
A12: Nombre del Valor | B12: Pensamiento logico y critico
A13: Tiempo Aproximado | B13: 5
A14: Descripcion
A15: Fomenta el pensamiento lógico y crítico en los estudiantes mediante el análisis y diseño de sistemas digitales secuenciales para la toma de decisiones
A17: Como se relaciona con los conocimientos de la sesion y se aplicaria
A18: Promover la capacidad de razonar sobre el comportamiento temporal de los circuitos y tomar decisiones fundamentadas en su funcionamiento.
A21: 2. Área Conocimiento (Saber) | G21: Tiempo Aproximado | H21: 60
G22: No puede exceder los 60 minutos
A23: Competencia a desarrollar | B23: Diseña Circuitos digitales combinacionales para operaciones aritméticas y lógicas mediante el uso de Proteus, Logisim y Arduino IDE para construir una Unidad Aritmética Lógica (ALU) funcional que ejecute suma, resta, multiplicación y potencias
A24: Competencia a desarrollar | B24: Implementa Circuitos digitales secuenciales utilizando flip-flops SR, D, JK y T mediante simulación en Proteus y montaje en protoboard aplicando técnicas de diseño lógico para crear y comprobar aplicaciones de almacenamiento, conteo y control de estados en sistemas electrónicos digitales
A26: 2.1 Contenido
A27: No. | B27: Unidad | D27: Tema | F27: Sub Tema
A28: 1 | B28: =IFERROR(__xludf.DUMMYFUNCTION("FILTER('Diseño'!D:D,'Diseño'!H:H=$C$5)"),"Bloques Digitales y Lógica Secuencial") -> Bloques Digitales y Lógica Secuencial | D28: =IFERROR(__xludf.DUMMYFUNCTION("FILTER('Diseño'!E:E,'Diseño'!H:H=$C$5)"),"Bloques Combinacionales") -> Bloques Combinacionales | F28: =IFERROR(__xludf.DUMMYFUNCTION("FILTER('Diseño'!F:F,'Diseño'!H:H=$C$5)"),"Display 7 segmentos (anodo y catodo comun)") -> Display 7 segmentos (anodo y catodo comun)
A29: 2 | B29: =IFERROR(__xludf.DUMMYFUNCTION("""COMPUTED_VALUE"""),"Bloques Digitales y Lógica Secuencial") -> Bloques Digitales y Lógica Secuencial | D29: =IFERROR(__xludf.DUMMYFUNCTION("""COMPUTED_VALUE"""),"Introduccion a la logica secuencial") -> Introduccion a la logica secuencial | F29: =IFERROR(__xludf.DUMMYFUNCTION("""COMPUTED_VALUE"""),"Circuitos Sincronicos") -> Circuitos Sincronicos
A30: 3 | B30: =IFERROR(__xludf.DUMMYFUNCTION("""COMPUTED_VALUE"""),"Bloques Digitales y Lógica Secuencial") -> Bloques Digitales y Lógica Secuencial | D30: =IFERROR(__xludf.DUMMYFUNCTION("""COMPUTED_VALUE"""),"Introduccion a la logica secuencial") -> Introduccion a la logica secuencial | F30: =IFERROR(__xludf.DUMMYFUNCTION("""COMPUTED_VALUE"""),"Circuitos Asincronicos") -> Circuitos Asincronicos
A31: 4 | B31: =IFERROR(__xludf.DUMMYFUNCTION("""COMPUTED_VALUE"""),"Bloques Digitales y Lógica Secuencial") -> Bloques Digitales y Lógica Secuencial | D31: =IFERROR(__xludf.DUMMYFUNCTION("""COMPUTED_VALUE"""),"Introduccion a la logica secuencial") -> Introduccion a la logica secuencial | F31: =IFERROR(__xludf.DUMMYFUNCTION("""COMPUTED_VALUE"""),"Latches") -> Latches
A32: 5
A33: 6
A34: 7
A36: 2.2 Recursos Educativos
A38: Tipo de Recurso a utilizar | B38: Tipo | C38: Rango Aproximando | D38: Tiempo Aproximado
A39: Presentacion | B39: Obligatorio | D39: 35
A40: Video | B40: Obligatorio | C40: 3 a 6 minutos | D40: 5
A41: Lectura | B41: Optativo
A42: Ejercicio Demostrativo | B42: Obligatorio | D42: 15
A44: 3. Área de Habilidades (Saber Hacer) | G44: Tiempo Aproximado | H44: 35
G45: Tiene que estar en un rango de 30 a 50 minutos
A46: Actividad 1 (Obligatoria)
A47: Competencia que predomina en la actividad | B47: Diseña Circuitos digitales combinacionales para operaciones aritméticas y lógicas mediante el uso de Proteus, Logisim y Arduino IDE para construir una Unidad Aritmética Lógica (ALU) funcional que ejecute suma, resta, multiplicación y potencias
A48: Tipo de Actividad | B48: actividades
A49: Ponderación | B49: 0
A50: Tiempo Aproximado | B50: 15
...

Sheet S.7
B2: Diseño de la Sesión de Laboratorio
B4: Curso | C4: ='Diseño'!C4 -> 964 - Organización Computacional
B5: Semana | C5: 7
B6: Tiempo | C6: =H10+H21+H44+H68 -> 110
B7: Ponderación | C7: =B49+B60 -> 0
B8: Validación de Tiempo | C8: =IF(H44<=0, "❌ ERROR: La Actividad 1 debe tener un tiempo mayor a 0.", IF(H21>60, "❌ ERROR: El 'Área de Conocimiento' no puede exceder los 60 min.", IF((H10+H21+H44)<100, "❌ ERROR: El tiempo total debe ser de al menos 100 min.", "✅ VALIDACIÓN CORRECTA"))) -> ✅ VALIDACIÓN CORRECTA
A10: 1. Área Actitudinal (Saber Ser) | G10: Tiempo Aproximado | H10: 10
G11: Tiene que estar en un rango de 3 a 5 minutos
A12: Nombre del Valor | B12: Responsabilidad y Precisión
A13: Tiempo Aproximado | B13: 5
A14: Descripcion
A15: Fomentar el compromiso y la exactitud en cada etapa del diseño, simulación y montaje de circuitos secuenciales, verificando que las conexiones y resultados sean correctos antes de su presentación.
A17: Como se relaciona con los conocimientos de la sesion y se aplicaria
A18: En la práctica de flip-flops SR, D, JK y T, la responsabilidad asegura que el estudiante siga las especificaciones del diseño y documente adecuadamente su trabajo, mientras que la precisión permite configurar correctamente las entradas y salidas para que los estados lógicos se comporten de acuerdo con la teoría de la lógica secuencial.
A21: 2. Área Conocimiento (Saber) | G21: Tiempo Aproximado | H21: 60
G22: No puede exceder los 60 minutos
A23: Competencia a desarrollar | B23: Implementa Circuitos digitales secuenciales utilizando flip-flops SR, D, JK y T mediante simulación en Proteus y montaje en protoboard aplicando técnicas de diseño lógico para crear y comprobar aplicaciones de almacenamiento, conteo y control de estados en sistemas electrónicos digitales
A24: Competencia a desarrollar
A26: 2.1 Contenido
A27: No. | B27: Unidad | D27: Tema | F27: Sub Tema
A28: 1 | B28: =IFERROR(__xludf.DUMMYFUNCTION("FILTER('Diseño'!D:D,'Diseño'!H:H=$C$5)"),"Bloques Digitales y Logica Secuencial") -> Bloques Digitales y Logica Secuencial | D28: =IFERROR(__xludf.DUMMYFUNCTION("FILTER('Diseño'!E:E,'Diseño'!H:H=$C$5)"),"Introduccion a la logica secuencial") -> Introduccion a la logica secuencial | F28: =IFERROR(__xludf.DUMMYFUNCTION("FILTER('Diseño'!F:F,'Diseño'!H:H=$C$5)"),"Flip-flop tipo SR") -> Flip-flop tipo SR
A29: 2 | B29: =IFERROR(__xludf.DUMMYFUNCTION("""COMPUTED_VALUE"""),"Bloques Digitales y Logica Secuencial") -> Bloques Digitales y Logica Secuencial | D29: =IFERROR(__xludf.DUMMYFUNCTION("""COMPUTED_VALUE"""),"Introduccion a la logica secuencial") -> Introduccion a la logica secuencial | F29: =IFERROR(__xludf.DUMMYFUNCTION("""COMPUTED_VALUE"""),"Flip-flop tipo D") -> Flip-flop tipo D
A30: 3 | B30: =IFERROR(__xludf.DUMMYFUNCTION("""COMPUTED_VALUE"""),"Bloques Digitales y Logica Secuencial") -> Bloques Digitales y Logica Secuencial | D30: =IFERROR(__xludf.DUMMYFUNCTION("""COMPUTED_VALUE"""),"Introduccion a la logica secuencial") -> Introduccion a la logica secuencial | F30: =IFERROR(__xludf.DUMMYFUNCTION("""COMPUTED_VALUE"""),"Flip-flop tipo JK") -> Flip-flop tipo JK
A31: 4 | B31: =IFERROR(__xludf.DUMMYFUNCTION("""COMPUTED_VALUE"""),"Bloques Digitales y Logica Secuencial") -> Bloques Digitales y Logica Secuencial | D31: =IFERROR(__xludf.DUMMYFUNCTION("""COMPUTED_VALUE"""),"Introduccion a la logica secuencial") -> Introduccion a la logica secuencial | F31: =IFERROR(__xludf.DUMMYFUNCTION("""COMPUTED_VALUE"""),"Flip-flop tipo T") -> Flip-flop tipo T
A32: 5 | B32: =IFERROR(__xludf.DUMMYFUNCTION("""COMPUTED_VALUE"""),"Bloques Digitales y Logica Secuencial") -> Bloques Digitales y Logica Secuencial | D32: =IFERROR(__xludf.DUMMYFUNCTION("""COMPUTED_VALUE"""),"Flip-Flops") -> Flip-Flops | F32: =IFERROR(__xludf.DUMMYFUNCTION("""COMPUTED_VALUE"""),"Aplicaciones de flip-flops en circuitos digitales") -> Aplicaciones de flip-flops en circuitos digitales
A33: 6
A34: 7
A36: 2.2 Recursos Educativos
A38: Tipo de Recurso a utilizar | B38: Tipo | C38: Rango Aproximando | D38: Tiempo Aproximado
A39: Presentacion | B39: Obligatorio | D39: 25
A40: Video | B40: Obligatorio | C40: 3 a 6 minutos | D40: 5
A41: Lectura | B41: Optativo | D41: 5
A42: Ejercicio Demostrativo | B42: Obligatorio | D42: 15
A44: 3. Área de Habilidades (Saber Hacer) | G44: Tiempo Aproximado | H44: 30
G45: Tiene que estar en un rango de 30 a 50 minutos
A46: Actividad 1 (Obligatoria)
A47: Competencia que predomina en la actividad | B47: Implementa Circuitos digitales secuenciales utilizando flip-flops SR, D, JK y T mediante simulación en Proteus y montaje en protoboard aplicando técnicas de diseño lógico para crear y comprobar aplicaciones de almacenamiento, conteo y control de estados en sistemas electrónicos digitales
A48: Tipo de Actividad | B48: actividades
A49: Ponderación | B49: 0
A50: Tiempo Aproximado | B50: 30
...

Sheet S.8
B2: Diseño de la Sesión de Laboratorio
B4: Curso | C4: ='Diseño'!C4 -> 964 - Organización Computacional
B5: Semana | C5: 8
B6: Tiempo | C6: =H10+H21+H44+H68 -> 100
B7: Ponderación | C7: =B49+B60 -> 0
B8: Validación de Tiempo | C8: =IF(H44<=0, "❌ ERROR: La Actividad 1 debe tener un tiempo mayor a 0.", IF(H21>60, "❌ ERROR: El 'Área de Conocimiento' no puede exceder los 60 min.", IF(C6<100, "❌ ERROR: El tiempo total debe ser de al menos 100 min.", "✅ VALIDACIÓN CORRECTA"))) -> ✅ VALIDACIÓN CORRECTA
A10: 1. Área Actitudinal (Saber Ser) | G10: Tiempo Aproximado | H10: =B13 -> 5
G11: Tiene que estar en un rango de 3 a 5 minutos
A12: Nombre del Valor | B12: Equidad
A13: Tiempo Aproximado | B13: 5
A14: Descripcion
A15: La equidad implica repartir de forma justa y equitativa las responsabilidades y actividades entre los integrantes del grupo, fomentando la colaboración y el respeto mutuo.
A17: Como se relaciona con los conocimientos de la sesion y se aplicaria
A18: En el desarrollo de proyectos de automatización con Arduino, es fundamental que todos los miembros del equipo participen de manera equitativa en las tareas de diseño, simulación y programación. Esto promueve un ambiente de aprendizaje inclusivo y colaborativo.
A21: 2. Área Conocimiento (Saber) | G21: Tiempo Aproximado | H21: =D39+D40+D41+D42 -> 50
G22: No puede exceder los 60 minutos
A23: Competencia a desarrollar | B23: Integra circuitos digitales y sistemas embebidos mediante el uso de bases numéricas, transistores, compuertas lógicas, bloques combinacionales y secuenciales, registros, memoria RAM, Arduino, actuadores, controladores y sensores para la resolución de problemas prácticos de automatización y control en contextos académicos y tecnológicos
A24: Competencia a desarrollar
A26: 2.1 Contenido
A27: No. | B27: Unidad | D27: Tema | F27: Sub Tema
A28: 1 | B28: =IFERROR(__xludf.DUMMYFUNCTION("FILTER('Diseño'!D:D,'Diseño'!H:H=$C$5)"),"Bloques Digitales y Logica Secuencial") -> Bloques Digitales y Logica Secuencial | D28: =IFERROR(__xludf.DUMMYFUNCTION("FILTER('Diseño'!E:E,'Diseño'!H:H=$C$5)"),"Contadores") -> Contadores | F28: =IFERROR(__xludf.DUMMYFUNCTION("FILTER('Diseño'!F:F,'Diseño'!H:H=$C$5)"),"Contadorres") -> Contadorres
A29: 2 | B29: =IFERROR(__xludf.DUMMYFUNCTION("""COMPUTED_VALUE"""),"Bloques Digitales y Logica Secuencial") -> Bloques Digitales y Logica Secuencial | D29: =IFERROR(__xludf.DUMMYFUNCTION("""COMPUTED_VALUE"""),"Contadores") -> Contadores | F29: =IFERROR(__xludf.DUMMYFUNCTION("""COMPUTED_VALUE"""),"Contadorres") -> Contadorres
A30: 3
A31: 4
A32: 5
A33: 6
A34: 7
A36: 2.2 Recursos Educativos
A38: Tipo de Recurso a utilizar | B38: Tipo | C38: Rango Aproximando | D38: Tiempo Aproximado
A39: Presentacion | B39: Obligatorio | D39: 35
A40: Video | B40: Obligatorio | C40: 3 a 6 minutos | D40: 5
A41: Lectura | B41: Optativo | D41: 0
A42: Ejercicio Demostrativo | B42: Obligatorio | D42: 10
A44: 3. Área de Habilidades (Saber Hacer) | G44: Tiempo Aproximado | H44: =B50+B61 -> 40
G45: Tiene que estar en un rango de 30 a 50 minutos
A46: Actividad 1 (Obligatoria)
A47: Competencia que predomina en la actividad | B47: Integra circuitos digitales y sistemas embebidos mediante el uso de bases numéricas, transistores, compuertas lógicas, bloques combinacionales y secuenciales, registros, memoria RAM, Arduino, actuadores, controladores y sensores para la resolución de problemas prácticos de automatización y control en contextos académicos y tecnológicos
A48: Tipo de Actividad | B48: Analisis
A49: Ponderación | B49: 0
A50: Tiempo Aproximado | B50: 40
...

Sheet S.9
B2: Diseño de la Sesión de Laboratorio
B4: Curso | C4: ='Diseño'!C4 -> 964 - Organización Computacional
B5: Semana | C5: 9
B6: Tiempo | C6: =H10+H21+H44+H68 -> 110
B7: Ponderación | C7: =B49+B60 -> 3
B8: Validación de Tiempo | C8: =IF(H44<=0, "❌ ERROR: La Actividad 1 debe tener un tiempo mayor a 0.", IF(H21>60, "❌ ERROR: El 'Área de Conocimiento' no puede exceder los 60 min.", IF((H10+H21+H44)<100, "❌ ERROR: El tiempo total debe ser de al menos 100 min.", "✅ VALIDACIÓN CORRECTA"))) -> ✅ VALIDACIÓN CORRECTA
A10: 1. Área Actitudinal (Saber Ser) | G10: Tiempo Aproximado | H10: 5
G11: Tiene que estar en un rango de 3 a 5 minutos
A12: Nombre del Valor | B12: Responsabilidad, paciencia, disciplina
A13: Tiempo Aproximado | B13: 5
A14: Descripcion
A15: Desarrollar la capacidad de asumir compromisos con el aprendizaje y manejo adecuado de componentes electrónicos, mantener perseverancia ante la complejidad de los sistemas de almacenamiento y transferencia de datos, y establecer métodos organizados para el análisis y implementación de registros y memorias.
A17: Como se relaciona con los conocimientos de la sesion y se aplicaria
A18: La responsabilidad, paciencia y disciplina se relacionan directamente con los conocimientos de registros y memoria RAM al requerir que los estudiantes asuman el compromiso de comprender correctamente el funcionamiento de los registros en paralelo y serie, mantengan paciencia durante el análisis de los procesos de transferencia de datos que pueden ser complejos, y desarrollen la disciplina necesaria para seguir metodologías estructuradas en el diseño de sistemas de almacenamiento.
A21: 2. Área Conocimiento (Saber) | G21: Tiempo Aproximado | H21: 50
G22: No puede exceder los 60 minutos
A23: Competencia a desarrollar | B23: Implementa soluciones de almacenamiento y conteo digital utilizando registros y contadores apoyándose en simuladores de circuitos digitales como Proteus para optimizar el manejo de datos y eventos secuenciales en sistemas electrónicos
A24: Competencia a desarrollar
A26: 2.1 Contenido
A27: No. | B27: Unidad | D27: Tema | F27: Sub Tema
A28: 1 | B28: Registros Digitales, Actuadores y Controladores Avanzados | D28: Registros digitales | F28: Registro en paralelo
A29: 2 | B29: Registros Digitales, Actuadores y Controladores Avanzados | D29: Registros digitales | F29: Registro en serie
A30: 3 | B30: Registros Digitales, Actuadores y Controladores Avanzados | D30: Registros digitales | F30: Registros en almacenamiento
A31: 4 | B31: Registros Digitales, Actuadores y Controladores Avanzados | D31: Registros digitales | F31: Transferencia de datos
A32: 5 | B32: Registros Digitales, Actuadores y Controladores Avanzados | D32: Registros digitales | F32: Memoria RAM
A33: 6
A34: 7
A36: 2.2 Recursos Educativos
A38: Tipo de Recurso a utilizar | B38: Tipo | C38: Rango Aproximando | D38: Tiempo Aproximado
A39: Presentacion | B39: Obligatorio
A40: Video | B40: Obligatorio | C40: 3 a 6 minutos
A41: Lectura | B41: Optativo
A42: Ejercicio Demostrativo | B42: Obligatorio
A44: 3. Área de Habilidades (Saber Hacer) | G44: Tiempo Aproximado | H44: 45
G45: Tiene que estar en un rango de 30 a 50 minutos
A46: Actividad 1 (Obligatoria)
A47: Competencia que predomina en la actividad | B47: Implementa soluciones de almacenamiento y conteo digital utilizando registros y contadores apoyándose en simuladores de circuitos digitales como Proteus para optimizar el manejo de datos y eventos secuenciales en sistemas electrónicos
A48: Tipo de Actividad | B48: Cuestionario
A49: Ponderación | B49: 3
A50: Tiempo Aproximado | B50: 15
...

Sheet S.10
B2: Diseño de la Sesión de Laboratorio
B4: Curso | C4: ='Diseño'!C4 -> 964 - Organización Computacional
B5: Semana | C5: 10
B6: Tiempo | C6: 100
B7: Ponderación | C7: =B49+B60 -> 0
B8: Validación de Tiempo | C8: =IF(H44<=0, "❌ ERROR: La Actividad 1 debe tener un tiempo mayor a 0.", IF(H21>60, "❌ ERROR: El 'Área de Conocimiento' no puede exceder los 60 min.", IF((H10+H21+H44)<100, "❌ ERROR: El tiempo total debe ser de al menos 100 min.", "✅ VALIDACIÓN CORRECTA"))) -> ✅ VALIDACIÓN CORRECTA
A10: 1. Área Actitudinal (Saber Ser) | G10: Tiempo Aproximado | H10: 5
G11: Tiene que estar en un rango de 3 a 5 minutos
A12: Nombre del Valor | B12: Organización, constancia
A13: Tiempo Aproximado | B13: 5
A14: Descripcion
A15: Utilizar la organización y constancia permite al estudiante planificar y estructurar el desarrollo de proyectos con Arduino, gestionando correctamente el código, los componentes y los protocolos de comunicación (Serial, I2C, SPI). Gracias a estos valores, se asegura un trabajo sistemático y continuo al implementar actuadores y verificar su funcionamiento, garantizando proyectos fiables y coherentes.
A17: Como se relaciona con los conocimientos de la sesion y se aplicaria
A18: La organización y constancia se relaciona con los conocimientos de la sesión al permitir al estudiante estructurar el código y los componentes de Arduino, así como planificar el uso de protocolos de comunicación y actuadores. Se aplica al desarrollar proyectos de manera sistemática, asegurando que las implementaciones funcionen correctamente y se puedan verificar de forma confiable.
A21: 2. Área Conocimiento (Saber) | G21: Tiempo Aproximado | H21: 50
G22: No puede exceder los 60 minutos
A23: Competencia a desarrollar | B23: Define los sistemas numéricos posicionales (binario, octal y decimal) y los componentes básicos de la electrónica digital (puertas lógicas, transistores, LEDs) ofreciendo explicaciones sobre su función y relación en la representación de la información en dispositivos digitales con precisión
A24: Competencia a desarrollar
A26: 2.1 Contenido
A27: No. | B27: Unidad | D27: Tema | F27: Sub Tema
A28: 1 | B28: =IFERROR(__xludf.DUMMYFUNCTION("FILTER('Diseño'!D:D,'Diseño'!H:H=$C$5)"),"Arduino") -> Arduino | D28: =IFERROR(__xludf.DUMMYFUNCTION("FILTER('Diseño'!E:E,'Diseño'!H:H=$C$5)"),"Introduccion a Arduino") -> Introduccion a Arduino | F28: =IFERROR(__xludf.DUMMYFUNCTION("FILTER('Diseño'!F:F,'Diseño'!H:H=$C$5)"),"Funcionamiento y partes de un Arduino ") -> Funcionamiento y partes de un Arduino
A29: 2 | B29: =IFERROR(__xludf.DUMMYFUNCTION("""COMPUTED_VALUE"""),"Arduino") -> Arduino | D29: =IFERROR(__xludf.DUMMYFUNCTION("""COMPUTED_VALUE"""),"Introduccion a Arduino") -> Introduccion a Arduino | F29: =IFERROR(__xludf.DUMMYFUNCTION("""COMPUTED_VALUE"""),"Codigo de Arduino y su implementación ") -> Codigo de Arduino y su implementación
A30: 3 | B30: =IFERROR(__xludf.DUMMYFUNCTION("""COMPUTED_VALUE"""),"Arduino") -> Arduino | D30: =IFERROR(__xludf.DUMMYFUNCTION("""COMPUTED_VALUE"""),"Introduccion a Arduino") -> Introduccion a Arduino | F30: =IFERROR(__xludf.DUMMYFUNCTION("""COMPUTED_VALUE"""),"Protocolos de Comunicación (Serial, I2C, SPI)") -> Protocolos de Comunicación (Serial, I2C, SPI)
A31: 4 | B31: =IFERROR(__xludf.DUMMYFUNCTION("""COMPUTED_VALUE"""),"Arduino") -> Arduino | D31: =IFERROR(__xludf.DUMMYFUNCTION("""COMPUTED_VALUE"""),"Introduccion a Arduino") -> Introduccion a Arduino | F31: =IFERROR(__xludf.DUMMYFUNCTION("""COMPUTED_VALUE"""),"Actuadores ") -> Actuadores
A32: 5
A33: 6
A34: 7
A36: 2.2 Recursos Educativos
A38: Tipo de Recurso a utilizar | B38: Tipo | C38: Rango Aproximando | D38: Tiempo Aproximado
A39: Presentacion | B39: Obligatorio | D39: 35
A40: Video | B40: Obligatorio | C40: 3 a 6 minutos | D40: 5
A41: Lectura | B41: Optativo
A42: Ejercicio Demostrativo | B42: Obligatorio | D42: 10
A44: 3. Área de Habilidades (Saber Hacer) | G44: Tiempo Aproximado | H44: 45
G45: Tiene que estar en un rango de 30 a 50 minutos
A46: Actividad 1 (Obligatoria)
A47: Competencia que predomina en la actividad | B47: Define los sistemas numéricos posicionales (binario, octal y decimal) y los componentes básicos de la electrónica digital (puertas lógicas, transistores, LEDs) ofreciendo explicaciones sobre su función y relación en la representación de la información en dispositivos digitales con precisión
