Workbook

Sheet Diseño
A2: =VALUE(LEFT(C4,FIND(" - ",C4)-1)) -> 781 | B2: Diseño de Contenido Curricular
B4: Curso | C4: 781 - Organización de Lenguajes y Compiladores 2
B5: Periodo al que aplica | C5: Primer Semestre 2026
B8: No. | C8: Competencia | D8: Nombre de la Unidad | E8: Tema | F8: Subtema | G8: Mes | H8: Semana
B9: 1 | C9: El estudiante comprende las fases de un compilador a través de diagramas de flujo y modelos teóricos con ejemplos de compilación real en lenguajes como C, Go o Java. | D9: 1 | E9: Fases de la compilación | F9: Motivaciones para estudiar compiladores | G9: Enero | H9: 1
B10: 2 | C10: El estudiante comprende las fases de un compilador a través de diagramas de flujo y modelos teóricos con ejemplos de compilación real en lenguajes como C, Go o Java. | D10: 1 | E10: Fases de la compilación | F10: Recomendaciones para el curso | G10: Enero | H10: 1
B11: 3 | C11: El estudiante evalúa el desempeño de cada fase del compilador a través de métricas de tiempo y uso de memoria para comparar implementaciones como GCC vs. Clang | D11: 1 | E11: Fases de la compilación | F11: ¿Qué es un compilador? | G11: Enero | H11: 1
B12: 4 | C12: El estudiante utiliza herramientas generadoras de lexers y parsers tales como Flex, Bison y ANTLR en proyectos de análisis léxico y sintáctico | D12: 1 | E12: Fases de la compilación | F12: Análisis Léxico | G12: Enero | H12: 1
B13: 5 | C13: El estudiante explica la eliminación de recursión por la izquierda con ejemplos paso a paso para preparar gramáticas para análisis sintáctico | D13: 1 | E13: Fases de la compilación | F13: Análisis Sintáctico | G13: Enero | H13: 1
B14: 6 | C14: El estudiante evalúa el desempeño de cada fase del compilador a través de métricas de tiempo y uso de memoria para comparar implementaciones como GCC vs. Clang | D14: 1 | E14: Fases de la compilación | F14: Análisis Semántico | G14: Enero | H14: 1
B15: 7 | C15: El estudiante comprende las fases de un compilador a través de diagramas de flujo y modelos teóricos con ejemplos de compilación real en lenguajes como C, Go o Java. | D15: 1 | E15: Fases de la compilación | F15: Compilar vs Interpretar vs Transpilar | G15: Enero | H15: 1
B16: 8 | C16: El estudiante comprende las fases de un compilador a través de diagramas de flujo y modelos teóricos con ejemplos de compilación real en lenguajes como C, Go o Java. | D16: 1 | E16: Interpretación de instruciones básicas | F16: Repaso de fases del compilador | G16: Enero | H16: 2
B17: 9 | C17: El estudiante utiliza herramientas generadoras de lexers y parsers tales como Flex, Bison y ANTLR en proyectos de análisis léxico y sintáctico | D17: 1 | E17: Interpretación de instruciones básicas | F17: Precedecia de operadores | G17: Enero | H17: 2
B18: 10 | C18: El estudiante utiliza herramientas generadoras de lexers y parsers tales como Flex, Bison y ANTLR en proyectos de análisis léxico y sintáctico | D18: 1 | E18: Interpretación de instruciones básicas | F18: Calculadora Básica | G18: Enero | H18: 2
B19: 11 | C19: El estudiante comprende las fases de un compilador a través de diagramas de flujo y modelos teóricos con ejemplos de compilación real en lenguajes como C, Go o Java. | D19: 1 | E19: Interpretación de instruciones básicas | F19: Acciones Semánticas | G19: Enero | H19: 2
B20: 12 | C20: El estudiante explica la eliminación de recursión por la izquierda con ejemplos paso a paso para preparar gramáticas para análisis sintáctico | D20: 1 | E20: Interpretación de instruciones básicas | F20: Tipos de analizadores sintácticos | G20: Enero | H20: 2
... B65: 57 | C65: El estudiante aplica técnicas de optimización de código como optimización local y global para reducir tamaño de código y mejorar rendimiento | D65: 4 | E65: Recolección de basura | F65: Memory Leaks | G65: Abril | H65: 11

Sheet Semana Diagnostico
B2: Diseño de Contenido Curricular
B4: Curso | C4: ='Diseño'!C4 -> 781 - Organización de Lenguajes y Compiladores 2
B5: Semana | C5: 1
B6: Tiempo | C6: =B15+B22+B29+B41+B47+C48 -> 100
A9: 1. Bienvenida y Presentación | G9: Tiempo Aproximado | H9: =B15 -> 15
G10: No puedes excederte mas de 15 minutos
A11: Nombre y Formacion Academica | B11: Estudiante de sistemas, cursando últimos semestres
A12: Experiencia docente y profecional | B12: Experiencia del auxiliar como docente (si aplica) y del área profesional | K12: Estos puntos son recomendaciones de los puntos a tratar durante tu presentacion, si no usaras estos eres libre de agregar mas filas para indicar que haras. En los recuadros de la derecha colocar breve resumen de lo que planeas decir. No debes ser muy especifico seran pequeñas anotaciones que te ayudaran a recordar lo que planeaste
A13: Rol del auxiliar dentro del curso (funciones, actividades y apoyo a los estudiantes). | B13: Impartir laboratorios, resolver dudas, calificar proyectos
A14: Expectativas sobre la dinámica del curso | B14: Participación activa en laboratorios
A15: Tiempo que emplearas | B15: 15
A18: 2. Evaluación de Conocimientos Previos | G18: Tiempo Aproximado | H18: =B22 -> 20
G19: No puedes excederte mas de 45 minutos
A20: Redactaras de 15 a 20 preguntas con sus respectivas respuestas , por lo que debes escoge los temas que evaluaras | B20: Preguntas en un kahoot sobre analisis léxico, sintáctico y árboles. | K20: En los recuadors de la derecha deberas colocar las preguntas que planeas realizar con sus respectivas respuestas. En el segundo recuadro deberas colocar un breve resumne de lo que tines planificado para la parte practica del curso previo al que estas impartiendo.
A21: Redactaras una parte practica | B21: Al construír un AST, ¿cuál es la ventaja principal de usar árboles frente a listas lineales de tokens?
A22: Tiempo que emplearas | B22: 20
A25: 3. Presentación de los Estudiantes | G25: Tiempo Aproximado | H25: =B29 -> 20
G26: No puedes excederte mas de 30 minutos
A27: Seleccion al Azar de 5 Estudiantes | B27: Se seleccionarán 5 estudiantes al azar para presentarse brevemente | K27: En el primer recuadro colocaras la metodollogia que adoptaras para la eleccion de los estudiantes. En el segundo recuadro colocaras la redaccion de las preguntas que comprendan los siguientes puntos respecto al estudiante: Nombre. Intereses y expectativas sobre el curso. Experiencia previa relacionada con el curso (si aplica). Un dato curioso sobre sí mismo. Consideras que la prueba de conociminetos previos esta acorde al conocimiento que se te brindo en su momento Que tan comodo se sintio con la prueba anterior.
A28: Preguntas que responderan los estudiantes afortunados | B28: Nombre Intereses o expectativas sobre el curso. Experiencia previa relacionada con el tema (si aplica). Un dato curioso sobre sí mismo.
A29: Tiempo que emplearas | B29: 20
A32: 4. Censo de Horarios de Calificación | G32: Tiempo Aproximado | H32: =B36 -> 5
A33: Deberas estar recordando que deben contestar el formulario asi mismo dejar el link fijado en la llamada | G33: Esta actividad quedara abierta hasta el fin de la clase. pero emplearas 5 min especificos para la actividad
A34: Link de google forms donde este el cuestionario | B34: Formulario para recopilar disponibilidad de horarios | K34: Esta actividad te ayudara a realizar un senso de posibles horarios de calificacion y que tus estudiantes esten enterados y puedan preveer los dias de calificacion y asi mismo el horario. Deberas colocar en los reacuadros de la derecha link de Google form libre para correos intitucionales, esto para garantizar una sola respuesta por estudiante. TAmbien deberas colocar los posibles horarios y dias que tentativamente tendrias disponibles. para colocarlos en el google form.
A35: Dias y posibles Horarios de calificacion | B35: Horarios y dias que esté disponible
A36: Tiempo que emplearas | B36: 5
A39: 4. Mostrar Programa del Curso | G39: Tiempo Aproximado | H39: =B41 -> 30
G40: No puedes excederte mas de 30 minutos
A41: Tiempo que emplearas | B41: 30
A44: 2. Evaluación de Conocimientos del Curso Actual | G44: Tiempo Aproximado | H44: =B47 -> 15
G45: No puedes excederte mas de 15 minutos
A46: Redactaras 20 preguntas con sus respectivas respuestas | B46: Preguntas sobre temas del curso: manejo de tabla de símbolos, tipos de datos, verificación semántica, código de tres direcciones
A47: Tiempo que emplearas | B47: 15

Sheet S.1
B2: Diseño de la Sesión de Laboratorio
B4: Curso | C4: ='Diseño'!C4 -> 781 - Organización de Lenguajes y Compiladores 2
B5: Semana | C5: 2
B6: Tiempo | C6: =H10+H21+H44+H68 -> 100
B7: Ponderación | C7: =B49+B60 -> 0
B8: Validación de Tiempo | C8: =IF(H44<=0, "❌ ERROR: La Actividad 1 debe tener un tiempo mayor a 0.", IF(H21>60, "❌ ERROR: El 'Área de Conocimiento' no puede exceder los 60 min.", IF((H10+H21+H44)<100, "❌ ERROR: El tiempo total debe ser de al menos 100 min.", "✅ VALIDACIÓN CORRECTA"))) -> ❌ ERROR: El tiempo total debe ser de al menos 100 min.
A10: 1. Área Actitudinal (Saber Ser) | G10: Tiempo Aproximado | H10: 5
G11: Tiene que estar en un rango de 3 a 5 minutos
A12: Nombre del Valor | B12: Curiosidad académica
A13: Tiempo Aproximado
A14: Descripcion
A15: Comprender las motivaciones y aplicaciones de los compiladores despierta interés en el diseño de lenguajes de programación y herramientas de desarrollo.
A17: Como se relaciona con los conocimientos de la sesion y se aplicaria
A18: Al conocer las fases de compilación y las diferencias entre compilar, interpretar y transpilar, se aprecia la complejidad y utilidad de estas herramientas en el desarrollo de software moderno.
A21: 2. Área Conocimiento (Saber) | G21: Tiempo Aproximado | H21: =D39+D40+D41+D42 -> 60
G22: No puede exceder los 60 minutos
A23: Competencia a desarrollar | B23: El estudiante comprende las fases de un compilador a través de diagramas de flujo y modelos teóricos con ejemplos de compilación real en lenguajes como C, Go o Java.
A24: Competencia a desarrollar | B24: El estudiante explica la eliminación de recursión por la izquierda con ejemplos paso a paso para preparar gramáticas para análisis sintáctico
A26: 2.1 Contenido
A27: No. | B27: Unidad | D27: Tema | F27: Sub Tema
A28: 1 | B28: =IFERROR(__xludf.DUMMYFUNCTION("FILTER('Diseño'!D:D,'Diseño'!H:H=$C$5)"),1.0) -> 1 | D28: Fases de la compilación | F28: Motivaciones para estudiar compiladores
A29: 2 | B29: =IFERROR(__xludf.DUMMYFUNCTION("""COMPUTED_VALUE"""),1.0) -> 1 | D29: Fases de la compilación | F29: Recomendaciones para el curso
A30: 3 | B30: =IFERROR(__xludf.DUMMYFUNCTION("""COMPUTED_VALUE"""),1.0) -> 1 | D30: Fases de la compilación | F30: ¿Qué es un compilador?
A31: 4 | B31: =IFERROR(__xludf.DUMMYFUNCTION("""COMPUTED_VALUE"""),1.0) -> 1 | D31: Fases de la compilación | F31: Análisis Léxico
A32: 5 | B32: =IFERROR(__xludf.DUMMYFUNCTION("""COMPUTED_VALUE"""),1.0) -> 1 | D32: Fases de la compilación | F32: Análisis Sintáctico
A33: 6 | B33: 1 | D33: Fases de la compilación | F33: Análisis Semántico
A34: 7 | B34: 1 | D34: Fases de la compilación | F34: Compilar vs Interpretar vs Transpilar
A36: 2.2 Recursos Educativos
A38: Tipo de Recurso a utilizar | B38: Tipo | C38: Rango Aproximando | D38: Tiempo Aproximado
A39: Presentacion | B39: Obligatorio | D39: 20
A40: Video | B40: Obligatorio | C40: 3 a 6 minutos | D40: 5
A41: Lectura | B41: Optativo
A42: Ejercicio Demostrativo | B42: Obligatorio | D42: 35
A44: 3. Área de Habilidades (Saber Hacer) | G44: Tiempo Aproximado | H44: =B50+B61 -> 25
G45: Tiene que estar en un rango de 30 a 50 minutos
A46: Actividad 1 (Obligatoria)
A47: Competencia que predomina en la actividad | B47: El estudiante explica la eliminación de recursión por la izquierda con ejemplos paso a paso para preparar gramáticas para análisis sintáctico
A48: Tipo de Actividad | B48: Ejercicio practico
A49: Ponderación | B49: 0
A50: Tiempo Aproximado | B50: 25
...

Sheet S.2
B2: Diseño de la Sesión de Laboratorio
B4: Curso | C4: ='Diseño'!C4 -> 781 - Organización de Lenguajes y Compiladores 2
B5: Semana | C5: 2
B6: Tiempo | C6: =H10+H21+H44+H68 -> 100
B7: Ponderación | C7: =B49+B60 -> 0
B8: Validación de Tiempo | C8: =IF(H44<=0, "❌ ERROR: La Actividad 1 debe tener un tiempo mayor a 0.", IF(H21>60, "❌ ERROR: El 'Área de Conocimiento' no puede exceder los 60 min.", IF((H10+H21+H44)<100, "❌ ERROR: El tiempo total debe ser de al menos 100 min.", "✅ VALIDACIÓN CORRECTA"))) -> ❌ ERROR: El tiempo total debe ser de al menos 100 min.
A10: 1. Área Actitudinal (Saber Ser) | G10: Tiempo Aproximado | H10: =B13 -> 5
G11: Tiene que estar en un rango de 3 a 5 minutos
A12: Nombre del Valor | B12: Precisión técnica
A13: Tiempo Aproximado | B13: 5
A14: Descripcion
A15: La precedencia de operadores y acciones semánticas requieren atención al detalle para evitar errores en la interpretación de expresiones matemáticas.
A17: Como se relaciona con los conocimientos de la sesion y se aplicaria
A18: Al implementar una calculadora básica, la correcta precedencia de operadores es fundamental para evaluar expresiones correctamente, aplicando las reglas matemáticas estándar.
A21: 2. Área Conocimiento (Saber) | G21: Tiempo Aproximado | H21: =D39+D40+D41+D42 -> 60
G22: No puede exceder los 60 minutos
A23: Competencia a desarrollar | B23: El estudiante utiliza herramientas generadoras de lexers y parsers tales como Flex, Bison y ANTLR en proyectos de análisis léxico y sintáctico
A24: Competencia a desarrollar
A26: 2.1 Contenido
A27: No. | B27: Unidad | D27: Tema | F27: Sub Tema
A28: 1 | B28: =IFERROR(__xludf.DUMMYFUNCTION("FILTER('Diseño'!D:D,'Diseño'!H:H=$C$5)"),1.0) -> 1 | D28: =IFERROR(__xludf.DUMMYFUNCTION("FILTER('Diseño'!E:E,'Diseño'!H:H=$C$5)"),"Interpretación de instruciones básicas") -> Interpretación de instruciones básicas | F28: =IFERROR(__xludf.DUMMYFUNCTION("FILTER('Diseño'!F:F,'Diseño'!H:H=$C$5)"),"Repaso de fases del compilador") -> Repaso de fases del compilador
A29: 2 | B29: =IFERROR(__xludf.DUMMYFUNCTION("""COMPUTED_VALUE"""),1.0) -> 1 | D29: =IFERROR(__xludf.DUMMYFUNCTION("""COMPUTED_VALUE"""),"Interpretación de instruciones básicas") -> Interpretación de instruciones básicas | F29: =IFERROR(__xludf.DUMMYFUNCTION("""COMPUTED_VALUE"""),"Precedecia de operadores") -> Precedecia de operadores
A30: 3 | B30: =IFERROR(__xludf.DUMMYFUNCTION("""COMPUTED_VALUE"""),1.0) -> 1 | D30: =IFERROR(__xludf.DUMMYFUNCTION("""COMPUTED_VALUE"""),"Interpretación de instruciones básicas") -> Interpretación de instruciones básicas | F30: =IFERROR(__xludf.DUMMYFUNCTION("""COMPUTED_VALUE"""),"Calculadora Básica") -> Calculadora Básica
A31: 4 | B31: =IFERROR(__xludf.DUMMYFUNCTION("""COMPUTED_VALUE"""),1.0) -> 1 | D31: =IFERROR(__xludf.DUMMYFUNCTION("""COMPUTED_VALUE"""),"Interpretación de instruciones básicas") -> Interpretación de instruciones básicas | F31: =IFERROR(__xludf.DUMMYFUNCTION("""COMPUTED_VALUE"""),"Acciones Semánticas") -> Acciones Semánticas
A32: 5 | B32: =IFERROR(__xludf.DUMMYFUNCTION("""COMPUTED_VALUE"""),1.0) -> 1 | D32: =IFERROR(__xludf.DUMMYFUNCTION("""COMPUTED_VALUE"""),"Interpretación de instruciones básicas") -> Interpretación de instruciones básicas | F32: =IFERROR(__xludf.DUMMYFUNCTION("""COMPUTED_VALUE"""),"Tipos de analizadores sintácticos") -> Tipos de analizadores sintácticos
A33: 6
A34: 7
A36: 2.2 Recursos Educativos
A38: Tipo de Recurso a utilizar | B38: Tipo | C38: Rango Aproximando | D38: Tiempo Aproximado
A39: Presentacion | B39: Obligatorio | D39: 20
A40: Video | B40: Obligatorio | C40: 3 a 6 minutos | D40: 5
A41: Lectura | B41: Optativo
A42: Ejercicio Demostrativo | B42: Obligatorio | D42: 35
A44: 3. Área de Habilidades (Saber Hacer) | G44: Tiempo Aproximado | H44: =B50+B61 -> 25
G45: Tiene que estar en un rango de 30 a 50 minutos
A46: Actividad 1 (Obligatoria)
A47: Competencia que predomina en la actividad | B47: El estudiante explica la eliminación de recursión por la izquierda con ejemplos paso a paso para preparar gramáticas para análisis sintáctico
A48: Tipo de Actividad | B48: Ejercicio practico
A49: Ponderación | B49: 0
A50: Tiempo Aproximado | B50: 25
...

Sheet S.3
B2: Diseño de la Sesión de Laboratorio
B4: Curso | C4: ='Diseño'!C4 -> 781 - Organización de Lenguajes y Compiladores 2
B5: Semana | C5: 3
B6: Tiempo | C6: =H10+H21+H44+H68 -> 100
B7: Ponderación | C7: =B49+B60 -> 0
B8: Validación de Tiempo | C8: =IF(H44<=0, "❌ ERROR: La Actividad 1 debe tener un tiempo mayor a 0.", IF(H21>60, "❌ ERROR: El 'Área de Conocimiento' no puede exceder los 60 min.", IF((H10+H21+H44)<100, "❌ ERROR: El tiempo total debe ser de al menos 100 min.", "✅ VALIDACIÓN CORRECTA"))) -> ❌ ERROR: El tiempo total debe ser de al menos 100 min.
A10: 1. Área Actitudinal (Saber Ser) | G10: Tiempo Aproximado | H10: =B13 -> 5
G11: Tiene que estar en un rango de 3 a 5 minutos
A12: Nombre del Valor | B12: Organización y estructura
A13: Tiempo Aproximado | B13: 5
A14: Descripcion
A15: El manejo de entornos y tabla de símbolos requiere una organización sistemática para gestionar correctamente el alcance de variables y sus valores.
A17: Como se relaciona con los conocimientos de la sesion y se aplicaria
A18: Al implementar entornos anidados con el patrón Visitor y tabla de símbolos, se mantiene un código estructurado que facilita el rastreo de declaraciones y asignaciones en diferentes scopes.
A21: 2. Área Conocimiento (Saber) | G21: Tiempo Aproximado | H21: =D39+D40+D41+D42 -> 60
G22: No puede exceder los 60 minutos
A23: Competencia a desarrollar | B23: El estudiante comprende las fases de un compilador a través de diagramas de flujo y modelos teóricos con ejemplos de compilación real en lenguajes como C, Go o Java.
A24: Competencia a desarrollar
A26: 2.1 Contenido
A27: No. | B27: Unidad | D27: Tema | F27: Sub Tema
A28: 1 | B28: =IFERROR(__xludf.DUMMYFUNCTION("FILTER('Diseño'!D:D,'Diseño'!H:H=$C$5)"),1.0) -> 1 | D28: =IFERROR(__xludf.DUMMYFUNCTION("FILTER('Diseño'!E:E,'Diseño'!H:H=$C$5)"),"Manejo de entornos dentro del intérprete") -> Manejo de entornos dentro del intérprete | F28: =IFERROR(__xludf.DUMMYFUNCTION("FILTER('Diseño'!F:F,'Diseño'!H:H=$C$5)"),"Patron Visitor") -> Patron Visitor
A29: 2 | B29: =IFERROR(__xludf.DUMMYFUNCTION("""COMPUTED_VALUE"""),1.0) -> 1 | D29: =IFERROR(__xludf.DUMMYFUNCTION("""COMPUTED_VALUE"""),"Manejo de entornos dentro del intérprete") -> Manejo de entornos dentro del intérprete | F29: =IFERROR(__xludf.DUMMYFUNCTION("""COMPUTED_VALUE"""),"Tabla de simbolos ") -> Tabla de simbolos
A30: 3 | B30: =IFERROR(__xludf.DUMMYFUNCTION("""COMPUTED_VALUE"""),1.0) -> 1 | D30: =IFERROR(__xludf.DUMMYFUNCTION("""COMPUTED_VALUE"""),"Manejo de entornos dentro del intérprete") -> Manejo de entornos dentro del intérprete | F30: =IFERROR(__xludf.DUMMYFUNCTION("""COMPUTED_VALUE"""),"Parent Pointer Tree") -> Parent Pointer Tree
A31: 4 | B31: =IFERROR(__xludf.DUMMYFUNCTION("""COMPUTED_VALUE"""),1.0) -> 1 | D31: =IFERROR(__xludf.DUMMYFUNCTION("""COMPUTED_VALUE"""),"Manejo de entornos dentro del intérprete") -> Manejo de entornos dentro del intérprete | F31: =IFERROR(__xludf.DUMMYFUNCTION("""COMPUTED_VALUE"""),"Declaraciones") -> Declaraciones
A32: 5 | B32: =IFERROR(__xludf.DUMMYFUNCTION("""COMPUTED_VALUE"""),1.0) -> 1 | D32: =IFERROR(__xludf.DUMMYFUNCTION("""COMPUTED_VALUE"""),"Manejo de entornos dentro del intérprete") -> Manejo de entornos dentro del intérprete | F32: =IFERROR(__xludf.DUMMYFUNCTION("""COMPUTED_VALUE"""),"Asignaciones") -> Asignaciones
A33: 6
A34: 7
A36: 2.2 Recursos Educativos
A38: Tipo de Recurso a utilizar | B38: Tipo | C38: Rango Aproximando | D38: Tiempo Aproximado
A39: Presentacion | B39: Obligatorio | D39: 20
A40: Video | B40: Obligatorio | C40: 3 a 6 minutos | D40: 5
A41: Lectura | B41: Optativo
A42: Ejercicio Demostrativo | B42: Obligatorio | D42: 35
A44: 3. Área de Habilidades (Saber Hacer) | G44: Tiempo Aproximado | H44: =B50+B61 -> 25
G45: Tiene que estar en un rango de 30 a 50 minutos
A46: Actividad 1 (Obligatoria)
A47: Competencia que predomina en la actividad | B47: El estudiante comprende las fases de un compilador a través de diagramas de flujo y modelos teóricos con ejemplos de compilación real en lenguajes como C, Go o Java.
A48: Tipo de Actividad | B48: Ejercicio practico
A49: Ponderación | B49: 0
A50: Tiempo Aproximado | B50: 25
...

Sheet S.4
B2: Diseño de la Sesión de Laboratorio
B4: Curso | C4: ='Diseño'!C4 -> 781 - Organización de Lenguajes y Compiladores 2
B5: Semana | C5: 4
B6: Tiempo | C6: =H10+H21+H44+H68 -> 100
B7: Ponderación | C7: =B49+B60 -> 0
B8: Validación de Tiempo | C8: =IF(H44<=0, "❌ ERROR: La Actividad 1 debe tener un tiempo mayor a 0.", IF(H21>60, "❌ ERROR: El 'Área de Conocimiento' no puede exceder los 60 min.", IF((H10+H21+H44)<100, "❌ ERROR: El tiempo total debe ser de al menos 100 min.", "✅ VALIDACIÓN CORRECTA"))) -> ❌ ERROR: El tiempo total debe ser de al menos 100 min.
A10: 1. Área Actitudinal (Saber Ser) | G10: Tiempo Aproximado | H10: 3
G11: Tiene que estar en un rango de 3 a 5 minutos
A12: Nombre del Valor | B12: Responsabilidad computacional
A13: Tiempo Aproximado | B13: 3
A14: Descripcion
A15: Entender el poder de un lenguaje implica usarlo de forma ética y consciente.
A17: Como se relaciona con los conocimientos de la sesion y se aplicaria
A18: Al saber más sobre lo que pasa detras de un lenguaje puede hacer que se intente "romper" programar.
A21: 2. Área Conocimiento (Saber) | G21: Tiempo Aproximado | H21: 45
G22: No puede exceder los 60 minutos
A23: Competencia a desarrollar | B23: El estudiante comprende las fases de un compilador a través de diagramas de flujo y modelos teóricos con ejemplos de compilación real en lenguajes como C, Go o Java.
A24: Competencia a desarrollar | B24: El estudiante utiliza herramientas generadoras de lexers y parsers tales como Flex, Bison y ANTLR en proyectos de análisis léxico y sintáctico
A26: 2.1 Contenido
A27: No. | B27: Unidad | D27: Tema | F27: Sub Tema
A28: 1 | B28: =IFERROR(__xludf.DUMMYFUNCTION("FILTER('Diseño'!D:D,'Diseño'!H:H=$C$5)"),1.0) -> 1 | D28: =IFERROR(__xludf.DUMMYFUNCTION("FILTER('Diseño'!E:E,'Diseño'!H:H=$C$5)"),"Estructuras cíclicas y de control de flujo") -> Estructuras cíclicas y de control de flujo | F28: =IFERROR(__xludf.DUMMYFUNCTION("FILTER('Diseño'!F:F,'Diseño'!H:H=$C$5)"),"Lenguajes Turing Completos") -> Lenguajes Turing Completos
A29: 2 | B29: =IFERROR(__xludf.DUMMYFUNCTION("""COMPUTED_VALUE"""),1.0) -> 1 | D29: =IFERROR(__xludf.DUMMYFUNCTION("""COMPUTED_VALUE"""),"Estructuras cíclicas y de control de flujo") -> Estructuras cíclicas y de control de flujo | F29: =IFERROR(__xludf.DUMMYFUNCTION("""COMPUTED_VALUE"""),"Estructuras de control") -> Estructuras de control
A30: 3 | B30: =IFERROR(__xludf.DUMMYFUNCTION("""COMPUTED_VALUE"""),1.0) -> 1 | D30: =IFERROR(__xludf.DUMMYFUNCTION("""COMPUTED_VALUE"""),"Estructuras cíclicas y de control de flujo") -> Estructuras cíclicas y de control de flujo | F30: =IFERROR(__xludf.DUMMYFUNCTION("""COMPUTED_VALUE"""),"Ciclos") -> Ciclos
A31: 4 | B31: =IFERROR(__xludf.DUMMYFUNCTION("""COMPUTED_VALUE"""),1.0) -> 1 | D31: =IFERROR(__xludf.DUMMYFUNCTION("""COMPUTED_VALUE"""),"Estructuras cíclicas y de control de flujo") -> Estructuras cíclicas y de control de flujo | F31: =IFERROR(__xludf.DUMMYFUNCTION("""COMPUTED_VALUE"""),"Sentencias de transferencia") -> Sentencias de transferencia
A32: 5
A33: 6
A34: 7
A36: 2.2 Recursos Educativos
A38: Tipo de Recurso a utilizar | B38: Tipo | C38: Rango Aproximando | D38: Tiempo Aproximado
A39: Presentacion | B39: Obligatorio
A40: Video | B40: Obligatorio | C40: 3 a 6 minutos
A41: Lectura | B41: Optativo
A42: Ejercicio Demostrativo | B42: Obligatorio
A44: 3. Área de Habilidades (Saber Hacer) | G44: Tiempo Aproximado | H44: 40
G45: Tiene que estar en un rango de 30 a 50 minutos
A46: Actividad 1 (Obligatoria)
A47: Competencia que predomina en la actividad | B47: El estudiante comprende las fases de un compilador a través de diagramas de flujo y modelos teóricos con ejemplos de compilación real en lenguajes como C, Go o Java.
A48: Tipo de Actividad | B48: otros
A49: Ponderación | B49: 0
A50: Tiempo Aproximado | B50: 40
...

Sheet S.5
B2: Diseño de la Sesión de Laboratorio
B4: Curso | C4: ='Diseño'!C4 -> 781 - Organización de Lenguajes y Compiladores 2
B5: Semana | C5: 5
B6: Tiempo | C6: =H10+H21+H44+H68 -> 100
B7: Ponderación | C7: =B49+B60 -> 0
B8: Validación de Tiempo | C8: =IF(H44<=0, "❌ ERROR: La Actividad 1 debe tener un tiempo mayor a 0.", IF(H21>60, "❌ ERROR: El 'Área de Conocimiento' no puede exceder los 60 min.", IF((H10+H21+H44)<100, "❌ ERROR: El tiempo total debe ser de al menos 100 min.", "✅ VALIDACIÓN CORRECTA"))) -> ❌ ERROR: El tiempo total debe ser de al menos 100 min.
A10: 1. Área Actitudinal (Saber Ser) | G10: Tiempo Aproximado | H10: 3
G11: Tiene que estar en un rango de 3 a 5 minutos
A12: Nombre del Valor | B12: Ética del alcance
A13: Tiempo Aproximado | B13: 3
A14: Descripcion
A15: Mantener el uso de variables dentro de su contexto lógico y justo.
A17: Como se relaciona con los conocimientos de la sesion y se aplicaria
A18: La verdad no hay valor que pueda relacionar a la sesión.
A21: 2. Área Conocimiento (Saber) | G21: Tiempo Aproximado | H21: 45
G22: No puede exceder los 60 minutos
A23: Competencia a desarrollar | B23: El estudiante evalúa el desempeño de cada fase del compilador a través de métricas de tiempo y uso de memoria para comparar implementaciones como GCC vs. Clang
A24: Competencia a desarrollar | B24: El estudiante utiliza herramientas generadoras de lexers y parsers tales como Flex, Bison y ANTLR en proyectos de análisis léxico y sintáctico
A26: 2.1 Contenido
A27: No. | B27: Unidad | D27: Tema | F27: Sub Tema
A28: 1 | B28: =IFERROR(__xludf.DUMMYFUNCTION("FILTER('Diseño'!D:D,'Diseño'!H:H=$C$5)"),2.0) -> 2 | D28: =IFERROR(__xludf.DUMMYFUNCTION("FILTER('Diseño'!E:E,'Diseño'!H:H=$C$5)"),"Funciones y cerraduras en un intérprete") -> Funciones y cerraduras en un intérprete | F28: =IFERROR(__xludf.DUMMYFUNCTION("FILTER('Diseño'!F:F,'Diseño'!H:H=$C$5)"),"Funciones embebidas") -> Funciones embebidas
A29: 2 | B29: =IFERROR(__xludf.DUMMYFUNCTION("""COMPUTED_VALUE"""),2.0) -> 2 | D29: =IFERROR(__xludf.DUMMYFUNCTION("""COMPUTED_VALUE"""),"Funciones y cerraduras en un intérprete") -> Funciones y cerraduras en un intérprete | F29: =IFERROR(__xludf.DUMMYFUNCTION("""COMPUTED_VALUE"""),"Funciones foráneas") -> Funciones foráneas
A30: 3 | B30: =IFERROR(__xludf.DUMMYFUNCTION("""COMPUTED_VALUE"""),2.0) -> 2 | D30: =IFERROR(__xludf.DUMMYFUNCTION("""COMPUTED_VALUE"""),"Funciones y cerraduras en un intérprete") -> Funciones y cerraduras en un intérprete | F30: =IFERROR(__xludf.DUMMYFUNCTION("""COMPUTED_VALUE"""),"Clousures") -> Clousures
A31: 4 | B31: =IFERROR(__xludf.DUMMYFUNCTION("""COMPUTED_VALUE"""),2.0) -> 2 | D31: =IFERROR(__xludf.DUMMYFUNCTION("""COMPUTED_VALUE"""),"Funciones y cerraduras en un intérprete") -> Funciones y cerraduras en un intérprete | F31: =IFERROR(__xludf.DUMMYFUNCTION("""COMPUTED_VALUE"""),"Resolución de variables") -> Resolución de variables
A32: 5 | B32: =IFERROR(__xludf.DUMMYFUNCTION("""COMPUTED_VALUE"""),2.0) -> 2 | D32: =IFERROR(__xludf.DUMMYFUNCTION("""COMPUTED_VALUE"""),"Funciones y cerraduras en un intérprete") -> Funciones y cerraduras en un intérprete | F32: =IFERROR(__xludf.DUMMYFUNCTION("""COMPUTED_VALUE"""),"Hoisting") -> Hoisting
A33: 6 | B33: =IFERROR(__xludf.DUMMYFUNCTION("""COMPUTED_VALUE"""),2.0) -> 2 | D33: =IFERROR(__xludf.DUMMYFUNCTION("""COMPUTED_VALUE"""),"Funciones y cerraduras en un intérprete") -> Funciones y cerraduras en un intérprete | F33: =IFERROR(__xludf.DUMMYFUNCTION("""COMPUTED_VALUE"""),"Call Stack") -> Call Stack
A34: 7
A36: 2.2 Recursos Educativos
A38: Tipo de Recurso a utilizar | B38: Tipo | C38: Rango Aproximando | D38: Tiempo Aproximado
A39: Presentacion | B39: Obligatorio
A40: Video | B40: Obligatorio | C40: 3 a 6 minutos
A41: Lectura | B41: Optativo
A42: Ejercicio Demostrativo | B42: Obligatorio
A44: 3. Área de Habilidades (Saber Hacer) | G44: Tiempo Aproximado | H44: 40
G45: Tiene que estar en un rango de 30 a 50 minutos
A46: Actividad 1 (Obligatoria)
A47: Competencia que predomina en la actividad | B47: El estudiante comprende las fases de un compilador a través de diagramas de flujo y modelos teóricos con ejemplos de compilación real en lenguajes como C, Go o Java.
A48: Tipo de Actividad | B48: otros
A49: Ponderación | B49: 0
A50: Tiempo Aproximado | B50: 40
...

Sheet S.6
B2: Diseño de la Sesión de Laboratorio
B4: Curso | C4: ='Diseño'!C4 -> 781 - Organización de Lenguajes y Compiladores 2
B5: Semana | C5: 6
B6: Tiempo | C6: =H10+H21+H44+H68 -> 100
B7: Ponderación | C7: =B49+B60 -> 0
B8: Validación de Tiempo | C8: =IF(H44<=0, "❌ ERROR: La Actividad 1 debe tener un tiempo mayor a 0.", IF(H21>60, "❌ ERROR: El 'Área de Conocimiento' no puede exceder los 60 min.", IF((H10+H21+H44)<100, "❌ ERROR: El tiempo total debe ser de al menos 100 min.", "✅ VALIDACIÓN CORRECTA"))) -> ❌ ERROR: El tiempo total debe ser de al menos 100 min.
A10: 1. Área Actitudinal (Saber Ser) | G10: Tiempo Aproximado | H10: 3
G11: Tiene que estar en un rango de 3 a 5 minutos
A12: Nombre del Valor | B12: Precisión
A13: Tiempo Aproximado | B13: 3
A14: Descripcion
A15: ya que al aplicar técnicas de optimización y análisis de código, se requiere atención a los detalles para lograr mejoras reales y evitar errores.
A17: Como se relaciona con los conocimientos de la sesion y se aplicaria
A18: La verdad no hay valor que pueda relacionar a la sesión.
A21: 2. Área Conocimiento (Saber) | G21: Tiempo Aproximado | H21: 45
G22: No puede exceder los 60 minutos
A23: Competencia a desarrollar | B23: El estudiante comprende las fases de un compilador a través de diagramas de flujo y modelos teóricos con ejemplos de compilación real en lenguajes como C, Go o Java.
A24: Competencia a desarrollar | B24: El estudiante utiliza herramientas generadoras de lexers y parsers tales como Flex, Bison y ANTLR en proyectos de análisis léxico y sintáctico
A26: 2.1 Contenido
A27: No. | B27: Unidad | D27: Tema | F27: Sub Tema
A28: 1 | B28: =IFERROR(__xludf.DUMMYFUNCTION("FILTER('Diseño'!D:D,'Diseño'!H:H=$C$5)"),2.0) -> 2 | D28: =IFERROR(__xludf.DUMMYFUNCTION("FILTER('Diseño'!E:E,'Diseño'!H:H=$C$5)"),"Programación orientada a objetos en un intérprete") -> Programación orientada a objetos en un intérprete | F28: =IFERROR(__xludf.DUMMYFUNCTION("FILTER('Diseño'!F:F,'Diseño'!H:H=$C$5)"),"Clases y Objetos") -> Clases y Objetos
A29: 2 | B29: =IFERROR(__xludf.DUMMYFUNCTION("""COMPUTED_VALUE"""),2.0) -> 2 | D29: =IFERROR(__xludf.DUMMYFUNCTION("""COMPUTED_VALUE"""),"Programación orientada a objetos en un intérprete") -> Programación orientada a objetos en un intérprete | F29: =IFERROR(__xludf.DUMMYFUNCTION("""COMPUTED_VALUE"""),"Prototipos") -> Prototipos
A30: 3 | B30: =IFERROR(__xludf.DUMMYFUNCTION("""COMPUTED_VALUE"""),2.0) -> 2 | D30: =IFERROR(__xludf.DUMMYFUNCTION("""COMPUTED_VALUE"""),"Programación orientada a objetos en un intérprete") -> Programación orientada a objetos en un intérprete | F30: =IFERROR(__xludf.DUMMYFUNCTION("""COMPUTED_VALUE"""),"Constructores") -> Constructores
A31: 4 | B31: =IFERROR(__xludf.DUMMYFUNCTION("""COMPUTED_VALUE"""),2.0) -> 2 | D31: =IFERROR(__xludf.DUMMYFUNCTION("""COMPUTED_VALUE"""),"Programación orientada a objetos en un intérprete") -> Programación orientada a objetos en un intérprete | F31: =IFERROR(__xludf.DUMMYFUNCTION("""COMPUTED_VALUE"""),"Sobrecarga de métodos") -> Sobrecarga de métodos
A32: 5
A33: 6
A34: 7
A36: 2.2 Recursos Educativos
A38: Tipo de Recurso a utilizar | B38: Tipo | C38: Rango Aproximando | D38: Tiempo Aproximado
A39: Presentacion | B39: Obligatorio
A40: Video | B40: Obligatorio | C40: 3 a 6 minutos
A41: Lectura | B41: Optativo
A42: Ejercicio Demostrativo | B42: Obligatorio
A44: 3. Área de Habilidades (Saber Hacer) | G44: Tiempo Aproximado | H44: 40
G45: Tiene que estar en un rango de 30 a 50 minutos
A46: Actividad 1 (Obligatoria)
A47: Competencia que predomina en la actividad | B47: El estudiante utiliza herramientas generadoras de lexers y parsers tales como Flex, Bison y ANTLR en proyectos de análisis léxico y sintáctico
A48: Tipo de Actividad | B48: otros
A49: Ponderación | B49: 0
A50: Tiempo Aproximado | B50: 40
...

Sheet S.7
B2: Diseño de la Sesión de Laboratorio
B4: Curso | C4: ='Diseño'!C4 -> 781 - Organización de Lenguajes y Compiladores 2
B5: Semana | C5: 7
B6: Tiempo | C6: =H10+H21+H44+H68 -> 100
B7: Ponderación | C7: =B49+B60 -> 0
B8: Validación de Tiempo | C8: =IF(H44<=0, "❌ ERROR: La Actividad 1 debe tener un tiempo mayor a 0.", IF(H21>60, "❌ ERROR: El 'Área de Conocimiento' no puede exceder los 60 min.", IF((H10+H21+H44)<100, "❌ ERROR: El tiempo total debe ser de al menos 100 min.", "✅ VALIDACIÓN CORRECTA"))) -> ❌ ERROR: El tiempo total debe ser de al menos 100 min.
A10: 1. Área Actitudinal (Saber Ser) | G10: Tiempo Aproximado | H10: 3
G11: Tiene que estar en un rango de 3 a 5 minutos
A12: Nombre del Valor | B12: Rigor
A13: Tiempo Aproximado | B13: 3
A14: Descripcion
A15: porque se trabaja con conceptos técnicos de bajo nivel, donde la precisión y estructura lógica son clave, especialmente en temas como ensamblador o representación en memoria.
A17: Como se relaciona con los conocimientos de la sesion y se aplicaria
A18: La verdad no hay valor que pueda relacionar a la sesión.
A21: 2. Área Conocimiento (Saber) | G21: Tiempo Aproximado | H21: 45
G22: No puede exceder los 60 minutos
A23: Competencia a desarrollar | B23: El estudiante utiliza herramientas generadoras de lexers y parsers tales como Flex, Bison y ANTLR en proyectos de análisis léxico y sintáctico
A24: Competencia a desarrollar | B24: El estudiante comprende las fases de un compilador a través de diagramas de flujo y modelos teóricos con ejemplos de compilación real en lenguajes como C, Go o Java.
A26: 2.1 Contenido
A27: No. | B27: Unidad | D27: Tema | F27: Sub Tema
A28: 1 | B28: =IFERROR(__xludf.DUMMYFUNCTION("FILTER('Diseño'!D:D,'Diseño'!H:H=$C$5)"),2.0) -> 2 | D28: =IFERROR(__xludf.DUMMYFUNCTION("FILTER('Diseño'!E:E,'Diseño'!H:H=$C$5)"),"Representaciones intermedias y generación de código") -> Representaciones intermedias y generación de código | F28: =IFERROR(__xludf.DUMMYFUNCTION("FILTER('Diseño'!F:F,'Diseño'!H:H=$C$5)"),"Código de 3 direcciones") -> Código de 3 direcciones
A29: 2 | B29: =IFERROR(__xludf.DUMMYFUNCTION("""COMPUTED_VALUE"""),2.0) -> 2 | D29: =IFERROR(__xludf.DUMMYFUNCTION("""COMPUTED_VALUE"""),"Representaciones intermedias y generación de código") -> Representaciones intermedias y generación de código | F29: =IFERROR(__xludf.DUMMYFUNCTION("""COMPUTED_VALUE"""),"Bytecode") -> Bytecode
A30: 3 | B30: =IFERROR(__xludf.DUMMYFUNCTION("""COMPUTED_VALUE"""),2.0) -> 2 | D30: =IFERROR(__xludf.DUMMYFUNCTION("""COMPUTED_VALUE"""),"Representaciones intermedias y generación de código") -> Representaciones intermedias y generación de código | F30: =IFERROR(__xludf.DUMMYFUNCTION("""COMPUTED_VALUE"""),"Assembly: RISC-V") -> Assembly: RISC-V
A31: 4 | B31: =IFERROR(__xludf.DUMMYFUNCTION("""COMPUTED_VALUE"""),2.0) -> 2 | D31: =IFERROR(__xludf.DUMMYFUNCTION("""COMPUTED_VALUE"""),"Tipos primitivos a bajo nivel") -> Tipos primitivos a bajo nivel | F31: =IFERROR(__xludf.DUMMYFUNCTION("""COMPUTED_VALUE"""),"Tipos enteros") -> Tipos enteros
A32: 5 | B32: =IFERROR(__xludf.DUMMYFUNCTION("""COMPUTED_VALUE"""),2.0) -> 2 | D32: =IFERROR(__xludf.DUMMYFUNCTION("""COMPUTED_VALUE"""),"Tipos primitivos a bajo nivel") -> Tipos primitivos a bajo nivel | F32: =IFERROR(__xludf.DUMMYFUNCTION("""COMPUTED_VALUE"""),"Representación de punto flotante") -> Representación de punto flotante
A33: 6 | B33: =IFERROR(__xludf.DUMMYFUNCTION("""COMPUTED_VALUE"""),2.0) -> 2 | D33: =IFERROR(__xludf.DUMMYFUNCTION("""COMPUTED_VALUE"""),"Tipos primitivos a bajo nivel") -> Tipos primitivos a bajo nivel | F33: =IFERROR(__xludf.DUMMYFUNCTION("""COMPUTED_VALUE"""),"Char") -> Char
A34: 7 | B34: =IFERROR(__xludf.DUMMYFUNCTION("""COMPUTED_VALUE"""),2.0) -> 2 | D34: =IFERROR(__xludf.DUMMYFUNCTION("""COMPUTED_VALUE"""),"Tipos primitivos a bajo nivel") -> Tipos primitivos a bajo nivel | F34: =IFERROR(__xludf.DUMMYFUNCTION("""COMPUTED_VALUE"""),"Strings") -> Strings
A36: 2.2 Recursos Educativos
A38: Tipo de Recurso a utilizar | B38: Tipo | C38: Rango Aproximando | D38: Tiempo Aproximado
A39: Presentacion | B39: Obligatorio
A40: Video | B40: Obligatorio | C40: 3 a 6 minutos
A41: Lectura | B41: Optativo
A42: Ejercicio Demostrativo | B42: Obligatorio
A44: 3. Área de Habilidades (Saber Hacer) | G44: Tiempo Aproximado | H44: 40
G45: Tiene que estar en un rango de 30 a 50 minutos
A46: Actividad 1 (Obligatoria)
A47: Competencia que predomina en la actividad | B47: El estudiante utiliza herramientas generadoras de lexers y parsers tales como Flex, Bison y ANTLR en proyectos de análisis léxico y sintáctico
A48: Tipo de Actividad | B48: otros
A49: Ponderación | B49: 0
A50: Tiempo Aproximado | B50: 0
...

Sheet S.8
B2: Diseño de la Sesión de Laboratorio
B4: Curso | C4: ='Diseño'!C4 -> 781 - Organización de Lenguajes y Compiladores 2
B5: Semana | C5: 8
B6: Tiempo | C6: =H10+H21+H44+H68 -> 100
B7: Ponderación | C7: =B49+B60 -> 0
B8: Validación de Tiempo | C8: =IF(H44<=0, "❌ ERROR: La Actividad 1 debe tener un tiempo mayor a 0.", IF(H21>60, "❌ ERROR: El 'Área de Conocimiento' no puede exceder los 60 min.", IF((H10+H21+H44+H68)<100, "❌ ERROR: El tiempo total debe ser de al menos 100 min.", "✅ VALIDACIÓN CORRECTA"))) -> ✅ VALIDACIÓN CORRECTA
A10: 1. Área Actitudinal (Saber Ser) | G10: Tiempo Aproximado | H10: =B13 -> 5
G11: Tiene que estar en un rango de 3 a 5 minutos
A12: Nombre del Valor | B12: Responsabilidad computacional
A13: Tiempo Aproximado | B13: 5
A14: Descripcion
A15: El uso correcto de las tablas de símbolos ayudan a la eficiencia del programa
A17: Como se relaciona con los conocimientos de la sesion y se aplicaria
A21: 2. Área Conocimiento (Saber) | G21: Tiempo Aproximado | H21: =D39+D40+D41+D42 -> 60
G22: No puede exceder los 60 minutos
A23: Competencia a desarrollar | B23: El estudiante genera código de bajo nivel y ensamblador a partir de plantillas de generación y asignación de registros considerando convenciones de llamada y optimización de registros
A24: Competencia a desarrollar
A26: 2.1 Contenido
A27: No. | B27: Unidad | D27: Tema | F27: Sub Tema
A28: 1 | B28: =IFERROR(__xludf.DUMMYFUNCTION("FILTER('Diseño'!D:D,'Diseño'!H:H=$C$5)"),3.0) -> 3 | D28: =IFERROR(__xludf.DUMMYFUNCTION("FILTER('Diseño'!E:E,'Diseño'!H:H=$C$5)"),"Entornos, variables globales y locales en un compilador") -> Entornos, variables globales y locales en un compilador | F28: =IFERROR(__xludf.DUMMYFUNCTION("FILTER('Diseño'!F:F,'Diseño'!H:H=$C$5)"),"Tabla de simbolos") -> Tabla de simbolos
A29: 2 | B29: =IFERROR(__xludf.DUMMYFUNCTION("""COMPUTED_VALUE"""),3.0) -> 3 | D29: =IFERROR(__xludf.DUMMYFUNCTION("""COMPUTED_VALUE"""),"Entornos, variables globales y locales en un compilador") -> Entornos, variables globales y locales en un compilador | F29: =IFERROR(__xludf.DUMMYFUNCTION("""COMPUTED_VALUE"""),"Manejo del stack para variables locales") -> Manejo del stack para variables locales
A30: 3 | B30: =IFERROR(__xludf.DUMMYFUNCTION("""COMPUTED_VALUE"""),3.0) -> 3 | D30: =IFERROR(__xludf.DUMMYFUNCTION("""COMPUTED_VALUE"""),"Entornos, variables globales y locales en un compilador") -> Entornos, variables globales y locales en un compilador | F30: =IFERROR(__xludf.DUMMYFUNCTION("""COMPUTED_VALUE"""),"Resolucion de variables") -> Resolucion de variables
A31: 4 | B31: =IFERROR(__xludf.DUMMYFUNCTION("""COMPUTED_VALUE"""),3.0) -> 3 | D31: =IFERROR(__xludf.DUMMYFUNCTION("""COMPUTED_VALUE"""),"Traducción de estructuras de control en un compilador") -> Traducción de estructuras de control en un compilador | F31: =IFERROR(__xludf.DUMMYFUNCTION("""COMPUTED_VALUE"""),"Etiquetas") -> Etiquetas
A32: 5 | B32: =IFERROR(__xludf.DUMMYFUNCTION("""COMPUTED_VALUE"""),3.0) -> 3 | D32: =IFERROR(__xludf.DUMMYFUNCTION("""COMPUTED_VALUE"""),"Traducción de estructuras de control en un compilador") -> Traducción de estructuras de control en un compilador | F32: =IFERROR(__xludf.DUMMYFUNCTION("""COMPUTED_VALUE"""),"Saltos condicionales") -> Saltos condicionales
A33: 6 | B33: =IFERROR(__xludf.DUMMYFUNCTION("""COMPUTED_VALUE"""),3.0) -> 3 | D33: =IFERROR(__xludf.DUMMYFUNCTION("""COMPUTED_VALUE"""),"Traducción de estructuras de control en un compilador") -> Traducción de estructuras de control en un compilador | F33: =IFERROR(__xludf.DUMMYFUNCTION("""COMPUTED_VALUE"""),"Saltos incondicionales") -> Saltos incondicionales
A34: 7
A36: 2.2 Recursos Educativos
A38: Tipo de Recurso a utilizar | B38: Tipo | C38: Rango Aproximando | D38: Tiempo Aproximado
A39: Presentacion | B39: Obligatorio | D39: 24
A40: Video | B40: Obligatorio | C40: 3 a 6 minutos | D40: 6
A41: Lectura | B41: Optativo
A42: Ejercicio Demostrativo | B42: Obligatorio | D42: 30
A44: 3. Área de Habilidades (Saber Hacer) | G44: Tiempo Aproximado | H44: =B50+B61 -> 25
G45: Tiene que estar en un rango de 30 a 50 minutos
A46: Actividad 1 (Obligatoria)
A47: Competencia que predomina en la actividad | B47: El estudiante genera código de bajo nivel y ensamblador a partir de plantillas de generación y asignación de registros considerando convenciones de llamada y optimización de registros
A48: Tipo de Actividad | B48: Ejercicio practico
A49: Ponderación | B49: 0
A50: Tiempo Aproximado | B50: 25
A51: Coloca el tiempo que usar en la actividad, un tiempo sugerido 30 minutos
...

Sheet S.9
B2: Diseño de la Sesión de Laboratorio
B4: Curso | C4: ='Diseño'!C4 -> 781 - Organización de Lenguajes y Compiladores 2
B5: Semana | C5: 9
B6: Tiempo | C6: =H10+H21+H44+H68 -> 100
B7: Ponderación | C7: =B49+B60 -> 0
B8: Validación de Tiempo | C8: =IF(H44<=0, "❌ ERROR: La Actividad 1 debe tener un tiempo mayor a 0.", IF(H21>60, "❌ ERROR: El 'Área de Conocimiento' no puede exceder los 60 min.", IF((H10+H21+H44+H68)<100, "❌ ERROR: El tiempo total debe ser de al menos 100 min.", "✅ VALIDACIÓN CORRECTA"))) -> ✅ VALIDACIÓN CORRECTA
A10: 1. Área Actitudinal (Saber Ser) | G10: Tiempo Aproximado | H10: =B13 -> 5
G11: Tiene que estar en un rango de 3 a 5 minutos
A12: Nombre del Valor | B12: Rigor técnico
A13: Tiempo Aproximado | B13: 5
A14: Descripcion
A15: La traducción de funciones e instrucciones ocupa la mayor parte de complejidad en un compilador por lo que mejora su uso
A17: Como se relaciona con los conocimientos de la sesion y se aplicaria
A21: 2. Área Conocimiento (Saber) | G21: Tiempo Aproximado | H21: =D39+D40+D41+D42 -> 60
G22: No puede exceder los 60 minutos
A23: Competencia a desarrollar | B23: El estudiante genera código de bajo nivel y ensamblador a partir de plantillas de generación y asignación de registros considerando convenciones de llamada y optimización de registros
A24: Competencia a desarrollar
A26: 2.1 Contenido
A27: No. | B27: Unidad | D27: Tema | F27: Sub Tema
A28: 1 | B28: =IFERROR(__xludf.DUMMYFUNCTION("FILTER('Diseño'!D:D,'Diseño'!H:H=$C$5)"),3.0) -> 3 | D28: =IFERROR(__xludf.DUMMYFUNCTION("FILTER('Diseño'!E:E,'Diseño'!H:H=$C$5)"),"Traducción de funciones de primera clase en un compilador") -> Traducción de funciones de primera clase en un compilador | F28: =IFERROR(__xludf.DUMMYFUNCTION("FILTER('Diseño'!F:F,'Diseño'!H:H=$C$5)"),"Paso de argumentos") -> Paso de argumentos
A29: 2 | B29: =IFERROR(__xludf.DUMMYFUNCTION("""COMPUTED_VALUE"""),3.0) -> 3 | D29: =IFERROR(__xludf.DUMMYFUNCTION("""COMPUTED_VALUE"""),"Traducción de funciones de primera clase en un compilador") -> Traducción de funciones de primera clase en un compilador | F29: =IFERROR(__xludf.DUMMYFUNCTION("""COMPUTED_VALUE"""),"Call Frames") -> Call Frames
A30: 3 | B30: =IFERROR(__xludf.DUMMYFUNCTION("""COMPUTED_VALUE"""),3.0) -> 3 | D30: =IFERROR(__xludf.DUMMYFUNCTION("""COMPUTED_VALUE"""),"Traducción de funciones de primera clase en un compilador") -> Traducción de funciones de primera clase en un compilador | F30: =IFERROR(__xludf.DUMMYFUNCTION("""COMPUTED_VALUE"""),"Valores de retorno") -> Valores de retorno
A31: 4 | B31: =IFERROR(__xludf.DUMMYFUNCTION("""COMPUTED_VALUE"""),3.0) -> 3 | D31: =IFERROR(__xludf.DUMMYFUNCTION("""COMPUTED_VALUE"""),"Programación orientada a objetos en un compilador") -> Programación orientada a objetos en un compilador | F31: =IFERROR(__xludf.DUMMYFUNCTION("""COMPUTED_VALUE"""),"Propiedades") -> Propiedades
A32: 5
A33: 6
A34: 7
A36: 2.2 Recursos Educativos
A38: Tipo de Recurso a utilizar | B38: Tipo | C38: Rango Aproximando | D38: Tiempo Aproximado
A39: Presentacion | B39: Obligatorio | D39: 24
A40: Video | B40: Obligatorio | C40: 3 a 6 minutos | D40: 6
A41: Lectura | B41: Optativo
A42: Ejercicio Demostrativo | B42: Obligatorio | D42: 30
A44: 3. Área de Habilidades (Saber Hacer) | G44: Tiempo Aproximado | H44: =B50+B61 -> 25
G45: Tiene que estar en un rango de 30 a 50 minutos
A46: Actividad 1 (Obligatoria)
A47: Competencia que predomina en la actividad | B47: El estudiante genera código de bajo nivel y ensamblador a partir de plantillas de generación y asignación de registros considerando convenciones de llamada y optimización de registros
A48: Tipo de Actividad | B48: Ejercicio practico
A49: Ponderación | B49: 0
A50: Tiempo Aproximado | B50: 25
A51: Coloca el tiempo que usar en la actividad, un tiempo sugerido 30 minutos
...

Sheet S.10
B2: Diseño de la Sesión de Laboratorio
B4: Curso | C4: ='Diseño'!C4 -> 781 - Organización de Lenguajes y Compiladores 2
B5: Semana | C5: 10
B6: Tiempo | C6: =H10+H21+H44+H68 -> 100
B7: Ponderación | C7: =B49+B60 -> 0
B8: Validación de Tiempo | C8: =IF(H44<=0, "❌ ERROR: La Actividad 1 debe tener un tiempo mayor a 0.", IF(H21>60, "❌ ERROR: El 'Área de Conocimiento' no puede exceder los 60 min.", IF((H10+H21+H44+H68)<100, "❌ ERROR: El tiempo total debe ser de al menos 100 min.", "✅ VALIDACIÓN CORRECTA"))) -> ✅ VALIDACIÓN CORRECTA
A10: 1. Área Actitudinal (Saber Ser) | G10: Tiempo Aproximado | H10: =B13 -> 5
G11: Tiene que estar en un rango de 3 a 5 minutos
A12: Nombre del Valor | B12: Responsabilidad computacional
A13: Tiempo Aproximado | B13: 5
A14: Descripcion
A15: El uso de la memoria permite que los programas generados por el compilador tengan un rendimiento adecuado
A17: Como se relaciona con los conocimientos de la sesion y se aplicaria
A21: 2. Área Conocimiento (Saber) | G21: Tiempo Aproximado | H21: =D39+D40+D41+D42 -> 60
G22: No puede exceder los 60 minutos
A23: Competencia a desarrollar
A24: Competencia a desarrollar
A26: 2.1 Contenido
A27: No. | B27: Unidad | D27: Tema | F27: Sub Tema
A28: 1 | B28: 3 | D28: Programación orientada a objetos en un compilador | F28: Métodos
A29: 2 | B29: 3 | D29: Programación orientada a objetos en un compilador | F29: Manejo de heap
A30: 3 | B30: 3 | D30: Optimización de código | F30: Eliminación de código muerto
A31: 4 | B31: 3 | D31: Optimización de código | F31: Propagación de constantes
A32: 5
A33: 6
A34: 7
A36: 2.2 Recursos Educativos
A38: Tipo de Recurso a utilizar | B38: Tipo | C38: Rango Aproximando | D38: Tiempo Aproximado
A39: Presentacion | B39: Obligatorio | D39: 24
A40: Video | B40: Obligatorio | C40: 3 a 6 minutos | D40: 6
A41: Lectura | B41: Optativo
A42: Ejercicio Demostrativo | B42: Obligatorio | D42: 30
A44: 3. Área de Habilidades (Saber Hacer) | G44: Tiempo Aproximado | H44: =B50+B61 -> 25
G45: Tiene que estar en un rango de 30 a 50 minutos
A46: Actividad 1 (Obligatoria)
A47: Competencia que predomina en la actividad | B47: El estudiante genera código de bajo nivel y ensamblador a partir de plantillas de generación y asignación de registros considerando convenciones de llamada y optimización de registros
A48: Tipo de Actividad | B48: Ejercicio practico
A49: Ponderación | B49: 0
A50: Tiempo Aproximado | B50: 25
A51: Coloca el tiempo que usar en la actividad, un tiempo sugerido 30 minutos
...

Sheet S.11
B2: Diseño de la Sesión de Laboratorio
B4: Curso | C4: ='Diseño'!C4 -> 781 - Organización de Lenguajes y Compiladores 2
B5: Semana | C5: 11
B6: Tiempo | C6: =H10+H21+H44+H68 -> 100
B7: Ponderación | C7: =B49+B60 -> 0
B8: Validación de Tiempo | C8: =IF(H44<=0, "❌ ERROR: La Actividad 1 debe tener un tiempo mayor a 0.", IF(H21>60, "❌ ERROR: El 'Área de Conocimiento' no puede exceder los 60 min.", IF((H10+H21+H44+H68)<100, "❌ ERROR: El tiempo total debe ser de al menos 100 min.", "✅ VALIDACIÓN CORRECTA"))) -> ✅ VALIDACIÓN CORRECTA
A10: 1. Área Actitudinal (Saber Ser) | G10: Tiempo Aproximado | H10: =B13 -> 5
G11: Tiene que estar en un rango de 3 a 5 minutos
A12: Nombre del Valor | B12: Precisión
A13: Tiempo Aproximado | B13: 5
A14: Descripcion
A15: La optimización es el paso que nos permite corregir aquello generado en el proceso de compilación lo que permite que el resultado final siempre sea óptimo
A17: Como se relaciona con los conocimientos de la sesion y se aplicaria
A21: 2. Área Conocimiento (Saber) | G21: Tiempo Aproximado | H21: =D39+D40+D41+D42 -> 60
G22: No puede exceder los 60 minutos
A23: Competencia a desarrollar | B23: El estudiante genera código de bajo nivel y ensamblador a partir de plantillas de generación y asignación de registros considerando convenciones de llamada y optimización de registros
A24: Competencia a desarrollar
A26: 2.1 Contenido
A27: No. | B27: Unidad | D27: Tema | F27: Sub Tema
A28: 1 | B28: =IFERROR(__xludf.DUMMYFUNCTION("FILTER('Diseño'!D:D,'Diseño'!H:H=$C$5)"),3.0) -> 3 | D28: =IFERROR(__xludf.DUMMYFUNCTION("FILTER('Diseño'!E:E,'Diseño'!H:H=$C$5)"),"Programación orientada a objetos en un compilador") -> Programación orientada a objetos en un compilador | F28: =IFERROR(__xludf.DUMMYFUNCTION("FILTER('Diseño'!F:F,'Diseño'!H:H=$C$5)"),"Métodos") -> Métodos
A29: 2 | B29: =IFERROR(__xludf.DUMMYFUNCTION("""COMPUTED_VALUE"""),3.0) -> 3 | D29: =IFERROR(__xludf.DUMMYFUNCTION("""COMPUTED_VALUE"""),"Programación orientada a objetos en un compilador") -> Programación orientada a objetos en un compilador | F29: =IFERROR(__xludf.DUMMYFUNCTION("""COMPUTED_VALUE"""),"Manejo del heap") -> Manejo del heap
A30: 3 | B30: =IFERROR(__xludf.DUMMYFUNCTION("""COMPUTED_VALUE"""),4.0) -> 4 | D30: =IFERROR(__xludf.DUMMYFUNCTION("""COMPUTED_VALUE"""),"Optimización de código") -> Optimización de código | F30: =IFERROR(__xludf.DUMMYFUNCTION("""COMPUTED_VALUE"""),"Eliminación de código muerto") -> Eliminación de código muerto
A31: 4 | B31: =IFERROR(__xludf.DUMMYFUNCTION("""COMPUTED_VALUE"""),4.0) -> 4 | D31: =IFERROR(__xludf.DUMMYFUNCTION("""COMPUTED_VALUE"""),"Optimización de código") -> Optimización de código | F31: =IFERROR(__xludf.DUMMYFUNCTION("""COMPUTED_VALUE"""),"Propagación de constantes") -> Propagación de constantes
A32: 5 | B32: =IFERROR(__xludf.DUMMYFUNCTION("""COMPUTED_VALUE"""),4.0) -> 4 | D32: =IFERROR(__xludf.DUMMYFUNCTION("""COMPUTED_VALUE"""),"Optimización de código") -> Optimización de código | F32: =IFERROR(__xludf.DUMMYFUNCTION("""COMPUTED_VALUE"""),"Optmización de bucles") -> Optmización de bucles
A33: 6 | B33: =IFERROR(__xludf.DUMMYFUNCTION("""COMPUTED_VALUE"""),4.0) -> 4 | D33: =IFERROR(__xludf.DUMMYFUNCTION("""COMPUTED_VALUE"""),"Optimización de código") -> Optimización de código | F33: =IFERROR(__xludf.DUMMYFUNCTION("""COMPUTED_VALUE"""),"Simplificación Algebraica") -> Simplificación Algebraica
A34: 7 | B34: =IFERROR(__xludf.DUMMYFUNCTION("""COMPUTED_VALUE"""),4.0) -> 4 | D34: =IFERROR(__xludf.DUMMYFUNCTION("""COMPUTED_VALUE"""),"Optimización de código") -> Optimización de código | F34: =IFERROR(__xludf.DUMMYFUNCTION("""COMPUTED_VALUE"""),"Optimización de saltos condicionales") -> Optimización de saltos condicionales
B35: =IFERROR(__xludf.DUMMYFUNCTION("""COMPUTED_VALUE"""),4.0) -> 4 | D35: =IFERROR(__xludf.DUMMYFUNCTION("""COMPUTED_VALUE"""),"Recolección de basura") -> Recolección de basura | F35: =IFERROR(__xludf.DUMMYFUNCTION("""COMPUTED_VALUE"""),"Garbage Collection") -> Garbage Collection
A36: 2.2 Recursos Educativos | B36: =IFERROR(__xludf.DUMMYFUNCTION("""COMPUTED_VALUE"""),4.0) -> 4 | D36: =IFERROR(__xludf.DUMMYFUNCTION("""COMPUTED_VALUE"""),"Recolección de basura") -> Recolección de basura | F36: =IFERROR(__xludf.DUMMYFUNCTION("""COMPUTED_VALUE"""),"Memory Leaks") -> Memory Leaks
A38: Tipo de Recurso a utilizar | B38: Tipo | C38: Rango Aproximando | D38: Tiempo Aproximado
A39: Presentacion | B39: Obligatorio | D39: 24
A40: Video | B40: Obligatorio | C40: 3 a 6 minutos | D40: 6
A41: Lectura | B41: Optativo
A42: Ejercicio Demostrativo | B42: Obligatorio | D42: 30
A44: 3. Área de Habilidades (Saber Hacer) | G44: Tiempo Aproximado | H44: =B50+B61 -> 25
G45: Tiene que estar en un rango de 30 a 50 minutos
A46: Actividad 1 (Obligatoria)
A47: Competencia que predomina en la actividad | B47: El estudiante genera código de bajo nivel y ensamblador a partir de plantillas de generación y asignación de registros considerando convenciones de llamada y optimización de registros
A48: Tipo de Actividad | B48: Ejercicio practico
A49: Ponderación | B49: 0
A50: Tiempo Aproximado | B50: 25
...

Sheet Proyectos
B2: Proyectos
B4: Curso | C4: ='Diseño'!C4 -> 781 - Organización de Lenguajes y Compiladores 2
B5: Tiempo | C5: =H9+H26+H43 -> 80
B6: Ponderación | C6: =F9+F26+F43 -> 90
B7: La sumatoria de los puntos de los proyectos debe superar el 70% del total de la nota, no puede ser un 100%
A9: 1. Primer Proyecto | E9: Ponderación | F9: 35 | G9: Horas para realizarlo | H9: 35
A10: Obligatorio
A11: Competencia a desarrollar | B11: El estudiante comprende las fases de un compilador a través de diagramas de flujo y modelos teóricos con ejemplos de compilación real en lenguajes como C, Go o Java.
A12: Competencia a desarrollar | B12: El estudiante evalúa el desempeño de cada fase del compilador a través de métricas de tiempo y uso de memoria para comparar implementaciones como GCC vs. Clang
A13: Competencia a desarrollar | B13: El estudiante utiliza herramientas generadoras de lexers y parsers tales como Flex, Bison y ANTLR en proyectos de análisis léxico y sintáctico
A14: Titulo | B14: Golampi Interpreter
A15: Qué tecnologías, lenguajes de programación, plataformas, hardware o software se utilizaran
A16: PHP LIME Linux
A19: Descripción de lo que se realizara
A20: Implementación de análisis lexico, semantico y sintactico para la elaboración de un intérprete.
A26: 2. Segundo Proyecto | E26: Ponderación | F26: 55 | G26: Horas para realizarlo | H26: 45
A27: Obligatorio
A28: Competencia a desarrollar | B28: El estudiante comprende las fases de un compilador a través de diagramas de flujo y modelos teóricos con ejemplos de compilación real en lenguajes como C, Go o Java.
A29: Competencia a desarrollar | B29: El estudiante aplica técnicas de optimización de código como optimización local y global para reducir tamaño de código y mejorar rendimiento
A30: Competencia a desarrollar | B30: El estudiante genera código de bajo nivel y ensamblador a partir de plantillas de generación y asignación de registros considerando convenciones de llamada y optimización de registros
A31: Titulo | B31: Golampi Compiler
A32: Qué tecnologías, lenguajes de programación, plataformas, hardware o software se utilizaran
A33: Lenguaje ensamblador. Qemu.
A36: Descripción de lo que se realizara
A37: Generacion de lenguaje a bajo nivel sobre las instrucciones realizadas en el primer proyecto, eliminando ciertas secciones del proyecto 1.
A43: 3. Tercer Proyecto | E43: Ponderación | G43: Horas para realizarlo
A44: Optativa
A45: Competencia a desarrollar
A46: Competencia a desarrollar
A47: Competencia a desarrollar
A48: Titulo
A49: Qué tecnologías, lenguajes de programación, plataformas, hardware o software se utilizaran
A53: Descripción de lo que se realizara

Sheet Practicas
B2: Practicas
B4: Curso | C4: ='Diseño'!C4 -> 781 - Organización de Lenguajes y Compiladores 2
B5: Tiempo | C5: =H9+H26+H43+H60+H77+H94+H111 -> 4
B6: Ponderación | C6: =F9+F26+F43+F60+F77+F94+F111 -> 4
B7: La sumatoria de los puntos de los practicas debe no debe super el 20%
A9: 1. Primera Practica | E9: Ponderación | F9: 1 | G9: Horas para realizarlo | H9: 1
A10: Obligatoria
A11: Competencia a desarrollar | B11: El estudiante comprende las fases de un compilador a través de diagramas de flujo y modelos teóricos con ejemplos de compilación real en lenguajes como C, Go o Java.
A12: Competencia a desarrollar | B12: El estudiante explica la eliminación de recursión por la izquierda con ejemplos paso a paso para preparar gramáticas para análisis sintáctico
A13: Competencia a desarrollar | B13: El estudiante utiliza herramientas generadoras de lexers y parsers tales como Flex, Bison y ANTLR en proyectos de análisis léxico y sintáctico
A14: Titulo
A15: Qué tecnologías, lenguajes de programación, plataformas, hardware o software se utilizaran
A19: Descripción de lo que se realizara
A20: Diseñar un analizador que reconozca literales de números binarios con parte entera y fraccionaria, usando dígitos {0,1} y un único punto .. El esquema de traducción debe calcular, su equivalente en base decimal
A26: 2. Segunda Practica | E26: Ponderación | F26: 1 | G26: Horas para realizarlo | H26: 1
A27: Optativa
A28: Competencia a desarrollar | B28: El estudiante comprende las fases de un compilador a través de diagramas de flujo y modelos teóricos con ejemplos de compilación real en lenguajes como C, Go o Java.
A29: Competencia a desarrollar
A30: Competencia a desarrollar
A31: Titulo
A32: Qué tecnologías, lenguajes de programación, plataformas, hardware o software se utilizaran
A36: Descripción de lo que se realizara
A37: Dado una entrada de declaraciones de variables con su tipo, propagar el tipo correspondiente a cada identificador usando atributos heredados, al final de la evaluación, una lista de pares (ID, Type) que representa todas las declaraciones del bloque.
A43: 3. Tercera Practica | E43: Ponderación | F43: 1 | G43: Horas para realizarlo | H43: 1
A44: Optativa
A45: Competencia a desarrollar | B45: El estudiante analiza representaciones intermedias de código mediante código de tres direcciones para identificar oportunidades de optimización
A46: Competencia a desarrollar
A47: Competencia a desarrollar
A48: Titulo
A49: Qué tecnologías, lenguajes de programación, plataformas, hardware o software se utilizaran
A53: Descripción de lo que se realizara
A54: Usando la herramienta, construir un traductor para un mini-lenguaje que soporte if/else y expresiones booleanas (&&, ||, !, relacionales). La salida debe ser C3D con corto-circuito.
A60: 4. Cuarta Practica | E60: Ponderación | F60: 1 | G60: Horas para realizarlo | H60: 1
A61: Optativa
A62: Competencia a desarrollar | B62: El estudiante analiza representaciones intermedias de código mediante código de tres direcciones para identificar oportunidades de optimización
A63: Competencia a desarrollar
A64: Competencia a desarrollar
A65: Titulo
A66: Qué tecnologías, lenguajes de programación, plataformas, hardware o software se utilizaran
A70: Descripción de lo que se realizara
...

Sheet Tareas
B2: Tareas
B4: Curso | C4: ='Diseño'!C4 -> 781 - Organización de Lenguajes y Compiladores 2
B5: Tiempo | C5: =H9+H26+H43+H60+H77+H94+H111 -> 33
B6: Ponderación | C6: =F9+F26+F43+F60+F77+F94+F111 -> 6
B7: La sumatoria de los puntos de los practicas debe no debe super el 20% de la nota
A9: 1. Primera Tarea | E9: Ponderación | F9: 1 | G9: Horas para realizarlo | H9: 3
A10: Obligatoria
A11: Competencia a desarrollar | B11: El estudiante comprende las fases de un compilador a través de diagramas de flujo y modelos teóricos con ejemplos de compilación real en lenguajes como C, Go o Java.
A12: Competencia a desarrollar | B12: El estudiante evalúa el desempeño de cada fase del compilador a través de métricas de tiempo y uso de memoria para comparar implementaciones como GCC vs. Clang
A13: Competencia a desarrollar | B13: El estudiante utiliza herramientas generadoras de lexers y parsers tales como Flex, Bison y ANTLR en proyectos de análisis léxico y sintáctico
A14: Titulo
A15: Qué tecnologías, lenguajes de programación, plataformas, hardware o software se utilizaran
A19: Descripción de lo que se realizara
