Workbook

Sheet Competencias_actuales
B1: Competencias actuales del laboratorio
A2: =VALUE(LEFT(F4,FIND(" - ",F4)-1)) -> 796
D3: Nombre del Curso | F3: =IFERROR(__xludf.DUMMYFUNCTION("VLOOKUP(A2,IMPORTRANGE(""1j2lHEvOoZ_EPY086Qt7f7AFaZGVfiYKJxXlsnNfWCA0"", ""Listado Cursos!$A$2:$H$100""),2,FALSE)"),"Lenguajes Formales y de Programación") -> Lenguajes Formales y de Programación
D4: Código del Curso | F4: 796 - Lenguajes Formales y de Programación
D5: Semestre | F5: =IFERROR(__xludf.DUMMYFUNCTION("VLOOKUP(A2,IMPORTRANGE(""1j2lHEvOoZ_EPY086Qt7f7AFaZGVfiYKJxXlsnNfWCA0"", ""Listado Cursos!A:G""),4,FALSE)"),4.0) -> 4
D6: Área de Conocimiento | F6: =IFERROR(__xludf.DUMMYFUNCTION("VLOOKUP(A2,IMPORTRANGE(""1j2lHEvOoZ_EPY086Qt7f7AFaZGVfiYKJxXlsnNfWCA0"", ""Listado Cursos!A:G""),6,FALSE)"),"Computación") -> Computación
D7: Cantidad de Creditos | F7: =IFERROR(__xludf.DUMMYFUNCTION("VLOOKUP(A2,IMPORTRANGE(""1j2lHEvOoZ_EPY086Qt7f7AFaZGVfiYKJxXlsnNfWCA0"", ""Listado Cursos!A:G""),3,FALSE)"),4.0) -> 4
D8: Horas de aprendizaje | F8: 4
B11: Descripción del Contexto
B13: Que cursos prerrequisito tiene | F13: Cursos que lleva en el mismo semestre | J13: Qué cursos posteriores dependen de este
B14: No. | C14: Codigo | D14: Nombre | F14: No. | G14: Codigo | H14: Nombre | J14: No. | K14: Codigo | L14: Nombre
B15: 1 | C15: =IFERROR(__xludf.DUMMYFUNCTION("ARRAYFORMULA(TRANSPOSE(SPLIT(FILTER(IMPORTRANGE(""1j2lHEvOoZ_EPY086Qt7f7AFaZGVfiYKJxXlsnNfWCA0"", ""Listado Cursos!E:E""), IMPORTRANGE(""1j2lHEvOoZ_EPY086Qt7f7AFaZGVfiYKJxXlsnNfWCA0"", ""Listado Cursos!A:A"")=A2), "","")))"),770.0) -> 770 | D15: =IFERROR(__xludf.DUMMYFUNCTION("IF(C15="""","""",VLOOKUP(C15,IMPORTRANGE(""1j2lHEvOoZ_EPY086Qt7f7AFaZGVfiYKJxXlsnNfWCA0"", ""Listado Cursos!A:B""),2,FALSE))"),"Introducción a ala programación y computación 1") -> Introducción a ala programación y computación 1 | F15: 1 | G15: =IFERROR(__xludf.DUMMYFUNCTION("FILTER(IMPORTRANGE(""1j2lHEvOoZ_EPY086Qt7f7AFaZGVfiYKJxXlsnNfWCA0"", ""Listado Cursos!A:B""),IMPORTRANGE(""1j2lHEvOoZ_EPY086Qt7f7AFaZGVfiYKJxXlsnNfWCA0"", ""Listado Cursos!D:D"")=F5,IMPORTRANGE(""1j2lHEvOoZ_EPY086Qt7f7AFaZGVfiYKJxXlsnNfWCA0"", ""Listado C"&"ursos!A:A"")<>150)"),796.0) -> 796 | H15: =IFERROR(__xludf.DUMMYFUNCTION("""COMPUTED_VALUE"""),"Lenguajes Formales y de Programación") -> Lenguajes Formales y de Programación | J15: 1 | K15: =IFERROR(__xludf.DUMMYFUNCTION("FILTER(IMPORTRANGE(""1j2lHEvOoZ_EPY086Qt7f7AFaZGVfiYKJxXlsnNfWCA0"", ""Listado Cursos!A:B""), ISNUMBER(SEARCH(A2, IMPORTRANGE(""1j2lHEvOoZ_EPY086Qt7f7AFaZGVfiYKJxXlsnNfWCA0"", ""Listado Cursos!E:E""))))"),777.0) -> 777 | L15: =IFERROR(__xludf.DUMMYFUNCTION("""COMPUTED_VALUE"""),"Organización de Lenguajes y Compiladores 1") -> Organización de Lenguajes y Compiladores 1
B16: 2 | C16: =IFERROR(__xludf.DUMMYFUNCTION("""COMPUTED_VALUE"""),795.0) -> 795 | D16: =IFERROR(__xludf.DUMMYFUNCTION("IF(C16="""","""",VLOOKUP(C16,IMPORTRANGE(""1j2lHEvOoZ_EPY086Qt7f7AFaZGVfiYKJxXlsnNfWCA0"", ""Listado Cursos!A:B""),2,FALSE))"),"Logica de Sitemas") -> Logica de Sitemas | F16: 2 | G16: =IFERROR(__xludf.DUMMYFUNCTION("""COMPUTED_VALUE"""),771.0) -> 771 | H16: =IFERROR(__xludf.DUMMYFUNCTION("""COMPUTED_VALUE"""),"Introducción a la Programación y Computación 2") -> Introducción a la Programación y Computación 2 | J16: 2 | K16: =IFERROR(__xludf.DUMMYFUNCTION("""COMPUTED_VALUE"""),772.0) -> 772 | L16: =IFERROR(__xludf.DUMMYFUNCTION("""COMPUTED_VALUE"""),"Estructuras de Datos") -> Estructuras de Datos
B17: 3 | C17: =IFERROR(__xludf.DUMMYFUNCTION("""COMPUTED_VALUE"""),960.0) -> 960 | D17: =IFERROR(__xludf.DUMMYFUNCTION("IF(C17="""","""",VLOOKUP(C17,IMPORTRANGE(""1j2lHEvOoZ_EPY086Qt7f7AFaZGVfiYKJxXlsnNfWCA0"", ""Listado Cursos!A:B""),2,FALSE))"),"Matemática Para Computación 1") -> Matemática Para Computación 1 | F17: 3 | G17: =IFERROR(__xludf.DUMMYFUNCTION("""COMPUTED_VALUE"""),112.0) -> 112 | H17: =IFERROR(__xludf.DUMMYFUNCTION("""COMPUTED_VALUE"""),"Área Matemática Intermedia 2") -> Área Matemática Intermedia 2 | J17: 3 | K17: =IFERROR(__xludf.DUMMYFUNCTION("""COMPUTED_VALUE"""),778.0) -> 778 | L17: =IFERROR(__xludf.DUMMYFUNCTION("""COMPUTED_VALUE"""),"Arquitectura de Computadoras y Ensambladores 1") -> Arquitectura de Computadoras y Ensambladores 1
B18: 4 | D18: =IFERROR(__xludf.DUMMYFUNCTION("IF(C18="""","""",VLOOKUP(C18,IMPORTRANGE(""1j2lHEvOoZ_EPY086Qt7f7AFaZGVfiYKJxXlsnNfWCA0"", ""Listado Cursos!A:B""),2,FALSE))"),"") | F18: 4 | G18: =IFERROR(__xludf.DUMMYFUNCTION("""COMPUTED_VALUE"""),114.0) -> 114 | H18: =IFERROR(__xludf.DUMMYFUNCTION("""COMPUTED_VALUE"""),"Área Matemática Intermedia 3") -> Área Matemática Intermedia 3 | J18: 4 | K18: =IFERROR(__xludf.DUMMYFUNCTION("""COMPUTED_VALUE"""),773.0) -> 773 | L18: =IFERROR(__xludf.DUMMYFUNCTION("""COMPUTED_VALUE"""),"Manejo e Implementación de Archivos") -> Manejo e Implementación de Archivos
B19: 5 | D19: =IFERROR(__xludf.DUMMYFUNCTION("IF(C19="""","""",VLOOKUP(C19,IMPORTRANGE(""1j2lHEvOoZ_EPY086Qt7f7AFaZGVfiYKJxXlsnNfWCA0"", ""Listado Cursos!A:B""),2,FALSE))"),"") | F19: 5 | G19: =IFERROR(__xludf.DUMMYFUNCTION("""COMPUTED_VALUE"""),152.0) -> 152 | H19: =IFERROR(__xludf.DUMMYFUNCTION("""COMPUTED_VALUE"""),"Física 2") -> Física 2 | J19: 5
B20: 6 | D20: =IFERROR(__xludf.DUMMYFUNCTION("IF(C20="""","""",VLOOKUP(C20,IMPORTRANGE(""1j2lHEvOoZ_EPY086Qt7f7AFaZGVfiYKJxXlsnNfWCA0"", ""Listado Cursos!A:B""),2,FALSE))"),"") | F20: 6 | G20: =IFERROR(__xludf.DUMMYFUNCTION("""COMPUTED_VALUE"""),10.0) -> 10 | H20: =IFERROR(__xludf.DUMMYFUNCTION("""COMPUTED_VALUE"""),"Lógica") -> Lógica | J20: 6
B21: 7 | D21: =IFERROR(__xludf.DUMMYFUNCTION("IF(C21="""","""",VLOOKUP(C21,IMPORTRANGE(""1j2lHEvOoZ_EPY086Qt7f7AFaZGVfiYKJxXlsnNfWCA0"", ""Listado Cursos!A:B""),2,FALSE))"),"") | F21: 7 | G21: =IFERROR(__xludf.DUMMYFUNCTION("""COMPUTED_VALUE"""),11.0) -> 11 | H21: =IFERROR(__xludf.DUMMYFUNCTION("""COMPUTED_VALUE"""),"Idioma Técnico 4") -> Idioma Técnico 4 | J21: 7
B22: 8 | D22: =IFERROR(__xludf.DUMMYFUNCTION("IF(C22="""","""",VLOOKUP(C22,IMPORTRANGE(""1j2lHEvOoZ_EPY086Qt7f7AFaZGVfiYKJxXlsnNfWCA0"", ""Listado Cursos!A:B""),2,FALSE))"),"") | F22: 8 | G22: =IFERROR(__xludf.DUMMYFUNCTION("""COMPUTED_VALUE"""),2025.0) -> 2025 | H22: =IFERROR(__xludf.DUMMYFUNCTION("""COMPUTED_VALUE"""),"Prácticas Iniciales") -> Prácticas Iniciales | J22: 8
B23: 9 | D23: =IFERROR(__xludf.DUMMYFUNCTION("IF(C23="""","""",VLOOKUP(C23,IMPORTRANGE(""1j2lHEvOoZ_EPY086Qt7f7AFaZGVfiYKJxXlsnNfWCA0"", ""Listado Cursos!A:B""),2,FALSE))"),"") | F23: 9 | J23: 9
B24: 10 | D24: =IFERROR(__xludf.DUMMYFUNCTION("IF(C24="""","""",VLOOKUP(C24,IMPORTRANGE(""1j2lHEvOoZ_EPY086Qt7f7AFaZGVfiYKJxXlsnNfWCA0"", ""Listado Cursos!A:B""),2,FALSE))"),"") | F24: 10 | J24: 10
B25: 11 | D25: =IFERROR(__xludf.DUMMYFUNCTION("IF(C25="""","""",VLOOKUP(C25,IMPORTRANGE(""1j2lHEvOoZ_EPY086Qt7f7AFaZGVfiYKJxXlsnNfWCA0"", ""Listado Cursos!A:B""),2,FALSE))"),"") | F25: 11 | J25: 11
B26: 12 | D26: =IFERROR(__xludf.DUMMYFUNCTION("IF(C26="""","""",VLOOKUP(C26,IMPORTRANGE(""1j2lHEvOoZ_EPY086Qt7f7AFaZGVfiYKJxXlsnNfWCA0"", ""Listado Cursos!A:B""),2,FALSE))"),"") | F26: 12 | J26: 12
B27: 13 | D27: =IFERROR(__xludf.DUMMYFUNCTION("IF(C27="""","""",VLOOKUP(C27,IMPORTRANGE(""1j2lHEvOoZ_EPY086Qt7f7AFaZGVfiYKJxXlsnNfWCA0"", ""Listado Cursos!A:B""),2,FALSE))"),"") | F27: 13 | J27: 13
B28: 14 | D28: =IFERROR(__xludf.DUMMYFUNCTION("IF(C28="""","""",VLOOKUP(C28,IMPORTRANGE(""1j2lHEvOoZ_EPY086Qt7f7AFaZGVfiYKJxXlsnNfWCA0"", ""Listado Cursos!A:B""),2,FALSE))"),"") | F28: 14 | J28: 14
B31: Competencias Actuales
B33: No. | C33: Tipo | D33: Competencia | L33: Nivel de la Taxonomina
B34: =IFERROR(__xludf.DUMMYFUNCTION("FILTER(METADA!D2:D17, ISEVEN(ROW(METADA!D2:D17)))"),1.0) -> 1 | C34: =IFERROR(__xludf.DUMMYFUNCTION("FILTER(METADA!E2:E17, ISEVEN(ROW(METADA!E2:E17)))"),"Especifica") -> Especifica | D34: =IFERROR(__xludf.DUMMYFUNCTION("FILTER(METADA!E2:E17, ISODD(ROW(METADA!E2:E17)))"),"El estudiante analiza la evolución y clasificación de los lenguajes formales y de programación mediante la comparación de sus características, estructuras y herramientas para comprender su organización y funcionamiento ") -> El estudiante analiza la evolución y clasificación de los lenguajes formales y de programación mediante la comparación de sus características, estructuras y herramientas para comprender su organización y funcionamiento | L34: =IFERROR(__xludf.DUMMYFUNCTION("FILTER(METADA!L2:L17, ISEVEN(ROW(METADA!L2:L17)))"),"Analizar") -> Analizar
B35: =IFERROR(__xludf.DUMMYFUNCTION("""COMPUTED_VALUE"""),2.0) -> 2 | C35: =IFERROR(__xludf.DUMMYFUNCTION("""COMPUTED_VALUE"""),"Especifica") -> Especifica | D35: =IFERROR(__xludf.DUMMYFUNCTION("""COMPUTED_VALUE"""),"El estudiante genera gramáticas libres de contexto mediante el análisis sintáctico para reconocer lenguajes formales. ") -> El estudiante genera gramáticas libres de contexto mediante el análisis sintáctico para reconocer lenguajes formales. | L35: =IFERROR(__xludf.DUMMYFUNCTION("""COMPUTED_VALUE"""),"Comprender") -> Comprender
B36: =IFERROR(__xludf.DUMMYFUNCTION("""COMPUTED_VALUE"""),3.0) -> 3 | C36: =IFERROR(__xludf.DUMMYFUNCTION("""COMPUTED_VALUE"""),"General") -> General | D36: =IFERROR(__xludf.DUMMYFUNCTION("""COMPUTED_VALUE"""),"El estudiante construye aplicaciones mediante el uso del análisis léxico y sintáctico utilizando herramientas de procesamiento de lenguajes formales para dar solución a enunciados que requieren el reconocimiento de lenguajes. ") -> El estudiante construye aplicaciones mediante el uso del análisis léxico y sintáctico utilizando herramientas de procesamiento de lenguajes formales para dar solución a enunciados que requieren el reconocimiento de lenguajes. | L36: =IFERROR(__xludf.DUMMYFUNCTION("""COMPUTED_VALUE"""),"Crear") -> Crear
B37: =IFERROR(__xludf.DUMMYFUNCTION("""COMPUTED_VALUE"""),4.0) -> 4 | C37: =IFERROR(__xludf.DUMMYFUNCTION("""COMPUTED_VALUE"""),"Especifica") -> Especifica | D37: =IFERROR(__xludf.DUMMYFUNCTION("""COMPUTED_VALUE"""),"El estudiante aplica el análisis léxico mediante el uso de expresiones regulares para solucionar problemas que requieran el reconocimiento de lenguajes. ") -> El estudiante aplica el análisis léxico mediante el uso de expresiones regulares para solucionar problemas que requieran el reconocimiento de lenguajes. | L37: =IFERROR(__xludf.DUMMYFUNCTION("""COMPUTED_VALUE"""),"Aplicar") -> Aplicar
B38: =IFERROR(__xludf.DUMMYFUNCTION("""COMPUTED_VALUE"""),5.0) -> 5 | C38: =IFERROR(__xludf.DUMMYFUNCTION("""COMPUTED_VALUE"""),"Especifica") -> Especifica | D38: =IFERROR(__xludf.DUMMYFUNCTION("""COMPUTED_VALUE"""),"El estudiante aplica el analisis sintactico mediante el uso de gramáticas formales y técnicas de parsing (descendente o ascendente) para verificar la estructura gramatical y construir árboles sintácticos que permitan solucionar problemas relacionados con "&"la interpretación de lenguajes formales. ") -> El estudiante aplica el analisis sintactico mediante el uso de gramáticas formales y técnicas de parsing (descendente o ascendente) para verificar la estructura gramatical y construir árboles sintácticos que permitan solucionar problemas relacionados con la interpretación de lenguajes formales. | L38: =IFERROR(__xludf.DUMMYFUNCTION("""COMPUTED_VALUE"""),"Aplicar") -> Aplicar
B39: =IFERROR(__xludf.DUMMYFUNCTION("""COMPUTED_VALUE"""),6.0) -> 6 | C39: =IFERROR(__xludf.DUMMYFUNCTION("""COMPUTED_VALUE"""),"Especifica") -> Especifica | D39: =IFERROR(__xludf.DUMMYFUNCTION("""COMPUTED_VALUE"""),"El estudiante comprende el funcionamiento del lenguaje de programación Java a través de su aplicación para la resolución de problemas relacionados con las fases del compilador. ") -> El estudiante comprende el funcionamiento del lenguaje de programación Java a través de su aplicación para la resolución de problemas relacionados con las fases del compilador. | L39: =IFERROR(__xludf.DUMMYFUNCTION("""COMPUTED_VALUE"""),"Comprende") -> Comprende
B40: =IFERROR(__xludf.DUMMYFUNCTION("""COMPUTED_VALUE"""),7.0) -> 7 | C40: =IFERROR(__xludf.DUMMYFUNCTION("""COMPUTED_VALUE"""),"Especifica") -> Especifica | D40: =IFERROR(__xludf.DUMMYFUNCTION("""COMPUTED_VALUE"""),"El estudiante aplica técnicas de minimización de autómatas finitos deterministas (AFD) mediante la identificación de estados equivalentes y particiones sucesivas para reducir el número de estados sin alterar el lenguaje reconocido ") -> El estudiante aplica técnicas de minimización de autómatas finitos deterministas (AFD) mediante la identificación de estados equivalentes y particiones sucesivas para reducir el número de estados sin alterar el lenguaje reconocido | L40: =IFERROR(__xludf.DUMMYFUNCTION("""COMPUTED_VALUE"""),"Aplicar") -> Aplicar

Sheet Referentes Internacionales
B1: Identificación de referentes internacionales
B3: Nombre del Curso | C3: =Competencias_actuales!F3 -> Lenguajes Formales y de Programación
B4: Codigo del Curso | C4: 796
B6: 1. Universidad Refente
B7: Analiza cursos similares en universidades internacionales reconocidas (como MIT, Stanford o ETH Zurich) para comparar temas, herramientas y competencias. Esto permite identificar buenas prácticas y alinear el laboratorio con tendencias globales en educación tecnológica.
B9: Nombre de la Universidad | C9: MIT
B10: Nombre del Curso | C10: Computer Language Engineering
B11: Fuente de Información | C11: https://ocw.mit.edu/courses/6-035-computer-language-engineering-spring-2010/pages/syllabus/
B13: Temas relacionados al laboratorio que se imparte
B14: Teoría de lenguajes, análisis léxico, análisis sintáctico, gramáticas, semántica,estructuras de compilador, práctica de implementación de compilador.
B17: Herramientas utilizadas relacionados al laboratorio que se imparte
B18: Herramientas propias de la asignatura, lenguaje de programación Java (ya que es prerequisito) para proyectos; posiblemente uso de herramientas de generación de parsers o construcción manual de parsers.
B21: Competencia(s) relacionada(s) al laboratorio que se imparte
B22: Diseño e implementación de compiladores, aplicar teoría de lenguajes formales, combinar teoría y práctica, trabajo grupal en proyecto de software, razonamiento formal, algoritmos para parsers, manejo de complejidad de software.
B26: 2. Estandar Internacional
B27: Se identifican estándares internacionales relevantes (como ABET, CDIO o IEEE/ACM) para verificar si el laboratorio cumple con criterios de calidad educativa, competencias clave y buenas prácticas recomendadas a nivel global.
B29: Nombre del Estandar | C29: ABET (Accreditation Board for Engineering and Technology)
B30: Sección , Capitulo , etc, | C30: Student Outcomes; Curriculum Requirements; General Criteria 2025‑2026, Computing Accreditation Commission (CAC) Criteria.
B31: Fuente de Información | C31: https://www.abet.org/accreditation/accreditation-criteria/criteria-for-accrediting-computing-programs-2025-2026/
B33: Contenidos relacionados al laboratorio que se imparte
B34: - Requiere que los egresados puedan aplicar teoría de ciencias de la computación (incluyendo teoría de lenguajes, autómatas, etc.) para producir soluciones basadas en cómputo.. - Que el currículo incluya conceptos de lenguajes de programación; tipos de lenguajes; estructuras de datos; software development fundamentals. - Que haya cobertura sustancial de teoría computacional (como autómatas, lenguajes formales) y programación fundamentada. - Que haya un proyecto mayor o experiencia integradora que use conocimientos previos. - Buenas prácticas de enseñanza que aseguren que los estudiantes desarrollan tanto conocimientos como habilidades prácticas.
B37: Nombre del Estandar | C37: ACM / IEEE‑CS Computing Curricula 2020 (CC2020)
B38: Sección , Capitulo , etc, | C38: “Knowledge‑based Computing Education” y “Competency‑based Computing Education”
B39: Funte de Información | C39: https://www.acm.org/binaries/content/assets/education/curricula-recommendations/cc2020.pdf?utm_source=chatgpt.com
B41: Contenidos relacionados al laboratorio que se imparte
B42: - Enumera conocimientos esperados para programas de CS: teoría de lenguajes, lenguajes de programación, parsers, compiladores, autómatas. - Competencias asociadas: análisis, diseño de software, evaluación de algoritmos, implementación, uso de abstracciones. - Importancia de aprendizaje basado en la habilidad de aplicar los conocimientos (no solo teoría). - Incluye disposición para trabajar en herramientas modernas, en proyectos integrados, buen conocimiento de arquitecturas, eficiencia, etc.

Sheet TCO_vrs_Referentes
B1: Comparación con referentes internacionales
A2: =C4&" - "&C3 -> 796 - Lenguajes Formales y de Programación
B3: Nombre del Curso | C3: =Competencias_actuales!F3 -> Lenguajes Formales y de Programación
B4: Codigo del Curso | C4: =Competencias_actuales!A2 -> 796
C5: =Competencias_actuales!A3
B6: Laboratorio Actual | F6: Universidad Referente | G6: Estandar Referente
B7: Competencia | C7: Unidad | D7: Tema | E7: SubTema | F7: Presente en el referente (Sí/No) | G7: Presente en el referente (Sí/No)
B8: =IFERROR(__xludf.DUMMYFUNCTION("QUERY(IMPORTRANGE(VLOOKUP(A2,METADA!A:B,2,FALSE), ""Diseño Curricular!B4:E500""), )"),"El estudiante comprende el funcionamiento del lenguaje de programación Java a través de su aplicación para la resolución de problemas relacionados con las fases del compilador. ") -> El estudiante comprende el funcionamiento del lenguaje de programación Java a través de su aplicación para la resolución de problemas relacionados con las fases del compilador. | C8: =IFERROR(__xludf.DUMMYFUNCTION("""COMPUTED_VALUE"""),"JAVA") -> JAVA | D8: =IFERROR(__xludf.DUMMYFUNCTION("""COMPUTED_VALUE"""),"Introduccion al lenguaje Java") -> Introduccion al lenguaje Java | E8: =IFERROR(__xludf.DUMMYFUNCTION("""COMPUTED_VALUE"""),"Historia de Java") -> Historia de Java | F8: No | G8: No
B9: =IFERROR(__xludf.DUMMYFUNCTION("""COMPUTED_VALUE"""),"El estudiante comprende el funcionamiento del lenguaje de programación Java a través de su aplicación para la resolución de problemas relacionados con las fases del compilador. ") -> El estudiante comprende el funcionamiento del lenguaje de programación Java a través de su aplicación para la resolución de problemas relacionados con las fases del compilador. | D9: =IFERROR(__xludf.DUMMYFUNCTION("""COMPUTED_VALUE"""),"Introduccion al lenguaje Java") -> Introduccion al lenguaje Java | E9: =IFERROR(__xludf.DUMMYFUNCTION("""COMPUTED_VALUE"""),"Aspectos Basicos de Java") -> Aspectos Basicos de Java | F9: No | G9: Si
B10: =IFERROR(__xludf.DUMMYFUNCTION("""COMPUTED_VALUE"""),"El estudiante comprende el funcionamiento del lenguaje de programación Java a través de su aplicación para la resolución de problemas relacionados con las fases del compilador. ") -> El estudiante comprende el funcionamiento del lenguaje de programación Java a través de su aplicación para la resolución de problemas relacionados con las fases del compilador. | D10: =IFERROR(__xludf.DUMMYFUNCTION("""COMPUTED_VALUE"""),"Introduccion al lenguaje Java") -> Introduccion al lenguaje Java | E10: =IFERROR(__xludf.DUMMYFUNCTION("""COMPUTED_VALUE"""),"Reglas de Sintaxis") -> Reglas de Sintaxis | F10: No | G10: Si
B11: =IFERROR(__xludf.DUMMYFUNCTION("""COMPUTED_VALUE"""),"El estudiante comprende el funcionamiento del lenguaje de programación Java a través de su aplicación para la resolución de problemas relacionados con las fases del compilador. ") -> El estudiante comprende el funcionamiento del lenguaje de programación Java a través de su aplicación para la resolución de problemas relacionados con las fases del compilador. | D11: =IFERROR(__xludf.DUMMYFUNCTION("""COMPUTED_VALUE"""),"Introduccion al lenguaje Java") -> Introduccion al lenguaje Java | E11: =IFERROR(__xludf.DUMMYFUNCTION("""COMPUTED_VALUE"""),"Estructura de un programa") -> Estructura de un programa | F11: No | G11: Si
B12: =IFERROR(__xludf.DUMMYFUNCTION("""COMPUTED_VALUE"""),"El estudiante comprende el funcionamiento del lenguaje de programación Java a través de su aplicación para la resolución de problemas relacionados con las fases del compilador. ") -> El estudiante comprende el funcionamiento del lenguaje de programación Java a través de su aplicación para la resolución de problemas relacionados con las fases del compilador. | D12: =IFERROR(__xludf.DUMMYFUNCTION("""COMPUTED_VALUE"""),"Buenas Practicas y funciones en Java") -> Buenas Practicas y funciones en Java | E12: =IFERROR(__xludf.DUMMYFUNCTION("""COMPUTED_VALUE"""),"Convenciones de nombres y estilo de código") -> Convenciones de nombres y estilo de código | F12: No | G12: Si
B13: =IFERROR(__xludf.DUMMYFUNCTION("""COMPUTED_VALUE"""),"El estudiante comprende el funcionamiento del lenguaje de programación Java a través de su aplicación para la resolución de problemas relacionados con las fases del compilador. ") -> El estudiante comprende el funcionamiento del lenguaje de programación Java a través de su aplicación para la resolución de problemas relacionados con las fases del compilador. | D13: =IFERROR(__xludf.DUMMYFUNCTION("""COMPUTED_VALUE"""),"Buenas Practicas y funciones en Java") -> Buenas Practicas y funciones en Java | E13: =IFERROR(__xludf.DUMMYFUNCTION("""COMPUTED_VALUE"""),"Gestión de memoria y optimización") -> Gestión de memoria y optimización | F13: No | G13: Si
B14: =IFERROR(__xludf.DUMMYFUNCTION("""COMPUTED_VALUE"""),"El estudiante comprende el funcionamiento del lenguaje de programación Java a través de su aplicación para la resolución de problemas relacionados con las fases del compilador. ") -> El estudiante comprende el funcionamiento del lenguaje de programación Java a través de su aplicación para la resolución de problemas relacionados con las fases del compilador. | D14: =IFERROR(__xludf.DUMMYFUNCTION("""COMPUTED_VALUE"""),"Buenas Practicas y funciones en Java") -> Buenas Practicas y funciones en Java | E14: =IFERROR(__xludf.DUMMYFUNCTION("""COMPUTED_VALUE"""),"Definición y uso de métodos y funciones") -> Definición y uso de métodos y funciones | F14: No | G14: Si
B15: =IFERROR(__xludf.DUMMYFUNCTION("""COMPUTED_VALUE"""),"El estudiante comprende el funcionamiento del lenguaje de programación Java a través de su aplicación para la resolución de problemas relacionados con las fases del compilador. ") -> El estudiante comprende el funcionamiento del lenguaje de programación Java a través de su aplicación para la resolución de problemas relacionados con las fases del compilador. | D15: =IFERROR(__xludf.DUMMYFUNCTION("""COMPUTED_VALUE"""),"Buenas Practicas y funciones en Java") -> Buenas Practicas y funciones en Java | E15: =IFERROR(__xludf.DUMMYFUNCTION("""COMPUTED_VALUE"""),"Creación y uso de clases") -> Creación y uso de clases | F15: No | G15: Si
B16: =IFERROR(__xludf.DUMMYFUNCTION("""COMPUTED_VALUE"""),"El estudiante comprende el funcionamiento del lenguaje de programación Java a través de su aplicación para la resolución de problemas relacionados con las fases del compilador. ") -> El estudiante comprende el funcionamiento del lenguaje de programación Java a través de su aplicación para la resolución de problemas relacionados con las fases del compilador. | D16: =IFERROR(__xludf.DUMMYFUNCTION("""COMPUTED_VALUE"""),"Buenas Practicas y funciones en Java") -> Buenas Practicas y funciones en Java | E16: =IFERROR(__xludf.DUMMYFUNCTION("""COMPUTED_VALUE"""),"Diferencias entre métodos y funciones") -> Diferencias entre métodos y funciones | F16: No | G16: Si
B17: =IFERROR(__xludf.DUMMYFUNCTION("""COMPUTED_VALUE"""),"El estudiante comprende el funcionamiento del lenguaje de programación Java a través de su aplicación para la resolución de problemas relacionados con las fases del compilador. ") -> El estudiante comprende el funcionamiento del lenguaje de programación Java a través de su aplicación para la resolución de problemas relacionados con las fases del compilador. | D17: =IFERROR(__xludf.DUMMYFUNCTION("""COMPUTED_VALUE"""),"Estructuras de Datos y Control en Java") -> Estructuras de Datos y Control en Java | E17: =IFERROR(__xludf.DUMMYFUNCTION("""COMPUTED_VALUE"""),"Arreglos en Java") -> Arreglos en Java | F17: Si | G17: Si
B18: =IFERROR(__xludf.DUMMYFUNCTION("""COMPUTED_VALUE"""),"El estudiante comprende el funcionamiento del lenguaje de programación Java a través de su aplicación para la resolución de problemas relacionados con las fases del compilador. ") -> El estudiante comprende el funcionamiento del lenguaje de programación Java a través de su aplicación para la resolución de problemas relacionados con las fases del compilador. | D18: =IFERROR(__xludf.DUMMYFUNCTION("""COMPUTED_VALUE"""),"Estructuras de Datos y Control en Java") -> Estructuras de Datos y Control en Java | E18: =IFERROR(__xludf.DUMMYFUNCTION("""COMPUTED_VALUE"""),"Diccionarios y estructuras de Datos") -> Diccionarios y estructuras de Datos | F18: No | G18: Si
B19: =IFERROR(__xludf.DUMMYFUNCTION("""COMPUTED_VALUE"""),"El estudiante comprende el funcionamiento del lenguaje de programación Java a través de su aplicación para la resolución de problemas relacionados con las fases del compilador. ") -> El estudiante comprende el funcionamiento del lenguaje de programación Java a través de su aplicación para la resolución de problemas relacionados con las fases del compilador. | D19: =IFERROR(__xludf.DUMMYFUNCTION("""COMPUTED_VALUE"""),"Estructuras de Datos y Control en Java") -> Estructuras de Datos y Control en Java | E19: =IFERROR(__xludf.DUMMYFUNCTION("""COMPUTED_VALUE"""),"Iteracion en Java") -> Iteracion en Java | F19: No | G19: Si
B20: =IFERROR(__xludf.DUMMYFUNCTION("""COMPUTED_VALUE"""),"El estudiante comprende el funcionamiento del lenguaje de programación Java a través de su aplicación para la resolución de problemas relacionados con las fases del compilador. ") -> El estudiante comprende el funcionamiento del lenguaje de programación Java a través de su aplicación para la resolución de problemas relacionados con las fases del compilador. | D20: =IFERROR(__xludf.DUMMYFUNCTION("""COMPUTED_VALUE"""),"Estructuras de Datos y Control en Java") -> Estructuras de Datos y Control en Java | E20: =IFERROR(__xludf.DUMMYFUNCTION("""COMPUTED_VALUE"""),"Lectura de Archivos") -> Lectura de Archivos | F20: No | G20: Si
B21: =IFERROR(__xludf.DUMMYFUNCTION("""COMPUTED_VALUE"""),"El estudiante comprende el funcionamiento del lenguaje de programación Java a través de su aplicación para la resolución de problemas relacionados con las fases del compilador. ") -> El estudiante comprende el funcionamiento del lenguaje de programación Java a través de su aplicación para la resolución de problemas relacionados con las fases del compilador. | D21: =IFERROR(__xludf.DUMMYFUNCTION("""COMPUTED_VALUE"""),"Estructuras de Datos y Control en Java") -> Estructuras de Datos y Control en Java | E21: =IFERROR(__xludf.DUMMYFUNCTION("""COMPUTED_VALUE"""),"Escritura de Archivos") -> Escritura de Archivos | F21: No | G21: Si
B22: =IFERROR(__xludf.DUMMYFUNCTION("""COMPUTED_VALUE"""),"El estudiante analiza la evolución y clasificación de los lenguajes formales y de programación mediante la comparación de sus características, estructuras y herramientas para comprender su organización y funcionamiento ") -> El estudiante analiza la evolución y clasificación de los lenguajes formales y de programación mediante la comparación de sus características, estructuras y herramientas para comprender su organización y funcionamiento | C22: =IFERROR(__xludf.DUMMYFUNCTION("""COMPUTED_VALUE"""),"Lenguajes Formales") -> Lenguajes Formales | D22: =IFERROR(__xludf.DUMMYFUNCTION("""COMPUTED_VALUE"""),"Lenguajes") -> Lenguajes | E22: =IFERROR(__xludf.DUMMYFUNCTION("""COMPUTED_VALUE"""),"Lenguajes Natural") -> Lenguajes Natural | F22: Si | G22: Si
B23: =IFERROR(__xludf.DUMMYFUNCTION("""COMPUTED_VALUE"""),"El estudiante analiza la evolución y clasificación de los lenguajes formales y de programación mediante la comparación de sus características, estructuras y herramientas para comprender su organización y funcionamiento ") -> El estudiante analiza la evolución y clasificación de los lenguajes formales y de programación mediante la comparación de sus características, estructuras y herramientas para comprender su organización y funcionamiento | D23: =IFERROR(__xludf.DUMMYFUNCTION("""COMPUTED_VALUE"""),"Lenguajes") -> Lenguajes | E23: =IFERROR(__xludf.DUMMYFUNCTION("""COMPUTED_VALUE"""),"Lenguajes Formales") -> Lenguajes Formales | F23: Si | G23: Si
B24: =IFERROR(__xludf.DUMMYFUNCTION("""COMPUTED_VALUE"""),"El estudiante analiza la evolución y clasificación de los lenguajes formales y de programación mediante la comparación de sus características, estructuras y herramientas para comprender su organización y funcionamiento ") -> El estudiante analiza la evolución y clasificación de los lenguajes formales y de programación mediante la comparación de sus características, estructuras y herramientas para comprender su organización y funcionamiento | D24: =IFERROR(__xludf.DUMMYFUNCTION("""COMPUTED_VALUE"""),"Lenguajes") -> Lenguajes | E24: =IFERROR(__xludf.DUMMYFUNCTION("""COMPUTED_VALUE"""),"Lenguajes de Programacion") -> Lenguajes de Programacion | F24: Si | G24: Si
B25: =IFERROR(__xludf.DUMMYFUNCTION("""COMPUTED_VALUE"""),"El estudiante analiza la evolución y clasificación de los lenguajes formales y de programación mediante la comparación de sus características, estructuras y herramientas para comprender su organización y funcionamiento ") -> El estudiante analiza la evolución y clasificación de los lenguajes formales y de programación mediante la comparación de sus características, estructuras y herramientas para comprender su organización y funcionamiento | D25: =IFERROR(__xludf.DUMMYFUNCTION("""COMPUTED_VALUE"""),"Lenguajes") -> Lenguajes | E25: =IFERROR(__xludf.DUMMYFUNCTION("""COMPUTED_VALUE"""),"Evolucion de los Lenguajes de Programacion") -> Evolucion de los Lenguajes de Programacion | F25: Si | G25: Si
B26: =IFERROR(__xludf.DUMMYFUNCTION("""COMPUTED_VALUE"""),"El estudiante analiza la evolución y clasificación de los lenguajes formales y de programación mediante la comparación de sus características, estructuras y herramientas para comprender su organización y funcionamiento ") -> El estudiante analiza la evolución y clasificación de los lenguajes formales y de programación mediante la comparación de sus características, estructuras y herramientas para comprender su organización y funcionamiento | D26: =IFERROR(__xludf.DUMMYFUNCTION("""COMPUTED_VALUE"""),"Lenguajes") -> Lenguajes | E26: =IFERROR(__xludf.DUMMYFUNCTION("""COMPUTED_VALUE"""),"Paradigmas") -> Paradigmas | F26: Si | G26: Si
B27: =IFERROR(__xludf.DUMMYFUNCTION("""COMPUTED_VALUE"""),"El estudiante analiza la evolución y clasificación de los lenguajes formales y de programación mediante la comparación de sus características, estructuras y herramientas para comprender su organización y funcionamiento ") -> El estudiante analiza la evolución y clasificación de los lenguajes formales y de programación mediante la comparación de sus características, estructuras y herramientas para comprender su organización y funcionamiento | D27: =IFERROR(__xludf.DUMMYFUNCTION("""COMPUTED_VALUE"""),"Lenguajes") -> Lenguajes | E27: =IFERROR(__xludf.DUMMYFUNCTION("""COMPUTED_VALUE"""),"Generaciones de lenguajes de programación") -> Generaciones de lenguajes de programación | F27: Si | G27: Si
B28: =IFERROR(__xludf.DUMMYFUNCTION("""COMPUTED_VALUE"""),"El estudiante analiza la evolución y clasificación de los lenguajes formales y de programación mediante la comparación de sus características, estructuras y herramientas para comprender su organización y funcionamiento ") -> El estudiante analiza la evolución y clasificación de los lenguajes formales y de programación mediante la comparación de sus características, estructuras y herramientas para comprender su organización y funcionamiento | D28: =IFERROR(__xludf.DUMMYFUNCTION("""COMPUTED_VALUE"""),"Procesadores de Lenguaje") -> Procesadores de Lenguaje | E28: =IFERROR(__xludf.DUMMYFUNCTION("""COMPUTED_VALUE"""),"Interprete") -> Interprete | F28: Si | G28: Si
B29: =IFERROR(__xludf.DUMMYFUNCTION("""COMPUTED_VALUE"""),"El estudiante analiza la evolución y clasificación de los lenguajes formales y de programación mediante la comparación de sus características, estructuras y herramientas para comprender su organización y funcionamiento ") -> El estudiante analiza la evolución y clasificación de los lenguajes formales y de programación mediante la comparación de sus características, estructuras y herramientas para comprender su organización y funcionamiento | D29: =IFERROR(__xludf.DUMMYFUNCTION("""COMPUTED_VALUE"""),"Procesadores de Lenguaje") -> Procesadores de Lenguaje | E29: =IFERROR(__xludf.DUMMYFUNCTION("""COMPUTED_VALUE"""),"Compilador") -> Compilador | F29: Si | G29: Si
B30: =IFERROR(__xludf.DUMMYFUNCTION("""COMPUTED_VALUE"""),"El estudiante analiza la evolución y clasificación de los lenguajes formales y de programación mediante la comparación de sus características, estructuras y herramientas para comprender su organización y funcionamiento ") -> El estudiante analiza la evolución y clasificación de los lenguajes formales y de programación mediante la comparación de sus características, estructuras y herramientas para comprender su organización y funcionamiento | D30: =IFERROR(__xludf.DUMMYFUNCTION("""COMPUTED_VALUE"""),"Procesadores de Lenguaje") -> Procesadores de Lenguaje | E30: =IFERROR(__xludf.DUMMYFUNCTION("""COMPUTED_VALUE"""),"Estructura de un compilador") -> Estructura de un compilador | F30: Si | G30: Si
B31: =IFERROR(__xludf.DUMMYFUNCTION("""COMPUTED_VALUE"""),"El estudiante analiza la evolución y clasificación de los lenguajes formales y de programación mediante la comparación de sus características, estructuras y herramientas para comprender su organización y funcionamiento ") -> El estudiante analiza la evolución y clasificación de los lenguajes formales y de programación mediante la comparación de sus características, estructuras y herramientas para comprender su organización y funcionamiento | D31: =IFERROR(__xludf.DUMMYFUNCTION("""COMPUTED_VALUE"""),"Procesadores de Lenguaje") -> Procesadores de Lenguaje | E31: =IFERROR(__xludf.DUMMYFUNCTION("""COMPUTED_VALUE"""),"Diferencias y Ejemplos") -> Diferencias y Ejemplos | F31: Si | G31: Si
B32: =IFERROR(__xludf.DUMMYFUNCTION("""COMPUTED_VALUE"""),"El estudiante analiza la evolución y clasificación de los lenguajes formales y de programación mediante la comparación de sus características, estructuras y herramientas para comprender su organización y funcionamiento ") -> El estudiante analiza la evolución y clasificación de los lenguajes formales y de programación mediante la comparación de sus características, estructuras y herramientas para comprender su organización y funcionamiento | D32: =IFERROR(__xludf.DUMMYFUNCTION("""COMPUTED_VALUE"""),"Procesadores de Lenguaje") -> Procesadores de Lenguaje | E32: =IFERROR(__xludf.DUMMYFUNCTION("""COMPUTED_VALUE"""),"Herramientas") -> Herramientas | F32: Si | G32: Si
B33: =IFERROR(__xludf.DUMMYFUNCTION("""COMPUTED_VALUE"""),"El estudiante analiza la evolución y clasificación de los lenguajes formales y de programación mediante la comparación de sus características, estructuras y herramientas para comprender su organización y funcionamiento ") -> El estudiante analiza la evolución y clasificación de los lenguajes formales y de programación mediante la comparación de sus características, estructuras y herramientas para comprender su organización y funcionamiento | D33: =IFERROR(__xludf.DUMMYFUNCTION("""COMPUTED_VALUE"""),"Procesadores de Lenguaje") -> Procesadores de Lenguaje | E33: =IFERROR(__xludf.DUMMYFUNCTION("""COMPUTED_VALUE"""),"Jerarquia de Chosmky") -> Jerarquia de Chosmky | F33: Si | G33: Si
B34: =IFERROR(__xludf.DUMMYFUNCTION("""COMPUTED_VALUE"""),"El estudiante analiza la evolución y clasificación de los lenguajes formales y de programación mediante la comparación de sus características, estructuras y herramientas para comprender su organización y funcionamiento ") -> El estudiante analiza la evolución y clasificación de los lenguajes formales y de programación mediante la comparación de sus características, estructuras y herramientas para comprender su organización y funcionamiento | D34: =IFERROR(__xludf.DUMMYFUNCTION("""COMPUTED_VALUE"""),"Procesadores de Lenguaje") -> Procesadores de Lenguaje | E34: =IFERROR(__xludf.DUMMYFUNCTION("""COMPUTED_VALUE"""),"Clasificacion de Gramaticas") -> Clasificacion de Gramaticas | F34: Si | G34: Si
B35: =IFERROR(__xludf.DUMMYFUNCTION("""COMPUTED_VALUE"""),"El estudiante aplica el análisis léxico mediante el uso de expresiones regulares para solucionar problemas que requieran el reconocimiento de lenguajes. ") -> El estudiante aplica el análisis léxico mediante el uso de expresiones regulares para solucionar problemas que requieran el reconocimiento de lenguajes. | C35: =IFERROR(__xludf.DUMMYFUNCTION("""COMPUTED_VALUE"""),"Analisis Lexico") -> Analisis Lexico | D35: =IFERROR(__xludf.DUMMYFUNCTION("""COMPUTED_VALUE"""),"Definicion y Funcion del analizador lexico ") -> Definicion y Funcion del analizador lexico | E35: =IFERROR(__xludf.DUMMYFUNCTION("""COMPUTED_VALUE"""),"Patrones") -> Patrones | F35: Si | G35: Si
B36: =IFERROR(__xludf.DUMMYFUNCTION("""COMPUTED_VALUE"""),"El estudiante aplica el análisis léxico mediante el uso de expresiones regulares para solucionar problemas que requieran el reconocimiento de lenguajes. ") -> El estudiante aplica el análisis léxico mediante el uso de expresiones regulares para solucionar problemas que requieran el reconocimiento de lenguajes. | D36: =IFERROR(__xludf.DUMMYFUNCTION("""COMPUTED_VALUE"""),"Definicion y Funcion del analizador lexico ") -> Definicion y Funcion del analizador lexico | E36: =IFERROR(__xludf.DUMMYFUNCTION("""COMPUTED_VALUE"""),"Tokens") -> Tokens | F36: Si | G36: Si
B37: =IFERROR(__xludf.DUMMYFUNCTION("""COMPUTED_VALUE"""),"El estudiante aplica el análisis léxico mediante el uso de expresiones regulares para solucionar problemas que requieran el reconocimiento de lenguajes. ") -> El estudiante aplica el análisis léxico mediante el uso de expresiones regulares para solucionar problemas que requieran el reconocimiento de lenguajes. | D37: =IFERROR(__xludf.DUMMYFUNCTION("""COMPUTED_VALUE"""),"Definicion y Funcion del analizador lexico ") -> Definicion y Funcion del analizador lexico | E37: =IFERROR(__xludf.DUMMYFUNCTION("""COMPUTED_VALUE"""),"Lexemas") -> Lexemas | F37: Si | G37: Si
B38: =IFERROR(__xludf.DUMMYFUNCTION("""COMPUTED_VALUE"""),"El estudiante aplica el análisis léxico mediante el uso de expresiones regulares para solucionar problemas que requieran el reconocimiento de lenguajes. ") -> El estudiante aplica el análisis léxico mediante el uso de expresiones regulares para solucionar problemas que requieran el reconocimiento de lenguajes. | D38: =IFERROR(__xludf.DUMMYFUNCTION("""COMPUTED_VALUE"""),"Definicion y Funcion del analizador lexico ") -> Definicion y Funcion del analizador lexico | E38: =IFERROR(__xludf.DUMMYFUNCTION("""COMPUTED_VALUE"""),"Errores Lexicos") -> Errores Lexicos | F38: Si | G38: Si
B39: =IFERROR(__xludf.DUMMYFUNCTION("""COMPUTED_VALUE"""),"El estudiante aplica el análisis léxico mediante el uso de expresiones regulares para solucionar problemas que requieran el reconocimiento de lenguajes. ") -> El estudiante aplica el análisis léxico mediante el uso de expresiones regulares para solucionar problemas que requieran el reconocimiento de lenguajes. | D39: =IFERROR(__xludf.DUMMYFUNCTION("""COMPUTED_VALUE"""),"Definicion y Funcion del analizador lexico ") -> Definicion y Funcion del analizador lexico | E39: =IFERROR(__xludf.DUMMYFUNCTION("""COMPUTED_VALUE"""),"Ejemplos de tokens en diferentes lenguajes") -> Ejemplos de tokens en diferentes lenguajes | F39: Si | G39: Si
B40: =IFERROR(__xludf.DUMMYFUNCTION("""COMPUTED_VALUE"""),"El estudiante aplica el análisis léxico mediante el uso de expresiones regulares para solucionar problemas que requieran el reconocimiento de lenguajes. ") -> El estudiante aplica el análisis léxico mediante el uso de expresiones regulares para solucionar problemas que requieran el reconocimiento de lenguajes. | D40: =IFERROR(__xludf.DUMMYFUNCTION("""COMPUTED_VALUE"""),"Operaciones Entre Lenguajes y Expresiones regulares") -> Operaciones Entre Lenguajes y Expresiones regulares | E40: =IFERROR(__xludf.DUMMYFUNCTION("""COMPUTED_VALUE"""),"Interoperabilidad entre Lenguajes") -> Interoperabilidad entre Lenguajes | F40: No | G40: No
...

Sheet TCO_Lab_Previo
B1: Que se impartio el en Curso Previo el Segundo Semestre 2025
B3: Nombre del Curso | C3: Introducción a ala programación y computación 1
B4: Codigo del Curso | C4: {=IFERROR(XLOOKUP(TRIM(C3), Competencias_actuales!D15:D1000, Competencias_actuales!C15:C1000), "Código no encontrado")} -> 770 | H4: =C4&" - "&C3 -> 770 - Introducción a ala programación y computación 1
B6: No | C6: Competencia | D6: Unidad | E6: Tema | F6: Subtema | G6: Mes | H6: Semana
B7: =IFERROR(__xludf.DUMMYFUNCTION("QUERY(IMPORTRANGE(VLOOKUP(H4,METADA!A:B,2,FALSE), ""Diseño Curricular!A4:G500""), )"),1.0) -> 1 | C7: =IFERROR(__xludf.DUMMYFUNCTION("""COMPUTED_VALUE"""),"Diseña algoritmos aplicando diagramas de flujo y pseudocódigo para resolver problemas básicos de lógica computacional ") -> Diseña algoritmos aplicando diagramas de flujo y pseudocódigo para resolver problemas básicos de lógica computacional | D7: =IFERROR(__xludf.DUMMYFUNCTION("""COMPUTED_VALUE"""),"1. Introducción a la Programación") -> 1. Introducción a la Programación | E7: =IFERROR(__xludf.DUMMYFUNCTION("""COMPUTED_VALUE"""),"Introducción a los fundamentos de Programación") -> Introducción a los fundamentos de Programación | F7: =IFERROR(__xludf.DUMMYFUNCTION("""COMPUTED_VALUE"""),"Algoritmos") -> Algoritmos | G7: =IFERROR(__xludf.DUMMYFUNCTION("""COMPUTED_VALUE"""),"Julio") -> Julio | H7: =IFERROR(__xludf.DUMMYFUNCTION("""COMPUTED_VALUE"""),1.0) -> 1
B8: =IFERROR(__xludf.DUMMYFUNCTION("""COMPUTED_VALUE"""),2.0) -> 2 | C8: =IFERROR(__xludf.DUMMYFUNCTION("""COMPUTED_VALUE"""),"Diseña algoritmos aplicando diagramas de flujo y pseudocódigo para resolver problemas básicos de lógica computacional ") -> Diseña algoritmos aplicando diagramas de flujo y pseudocódigo para resolver problemas básicos de lógica computacional | D8: =IFERROR(__xludf.DUMMYFUNCTION("""COMPUTED_VALUE"""),"1. Introducción a la Programación") -> 1. Introducción a la Programación | E8: =IFERROR(__xludf.DUMMYFUNCTION("""COMPUTED_VALUE"""),"Introducción a los fundamentos de Programación") -> Introducción a los fundamentos de Programación | F8: =IFERROR(__xludf.DUMMYFUNCTION("""COMPUTED_VALUE"""),"Diagramas de Flujo") -> Diagramas de Flujo | G8: =IFERROR(__xludf.DUMMYFUNCTION("""COMPUTED_VALUE"""),"Julio") -> Julio | H8: =IFERROR(__xludf.DUMMYFUNCTION("""COMPUTED_VALUE"""),1.0) -> 1
B9: =IFERROR(__xludf.DUMMYFUNCTION("""COMPUTED_VALUE"""),3.0) -> 3 | C9: =IFERROR(__xludf.DUMMYFUNCTION("""COMPUTED_VALUE"""),"Diseñar algoritmos aplicando diagramas de flujo y pseudocódigo para resolver problemas básicos de lógica computacional ") -> Diseñar algoritmos aplicando diagramas de flujo y pseudocódigo para resolver problemas básicos de lógica computacional | D9: =IFERROR(__xludf.DUMMYFUNCTION("""COMPUTED_VALUE"""),"1. Introducción a la Programación") -> 1. Introducción a la Programación | E9: =IFERROR(__xludf.DUMMYFUNCTION("""COMPUTED_VALUE"""),"Introducción a los fundamentos de Programación") -> Introducción a los fundamentos de Programación | F9: =IFERROR(__xludf.DUMMYFUNCTION("""COMPUTED_VALUE"""),"Pseudocódigo") -> Pseudocódigo | G9: =IFERROR(__xludf.DUMMYFUNCTION("""COMPUTED_VALUE"""),"Julio") -> Julio | H9: =IFERROR(__xludf.DUMMYFUNCTION("""COMPUTED_VALUE"""),2.0) -> 2
B10: =IFERROR(__xludf.DUMMYFUNCTION("""COMPUTED_VALUE"""),4.0) -> 4 | C10: =IFERROR(__xludf.DUMMYFUNCTION("""COMPUTED_VALUE"""),"Colaborar en proyectos de programación utilizando plataformas de control de versiones básicas promoviendo el trabajo en equipo y la responsabilidad ") -> Colaborar en proyectos de programación utilizando plataformas de control de versiones básicas promoviendo el trabajo en equipo y la responsabilidad | D10: =IFERROR(__xludf.DUMMYFUNCTION("""COMPUTED_VALUE"""),"2. Introducción al versionamiento") -> 2. Introducción al versionamiento | E10: =IFERROR(__xludf.DUMMYFUNCTION("""COMPUTED_VALUE"""),"Introducción al manejo de control de versiones") -> Introducción al manejo de control de versiones | F10: =IFERROR(__xludf.DUMMYFUNCTION("""COMPUTED_VALUE"""),"Introducción a versionamiento") -> Introducción a versionamiento | G10: =IFERROR(__xludf.DUMMYFUNCTION("""COMPUTED_VALUE"""),"Agosto") -> Agosto | H10: =IFERROR(__xludf.DUMMYFUNCTION("""COMPUTED_VALUE"""),3.0) -> 3
B11: =IFERROR(__xludf.DUMMYFUNCTION("""COMPUTED_VALUE"""),5.0) -> 5 | C11: =IFERROR(__xludf.DUMMYFUNCTION("""COMPUTED_VALUE"""),"Colaborar en proyectos de programación utilizando plataformas de control de versiones básicas promoviendo el trabajo en equipo y la responsabilidad ") -> Colaborar en proyectos de programación utilizando plataformas de control de versiones básicas promoviendo el trabajo en equipo y la responsabilidad | D11: =IFERROR(__xludf.DUMMYFUNCTION("""COMPUTED_VALUE"""),"2. Introducción al versionamiento") -> 2. Introducción al versionamiento | E11: =IFERROR(__xludf.DUMMYFUNCTION("""COMPUTED_VALUE"""),"Introducción al manejo de control de versiones") -> Introducción al manejo de control de versiones | F11: =IFERROR(__xludf.DUMMYFUNCTION("""COMPUTED_VALUE"""),"Herramientas de control de versiones") -> Herramientas de control de versiones | G11: =IFERROR(__xludf.DUMMYFUNCTION("""COMPUTED_VALUE"""),"Agosto") -> Agosto | H11: =IFERROR(__xludf.DUMMYFUNCTION("""COMPUTED_VALUE"""),3.0) -> 3
B12: =IFERROR(__xludf.DUMMYFUNCTION("""COMPUTED_VALUE"""),6.0) -> 6 | C12: =IFERROR(__xludf.DUMMYFUNCTION("""COMPUTED_VALUE"""),"Colaborar en proyectos de programación utilizando plataformas de control de versiones básicas promoviendo el trabajo en equipo y la responsabilidad ") -> Colaborar en proyectos de programación utilizando plataformas de control de versiones básicas promoviendo el trabajo en equipo y la responsabilidad | D12: =IFERROR(__xludf.DUMMYFUNCTION("""COMPUTED_VALUE"""),"2. Introducción al versionamiento") -> 2. Introducción al versionamiento | E12: =IFERROR(__xludf.DUMMYFUNCTION("""COMPUTED_VALUE"""),"Introducción al manejo de control de versiones") -> Introducción al manejo de control de versiones | F12: =IFERROR(__xludf.DUMMYFUNCTION("""COMPUTED_VALUE"""),"Tareas básicas de Git") -> Tareas básicas de Git | G12: =IFERROR(__xludf.DUMMYFUNCTION("""COMPUTED_VALUE"""),"Agosto") -> Agosto | H12: =IFERROR(__xludf.DUMMYFUNCTION("""COMPUTED_VALUE"""),3.0) -> 3
B13: =IFERROR(__xludf.DUMMYFUNCTION("""COMPUTED_VALUE"""),7.0) -> 7 | C13: =IFERROR(__xludf.DUMMYFUNCTION("""COMPUTED_VALUE"""),"Colaborar en proyectos de programación utilizando plataformas de control de versiones básicas promoviendo el trabajo en equipo y la responsabilidad ") -> Colaborar en proyectos de programación utilizando plataformas de control de versiones básicas promoviendo el trabajo en equipo y la responsabilidad | D13: =IFERROR(__xludf.DUMMYFUNCTION("""COMPUTED_VALUE"""),"2. Introducción al versionamiento") -> 2. Introducción al versionamiento | E13: =IFERROR(__xludf.DUMMYFUNCTION("""COMPUTED_VALUE"""),"Introducción al manejo de control de versiones") -> Introducción al manejo de control de versiones | F13: =IFERROR(__xludf.DUMMYFUNCTION("""COMPUTED_VALUE"""),"Colaboración en repositorios remotos") -> Colaboración en repositorios remotos | G13: =IFERROR(__xludf.DUMMYFUNCTION("""COMPUTED_VALUE"""),"Agosto") -> Agosto | H13: =IFERROR(__xludf.DUMMYFUNCTION("""COMPUTED_VALUE"""),3.0) -> 3
B14: =IFERROR(__xludf.DUMMYFUNCTION("""COMPUTED_VALUE"""),8.0) -> 8 | C14: =IFERROR(__xludf.DUMMYFUNCTION("""COMPUTED_VALUE"""),"Aplicar conceptos de programación mediante ejercicios prácticos y laboratorios respetando estándares básicos de calidad de software ") -> Aplicar conceptos de programación mediante ejercicios prácticos y laboratorios respetando estándares básicos de calidad de software | D14: =IFERROR(__xludf.DUMMYFUNCTION("""COMPUTED_VALUE"""),"3. Introducción a Java") -> 3. Introducción a Java | E14: =IFERROR(__xludf.DUMMYFUNCTION("""COMPUTED_VALUE"""),"Introducción a Java - Parte 1") -> Introducción a Java - Parte 1 | F14: =IFERROR(__xludf.DUMMYFUNCTION("""COMPUTED_VALUE"""),"¿Qué es Java?") -> ¿Qué es Java? | G14: =IFERROR(__xludf.DUMMYFUNCTION("""COMPUTED_VALUE"""),"Agosto") -> Agosto | H14: =IFERROR(__xludf.DUMMYFUNCTION("""COMPUTED_VALUE"""),4.0) -> 4
B15: =IFERROR(__xludf.DUMMYFUNCTION("""COMPUTED_VALUE"""),9.0) -> 9 | C15: =IFERROR(__xludf.DUMMYFUNCTION("""COMPUTED_VALUE"""),"Aplicar conceptos de programación mediante ejercicios prácticos y laboratorios respetando estándares básicos de calidad de software ") -> Aplicar conceptos de programación mediante ejercicios prácticos y laboratorios respetando estándares básicos de calidad de software | D15: =IFERROR(__xludf.DUMMYFUNCTION("""COMPUTED_VALUE"""),"3. Introducción a Java") -> 3. Introducción a Java | E15: =IFERROR(__xludf.DUMMYFUNCTION("""COMPUTED_VALUE"""),"Introducción a Java - Parte 2") -> Introducción a Java - Parte 2 | F15: =IFERROR(__xludf.DUMMYFUNCTION("""COMPUTED_VALUE"""),"Versiones y ambientes de java (JDK, JRE, JVM)") -> Versiones y ambientes de java (JDK, JRE, JVM) | G15: =IFERROR(__xludf.DUMMYFUNCTION("""COMPUTED_VALUE"""),"Agosto") -> Agosto | H15: =IFERROR(__xludf.DUMMYFUNCTION("""COMPUTED_VALUE"""),4.0) -> 4
B16: =IFERROR(__xludf.DUMMYFUNCTION("""COMPUTED_VALUE"""),10.0) -> 10 | C16: =IFERROR(__xludf.DUMMYFUNCTION("""COMPUTED_VALUE"""),"Aplicar conceptos de programación mediante ejercicios prácticos y laboratorios respetando estándares básicos de calidad de software ") -> Aplicar conceptos de programación mediante ejercicios prácticos y laboratorios respetando estándares básicos de calidad de software | D16: =IFERROR(__xludf.DUMMYFUNCTION("""COMPUTED_VALUE"""),"3. Introducción a Java") -> 3. Introducción a Java | E16: =IFERROR(__xludf.DUMMYFUNCTION("""COMPUTED_VALUE"""),"Introducción a Java - Parte 3") -> Introducción a Java - Parte 3 | F16: =IFERROR(__xludf.DUMMYFUNCTION("""COMPUTED_VALUE"""),"Características de Java") -> Características de Java | G16: =IFERROR(__xludf.DUMMYFUNCTION("""COMPUTED_VALUE"""),"Agosto") -> Agosto | H16: =IFERROR(__xludf.DUMMYFUNCTION("""COMPUTED_VALUE"""),4.0) -> 4
B17: =IFERROR(__xludf.DUMMYFUNCTION("""COMPUTED_VALUE"""),11.0) -> 11 | C17: =IFERROR(__xludf.DUMMYFUNCTION("""COMPUTED_VALUE"""),"Documentar programas desarrollados usando convenciones de codificación y comentarios estructurados para facilitar su comprensión y mantenimiento ") -> Documentar programas desarrollados usando convenciones de codificación y comentarios estructurados para facilitar su comprensión y mantenimiento | D17: =IFERROR(__xludf.DUMMYFUNCTION("""COMPUTED_VALUE"""),"3. Introducción a Java") -> 3. Introducción a Java | E17: =IFERROR(__xludf.DUMMYFUNCTION("""COMPUTED_VALUE"""),"Introducción a Java - Parte 4") -> Introducción a Java - Parte 4 | F17: =IFERROR(__xludf.DUMMYFUNCTION("""COMPUTED_VALUE"""),"Comentarios de una línea y multilínea") -> Comentarios de una línea y multilínea | G17: =IFERROR(__xludf.DUMMYFUNCTION("""COMPUTED_VALUE"""),"Agosto") -> Agosto | H17: =IFERROR(__xludf.DUMMYFUNCTION("""COMPUTED_VALUE"""),4.0) -> 4
B18: =IFERROR(__xludf.DUMMYFUNCTION("""COMPUTED_VALUE"""),12.0) -> 12 | C18: =IFERROR(__xludf.DUMMYFUNCTION("""COMPUTED_VALUE"""),"Implementar programas simples utilizando lenguaje de programación estructurado (JAVA) conforme a especificaciones dadas ") -> Implementar programas simples utilizando lenguaje de programación estructurado (JAVA) conforme a especificaciones dadas | D18: =IFERROR(__xludf.DUMMYFUNCTION("""COMPUTED_VALUE"""),"3. Introducción a Java") -> 3. Introducción a Java | E18: =IFERROR(__xludf.DUMMYFUNCTION("""COMPUTED_VALUE"""),"Introducción a Java - Parte 5") -> Introducción a Java - Parte 5 | F18: =IFERROR(__xludf.DUMMYFUNCTION("""COMPUTED_VALUE"""),"Variables") -> Variables | G18: =IFERROR(__xludf.DUMMYFUNCTION("""COMPUTED_VALUE"""),"Agosto") -> Agosto | H18: =IFERROR(__xludf.DUMMYFUNCTION("""COMPUTED_VALUE"""),4.0) -> 4
B19: =IFERROR(__xludf.DUMMYFUNCTION("""COMPUTED_VALUE"""),13.0) -> 13 | C19: =IFERROR(__xludf.DUMMYFUNCTION("""COMPUTED_VALUE"""),"Implementar programas simples utilizando lenguaje de programación estructurado (JAVA) conforme a especificaciones dadas ") -> Implementar programas simples utilizando lenguaje de programación estructurado (JAVA) conforme a especificaciones dadas | D19: =IFERROR(__xludf.DUMMYFUNCTION("""COMPUTED_VALUE"""),"3. Introducción a Java") -> 3. Introducción a Java | E19: =IFERROR(__xludf.DUMMYFUNCTION("""COMPUTED_VALUE"""),"Introducción a Java - Parte 6") -> Introducción a Java - Parte 6 | F19: =IFERROR(__xludf.DUMMYFUNCTION("""COMPUTED_VALUE"""),"Tipos primitivos y no primitivos") -> Tipos primitivos y no primitivos | G19: =IFERROR(__xludf.DUMMYFUNCTION("""COMPUTED_VALUE"""),"Agosto") -> Agosto | H19: =IFERROR(__xludf.DUMMYFUNCTION("""COMPUTED_VALUE"""),4.0) -> 4
B20: =IFERROR(__xludf.DUMMYFUNCTION("""COMPUTED_VALUE"""),14.0) -> 14 | C20: =IFERROR(__xludf.DUMMYFUNCTION("""COMPUTED_VALUE"""),"Implementar programas simples utilizando lenguaje de programación estructurado (JAVA) conforme a especificaciones dadas ") -> Implementar programas simples utilizando lenguaje de programación estructurado (JAVA) conforme a especificaciones dadas | D20: =IFERROR(__xludf.DUMMYFUNCTION("""COMPUTED_VALUE"""),"3. Introducción a Java") -> 3. Introducción a Java | E20: =IFERROR(__xludf.DUMMYFUNCTION("""COMPUTED_VALUE"""),"Introducción a Java - Parte 7") -> Introducción a Java - Parte 7 | F20: =IFERROR(__xludf.DUMMYFUNCTION("""COMPUTED_VALUE"""),"Casteos implícitos y explícitos") -> Casteos implícitos y explícitos | G20: =IFERROR(__xludf.DUMMYFUNCTION("""COMPUTED_VALUE"""),"Agosto") -> Agosto | H20: =IFERROR(__xludf.DUMMYFUNCTION("""COMPUTED_VALUE"""),4.0) -> 4
B21: =IFERROR(__xludf.DUMMYFUNCTION("""COMPUTED_VALUE"""),15.0) -> 15 | C21: =IFERROR(__xludf.DUMMYFUNCTION("""COMPUTED_VALUE"""),"Implementar programas simples utilizando lenguaje de programación estructurado (JAVA) conforme a especificaciones dadas ") -> Implementar programas simples utilizando lenguaje de programación estructurado (JAVA) conforme a especificaciones dadas | D21: =IFERROR(__xludf.DUMMYFUNCTION("""COMPUTED_VALUE"""),"3. Introducción a Java") -> 3. Introducción a Java | E21: =IFERROR(__xludf.DUMMYFUNCTION("""COMPUTED_VALUE"""),"Introducción a Java - Parte 2") -> Introducción a Java - Parte 2 | F21: =IFERROR(__xludf.DUMMYFUNCTION("""COMPUTED_VALUE"""),"Operadores aritméticos, relacionales y lógicos") -> Operadores aritméticos, relacionales y lógicos | G21: =IFERROR(__xludf.DUMMYFUNCTION("""COMPUTED_VALUE"""),"Agosto") -> Agosto | H21: =IFERROR(__xludf.DUMMYFUNCTION("""COMPUTED_VALUE"""),4.0) -> 4
B22: =IFERROR(__xludf.DUMMYFUNCTION("""COMPUTED_VALUE"""),16.0) -> 16 | C22: =IFERROR(__xludf.DUMMYFUNCTION("""COMPUTED_VALUE"""),"Implementar programas simples utilizando lenguaje de programación estructurado (JAVA) conforme a especificaciones dadas ") -> Implementar programas simples utilizando lenguaje de programación estructurado (JAVA) conforme a especificaciones dadas | D22: =IFERROR(__xludf.DUMMYFUNCTION("""COMPUTED_VALUE"""),"3. Introducción a Java") -> 3. Introducción a Java | E22: =IFERROR(__xludf.DUMMYFUNCTION("""COMPUTED_VALUE"""),"Introducción a Java - Parte 3") -> Introducción a Java - Parte 3 | F22: =IFERROR(__xludf.DUMMYFUNCTION("""COMPUTED_VALUE"""),"Input y output") -> Input y output | G22: =IFERROR(__xludf.DUMMYFUNCTION("""COMPUTED_VALUE"""),"Agosto") -> Agosto | H22: =IFERROR(__xludf.DUMMYFUNCTION("""COMPUTED_VALUE"""),4.0) -> 4
B23: =IFERROR(__xludf.DUMMYFUNCTION("""COMPUTED_VALUE"""),17.0) -> 17 | C23: =IFERROR(__xludf.DUMMYFUNCTION("""COMPUTED_VALUE"""),"Implementar programas simples utilizando lenguaje de programación estructurado (JAVA) conforme a especificaciones dadas ") -> Implementar programas simples utilizando lenguaje de programación estructurado (JAVA) conforme a especificaciones dadas | D23: =IFERROR(__xludf.DUMMYFUNCTION("""COMPUTED_VALUE"""),"3. Introducción a Java") -> 3. Introducción a Java | E23: =IFERROR(__xludf.DUMMYFUNCTION("""COMPUTED_VALUE"""),"Introducción a Java - Parte 4") -> Introducción a Java - Parte 4 | F23: =IFERROR(__xludf.DUMMYFUNCTION("""COMPUTED_VALUE"""),"Estructuras de control (if, else if, else y switch)") -> Estructuras de control (if, else if, else y switch) | G23: =IFERROR(__xludf.DUMMYFUNCTION("""COMPUTED_VALUE"""),"Agosto") -> Agosto | H23: =IFERROR(__xludf.DUMMYFUNCTION("""COMPUTED_VALUE"""),5.0) -> 5
B24: =IFERROR(__xludf.DUMMYFUNCTION("""COMPUTED_VALUE"""),18.0) -> 18 | C24: =IFERROR(__xludf.DUMMYFUNCTION("""COMPUTED_VALUE"""),"Implementar programas simples utilizando lenguaje de programación estructurado (JAVA) conforme a especificaciones dadas ") -> Implementar programas simples utilizando lenguaje de programación estructurado (JAVA) conforme a especificaciones dadas | D24: =IFERROR(__xludf.DUMMYFUNCTION("""COMPUTED_VALUE"""),"3. Introducción a Java") -> 3. Introducción a Java | E24: =IFERROR(__xludf.DUMMYFUNCTION("""COMPUTED_VALUE"""),"Introducción a Java - Parte 5") -> Introducción a Java - Parte 5 | F24: =IFERROR(__xludf.DUMMYFUNCTION("""COMPUTED_VALUE"""),"Ciclos (for, while, do-while)") -> Ciclos (for, while, do-while) | G24: =IFERROR(__xludf.DUMMYFUNCTION("""COMPUTED_VALUE"""),"Agosto") -> Agosto | H24: =IFERROR(__xludf.DUMMYFUNCTION("""COMPUTED_VALUE"""),5.0) -> 5
B25: =IFERROR(__xludf.DUMMYFUNCTION("""COMPUTED_VALUE"""),19.0) -> 19 | C25: =IFERROR(__xludf.DUMMYFUNCTION("""COMPUTED_VALUE"""),"Aplicar conceptos de programación mediante ejercicios prácticos y laboratorios respetando estándares básicos de calidad de software ") -> Aplicar conceptos de programación mediante ejercicios prácticos y laboratorios respetando estándares básicos de calidad de software | D25: =IFERROR(__xludf.DUMMYFUNCTION("""COMPUTED_VALUE"""),"3. Introducción a Java") -> 3. Introducción a Java | E25: =IFERROR(__xludf.DUMMYFUNCTION("""COMPUTED_VALUE"""),"Introducción a Java - Parte 6") -> Introducción a Java - Parte 6 | F25: =IFERROR(__xludf.DUMMYFUNCTION("""COMPUTED_VALUE"""),"Try-catch-finally") -> Try-catch-finally | G25: =IFERROR(__xludf.DUMMYFUNCTION("""COMPUTED_VALUE"""),"Agosto") -> Agosto | H25: =IFERROR(__xludf.DUMMYFUNCTION("""COMPUTED_VALUE"""),5.0) -> 5
B26: =IFERROR(__xludf.DUMMYFUNCTION("""COMPUTED_VALUE"""),20.0) -> 20 | C26: =IFERROR(__xludf.DUMMYFUNCTION("""COMPUTED_VALUE"""),"Aplicar conceptos de programación mediante ejercicios prácticos y laboratorios respetando estándares básicos de calidad de software ") -> Aplicar conceptos de programación mediante ejercicios prácticos y laboratorios respetando estándares básicos de calidad de software | D26: =IFERROR(__xludf.DUMMYFUNCTION("""COMPUTED_VALUE"""),"3. Introducción a Java") -> 3. Introducción a Java | E26: =IFERROR(__xludf.DUMMYFUNCTION("""COMPUTED_VALUE"""),"Introducción a Java - Parte 7") -> Introducción a Java - Parte 7 | F26: =IFERROR(__xludf.DUMMYFUNCTION("""COMPUTED_VALUE"""),"Procedimientos y funciones") -> Procedimientos y funciones | G26: =IFERROR(__xludf.DUMMYFUNCTION("""COMPUTED_VALUE"""),"Agosto") -> Agosto | H26: =IFERROR(__xludf.DUMMYFUNCTION("""COMPUTED_VALUE"""),5.0) -> 5
