Workbook

Sheet Diseño
A2: =VALUE(LEFT(C4,FIND(" - ",C4)-1)) -> 285 | B2: Diseño de Contenido Curricular
B4: Curso | C4: 285 - Sistemas Operativos 2
B5: Periodo al que aplica | C5: Primer Semestre 2026
B8: No. | C8: Competencia | D8: Nombre de la Unidad | E8: Tema | F8: Subtema | G8: Mes | H8: Semana
B9: 1 | C9: El estudiante describe la arquitectura y los componentes fundamentales de un S.O. analizando la separación entre el espacio de usuario y el espacio de kernel para establecer las bases conceptuales necesarias para la modificación del sistema. | D9: Introducción y Configuración del Entorno | E9: Fundamentos de Sistemas Operativos | F9: Repaso de conceptos clave de SO. Introducción a la arquitectura del kernel linux | H9: 2
B10: 2 | C10: El estudiante describe la arquitectura y los componentes fundamentales de un S.O. analizando la separación entre el espacio de usuario y el espacio de kernel para establecer las bases conceptuales necesarias para la modificación del sistema. | D10: Introducción y Configuración del Entorno | E10: Virtualización y Preparación | F10: Introducción al kernel USAX. Configuración del entorno con QEMU y el toolchain de compilación cruzada. | H10: 2
B11: 3 | C11: El estudiante describe la arquitectura y los componentes fundamentales de un S.O. analizando la separación entre el espacio de usuario y el espacio de kernel para establecer las bases conceptuales necesarias para la modificación del sistema. | D11: Introducción y Configuración del Entorno | E11: Arranque y Depuración del Kernel | F11: Proceso de arranque de USAX en QEMU. Uso de GDB para depuración remota: puntos de ruptura, inspección de memoria y registros. | H11: 3
B12: 4 | C12: El estudiante interpreta el flujo de ejecución y las interacciones clave dentro de un kernel mediante la compilación, ejecución y depuración del código fuente del kernel para comprender cómo el sistema operativo gestiona el hardware y los procesos desde el arranque. | D12: Gestión de Memoria | E12: Memoria Física y Virtual | F12: Proceso de arranque del kernel. Gestión de memoria física (mapa de memoria, alocadores básicos). Paginación y tablas de páginas. | H12: 4
B13: 5 | C13: El estudiante interpreta el flujo de ejecución y las interacciones clave dentro de un kernel mediante la compilación, ejecución y depuración del código fuente del kernel para comprender cómo el sistema operativo gestiona el hardware y los procesos desde el arranque. | D13: Gestión de Memoria | E13: Aislamiento y Espacio de Direcciones | F13: Traducción de direcciones. Separación entre el espacio de usuario y el espacio de kernel. | H13: 4
B14: 6 | C14: El estudiante interpreta el flujo de ejecución y las interacciones clave dentro de un kernel mediante la compilación, ejecución y depuración del código fuente del kernel para comprender cómo el sistema operativo gestiona el hardware y los procesos desde el arranque. | D14: Procesos e Interacción | E14: Estructura y Ciclo de Vida de un Proceso | F14: El Process Control Block (task_struct). Estados (Running, Sleeping, Zombie, etc.) y transiciones de un proceso. | H14: 5
B15: 7 | C15: El estudiante modifica el código fuente del kernel en lenguaje C para implementar nuevas llamadas al sistema (syscalls) que exponen funcionalidades y transfieren datos de forma segura entre el espacio de kernel y el de usuario. | D15: Procesos e Interacción | E15: La Interfaz de Llamadas al Sistema | F15: Mecanismo de traps. Implementación de una syscall hello_world() directamente en el kernel para validar la comunicación. | H15: 5
B16: 8 | C16: El estudiante modifica el código fuente del kernel en lenguaje C para implementar nuevas llamadas al sistema (syscalls) que exponen funcionalidades y transfieren datos de forma segura entre el espacio de kernel y el de usuario. | D16: Procesos e Interacción | E16: Modularizando el Kernel (LKM) | F16: Introducción a los Módulos Cargables del Kernel. Ventajas de la modularidad. Migración de la syscall hello_world() a un módulo. | H16: 6
B17: 9 | C17: El estudiante modifica el código fuente del kernel en lenguaje C para implementar nuevas llamadas al sistema (syscalls) que exponen funcionalidades y transfieren datos de forma segura entre el espacio de kernel y el de usuario. | D17: Procesos e Interacción | E17: Primer Programa Cliente | F17: Creación de un programa en C que invoca la syscall hello_world() desde el espacio de usuario. | H17: 6
B18: 10 | C18: El estudiante modifica el código fuente del kernel en lenguaje C para implementar nuevas llamadas al sistema (syscalls) que exponen funcionalidades y transfieren datos de forma segura entre el espacio de kernel y el de usuario. | D18: Procesos e Interacción | E18: Transferencia de Datos Estructurados | F18: Transfiriendo datos complejos del kernel al espacio de usuario. | H18: 7
B19: 11 | C19: El estudiante analiza las estructuras de datos internas del kernel que gestionan procesos, memoria y tiempo mediante la lectura e interpretación de su código fuente para extraer métricas de rendimiento y estado del sistema, como la lista de procesos o el uso de CPU. | D19: Monitoreo del Sistema | E19: Estructura de un proceso | F19: Estructuras del kernel para obtener campos clave de procesos como PID, estado, PPID. | G19: - | H19: 7
B20: 12 | C20: El estudiante analiza las estructuras de datos internas del kernel que gestionan procesos, memoria y tiempo mediante la lectura e interpretación de su código fuente para extraer métricas de rendimiento y estado del sistema, como la lista de procesos o el uso de CPU. | D20: Monitoreo del Sistema | E20: Concurrencia y Lectura Segura de Datos | F20: El problema de las condiciones de carrera al leer datos del kernel. Introducción a primitivas de sincronización. | H20: 8
B21: 13 | C21: El estudiante analiza las estructuras de datos internas del kernel que gestionan procesos, memoria y tiempo mediante la lectura e interpretación de su código fuente para extraer métricas de rendimiento y estado del sistema, como la lista de procesos o el uso de CPU. | D21: Monitoreo del Sistema | E21: Medición de Tiempo y Carga del Sistema | F21: Estructuras del kernel para obtener el tiempo de actividad (uptime) y la carga promedio (load average). | H21: 8
B22: 14 | C22: El estudiante analiza las estructuras de datos internas del kernel que gestionan procesos, memoria y tiempo mediante la lectura e interpretación de su código fuente para extraer métricas de rendimiento y estado del sistema, como la lista de procesos o el uso de CPU. | D22: Monitoreo del Sistema | E22: Medición de Memoria y Procesos | F22: Estructuras del kernel para obtener el uso total/libre de memoria y el número de procesos activos. | H22: 9
B23: 15 | C23: El estudiante analiza las estructuras de datos internas del kernel que gestionan procesos, memoria y tiempo mediante la lectura e interpretación de su código fuente para extraer métricas de rendimiento y estado del sistema, como la lista de procesos o el uso de CPU. | D23: Monitoreo del Sistema | E23: Procesos en ejecucion | F23: Listado de procesos: Aprender a iterar la lista de tareas del kernel (usando for_each_process) | H23: 9
B24: 16 | C24: El estudiante analiza las estructuras de datos internas del kernel que gestionan procesos, memoria y tiempo mediante la lectura e interpretación de su código fuente para extraer métricas de rendimiento y estado del sistema, como la lista de procesos o el uso de CPU. | D24: Monitoreo del Sistema | E24: Métricas Complejas de CPU | F24: Cálculo del uso de CPU: Entender los "jiffies" y las estadísticas por CPU. Investigar las estructuras del kernel para obtener los tiempos de CPU (usuario, sistema, idle). | H24: 10
B25: 17 | C25: El estudiante diseña aplicaciónes en espacio de usuario integrando las llamadas al sistema para generar funcionalidad y expandir las capacidades del sistema operativo que el usuario puede aprovechar | D25: Alternativas de Comunicación | E25: El Sistema de Archivos /proc | F25: Fundamentos del sistema de archivos /proc. Comparativa entre syscalls y la exportación de datos a través de archivos virtuales. | H25: 10
B26: 18 | C26: El estudiante diseña aplicaciónes en espacio de usuario integrando las llamadas al sistema para generar funcionalidad y expandir las capacidades del sistema operativo que el usuario puede aprovechar | D26: Alternativas de Comunicación | E26: Exposicion de datos vía /proc | F26: Análisis de /proc/meminfo y /proc/stat y cómo exponer estas métricas en el kernel | H26: 11

Sheet Semana Diagnostico
B2: Diseño de Contenido Curricular
B4: Curso | C4: ='Diseño'!C4 -> 285 - Sistemas Operativos 2
B5: Semana | C5: 1
B6: Tiempo | C6: =B15+B22+B29+B41+B47+C48 -> 100
A9: 1. Bienvenida y Presentación | G9: Tiempo Aproximado | H9: =B15 -> 15
G10: No puedes excederte mas de 15 minutos
A11: Nombre y Formacion Academica | B11: Explicar en que semestre me encuentro, que cursos llevo
A12: Experiencia docente y profecional | B12: Explicar cuantos semestres de auxiliatura llevo, si tengo alguna otra experiencia enseñando o trabajando en mi area | K12: Estos puntos son recomendaciones de los puntos a tratar durante tu presentacion, si no usaras estos eres libre de agregar mas filas para indicar que haras. En los recuadros de la derecha colocar breve resumen de lo que planeas decir. No debes ser muy especifico seran pequeñas anotaciones que te ayudaran a recordar lo que planeaste
A13: Rol del auxiliar dentro del curso (funciones, actividades y apoyo a los estudiantes). | B13: Explicar mi rol, que hare durante el semestre, como contactarme, como resolver dudas
A14: Expectativas sobre la dinámica del curso | B14: Explicar que se aprendera en el curso
A15: Tiempo que emplearas | B15: 15
A18: 2. Evaluación de Conocimientos Previos | G18: Tiempo Aproximado | H18: =B22 -> 25 | K18: En los recuadors de la derecha deberas colocar las preguntas que planeas realizar con sus respectivas respuestas. En el segundo recuadro deberas colocar un breve resumne de lo que tines planificado para la parte practica del curso previo al que estas impartiendo.
G19: No puedes excederte mas de 45 minutos
A20: Redactaras de 15 a 20 preguntas con sus respectivas respuestas , por lo que debes escoge los temas que evaluaras | B20: Se hara un cuestionario en kahoot con 20 preguntas, el mismo se encuentra en el portal de kahoot, usando las credenciales de sopes2
A21: Redactaras una parte practica | B21: Se realizaran ejemplos guiados durante las clases y se dejaran practicas que permitan progresivamente preparlos para el proyecto
A22: Tiempo que emplearas | B22: 25
A25: 3. Presentación de los Estudiantes | G25: Tiempo Aproximado | H25: =B29 -> 30
G26: No puedes excederte mas de 30 minutos
A27: Seleccion al Azar de 5 Estudiantes | B27: Se dara oportunidad de presentarse voluntariamente o se escogera al azar en base a la lista de conectados de meet | K27: En el primer recuadro colocaras la metodollogia que adoptaras para la eleccion de los estudiantes. En el segundo recuadro colocaras la redaccion de las preguntas que comprendan los siguientes puntos respecto al estudiante: Nombre. Intereses y expectativas sobre el curso. Experiencia previa relacionada con el curso (si aplica). Un dato curioso sobre sí mismo. Consideras que la prueba de conociminetos previos esta acorde al conocimiento que se te brindo en su momento Que tan comodo se sintio con la prueba anterior.
A28: Preguntas que responderan los estudiantes afortunados | B28: Cual es su nombre, si tienen alguna experiencia laborar, y su expectativa o idea de lo que tratara el curso
A29: Tiempo que emplearas | B29: 30
A32: 4. Senso de Horarios de Calificación | G32: Tiempo Aproximado | H32: =B36 -> 5
A33: Deberas estar recordando que deben contestar el formulario asi mismo dejar el link fijado en la llamada | G33: Esta actividad quedara abierta hasta el fin de la clase. pero emplearas 5 min especificos para la actividad
A34: Link de google forms donde este el cuestionario | B34: El link se generará en base a la disponibilidad del auxiliar de turno | K34: Esta actividad te ayudara a realizar un senso de posibles horarios de calificacion y que tus estudiantes esten enterados y puedan preveer los dias de calificacion y asi mismo el horario. Deberas colocar en los reacuadros de la derecha link de Google form libre para correos intitucionales, esto para garantizar una sola respuesta por estudiante. TAmbien deberas colocar los posibles horarios y dias que tentativamente tendrias disponibles. para colocarlos en el google form.
A35: Dias y posibles Horarios de calificacion
A36: Tiempo que emplearas | B36: 5
A39: 4. Mostrar Programa del Curso | G39: Tiempo Aproximado | H39: =B41 -> 15
G40: No puedes excederte mas de 30 minutos
A41: Tiempo que emplearas | B41: 15
A44: 2. Evaluación de Conocimientos del Curso Actual | G44: Tiempo Aproximado | H44: =B47 -> 15
G45: No puedes excederte mas de 15 minutos
A46: Redactaras 20 preguntas con sus respectivas respuestas | B46: Cuestionario disponible en kahoot usando las credenciales de sopes2
A47: Tiempo que emplearas | B47: 15

Sheet S.2
B2: Diseño de la Sesión de Laboratorio
B4: Curso | C4: ='Diseño'!C4 -> 285 - Sistemas Operativos 2
B5: Semana | C5: 2
B6: Tiempo | C6: =H10+H21+H44+H68 -> 100
B7: Ponderación | C7: =B49+B60 -> 0
B8: Validación de Tiempo | C8: =IF(H44<=0, "❌ ERROR: La Actividad 1 debe tener un tiempo mayor a 0.", IF(H21>60, "❌ ERROR: El 'Área de Conocimiento' no puede exceder los 60 min.", IF((H10+H21+H44)<100, "❌ ERROR: El tiempo total debe ser de al menos 100 min.", "✅ VALIDACIÓN CORRECTA"))) -> ❌ ERROR: El tiempo total debe ser de al menos 100 min.
A10: 1. Área Actitudinal (Saber Ser) | G10: Tiempo Aproximado | H10: =B13 -> 5
G11: Tiene que estar en un rango de 3 a 5 minutos
A12: Nombre del Valor | B12: Responsabilidad
A13: Tiempo Aproximado | B13: 5
A14: Descripcion
A15: Cumplir con los compromisos y obligaciones asumidas, respondiendo por las consecuencias de las propias acciones y decisiones.
A17: Como se relaciona con los conocimientos de la sesion y se aplicaria
A18: En contexto de programas libres como linux, se trata de codigo fuente de un sistema critico como linux, por lo que las modificaciones deben ser responsables y nunca con fines negativos.
A21: 2. Área Conocimiento (Saber) | G21: Tiempo Aproximado | H21: =D39+D40+D41+D42 -> 55
G22: No puede exceder los 60 minutos
A23: Competencia a desarrollar | B23: El estudiante describe la arquitectura y los componentes fundamentales de un S.O. analizando la separación entre el espacio de usuario y el espacio de kernel para establecer las bases conceptuales necesarias para la modificación del sistema.
A24: Competencia a desarrollar | B24: El estudiante describe la arquitectura y los componentes fundamentales de un S.O. analizando la separación entre el espacio de usuario y el espacio de kernel para establecer las bases conceptuales necesarias para la modificación del sistema.
A26: 2.1 Contenido
A27: No. | B27: Unidad | D27: Tema | F27: Sub Tema
A28: 1 | B28: =IFERROR(__xludf.DUMMYFUNCTION("FILTER('Diseño'!D:D,'Diseño'!H:H=$C$5)"),"Introducción y Configuración del Entorno") -> Introducción y Configuración del Entorno | D28: =IFERROR(__xludf.DUMMYFUNCTION("FILTER('Diseño'!E:E,'Diseño'!H:H=$C$5)"),"Fundamentos de Sistemas Operativos") -> Fundamentos de Sistemas Operativos | F28: =IFERROR(__xludf.DUMMYFUNCTION("FILTER('Diseño'!F:F,'Diseño'!H:H=$C$5)"),"Repaso de conceptos clave de SO. Introducción a la arquitectura del kernel linux") -> Repaso de conceptos clave de SO. Introducción a la arquitectura del kernel linux
A29: 2 | B29: =IFERROR(__xludf.DUMMYFUNCTION("""COMPUTED_VALUE"""),"Introducción y Configuración del Entorno") -> Introducción y Configuración del Entorno | D29: =IFERROR(__xludf.DUMMYFUNCTION("""COMPUTED_VALUE"""),"Virtualización y Preparación") -> Virtualización y Preparación | F29: =IFERROR(__xludf.DUMMYFUNCTION("""COMPUTED_VALUE"""),"Introducción al kernel USAX. Configuración del entorno con QEMU y el toolchain de compilación cruzada.") -> Introducción al kernel USAX. Configuración del entorno con QEMU y el toolchain de compilación cruzada.
A30: 3
A31: 4
A32: 5
A33: 6
A34: 7
A36: 2.2 Recursos Educativos
A38: Tipo de Recurso a utilizar | B38: Tipo | C38: Rango Aproximando | D38: Tiempo Aproximado
A39: Presentacion | B39: Obligatorio | D39: 25
A40: Video | B40: Obligatorio | C40: 3 a 6 minutos | D40: 5
A41: Lectura | B41: Optativo | D41: 0
A42: Ejercicio Demostrativo | B42: Obligatorio | D42: 25
A44: 3. Área de Habilidades (Saber Hacer) | G44: Tiempo Aproximado | H44: =B50+B61 -> 30
G45: Tiene que estar en un rango de 30 a 50 minutos
A46: Actividad 1 (Obligatoria)
A47: Competencia que predomina en la actividad | B47: El estudiante explica la historia de GNU/Linux usando puntos clave en el desarrollo del mismo para entender su origen y popularidad como sistema operativo libre
A48: Tipo de Actividad | B48: Cuestionario
A49: Ponderación | B49: 0
A50: Tiempo Aproximado | B50: 5
...

Sheet S.3
B2: Diseño de la Sesión de Laboratorio
B4: Curso | C4: ='Diseño'!C4 -> 285 - Sistemas Operativos 2
B5: Semana | C5: 3
B6: Tiempo | C6: =H10+H21+H44+H68 -> 90
B7: Ponderación | C7: =B49+B60 -> 0
B8: Validación de Tiempo | C8: =IF(H44<=0, "❌ ERROR: La Actividad 1 debe tener un tiempo mayor a 0.", IF(H21>60, "❌ ERROR: El 'Área de Conocimiento' no puede exceder los 60 min.", IF((H10+H21+H44)<100, "❌ ERROR: El tiempo total debe ser de al menos 100 min.", "✅ VALIDACIÓN CORRECTA"))) -> ❌ ERROR: El tiempo total debe ser de al menos 100 min.
A10: 1. Área Actitudinal (Saber Ser) | G10: Tiempo Aproximado | H10: =B13 -> 5
G11: Tiene que estar en un rango de 3 a 5 minutos
A12: Nombre del Valor | B12: Pensamiento Critico
A13: Tiempo Aproximado | B13: =S.2!B13 -> 5
A14: Descripcion
A15: Analizar y evaluar información de manera objetiva, cuestionando supuestos y buscando evidencias antes de llegar a una conclusión.
A17: Como se relaciona con los conocimientos de la sesion y se aplicaria
A18: Es posible que el estudiante se enfrente por primera vez, ya sea a descubrir y modificar el codigo del kernel de linux, o bien a modificarlo tan a fondo, es importante que fortalezca su pensamiento critico, enfocandose en este nuevo reto.
A21: 2. Área Conocimiento (Saber) | G21: Tiempo Aproximado | H21: =D39+D40+D41+D42 -> 55
G22: No puede exceder los 60 minutos
A23: Competencia a desarrollar | B23: El estudiante describe la arquitectura y los componentes fundamentales de un S.O. analizando la separación entre el espacio de usuario y el espacio de kernel para establecer las bases conceptuales necesarias para la modificación del sistema.
A24: Competencia a desarrollar | B24: El estudiante describe la arquitectura y los componentes fundamentales de un S.O. analizando la separación entre el espacio de usuario y el espacio de kernel para establecer las bases conceptuales necesarias para la modificación del sistema.
A26: 2.1 Contenido
A27: No. | B27: Unidad | D27: Tema | F27: Sub Tema
A28: 1 | B28: =IFERROR(__xludf.DUMMYFUNCTION("FILTER('Diseño'!D:D,'Diseño'!H:H=$C$5)"),"Introducción y Configuración del Entorno") -> Introducción y Configuración del Entorno | D28: =IFERROR(__xludf.DUMMYFUNCTION("FILTER('Diseño'!E:E,'Diseño'!H:H=$C$5)"),"Arranque y Depuración del Kernel") -> Arranque y Depuración del Kernel | F28: =IFERROR(__xludf.DUMMYFUNCTION("FILTER('Diseño'!F:F,'Diseño'!H:H=$C$5)"),"Proceso de arranque de USAX en QEMU. Uso de GDB para depuración remota: puntos de ruptura, inspección de memoria y registros.") -> Proceso de arranque de USAX en QEMU. Uso de GDB para depuración remota: puntos de ruptura, inspección de memoria y registros.
A29: 2
A30: 3
A31: 4
A32: 5
A33: 6
A34: 7
A36: 2.2 Recursos Educativos
A38: Tipo de Recurso a utilizar | B38: Tipo | C38: Rango Aproximando | D38: Tiempo Aproximado
A39: Presentacion | B39: Obligatorio | D39: 25
A40: Video | B40: Obligatorio | C40: 3 a 6 minutos | D40: 5
A41: Lectura | B41: Optativo | D41: 0
A42: Ejercicio Demostrativo | B42: Obligatorio | D42: 25
A44: 3. Área de Habilidades (Saber Hacer) | G44: Tiempo Aproximado | H44: =B50+B61 -> 30
G45: Tiene que estar en un rango de 30 a 50 minutos
A46: Actividad 1 (Obligatoria)
A47: Competencia que predomina en la actividad | B47: El estudiante comprende la estructura fundamental de un sistema operativo mediante el analisis del codigo fuente del kernel Linux para comprender como este gestion y administra los programas de usuario
A48: Tipo de Actividad | B48: =S.2!B48 -> Cuestionario
A49: Ponderación | B49: 0
A50: Tiempo Aproximado | B50: =S.2!B50 -> 5
...

Sheet S.4
B2: Diseño de la Sesión de Laboratorio
B4: Curso | C4: ='Diseño'!C4 -> 285 - Sistemas Operativos 2
B5: Semana | C5: 4
B6: Tiempo | C6: =H10+H21+H44+H68 -> 100
B7: Ponderación | C7: =B49+B60 -> 0
B8: Validación de Tiempo | C8: =IF(H44<=0, "❌ ERROR: La Actividad 1 debe tener un tiempo mayor a 0.", IF(H21>60, "❌ ERROR: El 'Área de Conocimiento' no puede exceder los 60 min.", IF((H10+H21+H44)<100, "❌ ERROR: El tiempo total debe ser de al menos 100 min.", "✅ VALIDACIÓN CORRECTA"))) -> ❌ ERROR: El tiempo total debe ser de al menos 100 min.
A10: 1. Área Actitudinal (Saber Ser) | G10: Tiempo Aproximado | H10: =B13 -> 5
G11: Tiene que estar en un rango de 3 a 5 minutos
A12: Nombre del Valor | B12: Consistencia
A13: Tiempo Aproximado | B13: =S.2!B13 -> 5
A14: Descripcion
A15: Mantener coherencia entre lo que se piensa, se dice y se hace, reflejando estabilidad y credibilidad en las acciones.
A17: Como se relaciona con los conocimientos de la sesion y se aplicaria
A18: El estudiante debe ser consistente en su participacion, en este punto (y varios mas adelante) sera necesario utilizar el cajon de herramientas que vamos formando con cada nuevo tema, el estudiante debe demostrar consistencia en su aprendizaje y el curso para poder avanzar de manera adecuada.
A21: 2. Área Conocimiento (Saber) | G21: Tiempo Aproximado | H21: =D39+D40+D41+D42 -> 55
G22: No puede exceder los 60 minutos
A23: Competencia a desarrollar | B23: El estudiante interpreta el flujo de ejecución y las interacciones clave dentro de un kernel mediante la compilación, ejecución y depuración del código fuente del kernel para comprender cómo el sistema operativo gestiona el hardware y los procesos desde el arranque.
A24: Competencia a desarrollar | B24: El estudiante interpreta el flujo de ejecución y las interacciones clave dentro de un kernel mediante la compilación, ejecución y depuración del código fuente del kernel para comprender cómo el sistema operativo gestiona el hardware y los procesos desde el arranque.
A26: 2.1 Contenido
A27: No. | B27: Unidad | D27: Tema | F27: Sub Tema
A28: 1 | B28: =IFERROR(__xludf.DUMMYFUNCTION("FILTER('Diseño'!D:D,'Diseño'!H:H=$C$5)"),"Gestión de Memoria") -> Gestión de Memoria | D28: =IFERROR(__xludf.DUMMYFUNCTION("FILTER('Diseño'!E:E,'Diseño'!H:H=$C$5)"),"Memoria Física y Virtual") -> Memoria Física y Virtual | F28: =IFERROR(__xludf.DUMMYFUNCTION("FILTER('Diseño'!F:F,'Diseño'!H:H=$C$5)"),"Proceso de arranque del kernel. Gestión de memoria física (mapa de memoria, alocadores básicos). Paginación y tablas de páginas.") -> Proceso de arranque del kernel. Gestión de memoria física (mapa de memoria, alocadores básicos). Paginación y tablas de páginas.
A29: 2 | B29: =IFERROR(__xludf.DUMMYFUNCTION("""COMPUTED_VALUE"""),"Gestión de Memoria") -> Gestión de Memoria | D29: =IFERROR(__xludf.DUMMYFUNCTION("""COMPUTED_VALUE"""),"Aislamiento y Espacio de Direcciones") -> Aislamiento y Espacio de Direcciones | F29: =IFERROR(__xludf.DUMMYFUNCTION("""COMPUTED_VALUE"""),"Traducción de direcciones. Separación entre el espacio de usuario y el espacio de kernel.") -> Traducción de direcciones. Separación entre el espacio de usuario y el espacio de kernel.
A30: 3
A31: 4
A32: 5
A33: 6
A34: 7
A36: 2.2 Recursos Educativos
A38: Tipo de Recurso a utilizar | B38: Tipo | C38: Rango Aproximando | D38: Tiempo Aproximado
A39: Presentacion | B39: Obligatorio | D39: 25
A40: Video | B40: Obligatorio | C40: 3 a 6 minutos | D40: 5
A41: Lectura | B41: Optativo | D41: 0
A42: Ejercicio Demostrativo | B42: Obligatorio | D42: 25
A44: 3. Área de Habilidades (Saber Hacer) | G44: Tiempo Aproximado | H44: =B50+B61 -> 30
G45: Tiene que estar en un rango de 30 a 50 minutos
A46: Actividad 1 (Obligatoria)
A47: Competencia que predomina en la actividad | B47: El estudiante comprende la estructura fundamental de un sistema operativo mediante el analisis del codigo fuente del kernel Linux para comprender como este gestion y administra los programas de usuario
A48: Tipo de Actividad | B48: =S.2!B48 -> Cuestionario
A49: Ponderación | B49: 0
A50: Tiempo Aproximado | B50: =S.2!B50 -> 5
...

Sheet S.5
B2: Diseño de la Sesión de Laboratorio
B4: Curso | C4: ='Diseño'!C4 -> 285 - Sistemas Operativos 2
B5: Semana | C5: 5
B6: Tiempo | C6: =H10+H21+H44+H68 -> 100
B7: Ponderación | C7: =B49+B60 -> 0
B8: Validación de Tiempo | C8: =IF(H44<=0, "❌ ERROR: La Actividad 1 debe tener un tiempo mayor a 0.", IF(H21>60, "❌ ERROR: El 'Área de Conocimiento' no puede exceder los 60 min.", IF((H10+H21+H44)<100, "❌ ERROR: El tiempo total debe ser de al menos 100 min.", "✅ VALIDACIÓN CORRECTA"))) -> ❌ ERROR: El tiempo total debe ser de al menos 100 min.
A10: 1. Área Actitudinal (Saber Ser) | G10: Tiempo Aproximado | H10: =B13 -> 5
G11: Tiene que estar en un rango de 3 a 5 minutos
A12: Nombre del Valor | B12: Diciplina
A13: Tiempo Aproximado | B13: =S.2!B13 -> 5
A14: Descripcion
A15: Seguir normas, métodos y hábitos de manera constante para alcanzar metas con esfuerzo y autocontrol.
A17: Como se relaciona con los conocimientos de la sesion y se aplicaria
A18: Trabajar con hilos y estructuras concurrentes, se cultiva diciplina y un pensamiento ordenado, que es fundamental para el diseño de sistemas.
A21: 2. Área Conocimiento (Saber) | G21: Tiempo Aproximado | H21: =D39+D40+D41+D42 -> 55
G22: No puede exceder los 60 minutos
A23: Competencia a desarrollar | B23: El estudiante interpreta el flujo de ejecución y las interacciones clave dentro de un kernel mediante la compilación, ejecución y depuración del código fuente del kernel para comprender cómo el sistema operativo gestiona el hardware y los procesos desde el arranque.
A24: Competencia a desarrollar | B24: El estudiante modifica el código fuente del kernel en lenguaje C para implementar nuevas llamadas al sistema (syscalls) que exponen funcionalidades y transfieren datos de forma segura entre el espacio de kernel y el de usuario.
A26: 2.1 Contenido
A27: No. | B27: Unidad | D27: Tema | F27: Sub Tema
A28: 1 | B28: =IFERROR(__xludf.DUMMYFUNCTION("FILTER('Diseño'!D:D,'Diseño'!H:H=$C$5)"),"Procesos e Interacción") -> Procesos e Interacción | D28: =IFERROR(__xludf.DUMMYFUNCTION("FILTER('Diseño'!E:E,'Diseño'!H:H=$C$5)"),"Estructura y Ciclo de Vida de un Proceso") -> Estructura y Ciclo de Vida de un Proceso | F28: =IFERROR(__xludf.DUMMYFUNCTION("FILTER('Diseño'!F:F,'Diseño'!H:H=$C$5)"),"El Process Control Block (task_struct). Estados (Running, Sleeping, Zombie, etc.) y transiciones de un proceso.") -> El Process Control Block (task_struct). Estados (Running, Sleeping, Zombie, etc.) y transiciones de un proceso.
A29: 2 | B29: =IFERROR(__xludf.DUMMYFUNCTION("""COMPUTED_VALUE"""),"Procesos e Interacción") -> Procesos e Interacción | D29: =IFERROR(__xludf.DUMMYFUNCTION("""COMPUTED_VALUE"""),"La Interfaz de Llamadas al Sistema") -> La Interfaz de Llamadas al Sistema | F29: =IFERROR(__xludf.DUMMYFUNCTION("""COMPUTED_VALUE"""),"Mecanismo de traps. Implementación de una syscall hello_world() directamente en el kernel para validar la comunicación.") -> Mecanismo de traps. Implementación de una syscall hello_world() directamente en el kernel para validar la comunicación.
A30: 3
A31: 4
A32: 5
A33: 6
A34: 7
A36: 2.2 Recursos Educativos
A38: Tipo de Recurso a utilizar | B38: Tipo | C38: Rango Aproximando | D38: Tiempo Aproximado
A39: Presentacion | B39: Obligatorio | D39: 25
A40: Video | B40: Obligatorio | C40: 3 a 6 minutos | D40: 5
A41: Lectura | B41: Optativo | D41: 0
A42: Ejercicio Demostrativo | B42: Obligatorio | D42: 25
A44: 3. Área de Habilidades (Saber Hacer) | G44: Tiempo Aproximado | H44: =B50+B61 -> 30
G45: Tiene que estar en un rango de 30 a 50 minutos
A46: Actividad 1 (Obligatoria)
A47: Competencia que predomina en la actividad | B47: El estudiante desarrolla nuevos programas usando sus conocimientos en hilos y sincronizacion que hacen uso eficiente y optimo de los recursos del sistema
A48: Tipo de Actividad | B48: =S.2!B48 -> Cuestionario
A49: Ponderación | B49: 0
A50: Tiempo Aproximado | B50: =S.2!B50 -> 5
...

Sheet S.6
B2: Diseño de la Sesión de Laboratorio
B4: Curso | C4: ='Diseño'!C4 -> 285 - Sistemas Operativos 2
B5: Semana | C5: 6
B6: Tiempo | C6: =H10+H21+H44+H68 -> 100
B7: Ponderación | C7: =B49+B60 -> 0
B8: Validación de Tiempo | C8: =IF(H44<=0, "❌ ERROR: La Actividad 1 debe tener un tiempo mayor a 0.", IF(H21>60, "❌ ERROR: El 'Área de Conocimiento' no puede exceder los 60 min.", IF((H10+H21+H44)<100, "❌ ERROR: El tiempo total debe ser de al menos 100 min.", "✅ VALIDACIÓN CORRECTA"))) -> ❌ ERROR: El tiempo total debe ser de al menos 100 min.
A10: 1. Área Actitudinal (Saber Ser) | G10: Tiempo Aproximado | H10: =B13 -> 5
G11: Tiene que estar en un rango de 3 a 5 minutos
A12: Nombre del Valor | B12: Criterio y toma de decisiones
A13: Tiempo Aproximado | B13: =S.2!B13 -> 5
A14: Descripcion
A15: Capacidad de evaluar alternativas y seleccionar la opción más adecuada con base en la razón, la experiencia y la información disponible.
A17: Como se relaciona con los conocimientos de la sesion y se aplicaria
A18: Al enfrentarse a probleams como condiciones de carrera, la sincronizacion de procesos es necesario, esto significa que el estudiante debe formar un criterio para decidir de manera responsable que herramientas y metodos utilizar considerando la estabilidad y eficiencia.
A21: 2. Área Conocimiento (Saber) | G21: Tiempo Aproximado | H21: =D39+D40+D41+D42 -> 55
G22: No puede exceder los 60 minutos
A23: Competencia a desarrollar | B23: El estudiante modifica el código fuente del kernel en lenguaje C para implementar nuevas llamadas al sistema (syscalls) que exponen funcionalidades y transfieren datos de forma segura entre el espacio de kernel y el de usuario.
A24: Competencia a desarrollar | B24: El estudiante modifica el código fuente del kernel en lenguaje C para implementar nuevas llamadas al sistema (syscalls) que exponen funcionalidades y transfieren datos de forma segura entre el espacio de kernel y el de usuario.
A26: 2.1 Contenido
A27: No. | B27: Unidad | D27: Tema | F27: Sub Tema
A28: 1 | B28: =IFERROR(__xludf.DUMMYFUNCTION("FILTER('Diseño'!D:D,'Diseño'!H:H=$C$5)"),"Procesos e Interacción") -> Procesos e Interacción | D28: =IFERROR(__xludf.DUMMYFUNCTION("FILTER('Diseño'!E:E,'Diseño'!H:H=$C$5)"),"Modularizando el Kernel (LKM)") -> Modularizando el Kernel (LKM) | F28: =IFERROR(__xludf.DUMMYFUNCTION("FILTER('Diseño'!F:F,'Diseño'!H:H=$C$5)"),"Introducción a los Módulos Cargables del Kernel. Ventajas de la modularidad. Migración de la syscall hello_world() a un módulo.") -> Introducción a los Módulos Cargables del Kernel. Ventajas de la modularidad. Migración de la syscall hello_world() a un módulo.
A29: 2 | B29: =IFERROR(__xludf.DUMMYFUNCTION("""COMPUTED_VALUE"""),"Procesos e Interacción") -> Procesos e Interacción | D29: =IFERROR(__xludf.DUMMYFUNCTION("""COMPUTED_VALUE"""),"Primer Programa Cliente") -> Primer Programa Cliente | F29: =IFERROR(__xludf.DUMMYFUNCTION("""COMPUTED_VALUE"""),"Creación de un programa en C que invoca la syscall hello_world() desde el espacio de usuario.") -> Creación de un programa en C que invoca la syscall hello_world() desde el espacio de usuario.
A30: 3
A31: 4
A32: 5
A33: 6
A34: 7
A36: 2.2 Recursos Educativos
A38: Tipo de Recurso a utilizar | B38: Tipo | C38: Rango Aproximando | D38: Tiempo Aproximado
A39: Presentacion | B39: Obligatorio | D39: 25
A40: Video | B40: Obligatorio | C40: 3 a 6 minutos | D40: 5
A41: Lectura | B41: Optativo | D41: 0
A42: Ejercicio Demostrativo | B42: Obligatorio | D42: 25
A44: 3. Área de Habilidades (Saber Hacer) | G44: Tiempo Aproximado | H44: =B50+B61 -> 30
G45: Tiene que estar en un rango de 30 a 50 minutos
A46: Actividad 1 (Obligatoria)
A47: Competencia que predomina en la actividad | B47: El estudiante explica las diferencias entre ejecución concurrente, ejecución paralela y paralelismo en el contexto de los sistemas operativos y aplica este conocimiento para seleccionar y emplear adecuadamente herramientas de gestión de memoria y procesos en sus desarrollos.
A48: Tipo de Actividad | B48: =S.2!B48 -> Cuestionario
A49: Ponderación | B49: 0
A50: Tiempo Aproximado | B50: =S.2!B50 -> 5
...

Sheet S.7
B2: Diseño de la Sesión de Laboratorio
B4: Curso | C4: ='Diseño'!C4 -> 285 - Sistemas Operativos 2
B5: Semana | C5: 7
B6: Tiempo | C6: =H10+H21+H44+H68 -> 100
B7: Ponderación | C7: =B49+B60 -> 0
B8: Validación de Tiempo | C8: =IF(H44<=0, "❌ ERROR: La Actividad 1 debe tener un tiempo mayor a 0.", IF(H21>60, "❌ ERROR: El 'Área de Conocimiento' no puede exceder los 60 min.", IF((H10+H21+H44)<100, "❌ ERROR: El tiempo total debe ser de al menos 100 min.", "✅ VALIDACIÓN CORRECTA"))) -> ❌ ERROR: El tiempo total debe ser de al menos 100 min.
A10: 1. Área Actitudinal (Saber Ser) | G10: Tiempo Aproximado | H10: =B13 -> 5
G11: Tiene que estar en un rango de 3 a 5 minutos
A12: Nombre del Valor | B12: Equidad
A13: Tiempo Aproximado | B13: =S.2!B13 -> 5
A14: Descripcion
A15: Actuar con justicia e imparcialidad, reconociendo y respetando los derechos de todas las personas.
A17: Como se relaciona con los conocimientos de la sesion y se aplicaria
A18: La planificacion/programacion de CPU se trata de darle el tiempo adecuado a cada proceso en ejecucion, muchas veces no se trata de igualdad y la igualdad no es lo optimo, sino de equidad, que en terminos generales significa darle a cada uno el tiempo que necesita para avanzar tanto como el resto.
A21: 2. Área Conocimiento (Saber) | G21: Tiempo Aproximado | H21: =D39+D40+D41+D42 -> 55
G22: No puede exceder los 60 minutos
A23: Competencia a desarrollar | B23: El estudiante modifica el código fuente del kernel en lenguaje C para implementar nuevas llamadas al sistema (syscalls) que exponen funcionalidades y transfieren datos de forma segura entre el espacio de kernel y el de usuario.
A24: Competencia a desarrollar | B24: El estudiante analiza las estructuras de datos internas del kernel que gestionan procesos, memoria y tiempo mediante la lectura e interpretación de su código fuente para extraer métricas de rendimiento y estado del sistema, como la lista de procesos o el uso de CPU.
A26: 2.1 Contenido
A27: No. | B27: Unidad | D27: Tema | F27: Sub Tema
A28: 1 | B28: =IFERROR(__xludf.DUMMYFUNCTION("FILTER('Diseño'!D:D,'Diseño'!H:H=$C$5)"),"Procesos e Interacción") -> Procesos e Interacción | D28: =IFERROR(__xludf.DUMMYFUNCTION("FILTER('Diseño'!E:E,'Diseño'!H:H=$C$5)"),"Transferencia de Datos Estructurados") -> Transferencia de Datos Estructurados | F28: =IFERROR(__xludf.DUMMYFUNCTION("FILTER('Diseño'!F:F,'Diseño'!H:H=$C$5)"),"Transfiriendo datos complejos del kernel al espacio de usuario.") -> Transfiriendo datos complejos del kernel al espacio de usuario.
A29: 2 | B29: =IFERROR(__xludf.DUMMYFUNCTION("""COMPUTED_VALUE"""),"Monitoreo del Sistema") -> Monitoreo del Sistema | D29: =IFERROR(__xludf.DUMMYFUNCTION("""COMPUTED_VALUE"""),"Estructura de un proceso") -> Estructura de un proceso | F29: =IFERROR(__xludf.DUMMYFUNCTION("""COMPUTED_VALUE"""),"Estructuras del kernel para obtener campos clave de procesos como PID, estado, PPID.") -> Estructuras del kernel para obtener campos clave de procesos como PID, estado, PPID.
A30: 3
A31: 4
A32: 5
A33: 6
A34: 7
A36: 2.2 Recursos Educativos
A38: Tipo de Recurso a utilizar | B38: Tipo | C38: Rango Aproximando | D38: Tiempo Aproximado
A39: Presentacion | B39: Obligatorio | D39: 25
A40: Video | B40: Obligatorio | C40: 3 a 6 minutos | D40: 5
A41: Lectura | B41: Optativo | D41: 0
A42: Ejercicio Demostrativo | B42: Obligatorio | D42: 25
A44: 3. Área de Habilidades (Saber Hacer) | G44: Tiempo Aproximado | H44: =B50+B61 -> 30
G45: Tiene que estar en un rango de 30 a 50 minutos
A46: Actividad 1 (Obligatoria)
A47: Competencia que predomina en la actividad | B47: El estudiante explica las diferencias entre ejecución concurrente, ejecución paralela y paralelismo en el contexto de los sistemas operativos y aplica este conocimiento para seleccionar y emplear adecuadamente herramientas de gestión de memoria y procesos en sus desarrollos.
A48: Tipo de Actividad | B48: =S.2!B48 -> Cuestionario
A49: Ponderación | B49: 0
A50: Tiempo Aproximado | B50: =S.2!B50 -> 5
...

Sheet S.8
B2: Diseño de la Sesión de Laboratorio
B4: Curso | C4: ='Diseño'!C4 -> 285 - Sistemas Operativos 2
B5: Semana | C5: 8
B6: Tiempo | C6: =H10+H21+H44+H68 -> 100
B7: Ponderación | C7: =B49+B60 -> 0
B8: Validación de Tiempo | C8: =IF(H44<=0, "❌ ERROR: La Actividad 1 debe tener un tiempo mayor a 0.", IF(H21>60, "❌ ERROR: El 'Área de Conocimiento' no puede exceder los 60 min.", IF((H10+H21+H44)<100, "❌ ERROR: El tiempo total debe ser de al menos 100 min.", "✅ VALIDACIÓN CORRECTA"))) -> ❌ ERROR: El tiempo total debe ser de al menos 100 min.
A10: 1. Área Actitudinal (Saber Ser) | G10: Tiempo Aproximado | H10: =B13 -> 5
G11: Tiene que estar en un rango de 3 a 5 minutos
A12: Nombre del Valor | B12: Precaucion
A13: Tiempo Aproximado | B13: =S.2!B13 -> 5
A14: Descripcion
A15: Adoptar medidas preventivas para reducir riesgos y consecuencias negativas, actuando con cuidado y previsión
A17: Como se relaciona con los conocimientos de la sesion y se aplicaria
A18: La paginacion, segmentacion y proteccion de memoria son temas delicados, comprender la importacia de estos temas, es garantizar el buen funcionamiento del sistema
A21: 2. Área Conocimiento (Saber) | G21: Tiempo Aproximado | H21: =D39+D40+D41+D42 -> 55
G22: No puede exceder los 60 minutos
A23: Competencia a desarrollar | B23: El estudiante analiza las estructuras de datos internas del kernel que gestionan procesos, memoria y tiempo mediante la lectura e interpretación de su código fuente para extraer métricas de rendimiento y estado del sistema, como la lista de procesos o el uso de CPU.
A24: Competencia a desarrollar | B24: El estudiante analiza las estructuras de datos internas del kernel que gestionan procesos, memoria y tiempo mediante la lectura e interpretación de su código fuente para extraer métricas de rendimiento y estado del sistema, como la lista de procesos o el uso de CPU.
A26: 2.1 Contenido
A27: No. | B27: Unidad | D27: Tema | F27: Sub Tema
A28: 1 | B28: =IFERROR(__xludf.DUMMYFUNCTION("FILTER('Diseño'!D:D,'Diseño'!H:H=$C$5)"),"Monitoreo del Sistema") -> Monitoreo del Sistema | D28: =IFERROR(__xludf.DUMMYFUNCTION("FILTER('Diseño'!E:E,'Diseño'!H:H=$C$5)"),"Concurrencia y Lectura Segura de Datos") -> Concurrencia y Lectura Segura de Datos | F28: =IFERROR(__xludf.DUMMYFUNCTION("FILTER('Diseño'!F:F,'Diseño'!H:H=$C$5)"),"El problema de las condiciones de carrera al leer datos del kernel. Introducción a primitivas de sincronización.") -> El problema de las condiciones de carrera al leer datos del kernel. Introducción a primitivas de sincronización.
A29: 2 | B29: =IFERROR(__xludf.DUMMYFUNCTION("""COMPUTED_VALUE"""),"Monitoreo del Sistema") -> Monitoreo del Sistema | D29: =IFERROR(__xludf.DUMMYFUNCTION("""COMPUTED_VALUE"""),"Medición de Tiempo y Carga del Sistema") -> Medición de Tiempo y Carga del Sistema | F29: =IFERROR(__xludf.DUMMYFUNCTION("""COMPUTED_VALUE"""),"Estructuras del kernel para obtener el tiempo de actividad (uptime) y la carga promedio (load average).") -> Estructuras del kernel para obtener el tiempo de actividad (uptime) y la carga promedio (load average).
A30: 3
A31: 4
A32: 5
A33: 6
A34: 7
A36: 2.2 Recursos Educativos
A38: Tipo de Recurso a utilizar | B38: Tipo | C38: Rango Aproximando | D38: Tiempo Aproximado
A39: Presentacion | B39: Obligatorio | D39: 25
A40: Video | B40: Obligatorio | C40: 3 a 6 minutos | D40: 5
A41: Lectura | B41: Optativo | D41: 0
A42: Ejercicio Demostrativo | B42: Obligatorio | D42: 25
A44: 3. Área de Habilidades (Saber Hacer) | G44: Tiempo Aproximado | H44: =B50+B61 -> 30
G45: Tiene que estar en un rango de 30 a 50 minutos
A46: Actividad 1 (Obligatoria)
A47: Competencia que predomina en la actividad | B47: El estudiante comprende la estructura fundamental de un sistema operativo mediante el analisis del codigo fuente del kernel Linux para comprender como este gestion y administra los programas de usuario
A48: Tipo de Actividad | B48: =S.2!B48 -> Cuestionario
A49: Ponderación | B49: 0
A50: Tiempo Aproximado | B50: =S.2!B50 -> 5
...

Sheet S.9
B2: Diseño de la Sesión de Laboratorio
B4: Curso | C4: ='Diseño'!C4 -> 285 - Sistemas Operativos 2
B5: Semana | C5: 9
B6: Tiempo | C6: =H10+H21+H44+H68 -> 100
B7: Ponderación | C7: =B49+B60 -> 0
B8: Validación de Tiempo | C8: =IF(H44<=0, "❌ ERROR: La Actividad 1 debe tener un tiempo mayor a 0.", IF(H21>60, "❌ ERROR: El 'Área de Conocimiento' no puede exceder los 60 min.", IF((H10+H21+H44)<100, "❌ ERROR: El tiempo total debe ser de al menos 100 min.", "✅ VALIDACIÓN CORRECTA"))) -> ❌ ERROR: El tiempo total debe ser de al menos 100 min.
A10: 1. Área Actitudinal (Saber Ser) | G10: Tiempo Aproximado | H10: =B13 -> 5
G11: Tiene que estar en un rango de 3 a 5 minutos
A12: Nombre del Valor | B12: Etica
A13: Tiempo Aproximado | B13: =S.2!B13 -> 5
A14: Descripcion
A15: Guiarse por principios morales que orientan el comportamiento hacia lo correcto, honesto y justo.
A17: Como se relaciona con los conocimientos de la sesion y se aplicaria
A18: Los mecanismos de control de acceso, privilegio y seguridad deben programarse de manera responsable, siendo que somos personas que potencialmente estaran detras de sistemas que requieren seguridad importante, es escencial mantener una etica intachable
A21: 2. Área Conocimiento (Saber) | G21: Tiempo Aproximado | H21: =D39+D40+D41+D42 -> 55
G22: No puede exceder los 60 minutos
A23: Competencia a desarrollar | B23: El estudiante analiza las estructuras de datos internas del kernel que gestionan procesos, memoria y tiempo mediante la lectura e interpretación de su código fuente para extraer métricas de rendimiento y estado del sistema, como la lista de procesos o el uso de CPU.
A24: Competencia a desarrollar | B24: El estudiante analiza las estructuras de datos internas del kernel que gestionan procesos, memoria y tiempo mediante la lectura e interpretación de su código fuente para extraer métricas de rendimiento y estado del sistema, como la lista de procesos o el uso de CPU.
A26: 2.1 Contenido
A27: No. | B27: Unidad | D27: Tema | F27: Sub Tema
A28: 1 | B28: =IFERROR(__xludf.DUMMYFUNCTION("FILTER('Diseño'!D:D,'Diseño'!H:H=$C$5)"),"Monitoreo del Sistema") -> Monitoreo del Sistema | D28: =IFERROR(__xludf.DUMMYFUNCTION("FILTER('Diseño'!E:E,'Diseño'!H:H=$C$5)"),"Medición de Memoria y Procesos") -> Medición de Memoria y Procesos | F28: =IFERROR(__xludf.DUMMYFUNCTION("FILTER('Diseño'!F:F,'Diseño'!H:H=$C$5)"),"Estructuras del kernel para obtener el uso total/libre de memoria y el número de procesos activos.") -> Estructuras del kernel para obtener el uso total/libre de memoria y el número de procesos activos.
A29: 2 | B29: =IFERROR(__xludf.DUMMYFUNCTION("""COMPUTED_VALUE"""),"Monitoreo del Sistema") -> Monitoreo del Sistema | D29: =IFERROR(__xludf.DUMMYFUNCTION("""COMPUTED_VALUE"""),"Procesos en ejecucion") -> Procesos en ejecucion | F29: =IFERROR(__xludf.DUMMYFUNCTION("""COMPUTED_VALUE"""),"Listado de procesos: Aprender a iterar la lista de tareas del kernel (usando for_each_process)") -> Listado de procesos: Aprender a iterar la lista de tareas del kernel (usando for_each_process)
A30: 3
A31: 4
A32: 5
A33: 6
A34: 7
A36: 2.2 Recursos Educativos
A38: Tipo de Recurso a utilizar | B38: Tipo | C38: Rango Aproximando | D38: Tiempo Aproximado
A39: Presentacion | B39: Obligatorio | D39: 25
A40: Video | B40: Obligatorio | C40: 3 a 6 minutos | D40: 5
A41: Lectura | B41: Optativo | D41: 0
A42: Ejercicio Demostrativo | B42: Obligatorio | D42: 25
A44: 3. Área de Habilidades (Saber Hacer) | G44: Tiempo Aproximado | H44: =B50+B61 -> 30
G45: Tiene que estar en un rango de 30 a 50 minutos
A46: Actividad 1 (Obligatoria)
A47: Competencia que predomina en la actividad | B47: El estudiante comprende la estructura fundamental de un sistema operativo mediante el analisis del codigo fuente del kernel Linux para comprender como este gestion y administra los programas de usuario
A48: Tipo de Actividad | B48: =S.2!B48 -> Cuestionario
A49: Ponderación | B49: 0
A50: Tiempo Aproximado | B50: =S.2!B50 -> 5
...

Sheet S.10
B2: Diseño de la Sesión de Laboratorio
B4: Curso | C4: ='Diseño'!C4 -> 285 - Sistemas Operativos 2
B5: Semana | C5: 10
B6: Tiempo | C6: =H10+H21+H44+H68 -> 100
B7: Ponderación | C7: =B49+B60 -> 0
B8: Validación de Tiempo | C8: =IF(H44<=0, "❌ ERROR: La Actividad 1 debe tener un tiempo mayor a 0.", IF(H21>60, "❌ ERROR: El 'Área de Conocimiento' no puede exceder los 60 min.", IF((H10+H21+H44)<100, "❌ ERROR: El tiempo total debe ser de al menos 100 min.", "✅ VALIDACIÓN CORRECTA"))) -> ❌ ERROR: El tiempo total debe ser de al menos 100 min.
A10: 1. Área Actitudinal (Saber Ser) | G10: Tiempo Aproximado | H10: =B13 -> 5
G11: Tiene que estar en un rango de 3 a 5 minutos
A12: Nombre del Valor | B12: Adaptabilidad
A13: Tiempo Aproximado | B13: =S.2!B13 -> 5
A14: Descripcion
A15: Ajustarse con flexibilidad a nuevas circunstancias, cambios o desafíos sin perder efectividad.
A17: Como se relaciona con los conocimientos de la sesion y se aplicaria
A18: Explorar diferentes enfoques es indispensable para aumentar nuestra biblioteca personal de conocimiento. Una solucion puede ser implementada de muchas formas, elegir la forma correcta es critico para el futuro del sistema y por eso debe analizarse con cuidado como adaptarse a nuevos entorno
A21: 2. Área Conocimiento (Saber) | G21: Tiempo Aproximado | H21: =D39+D40+D41+D42 -> 55
G22: No puede exceder los 60 minutos
A23: Competencia a desarrollar | B23: El estudiante analiza las estructuras de datos internas del kernel que gestionan procesos, memoria y tiempo mediante la lectura e interpretación de su código fuente para extraer métricas de rendimiento y estado del sistema, como la lista de procesos o el uso de CPU.
A24: Competencia a desarrollar | B24: El estudiante diseña aplicaciónes en espacio de usuario integrando las llamadas al sistema para generar funcionalidad y expandir las capacidades del sistema operativo que el usuario puede aprovechar
A26: 2.1 Contenido
A27: No. | B27: Unidad | D27: Tema | F27: Sub Tema
A28: 1 | B28: =IFERROR(__xludf.DUMMYFUNCTION("FILTER('Diseño'!D:D,'Diseño'!H:H=$C$5)"),"Monitoreo del Sistema") -> Monitoreo del Sistema | D28: =IFERROR(__xludf.DUMMYFUNCTION("FILTER('Diseño'!E:E,'Diseño'!H:H=$C$5)"),"Métricas Complejas de CPU") -> Métricas Complejas de CPU | F28: =IFERROR(__xludf.DUMMYFUNCTION("FILTER('Diseño'!F:F,'Diseño'!H:H=$C$5)"),"Cálculo del uso de CPU: Entender los ""jiffies"" y las estadísticas por CPU. Investigar las estructuras del kernel para obtener los tiempos de CPU (usuario, sistema, idle).") -> Cálculo del uso de CPU: Entender los "jiffies" y las estadísticas por CPU. Investigar las estructuras del kernel para obtener los tiempos de CPU (usuario, sistema, idle).
A29: 2 | B29: =IFERROR(__xludf.DUMMYFUNCTION("""COMPUTED_VALUE"""),"Alternativas de Comunicación") -> Alternativas de Comunicación | D29: =IFERROR(__xludf.DUMMYFUNCTION("""COMPUTED_VALUE"""),"El Sistema de Archivos /proc") -> El Sistema de Archivos /proc | F29: =IFERROR(__xludf.DUMMYFUNCTION("""COMPUTED_VALUE"""),"Fundamentos del sistema de archivos /proc. Comparativa entre syscalls y la exportación de datos a través de archivos virtuales.") -> Fundamentos del sistema de archivos /proc. Comparativa entre syscalls y la exportación de datos a través de archivos virtuales.
A30: 3
A31: 4
A32: 5
A33: 6
A34: 7
A36: 2.2 Recursos Educativos
A38: Tipo de Recurso a utilizar | B38: Tipo | C38: Rango Aproximando | D38: Tiempo Aproximado
A39: Presentacion | B39: Obligatorio | D39: 25
A40: Video | B40: Obligatorio | C40: 3 a 6 minutos | D40: 5
A41: Lectura | B41: Optativo | D41: 0
A42: Ejercicio Demostrativo | B42: Obligatorio | D42: 25
A44: 3. Área de Habilidades (Saber Hacer) | G44: Tiempo Aproximado | H44: =B50+B61 -> 30
G45: Tiene que estar en un rango de 30 a 50 minutos
A46: Actividad 1 (Obligatoria)
A47: Competencia que predomina en la actividad | B47: El estudiante evalua las capacidades y características de distintos sistemas operativos identificando sus fortalezas y limitaciones con el fin de seleccionarlos y aplicarlos de manera estratégica en sus proyectos y tareas profesionales
A48: Tipo de Actividad | B48: =S.2!B48 -> Cuestionario
A49: Ponderación | B49: 0
A50: Tiempo Aproximado | B50: =S.2!B50 -> 5
...

Sheet S.11
B2: Diseño de la Sesión de Laboratorio
B4: Curso | C4: ='Diseño'!C4 -> 285 - Sistemas Operativos 2
B5: Semana | C5: 11
B6: Tiempo | C6: =H10+H21+H44+H68 -> 100
B7: Ponderación | C7: =B49+B60 -> 0
B8: Validación de Tiempo | C8: =IF(H44<=0, "❌ ERROR: La Actividad 1 debe tener un tiempo mayor a 0.", IF(H21>60, "❌ ERROR: El 'Área de Conocimiento' no puede exceder los 60 min.", IF((H10+H21+H44)<100, "❌ ERROR: El tiempo total debe ser de al menos 100 min.", "✅ VALIDACIÓN CORRECTA"))) -> ❌ ERROR: El tiempo total debe ser de al menos 100 min.
A10: 1. Área Actitudinal (Saber Ser) | G10: Tiempo Aproximado | H10: =B13 -> 5
G11: Tiene que estar en un rango de 3 a 5 minutos
A12: Nombre del Valor | B12: Trabajo en Equipo
A13: Tiempo Aproximado | B13: =S.2!B13 -> 5
A14: Descripcion
A15: Colaborar y coordinarse con otros para alcanzar objetivos comunes, aportando habilidades individuales en beneficio del grupo.
A17: Como se relaciona con los conocimientos de la sesion y se aplicaria
A18: Cuando se trata de sistemas distribuidos, hablamos de que se logra mas teniendo muchos equipos trabajando juntos, esto aplica para todo, no solo la programacion, es importante saber adaptarse a un equipo y colaborar para lograr metas comunes, y a veces, individuales.
A21: 2. Área Conocimiento (Saber) | G21: Tiempo Aproximado | H21: =D39+D40+D41+D42 -> 55
G22: No puede exceder los 60 minutos
A23: Competencia a desarrollar | B23: El estudiante diseña aplicaciónes en espacio de usuario integrando las llamadas al sistema para generar funcionalidad y expandir las capacidades del sistema operativo que el usuario puede aprovechar
A24: Competencia a desarrollar | B24: El estudiante diseña aplicaciónes en espacio de usuario integrando las llamadas al sistema para generar funcionalidad y expandir las capacidades del sistema operativo que el usuario puede aprovechar
A26: 2.1 Contenido
A27: No. | B27: Unidad | D27: Tema | F27: Sub Tema
A28: 1 | B28: =IFERROR(__xludf.DUMMYFUNCTION("FILTER('Diseño'!D:D,'Diseño'!H:H=$C$5)"),"Alternativas de Comunicación") -> Alternativas de Comunicación | D28: =IFERROR(__xludf.DUMMYFUNCTION("FILTER('Diseño'!E:E,'Diseño'!H:H=$C$5)"),"Exposicion de datos vía /proc") -> Exposicion de datos vía /proc | F28: =IFERROR(__xludf.DUMMYFUNCTION("FILTER('Diseño'!F:F,'Diseño'!H:H=$C$5)"),"Análisis de /proc/meminfo y /proc/stat y cómo exponer estas métricas en el kernel") -> Análisis de /proc/meminfo y /proc/stat y cómo exponer estas métricas en el kernel
A29: 2
A30: 3
A31: 4
A32: 5
A33: 6
A34: 7
A36: 2.2 Recursos Educativos
A38: Tipo de Recurso a utilizar | B38: Tipo | C38: Rango Aproximando | D38: Tiempo Aproximado
A39: Presentacion | B39: Obligatorio | D39: 25
A40: Video | B40: Obligatorio | C40: 3 a 6 minutos | D40: 5
A41: Lectura | B41: Optativo | D41: 0
A42: Ejercicio Demostrativo | B42: Obligatorio | D42: 25
A44: 3. Área de Habilidades (Saber Hacer) | G44: Tiempo Aproximado | H44: =B50+B61 -> 30
G45: Tiene que estar en un rango de 30 a 50 minutos
A46: Actividad 1 (Obligatoria)
A47: Competencia que predomina en la actividad | B47: El estudiante evalua las capacidades y características de distintos sistemas operativos identificando sus fortalezas y limitaciones con el fin de seleccionarlos y aplicarlos de manera estratégica en sus proyectos y tareas profesionales
A48: Tipo de Actividad | B48: =S.2!B48 -> Cuestionario
A49: Ponderación | B49: 0
A50: Tiempo Aproximado | B50: =S.2!B50 -> 5
...

Sheet Proyectos
B2: Proyectos
B4: Curso | C4: ='Diseño'!C4 -> 285 - Sistemas Operativos 2
B5: Tiempo | C5: =H9+H26+H43 -> 40
B6: Ponderación | C6: =F9+F26+F43 -> 80
B7: La sumatoria de los puntos de los proyectos debe superar el 70% del total de la nota, no puede ser un 100%
A9: 1. Primer Proyecto | E9: Ponderación | F9: 80 | G9: Horas para realizarlo | H9: 40
A10: Obligatorio
A11: Competencia a desarrollar | B11: El estudiante comprende la estructura fundamental de un sistema operativo mediante el analisis del codigo fuente del kernel Linux para comprender como este gestion y administra los programas de usuario
A12: Competencia a desarrollar | B12: El estudiante desarrolla nuevos programas usando sus conocimientos en hilos y sincronizacion que hacen uso eficiente y optimo de los recursos del sistema
A13: Competencia a desarrollar | B13: El estudiante crea nuevas llamadas al sistema para el kernel linux usando lenguaje C y sus librerias estandar para ampliar las capacidades del kernel para coprender como el kernel puede limitar o dificultar la creacion de un programa de usuario
A14: Titulo | B14: Sistema de Notificaciones y Acciones Automatizadas del Kernel
A15: Qué tecnologías, lenguajes de programación, plataformas, hardware o software se utilizaran
A16: Linux Mint (VM) Kernel Linux (modificado) Lenguaje C Módulos de kernel Syscalls personalizadas Hilos y sincronización en programas de usuario
A19: Descripción de lo que se realizara
A20: El estudiante desarrollará un sistema que detecta eventos del sistema y ejecuta acciones automatizadas, integrando todas las prácticas previas. Componentes del proyecto: Módulo de kernel: Detecta eventos específicos del sistema, como creación o terminación de procesos, cambios en archivos específicos, o consumo excesivo de recursos por un proceso. Envía notificaciones al espacio de usuario usando mecanismos internos del kernel. Modificación del kernel: Agregar soporte para nuevas funciones que permitan la captura de eventos y su registro interno. Crear estructuras de datos en kernel para almacenar temporalmente los eventos y su metadata. Syscalls personalizadas: Una syscall para que programas de usuario puedan consultar eventos recientes. Otra syscall que permita enviar comandos al kernel para registrar nuevas acciones automatizadas (ej. ejecutar scripts, cerrar procesos, enviar señales). Programas de usuario: Un programa principal que reciba eventos mediante las syscalls y ejecute acciones predefinidas de manera concurrente usando hilos. Interfaz básica de configuración para seleccionar qué eventos se deben monitorear y qué acciones tomar. Integración y sincronización: Uso de mutexes y semáforos para manejar la comunicación entre el módulo de kernel y los programas de usuario de forma segura. Manejo de buffers compartidos y protección de datos para evitar condiciones de carrera. Pruebas y validación: Probar la captura de distintos tipos de eventos del sistema. Validar la ejecución correcta de acciones automatizadas. Verificar la estabilidad del kernel modificado bajo carga.
A26: 2. Segundo Proyecto | E26: Ponderación | G26: Horas para realizarlo
A27: Obligatorio
A28: Competencia a desarrollar
A29: Competencia a desarrollar
A30: Competencia a desarrollar
A31: Titulo
A32: Qué tecnologías, lenguajes de programación, plataformas, hardware o software se utilizaran
A36: Descripción de lo que se realizara
A43: 3. Tercer Proyecto | E43: Ponderación | G43: Horas para realizarlo
A44: Optativa
A45: Competencia a desarrollar
A46: Competencia a desarrollar
A47: Competencia a desarrollar
A48: Titulo
A49: Qué tecnologías, lenguajes de programación, plataformas, hardware o software se utilizaran
A53: Descripción de lo que se realizara

Sheet Practicas
B2: Practicas
B4: Curso | C4: ='Diseño'!C4 -> 285 - Sistemas Operativos 2
B5: Tiempo | C5: =H9+H26+H43+H60+H77+H94+H111 -> 34
B6: Ponderación | C6: =F9+F26+F43+F60+F77+F94+F111 -> 20
B7: La sumatoria de los puntos de los practicas debe no debe super el 20%
A9: 1. Primera Practica | E9: Ponderación | F9: 2 | G9: Horas para realizarlo | H9: 2
A10: Obligatoria
A11: Competencia a desarrollar | B11: El estudiante explica la historia de GNU/Linux usando puntos clave en el desarrollo del mismo para entender su origen y popularidad como sistema operativo libre
A12: Competencia a desarrollar | B12: El estudiante evalua las capacidades y características de distintos sistemas operativos identificando sus fortalezas y limitaciones con el fin de seleccionarlos y aplicarlos de manera estratégica en sus proyectos y tareas profesionales
A13: Competencia a desarrollar | B13: El estudiante comprende la estructura fundamental de un sistema operativo mediante el analisis del codigo fuente del kernel Linux para comprender como este gestion y administra los programas de usuario
A14: Titulo | B14: Instalación del virtualizador y Linux Mint
A15: Qué tecnologías, lenguajes de programación, plataformas, hardware o software se utilizaran
A16: VirtualBox o VMware, PC con capacidad de virtualización, Linux Mint ISO, gestor de particiones.
A19: Descripción de lo que se realizara
A20: El estudiante instalará y configurará un entorno de virtualización, creando una máquina virtual e instalando Linux Mint. Configurará CPU, RAM, disco, usuarios, permisos y red. Verificará que el sistema operativo funcione correctamente y que esté listo para desarrollo de sistemas.
A26: 2. Segunda Practica | E26: Ponderación | F26: 2 | G26: Horas para realizarlo | H26: 2
A27: Optativa
A28: Competencia a desarrollar | B28: El estudiante comprende la estructura fundamental de un sistema operativo mediante el analisis del codigo fuente del kernel Linux para comprender como este gestion y administra los programas de usuario
A29: Competencia a desarrollar | B29: El estudiante evalua las capacidades y características de distintos sistemas operativos identificando sus fortalezas y limitaciones con el fin de seleccionarlos y aplicarlos de manera estratégica en sus proyectos y tareas profesionales
A30: Competencia a desarrollar | B30: El estudiante explica la historia de GNU/Linux usando puntos clave en el desarrollo del mismo para entender su origen y popularidad como sistema operativo libre
A31: Titulo | B31: Exploración del kernel y laboratorio de módulos básicos
A32: Qué tecnologías, lenguajes de programación, plataformas, hardware o software se utilizaran
A33: Linux Mint, kernel Linux, lenguaje C, herramientas de compilación y depuración.
A36: Descripción de lo que se realizara
A37: El estudiante explorará la estructura del kernel Linux y desarrollará un módulo básico que se cargue y descargue. Se observará la interacción del módulo con dmesg y se analizará cómo el kernel registra eventos y maneja módulos externos.
A43: 3. Tercera Practica | E43: Ponderación | F43: 3 | G43: Horas para realizarlo | H43: 5
A44: Optativa
A45: Competencia a desarrollar | B45: El estudiante comprende la estructura fundamental de un sistema operativo mediante el analisis del codigo fuente del kernel Linux para comprender como este gestion y administra los programas de usuario
A46: Competencia a desarrollar | B46: El estudiante comprende la estructura fundamental de un sistema operativo mediante el analisis del codigo fuente del kernel Linux para comprender como este gestion y administra los programas de usuario
A47: Competencia a desarrollar | B47: El estudiante comprende la estructura fundamental de un sistema operativo mediante el analisis del codigo fuente del kernel Linux para comprender como este gestion y administra los programas de usuario
