Workbook

Sheet Diseño
A2: =VALUE(LEFT(C4,FIND(" - ",C4)-1)) -> 972 | B2: Diseño de Contenido Curricular
B4: Curso | C4: 972 - Inteligencia Artificial 1
B5: Periodo al que aplica | C5: Primer Semestre 2026
B8: No. | C8: Competencia | D8: Nombre de la Unidad | E8: Tema | F8: Subtema | G8: Mes | H8: Semana
B9: 1 | C9: desarrolla hechos, reglas, expresiones y predicados recursivos mediante el uso de cláusulas, ciclos, listas, unificación y cortes en Prolog para modelar bases de conocimiento y resolver problemas de inferencia lógica | D9: Logica e Inferencia | E9: Tipos de datos y variables | F9: Declaración de datos atómicos y compuestos | G9: Julio | H9: 2
B10: 2 | C10: desarrolla hechos, reglas, expresiones y predicados recursivos mediante el uso de cláusulas, ciclos, listas, unificación y cortes en Prolog para modelar bases de conocimiento y resolver problemas de inferencia lógica | D10: Logica e Inferencia | E10: Tipos de datos y variables | F10: Manipulación de variables en entornos lógicos | G10: Julio | H10: 2
B11: 3 | C11: desarrolla hechos, reglas, expresiones y predicados recursivos mediante el uso de cláusulas, ciclos, listas, unificación y cortes en Prolog para modelar bases de conocimiento y resolver problemas de inferencia lógica | D11: Logica e Inferencia | E11: Reglas, Hechos y Consultas | F11: Sintaxis de hechos y reglas en Prolog | G11: Julio | H11: 2
B12: 4 | C12: desarrolla hechos, reglas, expresiones y predicados recursivos mediante el uso de cláusulas, ciclos, listas, unificación y cortes en Prolog para modelar bases de conocimiento y resolver problemas de inferencia lógica | D12: Logica e Inferencia | E12: Reglas, Hechos y Consultas | F12: Realización de consultas simples y compuestas | G12: Julio | H12: 2
B13: 5 | C13: desarrolla hechos, reglas, expresiones y predicados recursivos mediante el uso de cláusulas, ciclos, listas, unificación y cortes en Prolog para modelar bases de conocimiento y resolver problemas de inferencia lógica | D13: Logica e Inferencia | E13: Expresiones y Cláusulas | F13: Construcción de expresiones condicionales | G13: Agosto | H13: 3
B14: 6 | C14: desarrolla hechos, reglas, expresiones y predicados recursivos mediante el uso de cláusulas, ciclos, listas, unificación y cortes en Prolog para modelar bases de conocimiento y resolver problemas de inferencia lógica | D14: Logica e Inferencia | E14: Expresiones y Cláusulas | F14: Encadenamiento de cláusulas para inferencias | G14: Agosto | H14: 3
B15: 7 | C15: desarrolla hechos, reglas, expresiones y predicados recursivos mediante el uso de cláusulas, ciclos, listas, unificación y cortes en Prolog para modelar bases de conocimiento y resolver problemas de inferencia lógica | D15: Logica e Inferencia | E15: Predicados | F15: Definición de predicados simples | G15: Agosto | H15: 3
B16: 8 | C16: desarrolla hechos, reglas, expresiones y predicados recursivos mediante el uso de cláusulas, ciclos, listas, unificación y cortes en Prolog para modelar bases de conocimiento y resolver problemas de inferencia lógica | D16: Logica e Inferencia | E16: Predicados | F16: Uso de predicados recursivos | G16: Agosto | H16: 3
B17: 9 | C17: desarrolla hechos, reglas, expresiones y predicados recursivos mediante el uso de cláusulas, ciclos, listas, unificación y cortes en Prolog para modelar bases de conocimiento y resolver problemas de inferencia lógica | D17: Logica e Inferencia | E17: Negación y Cortes | F17: Implementación de negación en inferencias | G17: Agosto | H17: 4
B18: 10 | C18: desarrolla hechos, reglas, expresiones y predicados recursivos mediante el uso de cláusulas, ciclos, listas, unificación y cortes en Prolog para modelar bases de conocimiento y resolver problemas de inferencia lógica | D18: Logica e Inferencia | E18: Negación y Cortes | F18: Control de flujo mediante cortes | G18: Agosto | H18: 4
B19: 11 | C19: desarrolla hechos, reglas, expresiones y predicados recursivos mediante el uso de cláusulas, ciclos, listas, unificación y cortes en Prolog para modelar bases de conocimiento y resolver problemas de inferencia lógica | D19: Logica e Inferencia | E19: Ciclos y Recursión | F19: Definición de ciclos recursivos | G19: Agosto | H19: 4
B20: 12 | C20: desarrolla hechos, reglas, expresiones y predicados recursivos mediante el uso de cláusulas, ciclos, listas, unificación y cortes en Prolog para modelar bases de conocimiento y resolver problemas de inferencia lógica | D20: Logica e Inferencia | E20: Ciclos y Recursión | F20: Resolución de problemas mediante recursividad | G20: Agosto | H20: 4
... B40: 32 | C40: mejora la eficiencia y realismo en simulaciones robóticas mediante ajuste de parámetros, uso de bibliotecas de control y pruebas iterativas para aumentar la precisión, eficiencia y realismo de entornos virtuales | D40: Simulación de Robots | E40: Simulación de Entornos Robóticos | F40: Interacción de múltiples robots en un mismo entorno | G40: Noviembre | H40: 11

Sheet Semana Diagnostico
B2: Diseño de Contenido Curricular
B4: Curso | C4: ='Diseño'!C4 -> 972 - Inteligencia Artificial 1
B5: Semana | C5: 1
B6: Tiempo | C6: =B15+B22+B29+B41+B47+C48 -> 100
A9: 1. Bienvenida y Presentación | G9: Tiempo Aproximado | H9: 10
G10: No puedes excederte mas de 15 minutos
A11: Nombre y Formacion Academica | B11: Presentación Quien soy y mi formación academica
A12: Experiencia docente y profesional | B12: Presentación de CV | K12: Estos puntos son recomendaciones de los puntos a tratar durante tu presentacion, si no usaras estos eres libre de agregar mas filas para indicar que haras. En los recuadros de la derecha colocar breve resumen de lo que planeas decir. No debes ser muy especifico seran pequeñas anotaciones que te ayudaran a recordar lo que planeaste
A13: Rol del auxiliar dentro del curso (funciones, actividades y apoyo a los estudiantes). | B13: Prsentación de funciones de auxiliar
A14: Expectativas sobre la dinámica del curso | B14: Diapositivas con la presentación personal, trayectoria y datos relevantes
A15: Tiempo que emplearas | B15: 10
A18: 2. Evaluación de Conocimientos Previos | G18: Tiempo Aproximado | H18: 20
G19: No puedes excederte mas de 45 minutos
A20: Redactaras de 15 a 20 preguntas con sus respectivas respuestas , por lo que debes escoge los temas que evaluaras | B20: ¿Cuál es la diferencia entre inteligencia artificial débil y fuerte?¿Qué características debe cumplir un agente para ser considerado "inteligente"? Explica el ciclo de percepción–razonamiento–acción de un agente. ¿Qué es un entorno completamente observable y cómo influye en el diseño de un agente? ¿Cuál es la diferencia entre agentes reactivos y agentes basados en modelos? ¿Qué significa que un agente sea autónomo y adaptativo? ¿Qué papel juega el aprendizaje automático dentro de la inteligencia artificial? ¿Por qué la representación del conocimiento es importante en los sistemas de IA? ¿Qué ventajas y limitaciones tiene el uso de heurísticas en la resolución de problemas? ¿En qué se diferencian los sistemas expertos de los sistemas basados en aprendizaje profundo?¿Cuáles son algunos ejemplos actuales del uso de agentes inteligentes en la vida diaria? ¿Qué riesgos éticos surgen al implementar agentes autónomos en áreas críticas como la salud o la seguridad? ¿Cómo puede un agente inteligente aprender de su experiencia pasada? ¿Por qué la definición del entorno es clave para el rendimiento de un agente? ¿Qué retos futuros enfrenta el desarrollo de agentes inteligentes en la inteligencia artificial general (AGI)? | K20: En los recuadors de la derecha deberas colocar las preguntas que planeas realizar con sus respectivas respuestas. En el segundo recuadro deberas colocar un breve resumne de lo que tines planificado para la parte practica del curso previo al que estas impartiendo.
A21: Redactaras una parte practica | B21: Crear formulario para contestar las preguntas
A22: Tiempo que emplearas | B22: 20
A25: 3. Presentación de los Estudiantes | G25: Tiempo Aproximado | H25: 25
G26: No puedes excederte mas de 30 minutos
A27: Seleccion al Azar de 5 Estudiantes | B27: Ruleta para que los alumnos se presenten y comenten sus expectativas | K27: En el primer recuadro colocaras la metodollogia que adoptaras para la eleccion de los estudiantes. En el segundo recuadro colocaras la redaccion de las preguntas que comprendan los siguientes puntos respecto al estudiante: Nombre. Intereses y expectativas sobre el curso. Experiencia previa relacionada con el curso (si aplica). Un dato curioso sobre sí mismo. Consideras que la prueba de conociminetos previos esta acorde al conocimiento que se te brindo en su momento Que tan comodo se sintio con la prueba anterior.
A28: Preguntas que responderan los estudiantes afortunados | B28: ¿Que le interesa del curso? ¿Cuanto le falta para terminar? Exéctativas del curso. Un dato curioso de si mismo.
A29: Tiempo que emplearas | B29: 25
A32: 4. Senso de Horarios de Calificación | G32: Tiempo Aproximado | H32: =B36 -> 5
A33: Deberas estar recordando que deben contestar el formulario asi mismo dejar el link fijado en la llamada | G33: Esta actividad quedara abierta hasta el fin de la clase. pero emplearas 5 min especificos para la actividad
A34: Link de google forms donde este el cuestionario | B34: https://docs.google.com/forms/d/e/1FAIpQLScyQDFV21dUEAiOdYenanfx4xXASPsUXGSI3wcBmX7M6zc7VA/viewform?usp=header | K34: Esta actividad te ayudara a realizar un senso de posibles horarios de calificacion y que tus estudiantes esten enterados y puedan preveer los dias de calificacion y asi mismo el horario. Deberas colocar en los reacuadros de la derecha link de Google form libre para correos intitucionales, esto para garantizar una sola respuesta por estudiante. TAmbien deberas colocar los posibles horarios y dias que tentativamente tendrias disponibles. para colocarlos en el google form.
A35: Dias y posibles Horarios de calificacion | B35: Viernes, sabados.
A36: Tiempo que emplearas | B36: 5
A39: 4. Mostrar Programa del Curso | G39: Tiempo Aproximado | H39: =B41 -> 30
G40: No puedes excederte mas de 30 minutos
A41: Tiempo que emplearas | B41: 30
A44: 2. Evaluación de Conocimientos del Curso Actual | G44: Tiempo Aproximado | H44: =B47 -> 15
G45: No puedes excederte mas de 15 minutos
A46: Redactaras 20 preguntas con sus respectivas respuestas | B46: ¿Cuál es la diferencia entre inteligencia artificial débil y fuerte? ¿Qué papel juega el aprendizaje automático dentro de la inteligencia artificial? ¿Por qué la representación del conocimiento es importante en los sistemas de IA? ¿Qué ventajas y limitaciones tiene el uso de heurísticas en la resolución de problemas? ¿En qué se diferencian los sistemas expertos de los sistemas basados en aprendizaje profundo? ¿Qué características debe cumplir un agente para ser considerado "inteligente"? Explica el ciclo de percepción–razonamiento–acción de un agente. ¿Qué es un entorno completamente observable y cómo influye en el diseño de un agente? ¿Cuál es la diferencia entre agentes reactivos y agentes basados en modelos? ¿Qué significa que un agente sea autónomo y adaptativo? ¿Cuáles son algunos ejemplos actuales del uso de agentes inteligentes en la vida diaria? ¿Qué riesgos éticos surgen al implementar agentes autónomos en áreas críticas como la salud o la seguridad? ¿Cómo puede un agente inteligente aprender de su experiencia pasada? ¿Por qué la definición del entorno es clave para el rendimiento de un agente? ¿Qué retos futuros enfrenta el desarrollo de agentes inteligentes en la inteligencia artificial general (AGI)?
A47: Tiempo que emplearas | B47: 15

Sheet S.2
B2: Diseño de la Sesión de Laboratorio
B4: Curso | C4: ='Diseño'!C4 -> 972 - Inteligencia Artificial 1
B5: Semana | C5: 2
B6: Tiempo | C6: =H10+H21+H44+H68 -> 126
B7: Ponderación | C7: =B49+B60 -> 3
B8: Validación de Tiempo | C8: =IF(H44<=0, "❌ ERROR: La Actividad 1 debe tener un tiempo mayor a 0.", IF(H21>60, "❌ ERROR: El 'Área de Conocimiento' no puede exceder los 60 min.", IF((H10+H21+H44)<100, "❌ ERROR: El tiempo total debe ser de al menos 100 min.", "✅ VALIDACIÓN CORRECTA"))) -> ✅ VALIDACIÓN CORRECTA
A10: 1. Área Actitudinal (Saber Ser) | G10: Tiempo Aproximado | H10: =B13 -> 5
G11: Tiene que estar en un rango de 3 a 5 minutos
A12: Nombre del Valor | B12: Responsabilidad
A13: Tiempo Aproximado | B13: 5
A14: Descripcion
A15: La responsabilidad implica asumir con compromiso las actividades asignadas, cumpliendo en tiempo y forma con lo solicitado, tanto en el aula como en el desarrollo de ejercicios prácticos.
A17: Como se relaciona con los conocimientos de la sesion y se aplicaria
A18: El valor de la responsabilidad se aplicará en la entrega puntual de los ejercicios de backtracking, en el cuidado de la calidad del código, así como en la preparación previa del estudiante para participar activamente en la sesión.
A21: 2. Área Conocimiento (Saber) | G21: Tiempo Aproximado | H21: =D39+D40+D41+D42 -> 56
G22: No puede exceder los 60 minutos
A23: Competencia a desarrollar | B23: desarrolla hechos, reglas, expresiones y predicados recursivos mediante el uso de cláusulas, ciclos, listas, unificación y cortes en Prolog para modelar bases de conocimiento y resolver problemas de inferencia lógica
A24: Competencia a desarrollar
A26: 2.1 Contenido
A27: No. | B27: Unidad | D27: Tema | F27: Sub Tema
A28: 1 | B28: =IFERROR(__xludf.DUMMYFUNCTION("FILTER('Diseño'!D:D,'Diseño'!H:H=$C$5)"),"Logica e Inferencia") -> Logica e Inferencia | D28: =IFERROR(__xludf.DUMMYFUNCTION("FILTER('Diseño'!E:E,'Diseño'!H:H=$C$5)"),"Tipos de datos y variables") -> Tipos de datos y variables | F28: =IFERROR(__xludf.DUMMYFUNCTION("FILTER('Diseño'!F:F,'Diseño'!H:H=$C$5)"),"Declaración de datos atómicos y compuestos") -> Declaración de datos atómicos y compuestos
A29: 2 | B29: =IFERROR(__xludf.DUMMYFUNCTION("""COMPUTED_VALUE"""),"Logica e Inferencia") -> Logica e Inferencia | D29: =IFERROR(__xludf.DUMMYFUNCTION("""COMPUTED_VALUE"""),"Tipos de datos y variables") -> Tipos de datos y variables | F29: =IFERROR(__xludf.DUMMYFUNCTION("""COMPUTED_VALUE"""),"Manipulación de variables en entornos lógicos") -> Manipulación de variables en entornos lógicos
A30: 3 | B30: =IFERROR(__xludf.DUMMYFUNCTION("""COMPUTED_VALUE"""),"Logica e Inferencia") -> Logica e Inferencia | D30: =IFERROR(__xludf.DUMMYFUNCTION("""COMPUTED_VALUE"""),"Reglas, Hechos y Consultas") -> Reglas, Hechos y Consultas | F30: =IFERROR(__xludf.DUMMYFUNCTION("""COMPUTED_VALUE"""),"Sintaxis de hechos y reglas en Prolog") -> Sintaxis de hechos y reglas en Prolog
A31: 4 | B31: =IFERROR(__xludf.DUMMYFUNCTION("""COMPUTED_VALUE"""),"Logica e Inferencia") -> Logica e Inferencia | D31: =IFERROR(__xludf.DUMMYFUNCTION("""COMPUTED_VALUE"""),"Reglas, Hechos y Consultas") -> Reglas, Hechos y Consultas | F31: =IFERROR(__xludf.DUMMYFUNCTION("""COMPUTED_VALUE"""),"Realización de consultas simples y compuestas") -> Realización de consultas simples y compuestas
A32: 5
A33: 6
A34: 7
A36: 2.2 Recursos Educativos
A38: Tipo de Recurso a utilizar | B38: Tipo | C38: Rango Aproximando | D38: Tiempo Aproximado
A39: Presentacion | B39: Obligatorio | C39: 40 | D39: 30
A40: Video | B40: Obligatorio | C40: 6 | D40: 3
A41: Lectura | B41: Optativo | C41: 3 | D41: 3
A42: Ejercicio Demostrativo | B42: Obligatorio | C42: 30 | D42: 20
A44: 3. Área de Habilidades (Saber Hacer) | G44: Tiempo Aproximado | H44: =B50+B61 -> 50
G45: Tiene que estar en un rango de 30 a 50 minutos
A46: Actividad 1 (Obligatoria)
A47: Competencia que predomina en la actividad | B47: desarrolla hechos, reglas, expresiones y predicados recursivos mediante el uso de cláusulas, ciclos, listas, unificación y cortes en Prolog para modelar bases de conocimiento y resolver problemas de inferencia lógica
A48: Tipo de Actividad | B48: Ejercicio practico
A49: Ponderación | B49: 1
A50: Tiempo Aproximado | B50: 50
...

Sheet S.3
B2: Diseño de la Sesión de Laboratorio
B4: Curso | C4: ='Diseño'!C4 -> 972 - Inteligencia Artificial 1
B5: Semana | C5: 3
B6: Tiempo | C6: =H10+H21+H44+H68 -> 112
B7: Ponderación | C7: =B49+B60 -> 3
B8: Validación de Tiempo | C8: =IF(H44<=0, "❌ ERROR: La Actividad 1 debe tener un tiempo mayor a 0.", IF(H21>60, "❌ ERROR: El 'Área de Conocimiento' no puede exceder los 60 min.", IF((H10+H21+H44)<100, "❌ ERROR: El tiempo total debe ser de al menos 100 min.", "✅ VALIDACIÓN CORRECTA"))) -> ✅ VALIDACIÓN CORRECTA
A10: 1. Área Actitudinal (Saber Ser) | G10: Tiempo Aproximado | H10: =B13 -> 5
G11: Tiene que estar en un rango de 3 a 5 minutos
A12: Nombre del Valor | B12: Claridad
A13: Tiempo Aproximado | B13: 5
A14: Descripcion
A15: La claridad implica expresarse y trabajar de manera comprensible, estructurada y ordenada, tanto al comunicar ideas como al escribir algoritmos o resolver problemas.
A17: Como se relaciona con los conocimientos de la sesion y se aplicaria
A18: Se aplicará en la forma en que los estudiantes: Documenten sus algoritmos de backtracking con comentarios que expliquen la lógica. Expongan con precisión los pasos seguidos en la solución de un problema. Eviten ambigüedades al presentar sus respuestas y justificaciones.
A21: 2. Área Conocimiento (Saber) | G21: Tiempo Aproximado | H21: =D39+D40+D41+D42 -> 56
G22: No puede exceder los 60 minutos
A23: Competencia a desarrollar | B23: desarrolla hechos, reglas, expresiones y predicados recursivos mediante el uso de cláusulas, ciclos, listas, unificación y cortes en Prolog para modelar bases de conocimiento y resolver problemas de inferencia lógica
A24: Competencia a desarrollar
A26: 2.1 Contenido
A27: No. | B27: Unidad | D27: Tema | F27: Sub Tema
A28: 1 | B28: =IFERROR(__xludf.DUMMYFUNCTION("FILTER('Diseño'!D:D,'Diseño'!H:H=$C$5)"),"Logica e Inferencia") -> Logica e Inferencia | D28: =IFERROR(__xludf.DUMMYFUNCTION("FILTER('Diseño'!E:E,'Diseño'!H:H=$C$5)"),"Expresiones y Cláusulas") -> Expresiones y Cláusulas | F28: =IFERROR(__xludf.DUMMYFUNCTION("FILTER('Diseño'!F:F,'Diseño'!H:H=$C$5)"),"Construcción de expresiones condicionales") -> Construcción de expresiones condicionales
A29: 2 | B29: =IFERROR(__xludf.DUMMYFUNCTION("""COMPUTED_VALUE"""),"Logica e Inferencia") -> Logica e Inferencia | D29: =IFERROR(__xludf.DUMMYFUNCTION("""COMPUTED_VALUE"""),"Expresiones y Cláusulas") -> Expresiones y Cláusulas | F29: =IFERROR(__xludf.DUMMYFUNCTION("""COMPUTED_VALUE"""),"Encadenamiento de cláusulas para inferencias") -> Encadenamiento de cláusulas para inferencias
A30: 3 | B30: =IFERROR(__xludf.DUMMYFUNCTION("""COMPUTED_VALUE"""),"Logica e Inferencia") -> Logica e Inferencia | D30: =IFERROR(__xludf.DUMMYFUNCTION("""COMPUTED_VALUE"""),"Predicados") -> Predicados | F30: =IFERROR(__xludf.DUMMYFUNCTION("""COMPUTED_VALUE"""),"Definición de predicados simples") -> Definición de predicados simples
A31: 4 | B31: =IFERROR(__xludf.DUMMYFUNCTION("""COMPUTED_VALUE"""),"Logica e Inferencia") -> Logica e Inferencia | D31: =IFERROR(__xludf.DUMMYFUNCTION("""COMPUTED_VALUE"""),"Predicados") -> Predicados | F31: =IFERROR(__xludf.DUMMYFUNCTION("""COMPUTED_VALUE"""),"Uso de predicados recursivos") -> Uso de predicados recursivos
A32: 5
A33: 6
A34: 7
A36: 2.2 Recursos Educativos
A38: Tipo de Recurso a utilizar | B38: Tipo | C38: Rango Aproximando | D38: Tiempo Aproximado
A39: Presentacion | B39: Obligatorio | D39: 30
A40: Video | B40: Obligatorio | C40: 3 a 6 minutos | D40: 3
A41: Lectura | B41: Optativo | D41: 3
A42: Ejercicio Demostrativo | B42: Obligatorio | D42: 20
A44: 3. Área de Habilidades (Saber Hacer) | G44: Tiempo Aproximado | H44: =B50+B61 -> 50
G45: Tiene que estar en un rango de 30 a 50 minutos
A46: Actividad 1 (Obligatoria)
A47: Competencia que predomina en la actividad | B47: desarrolla hechos, reglas, expresiones y predicados recursivos mediante el uso de cláusulas, ciclos, listas, unificación y cortes en Prolog para modelar bases de conocimiento y resolver problemas de inferencia lógica
A48: Tipo de Actividad | B48: actividades
A49: Ponderación | B49: 1
A50: Tiempo Aproximado | B50: 50
...

Sheet S.4
B2: Diseño de la Sesión de Laboratorio
B4: Curso | C4: ='Diseño'!C4 -> 972 - Inteligencia Artificial 1
B5: Semana | C5: 4
B6: Tiempo | C6: =H10+H21+H44+H68 -> 112
B7: Ponderación | C7: =B49+B60 -> 2
B8: Validación de Tiempo | C8: =IF(H44<=0, "❌ ERROR: La Actividad 1 debe tener un tiempo mayor a 0.", IF(H21>60, "❌ ERROR: El 'Área de Conocimiento' no puede exceder los 60 min.", IF((H10+H21+H44)<100, "❌ ERROR: El tiempo total debe ser de al menos 100 min.", "✅ VALIDACIÓN CORRECTA"))) -> ✅ VALIDACIÓN CORRECTA
A10: 1. Área Actitudinal (Saber Ser) | G10: Tiempo Aproximado | H10: =B13 -> 5
G11: Tiene que estar en un rango de 3 a 5 minutos
A12: Nombre del Valor | B12: Perseverancia
A13: Tiempo Aproximado | B13: 5
A14: Descripcion
A15: La perseverancia implica mantener el esfuerzo constante frente a la dificultad, insistiendo en encontrar soluciones y no rendirse fácilmente ante los errores o la complejidad de un problema.
A17: Como se relaciona con los conocimientos de la sesion y se aplicaria
A18: Porque resolver problemas con recursividad puede ser complejo y exige insistencia.
A21: 2. Área Conocimiento (Saber) | G21: Tiempo Aproximado | H21: =D39+D40+D41+D42 -> 56
G22: No puede exceder los 60 minutos
A23: Competencia a desarrollar | B23: desarrolla hechos, reglas, expresiones y predicados recursivos mediante el uso de cláusulas, ciclos, listas, unificación y cortes en Prolog para modelar bases de conocimiento y resolver problemas de inferencia lógica
A24: Competencia a desarrollar
A26: 2.1 Contenido
A27: No. | B27: Unidad | D27: Tema | F27: Sub Tema
A28: 1 | B28: =IFERROR(__xludf.DUMMYFUNCTION("FILTER('Diseño'!D:D,'Diseño'!H:H=$C$5)"),"Logica e Inferencia") -> Logica e Inferencia | D28: =IFERROR(__xludf.DUMMYFUNCTION("FILTER('Diseño'!E:E,'Diseño'!H:H=$C$5)"),"Negación y Cortes") -> Negación y Cortes | F28: =IFERROR(__xludf.DUMMYFUNCTION("FILTER('Diseño'!F:F,'Diseño'!H:H=$C$5)"),"Implementación de negación en inferencias") -> Implementación de negación en inferencias
A29: 2 | B29: =IFERROR(__xludf.DUMMYFUNCTION("""COMPUTED_VALUE"""),"Logica e Inferencia") -> Logica e Inferencia | D29: =IFERROR(__xludf.DUMMYFUNCTION("""COMPUTED_VALUE"""),"Negación y Cortes") -> Negación y Cortes | F29: =IFERROR(__xludf.DUMMYFUNCTION("""COMPUTED_VALUE"""),"Control de flujo mediante cortes") -> Control de flujo mediante cortes
A30: 3 | B30: =IFERROR(__xludf.DUMMYFUNCTION("""COMPUTED_VALUE"""),"Logica e Inferencia") -> Logica e Inferencia | D30: =IFERROR(__xludf.DUMMYFUNCTION("""COMPUTED_VALUE"""),"Ciclos y Recursión") -> Ciclos y Recursión | F30: =IFERROR(__xludf.DUMMYFUNCTION("""COMPUTED_VALUE"""),"Definición de ciclos recursivos") -> Definición de ciclos recursivos
A31: 4 | B31: =IFERROR(__xludf.DUMMYFUNCTION("""COMPUTED_VALUE"""),"Logica e Inferencia") -> Logica e Inferencia | D31: =IFERROR(__xludf.DUMMYFUNCTION("""COMPUTED_VALUE"""),"Ciclos y Recursión") -> Ciclos y Recursión | F31: =IFERROR(__xludf.DUMMYFUNCTION("""COMPUTED_VALUE"""),"Resolución de problemas mediante recursividad") -> Resolución de problemas mediante recursividad
A32: 5
A33: 6
A34: 7
A36: 2.2 Recursos Educativos
A38: Tipo de Recurso a utilizar | B38: Tipo | C38: Rango Aproximando | D38: Tiempo Aproximado
A39: Presentacion | B39: Obligatorio | D39: 30
A40: Video | B40: Obligatorio | C40: 3 a 6 minutos | D40: 3
A41: Lectura | B41: Optativo | D41: 3
A42: Ejercicio Demostrativo | B42: Obligatorio | D42: 20
A44: 3. Área de Habilidades (Saber Hacer) | G44: Tiempo Aproximado | H44: =B50+B61 -> 50
G45: Tiene que estar en un rango de 30 a 50 minutos
A46: Actividad 1 (Obligatoria)
A47: Competencia que predomina en la actividad | B47: desarrolla hechos, reglas, expresiones y predicados recursivos mediante el uso de cláusulas, ciclos, listas, unificación y cortes en Prolog para modelar bases de conocimiento y resolver problemas de inferencia lógica
A48: Tipo de Actividad | B48: otros
A49: Ponderación | B49: 2
A50: Tiempo Aproximado | B50: 50
...

Sheet S.5
B2: Diseño de la Sesión de Laboratorio
B4: Curso | C4: ='Diseño'!C4 -> 972 - Inteligencia Artificial 1
B5: Semana | C5: 5
B6: Tiempo | C6: =H10+H21+H44+H68 -> 110
B7: Ponderación | C7: =B49+B60 -> 3
B8: Validación de Tiempo | C8: =IF(H44<=0, "❌ ERROR: La Actividad 1 debe tener un tiempo mayor a 0.", IF(H21>60, "❌ ERROR: El 'Área de Conocimiento' no puede exceder los 60 min.", IF((H10+H21+H44)<100, "❌ ERROR: El tiempo total debe ser de al menos 100 min.", "✅ VALIDACIÓN CORRECTA"))) -> ✅ VALIDACIÓN CORRECTA
A10: 1. Área Actitudinal (Saber Ser) | G10: Tiempo Aproximado | H10: =B13 -> 3
G11: Tiene que estar en un rango de 3 a 5 minutos
A12: Nombre del Valor | B12: Curiosidad, innovación, exploración
A13: Tiempo Aproximado | B13: 3
A14: Descripcion
A15: La curiosidad motiva a los estudiantes a cuestionarse y comprender qué es la realidad aumentada, la innovación los impulsa a proponer ideas y aplicaciones creativas, y la exploración fomenta el descubrimiento de nuevas plataformas y herramientas tecnológicas que potencian su aprendizaje
A17: Como se relaciona con los conocimientos de la sesion y se aplicaria
A18: Curiosidad: Porque entender qué es la realidad aumentada impulsa la exploración de nuevas tecnologías. Innovación: Porque pensar en aplicaciones prácticas de AR requiere proponer ideas nuevas. Exploración: Porque se inicia el descubrimiento de plataformas y herramientas emergentes.
A21: 2. Área Conocimiento (Saber) | G21: Tiempo Aproximado | H21: =D39+D40+D41+D42 -> 56
G22: No puede exceder los 60 minutos
A23: Competencia a desarrollar | B23: desarrolla hechos, reglas, expresiones y predicados recursivos mediante el uso de cláusulas, ciclos, listas, unificación y cortes en Prolog para modelar bases de conocimiento y resolver problemas de inferencia lógica
A24: Competencia a desarrollar
A26: 2.1 Contenido
A27: No. | B27: Unidad | D27: Tema | F27: Sub Tema
A28: 1 | B28: =IFERROR(__xludf.DUMMYFUNCTION("FILTER('Diseño'!D:D,'Diseño'!H:H=$C$5)"),"Logica e Inferencia") -> Logica e Inferencia | D28: =IFERROR(__xludf.DUMMYFUNCTION("FILTER('Diseño'!E:E,'Diseño'!H:H=$C$5)"),"Átomos, Listas y Unificación") -> Átomos, Listas y Unificación | F28: =IFERROR(__xludf.DUMMYFUNCTION("FILTER('Diseño'!F:F,'Diseño'!H:H=$C$5)"),"Manejo de átomos y listas") -> Manejo de átomos y listas
A29: 2 | B29: =IFERROR(__xludf.DUMMYFUNCTION("""COMPUTED_VALUE"""),"Logica e Inferencia") -> Logica e Inferencia | D29: =IFERROR(__xludf.DUMMYFUNCTION("""COMPUTED_VALUE"""),"Átomos, Listas y Unificación") -> Átomos, Listas y Unificación | F29: =IFERROR(__xludf.DUMMYFUNCTION("""COMPUTED_VALUE"""),"Principios de unificación de términos") -> Principios de unificación de términos
A30: 3
A31: 4
A32: 5
A33: 6
A34: 7
A36: 2.2 Recursos Educativos
A38: Tipo de Recurso a utilizar | B38: Tipo | C38: Rango Aproximando | D38: Tiempo Aproximado
A39: Presentacion | B39: Obligatorio | D39: 30
A40: Video | B40: Obligatorio | C40: 3 a 6 minutos | D40: 3
A41: Lectura | B41: Optativo | D41: 3
A42: Ejercicio Demostrativo | B42: Obligatorio | D42: 20
A44: 3. Área de Habilidades (Saber Hacer) | G44: Tiempo Aproximado | H44: =B50+B61 -> 50
G45: Tiene que estar en un rango de 30 a 50 minutos
A46: Actividad 1 (Obligatoria)
A47: Competencia que predomina en la actividad | B47: evalúa plataformas de realidad aumentada usando criterios de compatibilidad, usabilidad y eficiencia bajo escenarios de prueba en dispositivos móviles y navegadores web
A48: Tipo de Actividad | B48: actividades
A49: Ponderación | B49: 3
A50: Tiempo Aproximado | B50: 50
...

Sheet S.6
B2: Diseño de la Sesión de Laboratorio
B4: Curso | C4: ='Diseño'!C4 -> 972 - Inteligencia Artificial 1
B5: Semana | C5: 6
B6: Tiempo | C6: =H10+H21+H44+H68 -> 110
B7: Ponderación | C7: =B49+B60 -> 2
B8: Validación de Tiempo | C8: =IF(H44<=0, "❌ ERROR: La Actividad 1 debe tener un tiempo mayor a 0.", IF(H21>60, "❌ ERROR: El 'Área de Conocimiento' no puede exceder los 60 min.", IF((H10+H21+H44)<100, "❌ ERROR: El tiempo total debe ser de al menos 100 min.", "✅ VALIDACIÓN CORRECTA"))) -> ✅ VALIDACIÓN CORRECTA
A10: 1. Área Actitudinal (Saber Ser) | G10: Tiempo Aproximado | H10: =B13 -> 3
G11: Tiene que estar en un rango de 3 a 5 minutos
A12: Nombre del Valor | B12: Evaluación crítica, adaptabilidad
A13: Tiempo Aproximado | B13: 3
A14: Descripcion
A15: La evaluación crítica consiste en analizar de manera reflexiva las soluciones y resultados, identificando fortalezas, debilidades y posibles mejoras. La adaptabilidad implica ajustarse a nuevas circunstancias, herramientas o formas de resolver un problema sin perder el objetivo final.
A17: Como se relaciona con los conocimientos de la sesion y se aplicaria
A18: "Evaluación crítica: Porque analizar plataformas de AR demanda valorar fortalezas y debilidades objetivamente. Adaptabilidad: Porque trabajar con distintas tecnologías requiere flexibilidad ante cambios y actualizaciones."
A21: 2. Área Conocimiento (Saber) | G21: Tiempo Aproximado | H21: =D39+D40+D41+D42 -> 56
G22: No puede exceder los 60 minutos
A23: Competencia a desarrollar | B23: crea aplicaciones de realidad aumentada con contenido digital interactivo mediante el uso de bibliotecas y técnicas de diseño de experiencias para integrar información virtual en el mundo real de forma efectiva y funcional
A24: Competencia a desarrollar
A26: 2.1 Contenido
A27: No. | B27: Unidad | D27: Tema | F27: Sub Tema
A28: 1 | B28: =IFERROR(__xludf.DUMMYFUNCTION("FILTER('Diseño'!D:D,'Diseño'!H:H=$C$5)"),"Realidad Aumentada") -> Realidad Aumentada | D28: =IFERROR(__xludf.DUMMYFUNCTION("FILTER('Diseño'!E:E,'Diseño'!H:H=$C$5)"),"Introducción a la Realidad Aumentada") -> Introducción a la Realidad Aumentada | F28: =IFERROR(__xludf.DUMMYFUNCTION("FILTER('Diseño'!F:F,'Diseño'!H:H=$C$5)"),"Definición y aplicaciones de la AR") -> Definición y aplicaciones de la AR
A29: 2 | B29: =IFERROR(__xludf.DUMMYFUNCTION("""COMPUTED_VALUE"""),"Realidad Aumentada") -> Realidad Aumentada | D29: =IFERROR(__xludf.DUMMYFUNCTION("""COMPUTED_VALUE"""),"Introducción a la Realidad Aumentada") -> Introducción a la Realidad Aumentada | F29: =IFERROR(__xludf.DUMMYFUNCTION("""COMPUTED_VALUE"""),"Componentes básicos de un sistema de AR") -> Componentes básicos de un sistema de AR
A30: 3 | B30: =IFERROR(__xludf.DUMMYFUNCTION("""COMPUTED_VALUE"""),"Realidad Aumentada") -> Realidad Aumentada | D30: =IFERROR(__xludf.DUMMYFUNCTION("""COMPUTED_VALUE"""),"Plataformas de Desarrollo de AR") -> Plataformas de Desarrollo de AR | F30: =IFERROR(__xludf.DUMMYFUNCTION("""COMPUTED_VALUE"""),"Plataformas de desarrollo de AR") -> Plataformas de desarrollo de AR
A31: 4
A32: 5
A33: 6
A34: 7
A36: 2.2 Recursos Educativos
A38: Tipo de Recurso a utilizar | B38: Tipo | C38: Rango Aproximando | D38: Tiempo Aproximado
A39: Presentacion | B39: Obligatorio | D39: 30
A40: Video | B40: Obligatorio | C40: 3 a 6 minutos | D40: 3
A41: Lectura | B41: Optativo | D41: 3
A42: Ejercicio Demostrativo | B42: Obligatorio | D42: 20
A44: 3. Área de Habilidades (Saber Hacer) | G44: Tiempo Aproximado | H44: =B50+B61 -> 50
G45: Tiene que estar en un rango de 30 a 50 minutos
A46: Actividad 1 (Obligatoria)
A47: Competencia que predomina en la actividad | B47: evalúa plataformas de realidad aumentada usando criterios de compatibilidad, usabilidad y eficiencia bajo escenarios de prueba en dispositivos móviles y navegadores web
A48: Tipo de Actividad | B48: actividades
A49: Ponderación | B49: 2
A50: Tiempo Aproximado | B50: 50
...

Sheet S.7
B2: Diseño de la Sesión de Laboratorio
B4: Curso | C4: ='Diseño'!C4 -> 972 - Inteligencia Artificial 1
B5: Semana | C5: 7
B6: Tiempo | C6: =H10+H21+H44+H68 -> 108
B7: Ponderación | C7: =B49+B60 -> 2
B8: Validación de Tiempo | C8: =IF(H44<=0, "❌ ERROR: La Actividad 1 debe tener un tiempo mayor a 0.", IF(H21>60, "❌ ERROR: El 'Área de Conocimiento' no puede exceder los 60 min.", IF((H10+H21+H44)<100, "❌ ERROR: El tiempo total debe ser de al menos 100 min.", "✅ VALIDACIÓN CORRECTA"))) -> ✅ VALIDACIÓN CORRECTA
A10: 1. Área Actitudinal (Saber Ser) | G10: Tiempo Aproximado | H10: 1
G11: Tiene que estar en un rango de 3 a 5 minutos
A12: Nombre del Valor | B12: Diseño creativo, empatía digital
A13: Tiempo Aproximado | B13: 5
A14: Descripcion
A15: El diseño creativo consiste en generar soluciones originales y visualmente atractivas, aplicando la imaginación y la innovación para comunicar ideas de manera efectiva. La empatía digital implica comprender y considerar las experiencias, necesidades y emociones de otros al interactuar y diseñar en entornos tecnológicos.
A17: Como se relaciona con los conocimientos de la sesion y se aplicaria
A18: "Diseño creativo: Porque planear flujos de usuario en AR implica crear experiencias nuevas y atractivas. Empatía digital: Porque el diseño debe considerar la facilidad de uso y experiencia del usuario."
A21: 2. Área Conocimiento (Saber) | G21: Tiempo Aproximado | H21: =D39+D40+D41+D42 -> 56
G22: No puede exceder los 60 minutos
A23: Competencia a desarrollar | B23: crea aplicaciones de realidad aumentada con contenido digital interactivo mediante el uso de bibliotecas y técnicas de diseño de experiencias para integrar información virtual en el mundo real de forma efectiva y funcional
A24: Competencia a desarrollar
A26: 2.1 Contenido
A27: No. | B27: Unidad | D27: Tema | F27: Sub Tema
A28: 1 | B28: =IFERROR(__xludf.DUMMYFUNCTION("FILTER('Diseño'!D:D,'Diseño'!H:H=$C$5)"),"Realidad Aumentada") -> Realidad Aumentada | D28: =IFERROR(__xludf.DUMMYFUNCTION("FILTER('Diseño'!E:E,'Diseño'!H:H=$C$5)"),"Plataformas de Desarrollo de AR") -> Plataformas de Desarrollo de AR | F28: =IFERROR(__xludf.DUMMYFUNCTION("FILTER('Diseño'!F:F,'Diseño'!H:H=$C$5)"),"Librerías de AR para entornos web") -> Librerías de AR para entornos web
A29: 2 | B29: =IFERROR(__xludf.DUMMYFUNCTION("""COMPUTED_VALUE"""),"Realidad Aumentada") -> Realidad Aumentada | D29: =IFERROR(__xludf.DUMMYFUNCTION("""COMPUTED_VALUE"""),"Diseño de Aplicaciones de Realidad Aumentada") -> Diseño de Aplicaciones de Realidad Aumentada | F29: =IFERROR(__xludf.DUMMYFUNCTION("""COMPUTED_VALUE"""),"Planeación de flujos de usuario en AR") -> Planeación de flujos de usuario en AR
A30: 3 | B30: =IFERROR(__xludf.DUMMYFUNCTION("""COMPUTED_VALUE"""),"Realidad Aumentada") -> Realidad Aumentada | D30: =IFERROR(__xludf.DUMMYFUNCTION("""COMPUTED_VALUE"""),"Diseño de Aplicaciones de Realidad Aumentada") -> Diseño de Aplicaciones de Realidad Aumentada | F30: =IFERROR(__xludf.DUMMYFUNCTION("""COMPUTED_VALUE"""),"Integración de interacción digital en entornos reales") -> Integración de interacción digital en entornos reales
A31: 4
A32: 5
A33: 6
A34: 7
A36: 2.2 Recursos Educativos
A38: Tipo de Recurso a utilizar | B38: Tipo | C38: Rango Aproximando | D38: Tiempo Aproximado
A39: Presentacion | B39: Obligatorio | D39: 30
A40: Video | B40: Obligatorio | C40: 3 a 6 minutos | D40: 3
A41: Lectura | B41: Optativo | D41: 3
A42: Ejercicio Demostrativo | B42: Obligatorio | D42: 20
A44: 3. Área de Habilidades (Saber Hacer) | G44: Tiempo Aproximado | H44: =B50+B61 -> 50
G45: Tiene que estar en un rango de 30 a 50 minutos
A46: Actividad 1 (Obligatoria)
A47: Competencia que predomina en la actividad | B47: crea aplicaciones de realidad aumentada con contenido digital interactivo mediante el uso de bibliotecas y técnicas de diseño de experiencias para integrar información virtual en el mundo real de forma efectiva y funcional
A48: Tipo de Actividad | B48: actividades
A49: Ponderación | B49: 2
A50: Tiempo Aproximado | B50: 50
...

Sheet S.8
B2: Diseño de la Sesión de Laboratorio
B4: Curso | C4: ='Diseño'!C4 -> 972 - Inteligencia Artificial 1
B5: Semana | C5: 8
B6: Tiempo | C6: =H10+H21+H44+H68 -> 107
B7: Ponderación | C7: =B49+B60 -> 3
B8: Validación de Tiempo | C8: =IF(H44<=0, "❌ ERROR: La Actividad 1 debe tener un tiempo mayor a 0.", IF(H21>60, "❌ ERROR: El 'Área de Conocimiento' no puede exceder los 60 min.", IF((H10+H21+H44)<100, "❌ ERROR: El tiempo total debe ser de al menos 100 min.", "✅ VALIDACIÓN CORRECTA"))) -> ✅ VALIDACIÓN CORRECTA
A10: 1. Área Actitudinal (Saber Ser) | G10: Tiempo Aproximado | H10: =B13
G11: Tiene que estar en un rango de 3 a 5 minutos
A12: Nombre del Valor | B12: Estetica, funcionalidad, optimización
A13: Tiempo Aproximado
A14: Descripcion
A15: La estética se relaciona con la capacidad de presentar soluciones de manera clara, atractiva y ordenada, favoreciendo la comprensión y la experiencia visual. La funcionalidad implica que las soluciones propuestas cumplan con su propósito de manera efectiva y práctica. La optimización se centra en mejorar los procesos y soluciones para que sean más rápidos, eficientes y con menor uso de recursos.
A17: Como se relaciona con los conocimientos de la sesion y se aplicaria
A18: "Estética: Porque el modelado de objetos digitales debe ser visualmente atractivo. Funcionalidad: Porque los objetos deben ser no solo bonitos, sino útiles en su integración con AR. Optimización: Porque en AR el rendimiento es clave, y el contenido debe estar optimizado para funcionar bien."
A21: 2. Área Conocimiento (Saber) | G21: Tiempo Aproximado | H21: =D39+D40+D41+D42 -> 56
G22: No puede exceder los 60 minutos
A23: Competencia a desarrollar | B23: crea aplicaciones de realidad aumentada con contenido digital interactivo mediante el uso de bibliotecas y técnicas de diseño de experiencias para integrar información virtual en el mundo real de forma efectiva y funcional
A24: Competencia a desarrollar
A26: 2.1 Contenido
A27: No. | B27: Unidad | D27: Tema | F27: Sub Tema
A28: 1 | B28: =IFERROR(__xludf.DUMMYFUNCTION("FILTER('Diseño'!D:D,'Diseño'!H:H=$C$5)"),"Realidad Aumentada") -> Realidad Aumentada | D28: =IFERROR(__xludf.DUMMYFUNCTION("FILTER('Diseño'!E:E,'Diseño'!H:H=$C$5)"),"Creación de Contenido Digital para AR") -> Creación de Contenido Digital para AR | F28: =IFERROR(__xludf.DUMMYFUNCTION("FILTER('Diseño'!F:F,'Diseño'!H:H=$C$5)"),"Modelado de objetos 2D y 3D para AR") -> Modelado de objetos 2D y 3D para AR
A29: 2 | B29: =IFERROR(__xludf.DUMMYFUNCTION("""COMPUTED_VALUE"""),"Realidad Aumentada") -> Realidad Aumentada | D29: =IFERROR(__xludf.DUMMYFUNCTION("""COMPUTED_VALUE"""),"Creación de Contenido Digital para AR") -> Creación de Contenido Digital para AR | F29: =IFERROR(__xludf.DUMMYFUNCTION("""COMPUTED_VALUE"""),"Técnicas de optimización de contenido digital") -> Técnicas de optimización de contenido digital
A30: 3
A31: 4
A32: 5
A33: 6
A34: 7
A36: 2.2 Recursos Educativos
A38: Tipo de Recurso a utilizar | B38: Tipo | C38: Rango Aproximando | D38: Tiempo Aproximado
A39: Presentacion | B39: Obligatorio | D39: 30
A40: Video | B40: Obligatorio | C40: 3 a 6 minutos | D40: 3
A41: Lectura | B41: Optativo | D41: 3
A42: Ejercicio Demostrativo | B42: Obligatorio | D42: 20
A44: 3. Área de Habilidades (Saber Hacer) | G44: Tiempo Aproximado | H44: =B50+B61 -> 50
G45: Tiene que estar en un rango de 30 a 50 minutos
A46: Actividad 1 (Obligatoria)
A47: Competencia que predomina en la actividad | B47: crea aplicaciones de realidad aumentada con contenido digital interactivo mediante el uso de bibliotecas y técnicas de diseño de experiencias para integrar información virtual en el mundo real de forma efectiva y funcional
A48: Tipo de Actividad | B48: Cuestionario
A49: Ponderación | B49: 3
A50: Tiempo Aproximado | B50: 50
...

Sheet S.9
B2: Diseño de la Sesión de Laboratorio
B4: Curso | C4: ='Diseño'!C4 -> 972 - Inteligencia Artificial 1
B5: Semana | C5: 9
B6: Tiempo | C6: =H10+H21+H44+H68 -> 107
B7: Ponderación | C7: =B49+B60 -> 2
B8: Validación de Tiempo | C8: =IF(H44<=0, "❌ ERROR: La Actividad 1 debe tener un tiempo mayor a 0.", IF(H21>60, "❌ ERROR: El 'Área de Conocimiento' no puede exceder los 60 min.", IF((H10+H21+H44)<100, "❌ ERROR: El tiempo total debe ser de al menos 100 min.", "✅ VALIDACIÓN CORRECTA"))) -> ✅ VALIDACIÓN CORRECTA
A10: 1. Área Actitudinal (Saber Ser) | G10: Tiempo Aproximado | H10: =B13
G11: Tiene que estar en un rango de 3 a 5 minutos
A12: Nombre del Valor | B12: investigación, Iniciativa
A13: Tiempo Aproximado
A14: Descripcion
A15: La investigación impulsa a los estudiantes a indagar, buscar información y profundizar en nuevos conocimientos para comprender mejor un tema. La iniciativa fomenta la proactividad, motivando a los estudiantes a proponer ideas, experimentar soluciones y tomar acción sin esperar instrucciones.
A17: Como se relaciona con los conocimientos de la sesion y se aplicaria
A18: "Investigación: Porque conocer plataformas y bibliotecas de simulación exige indagar en documentación y ejemplos. Iniciativa: Porque construir simulaciones propias requiere tomar acción y experimentar."
A21: 2. Área Conocimiento (Saber) | G21: Tiempo Aproximado | H21: =D39+D40+D41+D42 -> 56
G22: No puede exceder los 60 minutos
A23: Competencia a desarrollar | B23: integra diseños 2D y 3D de robots la eficiencia y realismo en simulaciones robóticas para aumentar la precisión, eficiencia y realismo de entornos virtuales
A24: Competencia a desarrollar
A26: 2.1 Contenido
A27: No. | B27: Unidad | D27: Tema | F27: Sub Tema
A28: 1 | B28: =IFERROR(__xludf.DUMMYFUNCTION("FILTER('Diseño'!D:D,'Diseño'!H:H=$C$5)"),"Simulación de Robots") -> Simulación de Robots | D28: =IFERROR(__xludf.DUMMYFUNCTION("FILTER('Diseño'!E:E,'Diseño'!H:H=$C$5)"),"Introducción a la Simulación Robótica") -> Introducción a la Simulación Robótica | F28: =IFERROR(__xludf.DUMMYFUNCTION("FILTER('Diseño'!F:F,'Diseño'!H:H=$C$5)"),"Definición y aplicaciones de la simulación de robots") -> Definición y aplicaciones de la simulación de robots
A29: 2 | B29: =IFERROR(__xludf.DUMMYFUNCTION("""COMPUTED_VALUE"""),"Simulación de Robots") -> Simulación de Robots | D29: =IFERROR(__xludf.DUMMYFUNCTION("""COMPUTED_VALUE"""),"Introducción a la Simulación Robótica") -> Introducción a la Simulación Robótica | F29: =IFERROR(__xludf.DUMMYFUNCTION("""COMPUTED_VALUE"""),"Plataformas y bibliotecas de simulación 3D y 2D") -> Plataformas y bibliotecas de simulación 3D y 2D
A30: 3
A31: 4
A32: 5
A33: 6
A34: 7
A36: 2.2 Recursos Educativos
A38: Tipo de Recurso a utilizar | B38: Tipo | C38: Rango Aproximando | D38: Tiempo Aproximado
A39: Presentacion | B39: Obligatorio | D39: 30
A40: Video | B40: Obligatorio | C40: 3 a 6 minutos | D40: 3
A41: Lectura | B41: Optativo | D41: 3
A42: Ejercicio Demostrativo | B42: Obligatorio | D42: 20
A44: 3. Área de Habilidades (Saber Hacer) | G44: Tiempo Aproximado | H44: =B50+B61 -> 50
G45: Tiene que estar en un rango de 30 a 50 minutos
A46: Actividad 1 (Obligatoria)
A47: Competencia que predomina en la actividad | B47: integra diseños 2D y 3D de robots la eficiencia y realismo en simulaciones robóticas para aumentar la precisión, eficiencia y realismo de entornos virtuales
A48: Tipo de Actividad | B48: actividades
A49: Ponderación | B49: 2
A50: Tiempo Aproximado | B50: 50
...

Sheet S.10
B2: Diseño de la Sesión de Laboratorio
B4: Curso | C4: ='Diseño'!C4 -> 972 - Inteligencia Artificial 1
B5: Semana | C5: 10
B6: Tiempo | C6: =H10+H21+H44+H68 -> 105
B7: Ponderación | C7: =B49+B60 -> 2
B8: Validación de Tiempo | C8: =IF(H44<=0, "❌ ERROR: La Actividad 1 debe tener un tiempo mayor a 0.", IF(H21>60, "❌ ERROR: El 'Área de Conocimiento' no puede exceder los 60 min.", IF((H10+H21+H44)<100, "❌ ERROR: El tiempo total debe ser de al menos 100 min.", "✅ VALIDACIÓN CORRECTA"))) -> ✅ VALIDACIÓN CORRECTA
A10: 1. Área Actitudinal (Saber Ser) | G10: Tiempo Aproximado | H10: =B13 -> 5
G11: Tiene que estar en un rango de 3 a 5 minutos
A12: Nombre del Valor | B12: Creatividad técnica, Precisión espacial
A13: Tiempo Aproximado | B13: 5
A14: Descripcion
A15: Creatividad técnica: Capacidad de proponer soluciones innovadoras aplicando conocimientos científicos y tecnológicos. Precisión espacial: Habilidad para interpretar y representar con exactitud las relaciones entre objetos en el espacio.
A17: Como se relaciona con los conocimientos de la sesion y se aplicaria
A18: Porque modelar robots en 2D y 3D combina habilidades técnicas y creatividad visual. Porque diseñar robots funcionales en un entorno tridimensional requiere mucha exactitud en medidas y posiciones.
A21: 2. Área Conocimiento (Saber) | G21: Tiempo Aproximado | H21: =D39+D40+D41+D42 -> 55
G22: No puede exceder los 60 minutos
A23: Competencia a desarrollar | B23: integra diseños 2D y 3D de robots la eficiencia y realismo en simulaciones robóticas para aumentar la precisión, eficiencia y realismo de entornos virtuales
A24: Competencia a desarrollar
A26: 2.1 Contenido
A27: No. | B27: Unidad | D27: Tema | F27: Sub Tema
A28: 1 | B28: =IFERROR(__xludf.DUMMYFUNCTION("FILTER('Diseño'!D:D,'Diseño'!H:H=$C$5)"),"Simulación de Robots") -> Simulación de Robots | D28: =IFERROR(__xludf.DUMMYFUNCTION("FILTER('Diseño'!E:E,'Diseño'!H:H=$C$5)"),"Diseño de Robots en 2D") -> Diseño de Robots en 2D | F28: =IFERROR(__xludf.DUMMYFUNCTION("FILTER('Diseño'!F:F,'Diseño'!H:H=$C$5)"),"Modelado de robots en entornos bidimensionales") -> Modelado de robots en entornos bidimensionales
A29: 2 | B29: =IFERROR(__xludf.DUMMYFUNCTION("""COMPUTED_VALUE"""),"Simulación de Robots") -> Simulación de Robots | D29: =IFERROR(__xludf.DUMMYFUNCTION("""COMPUTED_VALUE"""),"Diseño de Robots en 2D") -> Diseño de Robots en 2D | F29: =IFERROR(__xludf.DUMMYFUNCTION("""COMPUTED_VALUE"""),"Definición de acciones básicas en 2D") -> Definición de acciones básicas en 2D
A30: 3 | B30: =IFERROR(__xludf.DUMMYFUNCTION("""COMPUTED_VALUE"""),"Simulación de Robots") -> Simulación de Robots | D30: =IFERROR(__xludf.DUMMYFUNCTION("""COMPUTED_VALUE"""),"Diseño de Robots en 3D") -> Diseño de Robots en 3D | F30: =IFERROR(__xludf.DUMMYFUNCTION("""COMPUTED_VALUE"""),"Creación de modelos tridimensionales de robots") -> Creación de modelos tridimensionales de robots
A31: 4 | B31: =IFERROR(__xludf.DUMMYFUNCTION("""COMPUTED_VALUE"""),"Simulación de Robots") -> Simulación de Robots | D31: =IFERROR(__xludf.DUMMYFUNCTION("""COMPUTED_VALUE"""),"Diseño de Robots en 3D") -> Diseño de Robots en 3D | F31: =IFERROR(__xludf.DUMMYFUNCTION("""COMPUTED_VALUE"""),"Implementación de texturas y materiales") -> Implementación de texturas y materiales
A32: 5
A33: 6
A34: 7
A36: 2.2 Recursos Educativos
A38: Tipo de Recurso a utilizar | B38: Tipo | C38: Rango Aproximando | D38: Tiempo Aproximado
A39: Presentacion | B39: Obligatorio | D39: 25
A40: Video | B40: Obligatorio | C40: 3 a 6 minutos | D40: 5
A41: Lectura | B41: Optativo
A42: Ejercicio Demostrativo | B42: Obligatorio | D42: 25
A44: 3. Área de Habilidades (Saber Hacer) | G44: Tiempo Aproximado | H44: =B50 -> 40
G45: Tiene que estar en un rango de 30 a 50 minutos
A46: Actividad 1 (Obligatoria)
A47: Competencia que predomina en la actividad | B47: integra diseños 2D y 3D de robots la eficiencia y realismo en simulaciones robóticas para aumentar la precisión, eficiencia y realismo de entornos virtuales
A48: Tipo de Actividad | B48: Ejercicio practico
A49: Ponderación | B49: 2
A50: Tiempo Aproximado | B50: 40
...

Sheet S.11
B2: Diseño de la Sesión de Laboratorio
B4: Curso | C4: ='Diseño'!C4 -> 972 - Inteligencia Artificial 1
B5: Semana | C5: 11
B6: Tiempo | C6: =H10+H21+H44+H68 -> 105
B7: Ponderación | C7: =B49+B60 -> 3
B8: Validación de Tiempo | C8: =IF(H44<=0, "❌ ERROR: La Actividad 1 debe tener un tiempo mayor a 0.", IF(H21>60, "❌ ERROR: El 'Área de Conocimiento' no puede exceder los 60 min.", IF((H10+H21+H44)<100, "❌ ERROR: El tiempo total debe ser de al menos 100 min.", "✅ VALIDACIÓN CORRECTA"))) -> ✅ VALIDACIÓN CORRECTA
A10: 1. Área Actitudinal (Saber Ser) | G10: Tiempo Aproximado | H10: =B13 -> 5
G11: Tiene que estar en un rango de 3 a 5 minutos
A12: Nombre del Valor | B12: Trabajo colaborativo, Mejora continua, Responsabilidad técnica
A13: Tiempo Aproximado | B13: 5
A14: Descripcion
A15: Trabajo colaborativo: Capacidad de coordinarse con otros para alcanzar objetivos comunes de manera eficiente. Mejora continua: Disposición a optimizar procesos mediante pruebas, ajustes y aprendizajes constantes. Responsabilidad técnica: Compromiso de ejecutar tareas con rigor, considerando el impacto en la calidad y eficiencia de los resultados.
A17: Como se relaciona con los conocimientos de la sesion y se aplicaria
A18: Trabajo colaborativo: Porque interactuar múltiples robots en simulaciones promueve la coordinación y el trabajo en equipo. Mejora continua: Porque optimizar simulaciones implica un proceso constante de prueba y ajuste. Responsabilidad técnica: Porque cada ajuste o programación impacta el realismo y eficiencia de la simulación.
A21: 2. Área Conocimiento (Saber) | G21: Tiempo Aproximado | H21: =D39+D40+D41+D42 -> 50
G22: No puede exceder los 60 minutos
A23: Competencia a desarrollar | B23: integra diseños 2D y 3D de robots la eficiencia y realismo en simulaciones robóticas para aumentar la precisión, eficiencia y realismo de entornos virtuales
A24: Competencia a desarrollar
A26: 2.1 Contenido
A27: No. | B27: Unidad | D27: Tema | F27: Sub Tema
A28: 1 | B28: =IFERROR(__xludf.DUMMYFUNCTION("FILTER('Diseño'!D:D,'Diseño'!H:H=$C$5)"),"Simulación de Robots") -> Simulación de Robots | D28: =IFERROR(__xludf.DUMMYFUNCTION("FILTER('Diseño'!E:E,'Diseño'!H:H=$C$5)"),"Programación de Acciones Robóticas") -> Programación de Acciones Robóticas | F28: =IFERROR(__xludf.DUMMYFUNCTION("FILTER('Diseño'!F:F,'Diseño'!H:H=$C$5)"),"Definición de trayectorias y movimientos") -> Definición de trayectorias y movimientos
A29: 2 | B29: =IFERROR(__xludf.DUMMYFUNCTION("""COMPUTED_VALUE"""),"Simulación de Robots") -> Simulación de Robots | D29: =IFERROR(__xludf.DUMMYFUNCTION("""COMPUTED_VALUE"""),"Programación de Acciones Robóticas") -> Programación de Acciones Robóticas | F29: =IFERROR(__xludf.DUMMYFUNCTION("""COMPUTED_VALUE"""),"Respuesta a eventos en simulaciones robóticas") -> Respuesta a eventos en simulaciones robóticas
A30: 3 | B30: =IFERROR(__xludf.DUMMYFUNCTION("""COMPUTED_VALUE"""),"Simulación de Robots") -> Simulación de Robots | D30: =IFERROR(__xludf.DUMMYFUNCTION("""COMPUTED_VALUE"""),"Simulación de Entornos Robóticos") -> Simulación de Entornos Robóticos | F30: =IFERROR(__xludf.DUMMYFUNCTION("""COMPUTED_VALUE"""),"Implementación de simuladores básicos (p5.js, Three.js)") -> Implementación de simuladores básicos (p5.js, Three.js)
A31: 4 | B31: =IFERROR(__xludf.DUMMYFUNCTION("""COMPUTED_VALUE"""),"Simulación de Robots") -> Simulación de Robots | D31: =IFERROR(__xludf.DUMMYFUNCTION("""COMPUTED_VALUE"""),"Simulación de Entornos Robóticos") -> Simulación de Entornos Robóticos | F31: =IFERROR(__xludf.DUMMYFUNCTION("""COMPUTED_VALUE"""),"Interacción de múltiples robots en un mismo entorno") -> Interacción de múltiples robots en un mismo entorno
A32: 5
A33: 6
A34: 7
A36: 2.2 Recursos Educativos
A38: Tipo de Recurso a utilizar | B38: Tipo | C38: Rango Aproximando | D38: Tiempo Aproximado
A39: Presentacion | B39: Obligatorio | D39: 25
A40: Video | B40: Obligatorio | C40: 3 a 6 minutos | D40: 5
A41: Lectura | B41: Optativo | D41: 10
A42: Ejercicio Demostrativo | B42: Obligatorio | D42: 10
A44: 3. Área de Habilidades (Saber Hacer) | G44: Tiempo Aproximado | H44: =B50+B61 -> 45
G45: Tiene que estar en un rango de 30 a 50 minutos
A46: Actividad 1 (Obligatoria)
A47: Competencia que predomina en la actividad | B47: crea aplicaciones de realidad aumentada con contenido digital interactivo mediante el uso de bibliotecas y técnicas de diseño de experiencias para integrar información virtual en el mundo real de forma efectiva y funcional
A48: Tipo de Actividad | B48: Cuestionario
A49: Ponderación | B49: 3
A50: Tiempo Aproximado | B50: 45
...

Sheet Proyectos
B2: Proyectos
B4: Curso | C4: ='Diseño'!C4 -> 972 - Inteligencia Artificial 1
B5: Tiempo | C5: =H9+H26+H43 -> 108
B6: Ponderación | C6: =F9+F26+F43 -> 70
B7: La sumatoria de los puntos de los proyectos debe superar el 70% del total de la nota, no puede ser un 100%
A9: 1. Primer Proyecto | E9: Ponderación | F9: 30 | G9: Horas para realizarlo | H9: 50
A10: Obligatorio
A11: Competencia a desarrollar | B11: Integra fundamentos de lógica, realidad aumentada y simulación robótica mediante el uso de entornos de desarrollo para resolver problemas relacionados a inferencia, interacción digital y simulación de comportamientos autónomos
A12: Competencia a desarrollar | B12: implementa soluciones de inteligencia artificial empleando técnicas de inferencia lógica, diseño de entornos virtuales y control de robots en distintos escenarios de optimización, clasificación y toma de decisiones
A13: Competencia a desarrollar | B13: desarrolla hechos, reglas, expresiones y predicados recursivos mediante el uso de cláusulas, ciclos, listas, unificación y cortes en Prolog para modelar bases de conocimiento y resolver problemas de inferencia lógica
A14: Titulo | B14: Lógica e Inferencia con Prolog
A15: Qué tecnologías, lenguajes de programación, plataformas, hardware o software se utilizaran
A16: Prolog (Python)
A19: Descripción de lo que se realizara
A20: Desarrollo de una aplicación que emplee lógica formal para modelar y resolver problemas mediante Prolog. El proyecto puede involucrar la creación de una base de conocimiento con hechos y reglas, y la implementación de inferencia lógica para realizar consultas. La resolución de un problema práctico, como un sistema de recomendaciones o diagnóstico basado en reglas lógicas, será el enfoque principal.
A26: 2. Segundo Proyecto | E26: Ponderación | F26: 40 | G26: Horas para realizarlo | H26: 58
A27: Obligatorio
A28: Competencia a desarrollar | B28: Integra fundamentos de lógica, realidad aumentada y simulación robótica mediante el uso de entornos de desarrollo para resolver problemas relacionados a inferencia, interacción digital y simulación de comportamientos autónomos
A29: Competencia a desarrollar | B29: implementa soluciones de inteligencia artificial empleando técnicas de inferencia lógica, diseño de entornos virtuales y control de robots en distintos escenarios de optimización, clasificación y toma de decisiones
A30: Competencia a desarrollar | B30: crea aplicaciones de realidad aumentada con contenido digital interactivo mediante el uso de bibliotecas y técnicas de diseño de experiencias para integrar información virtual en el mundo real de forma efectiva y funcional
A31: Titulo | B31: Aplicación de Realidad Aumentada
A32: Qué tecnologías, lenguajes de programación, plataformas, hardware o software se utilizaran
A33: AR (Raspberry y Python)
A36: Descripción de lo que se realizara
A37: Creación de una aplicación de realidad aumentada que permita interactuar con el entorno físico mediante contenido digital. El proyecto podría incluir el desarrollo de un sistema que integre modelos 3D en el mundo real o una experiencia de AR interactiva, donde el usuario pueda visualizar y manipular objetos virtuales en tiempo real.
A43: 3. Tercer Proyecto | E43: Ponderación | G43: Horas para realizarlo
A44: Optativa
A45: Competencia a desarrollar
A46: Competencia a desarrollar
A47: Competencia a desarrollar
A48: Titulo
A49: Qué tecnologías, lenguajes de programación, plataformas, hardware o software se utilizaran
A53: Descripción de lo que se realizara

Sheet Practicas
B2: Practicas
B4: Curso | C4: ='Diseño'!C4 -> 972 - Inteligencia Artificial 1
B5: Tiempo | C5: =H9+H26+H43+H60+H77+H94+H111 -> 0
B6: Ponderación | C6: =F9+F26+F43+F60+F77+F94+F111 -> 0
B7: La sumatoria de los puntos de los practicas debe no debe super el 20%
A9: 1. Primera Practica | E9: Ponderación | G9: Horas para realizarlo
A10: Obligatoria
A11: Competencia a desarrollar
A12: Competencia a desarrollar
A13: Competencia a desarrollar
A14: Titulo
A15: Qué tecnologías, lenguajes de programación, plataformas, hardware o software se utilizaran
A19: Descripción de lo que se realizara
A26: 2. Segunda Practica | E26: Ponderación | G26: Horas para realizarlo
A27: Optativa
A28: Competencia a desarrollar
A29: Competencia a desarrollar
A30: Competencia a desarrollar
A31: Titulo
A32: Qué tecnologías, lenguajes de programación, plataformas, hardware o software se utilizaran
A36: Descripción de lo que se realizara
A43: 3. Tercera Practica | E43: Ponderación | G43: Horas para realizarlo
A44: Optativa
A45: Competencia a desarrollar
A46: Competencia a desarrollar
A47: Competencia a desarrollar
A48: Titulo
A49: Qué tecnologías, lenguajes de programación, plataformas, hardware o software se utilizaran
A53: Descripción de lo que se realizara
A60: 4. Cuarta Practica | E60: Ponderación | G60: Horas para realizarlo
A61: Optativa
A62: Competencia a desarrollar
A63: Competencia a desarrollar
A64: Competencia a desarrollar
A65: Titulo
A66: Qué tecnologías, lenguajes de programación, plataformas, hardware o software se utilizaran
A70: Descripción de lo que se realizara
A77: 5. Quinta Practica | E77: Ponderación | G77: Horas para realizarlo
A78: Optativa
A79: Competencia a desarrollar
...

Sheet Tareas
B2: Tareas
B4: Curso | C4: ='Diseño'!C4 -> 972 - Inteligencia Artificial 1
B5: Tiempo | C5: =H9+H26+H43+H60+H77+H94+H111 -> 0
B6: Ponderación | C6: =F9+F26+F43+F60+F77+F94+F111 -> 0
B7: La sumatoria de los puntos de los practicas debe no debe super el 20% de la nota
A9: 1. Primera Tarea | E9: Ponderación | G9: Horas para realizarlo
A10: Obligatoria
A11: Competencia a desarrollar
A12: Competencia a desarrollar
A13: Competencia a desarrollar
A14: Titulo
A15: Qué tecnologías, lenguajes de programación, plataformas, hardware o software se utilizaran
A19: Descripción de lo que se realizara
A26: 2. Segunda Tarea | E26: Ponderación | G26: Horas para realizarlo
A27: Obligatoria
A28: Competencia a desarrollar
A29: Competencia a desarrollar
A30: Competencia a desarrollar
A31: Titulo
A32: Qué tecnologías, lenguajes de programación, plataformas, hardware o software se utilizaran
A36: Descripción de lo que se realizara
A43: 3. Tercera Tarea | E43: Ponderación | G43: Horas para realizarlo
A44: Optativa
A45: Competencia a desarrollar
A46: Competencia a desarrollar
A47: Competencia a desarrollar
A48: Titulo
A49: Qué tecnologías, lenguajes de programación, plataformas, hardware o software se utilizaran
A53: Descripción de lo que se realizara
A60: 4. Cuarta Tarea | E60: Ponderación | G60: Horas para realizarlo
A61: Optativa
A62: Competencia a desarrollar
A63: Competencia a desarrollar
A64: Competencia a desarrollar
A65: Titulo
A66: Qué tecnologías, lenguajes de programación, plataformas, hardware o software se utilizaran
A70: Descripción de lo que se realizara
A77: 5. Quinta Tarea | E77: Ponderación | G77: Horas para realizarlo
A78: Optativa
A79: Competencia a desarrollar
...

Sheet Resumen
B2: Resumen de Ponderacion y Horas para realizar las actividades
B4: Curso | C4: ='Diseño'!C4 -> 972 - Inteligencia Artificial 1
B5: Periodo al que aplica | C5: Primer Semestre 2026
B6: Total de Puntos del Laboratorio
A9: Actividades Formativas | B9: 8 | D9: Proyectos | E9: 2
A10: Debe abarcar entre el 20% y 30% de la Nota | D10: Debe abarcar entre el 60% y 70% de la Nota
A12: Tipo de Actividad | B12: Ponderacion | C12: Horas Aproximadas para realizarlo | D12: Observaciones
A13: Actividades durante el peridodo de laboratorio | B13: 30 | E13: Sumatoria de todas las semas
A14: Proyectos | B14: =Proyectos!C6 -> 70 | C14: =Proyectos!C5 -> 108
A15: Practicas | B15: =Practicas!C6 -> 0 | C15: =Practicas!C5 -> 0
A16: Tareas | B16: =Tareas!C6 -> 0 | C16: =Tareas!C5 -> 0
A17: Total | B17: =SUM(B13:B16) -> 100 | C17: =SUM(C13:C16) -> 108

Sheet METADATA
