Workbook

Sheet Diseño
A2: =VALUE(LEFT(C4,FIND(" - ",C4)-1)) -> 778 | B2: Diseño de Contenido Curricular
B4: Curso | C4: 778 - Arquitectura de Computadoras y Ensambladores 1
B5: Periodo al que aplica | C5: Primer Semestre 2026
B8: No. | C8: Competencia | D8: Nombre de la Unidad | E8: Tema | F8: Subtema | G8: Mes | H8: Semana
B9: 1 | C9: El estudiante Identifica los componentes esenciales de un sistema IoT mediante el análisis de documentación técnica y catálogos de hardware para describir las funcionalidades básicas de cada elemento del sistema | D9: Arquitectura De Computadores y Lineas Tecnologicas | E9: Arquitectura Y Tecnologias | F9: Arquitectura Von Neuman | G9: Enero | H9: 1
B10: 2 | C10: El estudiante Identifica los componentes esenciales de un sistema IoT mediante el análisis de documentación técnica y catálogos de hardware para describir las funcionalidades básicas de cada elemento del sistema | D10: Arquitectura De Computadores y Lineas Tecnologicas | E10: Arquitectura Y Tecnologias | F10: Arquitectura Harvard | G10: Enero | H10: 1
B11: 3 | C11: El estudiante Identifica los componentes esenciales de un sistema IoT mediante el análisis de documentación técnica y catálogos de hardware para describir las funcionalidades básicas de cada elemento del sistema | D11: Arquitectura De Computadores y Lineas Tecnologicas | E11: Arquitectura Y Tecnologias | F11: Linea Tecnologia RISC | G11: Enero | H11: 1
B12: 4 | C12: El estudiante Identifica los componentes esenciales de un sistema IoT mediante el análisis de documentación técnica y catálogos de hardware para describir las funcionalidades básicas de cada elemento del sistema | D12: Arquitectura De Computadores y Lineas Tecnologicas | E12: Arquitectura Y Tecnologias | F12: Linea Tecnologica CISC | G12: Enero | H12: 1
B13: 5 | C13: El estudiante implementa estructuras de control utilizando instrucciones de saltos en lenguaje ensamblador, mediante técnicas de programación a bajo nivel, para desarrollar soluciones orientadas a sistemas IoT mediante la solucion de problemas aplicacio al hardware. | D13: Arquitectura De Computadores y Lineas Tecnologicas | E13: Evolucion De Los Procesadores Hasta La Actualidad | F13: Procesadores x86 | G13: Enero | H13: 2
B14: 6 | C14: El estudiante implementa estructuras de control utilizando instrucciones de saltos en lenguaje ensamblador, mediante técnicas de programación a bajo nivel, para desarrollar soluciones orientadas a sistemas IoT mediante la solucion de problemas aplicacio al hardware. | D14: Arquitectura De Computadores y Lineas Tecnologicas | E14: Evolucion De Los Procesadores Hasta La Actualidad | F14: Procesadores ARM | G14: Enero | H14: 2
B15: 7 | C15: El estudiante implementa estructuras de control utilizando instrucciones de saltos en lenguaje ensamblador, mediante técnicas de programación a bajo nivel, para desarrollar soluciones orientadas a sistemas IoT mediante la solucion de problemas aplicacio al hardware. | D15: Arquitectura De Computadores y Lineas Tecnologicas | E15: Evolucion De Los Procesadores Hasta La Actualidad | F15: ARM vs X86 (En La Actualidad) | G15: Enero | H15: 2
B16: 8 | C16: El estudiante implementa prototipos funcionales de sistemas electronicos utilizando la Raspberry Pi y sensores digitales aplicando un procedimiento de modelado en forma de simulacion para resolver necesidades específicas de monitoreo o automatización | D16: Electronica Digital Orientado A Sistemas IoT | E16: Electronica Digital | F16: Raspberry Pi | G16: Enero | H16: 2
B17: 9 | C17: El estudiante Identifica los componentes esenciales de un sistema IoT mediante el análisis de documentación técnica y catálogos de hardware para describir las funcionalidades básicas de cada elemento del sistema | D17: Electronica Digital Orientado A Sistemas IoT | E17: Electronica Digital | F17: Componentes Electronicos | G17: Febrero | H17: 3
B18: 10 | C18: El estudiante Identifica los componentes esenciales de un sistema IoT mediante el análisis de documentación técnica y catálogos de hardware para describir las funcionalidades básicas de cada elemento del sistema | D18: Electronica Digital Orientado A Sistemas IoT | E18: Electronica Digital | F18: Controladores De Dispositivos | G18: Febrero | H18: 3
B19: 11 | C19: El estudiante Identifica los componentes esenciales de un sistema IoT mediante el análisis de documentación técnica y catálogos de hardware para describir las funcionalidades básicas de cada elemento del sistema | D19: Electronica Digital Orientado A Sistemas IoT | E19: Electronica Digital | F19: Interfaces De Comunicacion | G19: Febrero | H19: 3
B20: 12 | C20: El estudiante Identifica los componentes esenciales de un sistema IoT mediante el análisis de documentación técnica y catálogos de hardware para describir las funcionalidades básicas de cada elemento del sistema | D20: Electronica Digital Orientado A Sistemas IoT | E20: Electronica Digital | F20: Simulacion De Circuitos Electronicos | G20: Febrero | H20: 3
... B53: 45 | C53: El estudiante evalúa el uso de instrucciones de bajo nivel en diferentes plataformas de desarrollo, mediante la comparación de eficiencia, recursos y ciclos de ejecución, para seleccionar la alternativa más adecuada en cada escenario práctico. | D53: Programacion Hibrida ARM-64 bits | E53: Compatibilidad de ARM Con C | F53: Integracion De Librerias De C En ARM | G53: Abril | H53: 11

Sheet Semana Diagnostico
B2: Diseño de Contenido Curricular
B4: Curso | C4: ='Diseño'!C4 -> 778 - Arquitectura de Computadoras y Ensambladores 1
B5: Semana | C5: 1
B6: Tiempo | C6: =B22+B29+B36+B41+B47+B15 -> 100
A9: 1. Bienvenida y Presentación | G9: Tiempo Aproximado | H9: =B15 -> 15
G10: No puedes excederte mas de 15 minutos
A11: Nombre y Formacion Academica | B11: Titulo de la carrera a nivel diversificado, semestre actual, y cursos que estoy llevando
A12: Experiencia docente y profecional | B12: De tener experiencia laboral, indicarlo y si esta relacionada al curso ampliar. | K12: Estos puntos son recomendaciones de los puntos a tratar durante tu presentacion, si no usaras estos eres libre de agregar mas filas para indicar que haras. En los recuadros de la derecha colocar breve resumen de lo que planeas decir. No debes ser muy especifico seran pequeñas anotaciones que te ayudaran a recordar lo que planeaste
A13: Rol del auxiliar dentro del curso (funciones, actividades y apoyo a los estudiantes). | B13: IMPORTANTE: mostrar confianza a los estudiantes, para que el resto del semestre se sientan en un ambiente agradable lo cual hará que participen, demostrar que se ayudara con temas personales, o con lo que necesiten
A14: Expectativas sobre la dinámica del curso | B14: Hablar acerca de lo que se espera de la metodologia, como ellos participaran en clase, indicaciones generales como entregas de tareas, proyectos, y acttividades diarias
A15: Tiempo que emplearas | B15: 15
A18: 2. Evaluación de Conocimientos Previos | G18: Tiempo Aproximado | H18: 30
G19: No puedes excederte mas de 45 minutos
A20: Redactaras de 15 a 20 preguntas con sus respectivas respuestas , por lo que debes escoge los temas que evaluaras | B20: 1. ¿Qué componente realiza operaciones matemáticas y lógicas dentro del CPU? a) Memoria b) Unidad de control c) ALU d) Registro 2. ¿Cuál es el valor de salida de una compuerta AND si ambas entradas son 1? a) No se puede determinar b) 0 c) 1 d) Depende 3. ¿Cuál es la función principal de una resistencia pull-up? a) Disminuir el voltaje de entrada a un valor bajo cuando no hay señal b) Elevar el voltaje de salida c) Elevar el voltaje de entrada a un valor alto cuando no hay señal d) Disminuir el voltaje de salida 4. ¿Qué representa un bit dentro del sistema binario? a) Una celda de memoria b) Una dirección c) Un estado lógico d) Un número hexadecimal 5. ¿Qué pasa si no se usan resistencias de pull-up o pull-down en las entradas digitales de un microcontrolador? a) Las entradas funcionan correctamente sin problemas. b) Las entradas pueden tener valores aleatorios o inestables. c) El microcontrolador ajusta los niveles de voltaje automáticamente. d) Los pines se desconectan para proteger el sistema. 6. Una compuerta OR solo entrega 1 si ambas entradas son 1. a) VERDADERO b) FALSO 7. La memoria RAM es volátil, es decir, se borra al apagar el sistema. a) FALSA b) VERDADERO 8. Una resistencia pull-down mantiene la entrada lógica en estado bajo (0) si no hay señal. a) VERDADERO b) FALSO 9. Los buses de datos se usan para indicar direcciones de memoria. a) VERDADERO b) FALSO 10. Un transistor puede comportarse como un interruptor. a) FALSO b) VERDADERO 11. Almacena un bit de información sincronizado por reloj a) Latch b) Flip-Flop tipo D c) Registro de desplazamiento d) Contador binario 12. Mueve datos a la izquierda o derecha en cada pulso de reloj a) Contador binario b) Registro de desplazamiento c) Latch d) Flip-Flop tipo D 13. Incrementa su valor en cada ciclo de reloj a) Flip-Flop tipo D b) Registro de desplazamiento c) Contador binario d) Latch 14. Almacena un bit de forma asíncrona (sin reloj) a) Flip-Flop tipo D b) Registro de desplazamiento c) Latch d) Contador binario | K20: En los recuadors de la derecha deberas colocar las preguntas que planeas realizar con sus respectivas respuestas. En el segundo recuadro deberas colocar un breve resumne de lo que tines planificado para la parte practica del curso previo al que estas impartiendo.
A21: Redactaras una parte practica | B21: La practica será será un caso real, y deberan indicar con que tecnologias y sensores la desarrollarian
A22: Tiempo que emplearas | B22: 20
A25: 3. Presentación de los Estudiantes | G25: Tiempo Aproximado | H25: =B29 -> 15
G26: No puedes excederte mas de 30 minutos
A27: Seleccion al Azar de 5 Estudiantes | B27: Como primera opcion pasaran de forma democratica, de lo contrario hacer uso de una ruleta online | K27: En el primer recuadro colocaras la metodollogia que adoptaras para la eleccion de los estudiantes. En el segundo recuadro colocaras la redaccion de las preguntas que comprendan los siguientes puntos respecto al estudiante: Nombre. Intereses y expectativas sobre el curso. Experiencia previa relacionada con el curso (si aplica). Un dato curioso sobre sí mismo. Consideras que la prueba de conociminetos previos esta acorde al conocimiento que se te brindo en su momento Que tan comodo se sintio con la prueba anterior.
A28: Preguntas que responderan los estudiantes afortunados | B28: Cual ha sido el curso que mas se te ha dificultado? Cual ha sido el curso que menos se te ha dificultado? que te gusta realizar en tus tiempos libres? es primera vez que cursas arqui? que has escuchado del curso?
A29: Tiempo que emplearas | B29: 15
A32: 4. Senso de Horarios de Calificación | G32: Tiempo Aproximado | H32: =B36 -> 15
A33: Deberas estar recordando que deben contestar el formulario asi mismo dejar el link fijado en la llamada | G33: Esta actividad quedara abierta hasta el fin de la clase. pero emplearas 5 min especificos para la actividad
A34: Link de google forms donde este el cuestionario | K34: Esta actividad te ayudara a realizar un senso de posibles horarios de calificacion y que tus estudiantes esten enterados y puedan preveer los dias de calificacion y asi mismo el horario. Deberas colocar en los reacuadros de la derecha link de Google form libre para correos intitucionales, esto para garantizar una sola respuesta por estudiante. TAmbien deberas colocar los posibles horarios y dias que tentativamente tendrias disponibles. para colocarlos en el google form.
A35: Dias y posibles Horarios de calificacion
A36: Tiempo que emplearas | B36: 15
A39: 4. Mostrar Programa del Curso | G39: Tiempo Aproximado | H39: =B41 -> 20
G40: No puedes excederte mas de 30 minutos
A41: Tiempo que emplearas | B41: 20
A44: 2. Evaluación de Conocimientos del Curso Actual | G44: Tiempo Aproximado | H44: =B47 -> 15
G45: No puedes excederte mas de 15 minutos
A46: Redactaras 20 preguntas con sus respectivas respuestas | B46: 1. ¿Qué característica es más importante al elegir un sensor de temperatura para un cuarto de servidores? a) Que tenga colores llamativos b) Alta precisión y estabilidad térmica c) Que incluya una pantalla integrada d) Que funcione únicamente por batería Correcta: b 2. ¿Cuál de los siguientes sensores es más adecuado para medir temperatura ambiental? a) LDR b) DHT22 c) Acelerómetro MPU6050 d) Sensor Hall Correcta: b 3. ¿Qué tipo de alimentación requieren normalmente los sensores de temperatura digitales como el DHT22? a) 110V AC b) 3.3V o 5V DC c) 24V DC industrial d) Energía solar Correcta: b 4. ¿Por qué se recomienda usar un microcontrolador como Arduino o ESP32 para el proyecto? a) Porque incluye un disco duro b) Porque son fáciles de programar y manejar entradas/salidas c) Porque funcionan sin energía d) Porque son exclusivamente para robótica Correcta: b 5. ¿Qué microcontrolador permite enviar datos por WiFi sin módulos adicionales? a) ATmega328 puro b) ESP32 c) PIC16F84 d) 8051 Correcta: b 6. Si se necesita enviar datos hacia un servidor remoto, la opción más práctica es: a) Infrarrojo b) WiFi c) Cable VGA d) Puerto paralelo Correcta: b 7. ¿Cuál es una ventaja de enviar datos mediante WiFi? a) No requiere configuración b) Permite comunicación inalámbrica a una red existente c) Funciona aunque no haya router d) Consume cero energía Correcta: b 8. ¿Dónde sería más adecuado almacenar los registros de temperatura para análisis histórico? a) En una hoja de papel b) En una base de datos local o en la nube c) En un archivo de Word d) En un USB conectado al microcontrolador Correcta: b 9. ¿Qué plataforma común podría usarse para visualizar los datos en tiempo real? a) PowerPoint b) Grafana o una app web c) Photoshop d) Excel sin conexión Correcta: b 10. En la programación del sistema, la lógica principal debería: a) Encender luces decorativas b) Leer el sensor continuamente y enviar alertas si pasa el límite c) Reproducir sonidos d) Detenerse después de la primera lectura Correcta: b 11. ¿Qué estructura de control es ideal para verificar continuamente la temperatura? a) for b) while(true) c) switch-case d) try-catch Correcta: b 12. ¿Cuál sería la parte más crítica del sistema de monitoreo? a) El color del gabinete b) La precisión del sensor y la comunicación de datos c) El tamaño del cable USB d) El diseño del logo Correcta: b 13. ¿Qué riesgo existe si el sensor falla sin detección de error? a) Que el sistema funcione más rápido b) Que se ignoren temperaturas peligrosas c) Que el servidor aumente su velocidad d) Que el WiFi se haga más fuerte Correcta: b 14. ¿Qué técnica ayuda a validar si un sensor está funcionando correctamente? a) Reiniciar el edificio b) Comparar lecturas con valores razonables y límites c) Golpear el sensor suavemente d) Usar un lente de aumento Correcta: b 15. ¿Qué acción debe realizar el sistema si detecta una lectura imposible, como -200°C? a) Considerarla válida b) Enviar alerta y descartar la lectura c) Apagar todo el sistema d) Reiniciar el sistema operativo del servidor Correcta: b 16. ¿Cuál es una buena práctica para evitar sobrecargar la red WiFi? a) Enviar datos cada microsegundo b) Enviar datos a intervalos razonables c) Nunca enviar datos d) Usar WiFi 2.4 GHz únicamente Correcta: b 17. ¿Por qué es útil almacenar los valores promedio además de las lecturas instantáneas? a) Para decorar la interfaz b) Para identificar tendencias y picos térmicos c) Para que el archivo sea más grande d) Para evitar usar ecuaciones Correcta: b 18. Si el microcontrolador pierde conexión WiFi, lo más adecuado sería: a) Apagar el sensor b) Guardar datos temporalmente y reintentar la conexión c) Formatear la memoria Flash d) Subir la temperatura Correcta: b 19. ¿Qué tipo de alerta es más conveniente para temperaturas críticas? a) Notificación por correo o app b) Cambiar el fondo de pantalla c) Imprimir una hoja d) Encender un foco azul Correcta: a 20. ¿Cuál de los siguientes elementos NO es necesario para resolver el problema del PDF? a) Sensor de temperatura b) Microcontrolador c) Sistema de comunicación d) Tarjeta gráfica dedicada Correcta: d
A47: Tiempo que emplearas | B47: 15

Sheet S.2
B2: Diseño de la Sesión de Laboratorio
B4: Curso | C4: ='Diseño'!C4 -> 778 - Arquitectura de Computadoras y Ensambladores 1
B5: Semana | C5: 2
B6: Tiempo | C6: =H10+H21+H44+H68 -> 105
B7: Ponderación | C7: =B49+B60 -> 2
B8: Validación de Tiempo | C8: =IF(H44<=0, "❌ ERROR: La Actividad 1 debe tener un tiempo mayor a 0.", IF(H21>60, "❌ ERROR: El 'Área de Conocimiento' no puede exceder los 60 min.", IF((H10+H21+H44)<100, "❌ ERROR: El tiempo total debe ser de al menos 100 min.", "✅ VALIDACIÓN CORRECTA"))) -> ❌ ERROR: El tiempo total debe ser de al menos 100 min.
A10: 1. Área Actitudinal (Saber Ser) | G10: Tiempo Aproximado | H10: 5
G11: Tiene que estar en un rango de 3 a 5 minutos
A12: Nombre del Valor | B12: Curiosidad
A13: Tiempo Aproximado | B13: 10
A14: Descripcion
A15: es una cualidad o principio que una persona o sociedad estima como importante, bueno o deseable, ya sea por su utilidad, su significado, su importancia o por la apreciación que genera
A17: Como se relaciona con los conocimientos de la sesion y se aplicaria
A18: comprender cómo funcionan los sistemas nos impulsa a investigar más allá de lo superficial.
A21: 2. Área Conocimiento (Saber) | G21: Tiempo Aproximado | H21: 60
G22: No puede exceder los 60 minutos
A23: Competencia a desarrollar | B23: El estudiante comprende e integra los fundamentos de la arquitectura ARM, el funcionamiento de programas en lenguaje ensamblador y la interaccion con el hardware mediante el analisis de instrucciones, estructuras de control y manipulacion de memoria, para desarrollar soluciones optimas en sistemas embebidos y entornos IoT
A24: Competencia a desarrollar
A26: 2.1 Contenido
A27: No. | B27: Unidad | D27: Tema | F27: Sub Tema
A28: 1 | B28: =IFERROR(__xludf.DUMMYFUNCTION("FILTER('Diseño'!D:D,'Diseño'!H:H=$C$5)"),"Arquitectura De Computadores y Lineas Tecnologicas") -> Arquitectura De Computadores y Lineas Tecnologicas | D28: =IFERROR(__xludf.DUMMYFUNCTION("FILTER('Diseño'!E:E,'Diseño'!H:H=$C$5)"),"Evolucion De Los Procesadores Hasta La Actualidad") -> Evolucion De Los Procesadores Hasta La Actualidad | F28: =IFERROR(__xludf.DUMMYFUNCTION("FILTER('Diseño'!F:F,'Diseño'!H:H=$C$5)"),"Procesadores x86") -> Procesadores x86
A29: 2 | B29: =IFERROR(__xludf.DUMMYFUNCTION("""COMPUTED_VALUE"""),"Arquitectura De Computadores y Lineas Tecnologicas") -> Arquitectura De Computadores y Lineas Tecnologicas | D29: =IFERROR(__xludf.DUMMYFUNCTION("""COMPUTED_VALUE"""),"Evolucion De Los Procesadores Hasta La Actualidad") -> Evolucion De Los Procesadores Hasta La Actualidad | F29: =IFERROR(__xludf.DUMMYFUNCTION("""COMPUTED_VALUE"""),"Procesadores ARM") -> Procesadores ARM
A30: 3 | B30: =IFERROR(__xludf.DUMMYFUNCTION("""COMPUTED_VALUE"""),"Arquitectura De Computadores y Lineas Tecnologicas") -> Arquitectura De Computadores y Lineas Tecnologicas | D30: =IFERROR(__xludf.DUMMYFUNCTION("""COMPUTED_VALUE"""),"Evolucion De Los Procesadores Hasta La Actualidad") -> Evolucion De Los Procesadores Hasta La Actualidad | F30: =IFERROR(__xludf.DUMMYFUNCTION("""COMPUTED_VALUE"""),"ARM vs X86 (En La Actualidad)") -> ARM vs X86 (En La Actualidad)
A31: 4 | B31: =IFERROR(__xludf.DUMMYFUNCTION("""COMPUTED_VALUE"""),"Electronica Digital Orientado A Sistemas IoT") -> Electronica Digital Orientado A Sistemas IoT | D31: =IFERROR(__xludf.DUMMYFUNCTION("""COMPUTED_VALUE"""),"Electronica Digital") -> Electronica Digital | F31: =IFERROR(__xludf.DUMMYFUNCTION("""COMPUTED_VALUE"""),"Raspberry Pi") -> Raspberry Pi
A32: 5
A33: 6
A34: 7
A36: 2.2 Recursos Educativos
A38: Tipo de Recurso a utilizar | B38: Tipo | C38: Rango Aproximando | D38: Tiempo Aproximado
A39: Presentacion | B39: Obligatorio | D39: 10
A40: Video | B40: Obligatorio | C40: 3 a 6 minutos | D40: 10
A41: Lectura | B41: Optativo | D41: 10
A42: Ejercicio Demostrativo | B42: Obligatorio | D42: 10
A44: 3. Área de Habilidades (Saber Hacer) | G44: Tiempo Aproximado | H44: 30
G45: Tiene que estar en un rango de 30 a 50 minutos
A46: Actividad 1 (Obligatoria)
A47: Competencia que predomina en la actividad | B47: El estudiante comprende e integra los fundamentos de la arquitectura ARM, el funcionamiento de programas en lenguaje ensamblador y la interaccion con el hardware mediante el analisis de instrucciones, estructuras de control y manipulacion de memoria, para desarrollar soluciones optimas en sistemas embebidos y entornos IoT
A48: Tipo de Actividad | B48: Cuestionario
A49: Ponderación | B49: 2
A50: Tiempo Aproximado | B50: 10
...

Sheet S.3
B2: Diseño de la Sesión de Laboratorio
B4: Curso | C4: ='Diseño'!C4 -> 778 - Arquitectura de Computadoras y Ensambladores 1
B5: Semana | C5: 3
B6: Tiempo | C6: =H10+H21+H44+H68 -> 110
B7: Ponderación | C7: =B49+B60 -> 2
B8: Validación de Tiempo | C8: =IF(H44<=0, "❌ ERROR: La Actividad 1 debe tener un tiempo mayor a 0.", IF(H21>60, "❌ ERROR: El 'Área de Conocimiento' no puede exceder los 60 min.", IF((H10+H21+H44)<100, "❌ ERROR: El tiempo total debe ser de al menos 100 min.", "✅ VALIDACIÓN CORRECTA"))) -> ❌ ERROR: El tiempo total debe ser de al menos 100 min.
A10: 1. Área Actitudinal (Saber Ser) | G10: Tiempo Aproximado | H10: 5
G11: Tiene que estar en un rango de 3 a 5 minutos
A12: Nombre del Valor | B12: Adaptabilidad
A13: Tiempo Aproximado | B13: 10
A14: Descripcion
A15: capacidad de una persona o sistema para ajustarse y responder de manera efectiva a cambios en su entorno
A17: Como se relaciona con los conocimientos de la sesion y se aplicaria
A18: tecnologías como Raspberry Pi muestran cómo el conocimiento técnico se aplica en contextos diversos.
A21: 2. Área Conocimiento (Saber) | G21: Tiempo Aproximado | H21: 50
G22: No puede exceder los 60 minutos
A23: Competencia a desarrollar | B23: Recuerda diferentes dispositivos de electronica digital que le permitan dar soluciones a sistemas IoT analizando documentacion tecnica, catalogos de hardware que aporten un valor agregado a la solucion de sistemas embebidos y su interaccion con el entorno
A24: Competencia a desarrollar
A26: 2.1 Contenido
A27: No. | B27: Unidad | D27: Tema | F27: Sub Tema
A28: 1 | B28: =IFERROR(__xludf.DUMMYFUNCTION("FILTER('Diseño'!D:D,'Diseño'!H:H=$C$5)"),"Electronica Digital Orientado A Sistemas IoT") -> Electronica Digital Orientado A Sistemas IoT | D28: =IFERROR(__xludf.DUMMYFUNCTION("FILTER('Diseño'!E:E,'Diseño'!H:H=$C$5)"),"Electronica Digital") -> Electronica Digital | F28: =IFERROR(__xludf.DUMMYFUNCTION("FILTER('Diseño'!F:F,'Diseño'!H:H=$C$5)"),"Componentes Electronicos") -> Componentes Electronicos
A29: 2 | B29: =IFERROR(__xludf.DUMMYFUNCTION("""COMPUTED_VALUE"""),"Electronica Digital Orientado A Sistemas IoT") -> Electronica Digital Orientado A Sistemas IoT | D29: =IFERROR(__xludf.DUMMYFUNCTION("""COMPUTED_VALUE"""),"Electronica Digital") -> Electronica Digital | F29: =IFERROR(__xludf.DUMMYFUNCTION("""COMPUTED_VALUE"""),"Controladores De Dispositivos") -> Controladores De Dispositivos
A30: 3 | B30: =IFERROR(__xludf.DUMMYFUNCTION("""COMPUTED_VALUE"""),"Electronica Digital Orientado A Sistemas IoT") -> Electronica Digital Orientado A Sistemas IoT | D30: =IFERROR(__xludf.DUMMYFUNCTION("""COMPUTED_VALUE"""),"Electronica Digital") -> Electronica Digital | F30: =IFERROR(__xludf.DUMMYFUNCTION("""COMPUTED_VALUE"""),"Interfaces De Comunicacion") -> Interfaces De Comunicacion
A31: 4 | B31: =IFERROR(__xludf.DUMMYFUNCTION("""COMPUTED_VALUE"""),"Electronica Digital Orientado A Sistemas IoT") -> Electronica Digital Orientado A Sistemas IoT | D31: =IFERROR(__xludf.DUMMYFUNCTION("""COMPUTED_VALUE"""),"Electronica Digital") -> Electronica Digital | F31: =IFERROR(__xludf.DUMMYFUNCTION("""COMPUTED_VALUE"""),"Simulacion De Circuitos Electronicos") -> Simulacion De Circuitos Electronicos
A32: 5
A33: 6
A34: 7
A36: 2.2 Recursos Educativos
A38: Tipo de Recurso a utilizar | B38: Tipo | C38: Rango Aproximando | D38: Tiempo Aproximado
A39: Presentacion | B39: Obligatorio | D39: 10
A40: Video | B40: Obligatorio | C40: 3 a 6 minutos | D40: 5
A41: Lectura | B41: Optativo | D41: 5
A42: Ejercicio Demostrativo | B42: Obligatorio | D42: 20
A44: 3. Área de Habilidades (Saber Hacer) | G44: Tiempo Aproximado | H44: 40
G45: Tiene que estar en un rango de 30 a 50 minutos
A46: Actividad 1 (Obligatoria)
A47: Competencia que predomina en la actividad | B47: Comprende el funcionamiento de la arquitectura ARM, la interaccion del hardware con el lenguaje a bajo nivel analizando instrucciones, estructuras de control y manejo de pines multiproposito permitiendole desarrollar sismteas embebidos y entornos IoT
A48: Tipo de Actividad | B48: Cuestionario
A49: Ponderación | B49: 2
A50: Tiempo Aproximado | B50: 15
...

Sheet S.4
B2: Diseño de la Sesión de Laboratorio
B4: Curso | C4: ='Diseño'!C4 -> 778 - Arquitectura de Computadoras y Ensambladores 1
B5: Semana | C5: 4
B6: Tiempo | C6: =H10+H21+H44+H68 -> 100
B7: Ponderación | C7: =B49+B60 -> 2
B8: Validación de Tiempo | C8: =IF(H44<=0, "❌ ERROR: La Actividad 1 debe tener un tiempo mayor a 0.", IF(H21>60, "❌ ERROR: El 'Área de Conocimiento' no puede exceder los 60 min.", IF((H10+H21+H44)<100, "❌ ERROR: El tiempo total debe ser de al menos 100 min.", "✅ VALIDACIÓN CORRECTA"))) -> ❌ ERROR: El tiempo total debe ser de al menos 100 min.
A10: 1. Área Actitudinal (Saber Ser) | G10: Tiempo Aproximado | H10: 5
G11: Tiene que estar en un rango de 3 a 5 minutos
A12: Nombre del Valor | B12: Precisión
A13: Tiempo Aproximado | B13: 5
A14: Descripcion
A15: cercanía entre mediciones repetidas, indicando la reproducibilidad de un proceso o instrumento
A17: Como se relaciona con los conocimientos de la sesion y se aplicaria
A18: trabajar con componentes electrónicos requiere atención al detalle y exactitud en su manejo.
A21: 2. Área Conocimiento (Saber) | G21: Tiempo Aproximado | H21: =D39+D40+D41+D42 -> 50
G22: No puede exceder los 60 minutos
A23: Competencia a desarrollar | B23: Recuerda diferentes dispositivos de electronica digital que le permitan dar soluciones a sistemas IoT analizando documentacion tecnica, catalogos de hardware que aporten un valor agregado a la solucion de sistemas embebidos y su interaccion con el entorno
A24: Competencia a desarrollar
A26: 2.1 Contenido
A27: No. | B27: Unidad | D27: Tema | F27: Sub Tema
A28: 1 | B28: =IFERROR(__xludf.DUMMYFUNCTION("FILTER('Diseño'!D:D,'Diseño'!H:H=$C$5)"),"Electronica Digital Orientado A Sistemas IoT") -> Electronica Digital Orientado A Sistemas IoT | D28: =IFERROR(__xludf.DUMMYFUNCTION("FILTER('Diseño'!E:E,'Diseño'!H:H=$C$5)"),"Sistemas IoT") -> Sistemas IoT | F28: =IFERROR(__xludf.DUMMYFUNCTION("FILTER('Diseño'!F:F,'Diseño'!H:H=$C$5)"),"Que es IoT?") -> Que es IoT?
A29: 2 | B29: =IFERROR(__xludf.DUMMYFUNCTION("""COMPUTED_VALUE"""),"Electronica Digital Orientado A Sistemas IoT") -> Electronica Digital Orientado A Sistemas IoT | D29: =IFERROR(__xludf.DUMMYFUNCTION("""COMPUTED_VALUE"""),"Sistemas IoT") -> Sistemas IoT | F29: =IFERROR(__xludf.DUMMYFUNCTION("""COMPUTED_VALUE"""),"Caracteristicas principales de un sistema IoT") -> Caracteristicas principales de un sistema IoT
A30: 3 | B30: =IFERROR(__xludf.DUMMYFUNCTION("""COMPUTED_VALUE"""),"Electronica Digital Orientado A Sistemas IoT") -> Electronica Digital Orientado A Sistemas IoT | D30: =IFERROR(__xludf.DUMMYFUNCTION("""COMPUTED_VALUE"""),"Sistemas IoT") -> Sistemas IoT | F30: =IFERROR(__xludf.DUMMYFUNCTION("""COMPUTED_VALUE"""),"IoT en la actualidad") -> IoT en la actualidad
A31: 4 | B31: =IFERROR(__xludf.DUMMYFUNCTION("""COMPUTED_VALUE"""),"Electronica Digital Orientado A Sistemas IoT") -> Electronica Digital Orientado A Sistemas IoT | D31: =IFERROR(__xludf.DUMMYFUNCTION("""COMPUTED_VALUE"""),"Sistemas IoT") -> Sistemas IoT | F31: =IFERROR(__xludf.DUMMYFUNCTION("""COMPUTED_VALUE"""),"Implementacion De IoT En La Industria") -> Implementacion De IoT En La Industria
A32: 5 | B32: =IFERROR(__xludf.DUMMYFUNCTION("""COMPUTED_VALUE"""),"Electronica Digital Orientado A Sistemas IoT") -> Electronica Digital Orientado A Sistemas IoT | D32: =IFERROR(__xludf.DUMMYFUNCTION("""COMPUTED_VALUE"""),"Sistemas IoT") -> Sistemas IoT | F32: =IFERROR(__xludf.DUMMYFUNCTION("""COMPUTED_VALUE"""),"Ventajas Y Desventajas Del IoT") -> Ventajas Y Desventajas Del IoT
A33: 6
A34: 7
A36: 2.2 Recursos Educativos
A38: Tipo de Recurso a utilizar | B38: Tipo | C38: Rango Aproximando | D38: Tiempo Aproximado
A39: Presentacion | B39: Obligatorio | D39: 5
A40: Video | B40: Obligatorio | C40: 3 a 6 minutos | D40: 5
A41: Lectura | B41: Optativo | D41: 5
A42: Ejercicio Demostrativo | B42: Obligatorio | D42: 35
A44: 3. Área de Habilidades (Saber Hacer) | G44: Tiempo Aproximado | H44: =B50+B61 -> 30
G45: Tiene que estar en un rango de 30 a 50 minutos
A46: Actividad 1 (Obligatoria)
A47: Competencia que predomina en la actividad | B47: Recuerda diferentes dispositivos de electronica digital que le permitan dar soluciones a sistemas IoT analizando documentacion tecnica, catalogos de hardware que aporten un valor agregado a la solucion de sistemas embebidos y su interaccion con el entorno
A48: Tipo de Actividad | B48: Cuestionario
A49: Ponderación | B49: 2
A50: Tiempo Aproximado | B50: 30
...

Sheet S.5
B2: Diseño de la Sesión de Laboratorio
B4: Curso | C4: ='Diseño'!C4 -> 778 - Arquitectura de Computadoras y Ensambladores 1
B5: Semana | C5: 5
B6: Tiempo | C6: =H10+H21+H44+H68 -> 100
B7: Ponderación | C7: =B49+B60 -> 2
B8: Validación de Tiempo | C8: =IF(H44<=0, "❌ ERROR: La Actividad 1 debe tener un tiempo mayor a 0.", IF(H21>60, "❌ ERROR: El 'Área de Conocimiento' no puede exceder los 60 min.", IF((H10+H21+H44)<100, "❌ ERROR: El tiempo total debe ser de al menos 100 min.", "✅ VALIDACIÓN CORRECTA"))) -> ❌ ERROR: El tiempo total debe ser de al menos 100 min.
A10: 1. Área Actitudinal (Saber Ser) | G10: Tiempo Aproximado | H10: =B13 -> 5
G11: Tiene que estar en un rango de 3 a 5 minutos
A12: Nombre del Valor | B12: Innovacion
A13: Tiempo Aproximado | B13: 5
A14: Descripcion
A15: reación, mejora e implementación de nuevas ideas, procesos y tecnologías para resolver problemas y desarrollar soluciones que impulsen el progreso de la sociedad y la industria
A17: Como se relaciona con los conocimientos de la sesion y se aplicaria
A18: el estudio del IoT impulsa la búsqueda de soluciones tecnológicas creativas.
A21: 2. Área Conocimiento (Saber) | G21: Tiempo Aproximado | H21: =D39+D40+D41+D42 -> 50
G22: No puede exceder los 60 minutos
A23: Competencia a desarrollar | B23: Aplica conceptos de electronica para la construccion de prototipos IoT orientados a casos de uso del mundo real mediante placas de desarrollo como raspberry pi, sensores digitales y diseño de sistemas para la automatizacion de procesos logrando mayor eficiencia
A24: Competencia a desarrollar
A26: 2.1 Contenido
A27: No. | B27: Unidad | D27: Tema | F27: Sub Tema
A28: 1 | B28: =IFERROR(__xludf.DUMMYFUNCTION("FILTER('Diseño'!D:D,'Diseño'!H:H=$C$5)"),"Electronica Digital Orientado A Sistemas IoT") -> Electronica Digital Orientado A Sistemas IoT | D28: =IFERROR(__xludf.DUMMYFUNCTION("FILTER('Diseño'!E:E,'Diseño'!H:H=$C$5)"),"Sistemas IoT") -> Sistemas IoT | F28: =IFERROR(__xludf.DUMMYFUNCTION("FILTER('Diseño'!F:F,'Diseño'!H:H=$C$5)"),"Control Del Hardware de Raspberry Con Python") -> Control Del Hardware de Raspberry Con Python
A29: 2 | B29: =IFERROR(__xludf.DUMMYFUNCTION("""COMPUTED_VALUE"""),"Electronica Digital Orientado A Sistemas IoT") -> Electronica Digital Orientado A Sistemas IoT | D29: =IFERROR(__xludf.DUMMYFUNCTION("""COMPUTED_VALUE"""),"Sistemas IoT") -> Sistemas IoT | F29: =IFERROR(__xludf.DUMMYFUNCTION("""COMPUTED_VALUE"""),"Control De Sensores Y Actuadores Con Python") -> Control De Sensores Y Actuadores Con Python
A30: 3 | B30: =IFERROR(__xludf.DUMMYFUNCTION("""COMPUTED_VALUE"""),"Electronica Digital Orientado A Sistemas IoT") -> Electronica Digital Orientado A Sistemas IoT | D30: =IFERROR(__xludf.DUMMYFUNCTION("""COMPUTED_VALUE"""),"Sistemas IoT") -> Sistemas IoT | F30: =IFERROR(__xludf.DUMMYFUNCTION("""COMPUTED_VALUE"""),"Raspberry Y Cloud") -> Raspberry Y Cloud
A31: 4 | B31: =IFERROR(__xludf.DUMMYFUNCTION("""COMPUTED_VALUE"""),"Electronica Digital Orientado A Sistemas IoT") -> Electronica Digital Orientado A Sistemas IoT | D31: =IFERROR(__xludf.DUMMYFUNCTION("""COMPUTED_VALUE"""),"Sistemas IoT") -> Sistemas IoT | F31: =IFERROR(__xludf.DUMMYFUNCTION("""COMPUTED_VALUE"""),"Principales Servicios Para Sistemas IoT") -> Principales Servicios Para Sistemas IoT
A32: 5
A33: 6
A34: 7
A36: 2.2 Recursos Educativos
A38: Tipo de Recurso a utilizar | B38: Tipo | C38: Rango Aproximando | D38: Tiempo Aproximado
A39: Presentacion | B39: Obligatorio | D39: 15
A40: Video | B40: Obligatorio | C40: 3 a 6 minutos | D40: 0
A41: Lectura | B41: Optativo | D41: 5
A42: Ejercicio Demostrativo | B42: Obligatorio | D42: 30
A44: 3. Área de Habilidades (Saber Hacer) | G44: Tiempo Aproximado | H44: =B50+B61 -> 30
G45: Tiene que estar en un rango de 30 a 50 minutos
A46: Actividad 1 (Obligatoria)
A47: Competencia que predomina en la actividad | B47: Aplica conceptos de electronica para la construccion de prototipos IoT orientados a casos de uso del mundo real mediante placas de desarrollo como raspberry pi, sensores digitales y diseño de sistemas para la automatizacion de procesos logrando mayor eficiencia
A48: Tipo de Actividad | B48: Ejercicio practico
A49: Ponderación | B49: 2
A50: Tiempo Aproximado | B50: 30
...

Sheet S.6
B2: Diseño de la Sesión de Laboratorio
B4: Curso | C4: ='Diseño'!C4 -> 778 - Arquitectura de Computadoras y Ensambladores 1
B5: Semana | C5: 6
B6: Tiempo | C6: =H10+H21+H44+H68 -> 115
B7: Ponderación | C7: =B49+B60 -> 2
B8: Validación de Tiempo | C8: =IF(H44<=0, "❌ ERROR: La Actividad 1 debe tener un tiempo mayor a 0.", IF(H21>60, "❌ ERROR: El 'Área de Conocimiento' no puede exceder los 60 min.", IF((H10+H21+H44)<100, "❌ ERROR: El tiempo total debe ser de al menos 100 min.", "✅ VALIDACIÓN CORRECTA"))) -> ✅ VALIDACIÓN CORRECTA
A10: 1. Área Actitudinal (Saber Ser) | G10: Tiempo Aproximado | H10: =B13 -> 10
G11: Tiene que estar en un rango de 3 a 5 minutos
A12: Nombre del Valor | B12: Disciplina
A13: Tiempo Aproximado | B13: 10
A14: Descripcion
A15: Estudia las bases del lenguaje ensamblador de forma didactica, un tiempo prudente y constante para comprender el tema.
A17: Como se relaciona con los conocimientos de la sesion y se aplicaria
A18: Desarrollo de programas a bajo nivel optimos
A21: 2. Área Conocimiento (Saber) | G21: Tiempo Aproximado | H21: =D39+D40+D41+D42 -> 60
G22: No puede exceder los 60 minutos
A23: Competencia a desarrollar | B23: Comprende el funcionamiento de la arquitectura ARM, la interaccion del hardware con el lenguaje a bajo nivel analizando instrucciones, estructuras de control y manejo de pines multiproposito permitiendole desarrollar sismteas embebidos y entornos IoT
A24: Competencia a desarrollar
A26: 2.1 Contenido
A27: No. | B27: Unidad | D27: Tema | F27: Sub Tema
A28: 1 | B28: =IFERROR(__xludf.DUMMYFUNCTION("FILTER('Diseño'!D:D,'Diseño'!H:H=$C$5)"),"Lenguaje Ensamblador ARM-64 bits") -> Lenguaje Ensamblador ARM-64 bits | D28: =IFERROR(__xludf.DUMMYFUNCTION("FILTER('Diseño'!E:E,'Diseño'!H:H=$C$5)"),"Introduccion ARM") -> Introduccion ARM | F28: =IFERROR(__xludf.DUMMYFUNCTION("FILTER('Diseño'!F:F,'Diseño'!H:H=$C$5)"),"Que Es Ensamblador") -> Que Es Ensamblador
A29: 2 | B29: =IFERROR(__xludf.DUMMYFUNCTION("""COMPUTED_VALUE"""),"Lenguaje Ensamblador ARM-64 bits") -> Lenguaje Ensamblador ARM-64 bits | D29: =IFERROR(__xludf.DUMMYFUNCTION("""COMPUTED_VALUE"""),"Introduccion ARM") -> Introduccion ARM | F29: =IFERROR(__xludf.DUMMYFUNCTION("""COMPUTED_VALUE"""),"Vocabulario Basico y Tipos De Datos") -> Vocabulario Basico y Tipos De Datos
A30: 3 | B30: =IFERROR(__xludf.DUMMYFUNCTION("""COMPUTED_VALUE"""),"Lenguaje Ensamblador ARM-64 bits") -> Lenguaje Ensamblador ARM-64 bits | D30: =IFERROR(__xludf.DUMMYFUNCTION("""COMPUTED_VALUE"""),"Introduccion ARM") -> Introduccion ARM | F30: =IFERROR(__xludf.DUMMYFUNCTION("""COMPUTED_VALUE"""),"Registros Basicos Del Procesador") -> Registros Basicos Del Procesador
A31: 4 | B31: =IFERROR(__xludf.DUMMYFUNCTION("""COMPUTED_VALUE"""),"Lenguaje Ensamblador ARM-64 bits") -> Lenguaje Ensamblador ARM-64 bits | D31: =IFERROR(__xludf.DUMMYFUNCTION("""COMPUTED_VALUE"""),"Introduccion ARM") -> Introduccion ARM | F31: =IFERROR(__xludf.DUMMYFUNCTION("""COMPUTED_VALUE"""),"Instalacion De Herramientas En Linux") -> Instalacion De Herramientas En Linux
A32: 5
A33: 6
A34: 7
A36: 2.2 Recursos Educativos
A38: Tipo de Recurso a utilizar | B38: Tipo | C38: Rango Aproximando | D38: Tiempo Aproximado
A39: Presentacion | B39: Obligatorio | D39: 35
A40: Video | B40: Obligatorio | C40: 3 a 6 minutos | D40: 5
A41: Lectura | B41: Optativo | D41: 10
A42: Ejercicio Demostrativo | B42: Obligatorio | D42: 10
A44: 3. Área de Habilidades (Saber Hacer) | G44: Tiempo Aproximado | H44: =B50+B61 -> 30
G45: Tiene que estar en un rango de 30 a 50 minutos
A46: Actividad 1 (Obligatoria)
A47: Competencia que predomina en la actividad | B47: Comprende el funcionamiento de la arquitectura ARM, la interaccion del hardware con el lenguaje a bajo nivel analizando instrucciones, estructuras de control y manejo de pines multiproposito permitiendole desarrollar sismteas embebidos y entornos IoT
A48: Tipo de Actividad | B48: actividades
A49: Ponderación | B49: 2
A50: Tiempo Aproximado | B50: 30
...

Sheet S.7
B2: Diseño de la Sesión de Laboratorio
B4: Curso | C4: ='Diseño'!C4 -> 778 - Arquitectura de Computadoras y Ensambladores 1
B5: Semana | C5: 7
B6: Tiempo | C6: =H10+H21+H44+H68 -> 115
B7: Ponderación | C7: =B49+B60 -> 2
B8: Validación de Tiempo | C8: =IF(H44<=0, "❌ ERROR: La Actividad 1 debe tener un tiempo mayor a 0.", IF(H21>60, "❌ ERROR: El 'Área de Conocimiento' no puede exceder los 60 min.", IF((H10+H21+H44)<100, "❌ ERROR: El tiempo total debe ser de al menos 100 min.", "✅ VALIDACIÓN CORRECTA"))) -> ✅ VALIDACIÓN CORRECTA
A10: 1. Área Actitudinal (Saber Ser) | G10: Tiempo Aproximado | H10: =B13 -> 10
G11: Tiene que estar en un rango de 3 a 5 minutos
A12: Nombre del Valor | B12: Claridad Mental
A13: Tiempo Aproximado | B13: 10
A14: Descripcion
A15: Piensa de forma abstracta problemas de dificultad media para poder realizar una representacion visual o escrita desarrollando la logica de programacion y la solucion de problemas.
A17: Como se relaciona con los conocimientos de la sesion y se aplicaria
A18: Manipulacion de la memoria y su indexado utilizando aritmetica y logica
A21: 2. Área Conocimiento (Saber) | G21: Tiempo Aproximado | H21: =D39+D40+D41+D42 -> 55
G22: No puede exceder los 60 minutos
A23: Competencia a desarrollar | B23: Comprende el funcionamiento de la arquitectura ARM, la interaccion del hardware con el lenguaje a bajo nivel analizando instrucciones, estructuras de control y manejo de pines multiproposito permitiendole desarrollar sismteas embebidos y entornos IoT
A24: Competencia a desarrollar
A26: 2.1 Contenido
A27: No. | B27: Unidad | D27: Tema | F27: Sub Tema
A28: 1 | B28: =IFERROR(__xludf.DUMMYFUNCTION("FILTER('Diseño'!D:D,'Diseño'!H:H=$C$5)"),"Lenguaje Ensamblador ARM-64 bits") -> Lenguaje Ensamblador ARM-64 bits | D28: =IFERROR(__xludf.DUMMYFUNCTION("FILTER('Diseño'!E:E,'Diseño'!H:H=$C$5)"),"Set Instrucciones ARM") -> Set Instrucciones ARM | F28: =IFERROR(__xludf.DUMMYFUNCTION("FILTER('Diseño'!F:F,'Diseño'!H:H=$C$5)"),"Instrucciones Aritmeticas") -> Instrucciones Aritmeticas
A29: 2 | B29: =IFERROR(__xludf.DUMMYFUNCTION("""COMPUTED_VALUE"""),"Lenguaje Ensamblador ARM-64 bits") -> Lenguaje Ensamblador ARM-64 bits | D29: =IFERROR(__xludf.DUMMYFUNCTION("""COMPUTED_VALUE"""),"Set Instrucciones ARM") -> Set Instrucciones ARM | F29: =IFERROR(__xludf.DUMMYFUNCTION("""COMPUTED_VALUE"""),"Instrucciones Logicas") -> Instrucciones Logicas
A30: 3 | B30: =IFERROR(__xludf.DUMMYFUNCTION("""COMPUTED_VALUE"""),"Lenguaje Ensamblador ARM-64 bits") -> Lenguaje Ensamblador ARM-64 bits | D30: =IFERROR(__xludf.DUMMYFUNCTION("""COMPUTED_VALUE"""),"Set Instrucciones ARM") -> Set Instrucciones ARM | F30: =IFERROR(__xludf.DUMMYFUNCTION("""COMPUTED_VALUE"""),"Instrucciones De Carga y Almacenamiento ") -> Instrucciones De Carga y Almacenamiento
A31: 4 | B31: =IFERROR(__xludf.DUMMYFUNCTION("""COMPUTED_VALUE"""),"Lenguaje Ensamblador ARM-64 bits") -> Lenguaje Ensamblador ARM-64 bits | D31: =IFERROR(__xludf.DUMMYFUNCTION("""COMPUTED_VALUE"""),"Set Instrucciones ARM") -> Set Instrucciones ARM | F31: =IFERROR(__xludf.DUMMYFUNCTION("""COMPUTED_VALUE"""),"Pre y Post Indexing ") -> Pre y Post Indexing
A32: 5
A33: 6
A34: 7
A36: 2.2 Recursos Educativos
A38: Tipo de Recurso a utilizar | B38: Tipo | C38: Rango Aproximando | D38: Tiempo Aproximado
A39: Presentacion | B39: Obligatorio | D39: 40
A40: Video | B40: Obligatorio | C40: 3 a 6 minutos | D40: 5
A41: Lectura | B41: Optativo | D41: 10
A42: Ejercicio Demostrativo | B42: Obligatorio
A44: 3. Área de Habilidades (Saber Hacer) | G44: Tiempo Aproximado | H44: =B50+B61 -> 35
G45: Tiene que estar en un rango de 30 a 50 minutos
A46: Actividad 1 (Obligatoria)
A47: Competencia que predomina en la actividad | B47: Comprende el funcionamiento de la arquitectura ARM, la interaccion del hardware con el lenguaje a bajo nivel analizando instrucciones, estructuras de control y manejo de pines multiproposito permitiendole desarrollar sismteas embebidos y entornos IoT
A48: Tipo de Actividad | B48: actividades
A49: Ponderación | B49: 2
A50: Tiempo Aproximado | B50: 35
...

Sheet S.8
B2: Diseño de la Sesión de Laboratorio
B4: Curso | C4: ='Diseño'!C4 -> 778 - Arquitectura de Computadoras y Ensambladores 1
B5: Semana | C5: 8
B6: Tiempo | C6: =H10+H21+H44+H68 -> 115
B7: Ponderación | C7: =B49+B60 -> 2
B8: Validación de Tiempo | C8: =IF(H44<=0, "❌ ERROR: La Actividad 1 debe tener un tiempo mayor a 0.", IF(H21>60, "❌ ERROR: El 'Área de Conocimiento' no puede exceder los 60 min.", IF((H10+H21+H44)<100, "❌ ERROR: El tiempo total debe ser de al menos 100 min.", "✅ VALIDACIÓN CORRECTA"))) -> ✅ VALIDACIÓN CORRECTA
A10: 1. Área Actitudinal (Saber Ser) | G10: Tiempo Aproximado | H10: =B13 -> 10
G11: Tiene que estar en un rango de 3 a 5 minutos
A12: 0 | B12: Pensamiento Critico
A13: Tiempo Aproximado | B13: 10
A14: Descripcion
A15: Analiza estructuras, comprende el funcionamiento y desarrolla algoritmos eficientes que cumplen con la tarea solicitada.
A17: Como se relaciona con los conocimientos de la sesion y se aplicaria
A18: Desarrollar estructuras de control, requiere una comprension de la estructura del programa y la implementacion de estructuras optimas
A21: 2. Área Conocimiento (Saber) | G21: Tiempo Aproximado | H21: =D39+D40+D41+D42 -> 55
G22: No puede exceder los 60 minutos
A23: Competencia a desarrollar | B23: Analiza el comportamiento de la arquitectura ARM utilizando registros, instrucciones y diagramas de bloques optimizando programas a bajo nivel en microprocesadores
A24: Competencia a desarrollar
A26: 2.1 Contenido
A27: No. | B27: Unidad | D27: Tema | F27: Sub Tema
A28: 1 | B28: =IFERROR(__xludf.DUMMYFUNCTION("FILTER('Diseño'!D:D,'Diseño'!H:H=$C$5)"),"Lenguaje Ensamblador ARM-64 bits") -> Lenguaje Ensamblador ARM-64 bits | D28: =IFERROR(__xludf.DUMMYFUNCTION("FILTER('Diseño'!E:E,'Diseño'!H:H=$C$5)"),"Set Instrucciones ARM") -> Set Instrucciones ARM | F28: =IFERROR(__xludf.DUMMYFUNCTION("FILTER('Diseño'!F:F,'Diseño'!H:H=$C$5)"),"Desplazamientos Y Rotaciones") -> Desplazamientos Y Rotaciones
A29: 2 | B29: =IFERROR(__xludf.DUMMYFUNCTION("""COMPUTED_VALUE"""),"Lenguaje Ensamblador ARM-64 bits") -> Lenguaje Ensamblador ARM-64 bits | D29: =IFERROR(__xludf.DUMMYFUNCTION("""COMPUTED_VALUE"""),"Set Instrucciones ARM") -> Set Instrucciones ARM | F29: =IFERROR(__xludf.DUMMYFUNCTION("""COMPUTED_VALUE"""),"Banderas") -> Banderas
A30: 3 | B30: =IFERROR(__xludf.DUMMYFUNCTION("""COMPUTED_VALUE"""),"Lenguaje Ensamblador ARM-64 bits") -> Lenguaje Ensamblador ARM-64 bits | D30: =IFERROR(__xludf.DUMMYFUNCTION("""COMPUTED_VALUE"""),"Set Instrucciones ARM") -> Set Instrucciones ARM | F30: =IFERROR(__xludf.DUMMYFUNCTION("""COMPUTED_VALUE"""),"Seleccion condicional") -> Seleccion condicional
A31: 4 | B31: =IFERROR(__xludf.DUMMYFUNCTION("""COMPUTED_VALUE"""),"Lenguaje Ensamblador ARM-64 bits") -> Lenguaje Ensamblador ARM-64 bits | D31: =IFERROR(__xludf.DUMMYFUNCTION("""COMPUTED_VALUE"""),"Set Instrucciones ARM") -> Set Instrucciones ARM | F31: =IFERROR(__xludf.DUMMYFUNCTION("""COMPUTED_VALUE"""),"Ciclos y Branching") -> Ciclos y Branching
A32: 5
A33: 6
A34: 7
A36: 2.2 Recursos Educativos
A38: Tipo de Recurso a utilizar | B38: Tipo | C38: Rango Aproximando | D38: Tiempo Aproximado
A39: Presentacion | B39: Obligatorio | D39: 40
A40: Video | B40: Obligatorio | C40: 3 a 6 minutos | D40: 5
A41: Lectura | B41: Optativo | D41: 10
A42: Ejercicio Demostrativo | B42: Obligatorio
A44: 3. Área de Habilidades (Saber Hacer) | G44: Tiempo Aproximado | H44: =B50+B61 -> 35
G45: Tiene que estar en un rango de 30 a 50 minutos
A46: Actividad 1 (Obligatoria)
A47: Competencia que predomina en la actividad | B47: Analiza el comportamiento de la arquitectura ARM utilizando registros, instrucciones y diagramas de bloques optimizando programas a bajo nivel en microprocesadores
A48: Tipo de Actividad | B48: actividades
A49: Ponderación | B49: 2
A50: Tiempo Aproximado | B50: 35
...

Sheet S.9
B2: Diseño de la Sesión de Laboratorio
B4: Curso | C4: ='Diseño'!C4 -> 778 - Arquitectura de Computadoras y Ensambladores 1
B5: Semana | C5: 9
B6: Tiempo | C6: =H10+H21+H44+H68 -> 115
B7: Ponderación | C7: =B49+B60 -> 2
B8: Validación de Tiempo | C8: =IF(H44<=0, "❌ ERROR: La Actividad 1 debe tener un tiempo mayor a 0.", IF(H21>60, "❌ ERROR: El 'Área de Conocimiento' no puede exceder los 60 min.", IF((H10+H21+H44)<100, "❌ ERROR: El tiempo total debe ser de al menos 100 min.", "✅ VALIDACIÓN CORRECTA"))) -> ✅ VALIDACIÓN CORRECTA
A10: 1. Área Actitudinal (Saber Ser) | G10: Tiempo Aproximado | H10: =B13 -> 10
G11: Tiene que estar en un rango de 3 a 5 minutos
A12: Nombre del Valor | B12: Comprension
A13: Tiempo Aproximado | B13: 10
A14: Descripcion
A15: Entiende el contenido en cierto nivel, ya sea a traves de diferentes recursos audiovisuales que lo ayudan a entender mucho mas el tema.
A17: Como se relaciona con los conocimientos de la sesion y se aplicaria
A18: La comunicacion de ARM desde el software que es el lenguaje ensamblador al hardware, y como trabajar con ellas a traves de las llamadas al sistema.
A21: 2. Área Conocimiento (Saber) | G21: Tiempo Aproximado | H21: =D39+D40+D41+D42 -> 60
G22: No puede exceder los 60 minutos
A23: Competencia a desarrollar | B23: Analiza el comportamiento de la arquitectura ARM utilizando registros, instrucciones y diagramas de bloques optimizando programas a bajo nivel en microprocesadores
A24: Competencia a desarrollar
A26: 2.1 Contenido
A27: No. | B27: Unidad | D27: Tema | F27: Sub Tema
A28: 1 | B28: =IFERROR(__xludf.DUMMYFUNCTION("FILTER('Diseño'!D:D,'Diseño'!H:H=$C$5)"),"Lenguaje Ensamblador ARM-64 bits") -> Lenguaje Ensamblador ARM-64 bits | D28: =IFERROR(__xludf.DUMMYFUNCTION("FILTER('Diseño'!E:E,'Diseño'!H:H=$C$5)"),"Set Instrucciones ARM") -> Set Instrucciones ARM | F28: =IFERROR(__xludf.DUMMYFUNCTION("FILTER('Diseño'!F:F,'Diseño'!H:H=$C$5)"),"Niveles Y Tipos De Excepciones") -> Niveles Y Tipos De Excepciones
A29: 2 | B29: =IFERROR(__xludf.DUMMYFUNCTION("""COMPUTED_VALUE"""),"Lenguaje Ensamblador ARM-64 bits") -> Lenguaje Ensamblador ARM-64 bits | D29: =IFERROR(__xludf.DUMMYFUNCTION("""COMPUTED_VALUE"""),"Set Instrucciones ARM") -> Set Instrucciones ARM | F29: =IFERROR(__xludf.DUMMYFUNCTION("""COMPUTED_VALUE"""),"Syscalls") -> Syscalls
A30: 3 | B30: =IFERROR(__xludf.DUMMYFUNCTION("""COMPUTED_VALUE"""),"Lenguaje Ensamblador ARM-64 bits") -> Lenguaje Ensamblador ARM-64 bits | D30: =IFERROR(__xludf.DUMMYFUNCTION("""COMPUTED_VALUE"""),"Set Instrucciones ARM") -> Set Instrucciones ARM | F30: =IFERROR(__xludf.DUMMYFUNCTION("""COMPUTED_VALUE"""),"Directivas De Ensamblador") -> Directivas De Ensamblador
A31: 4 | B31: =IFERROR(__xludf.DUMMYFUNCTION("""COMPUTED_VALUE"""),"Programacion Hibrida ARM-64 bits") -> Programacion Hibrida ARM-64 bits | D31: =IFERROR(__xludf.DUMMYFUNCTION("""COMPUTED_VALUE"""),"Herramientas ARM") -> Herramientas ARM | F31: =IFERROR(__xludf.DUMMYFUNCTION("""COMPUTED_VALUE"""),"Usando El Ensamblador De ARM (GDB)") -> Usando El Ensamblador De ARM (GDB)
A32: 5
A33: 6
A34: 7
A36: 2.2 Recursos Educativos
A38: Tipo de Recurso a utilizar | B38: Tipo | C38: Rango Aproximando | D38: Tiempo Aproximado
A39: Presentacion | B39: Obligatorio | D39: 35
A40: Video | B40: Obligatorio | C40: 3 a 6 minutos | D40: 5
A41: Lectura | B41: Optativo | D41: 10
A42: Ejercicio Demostrativo | B42: Obligatorio | D42: 10
A44: 3. Área de Habilidades (Saber Hacer) | G44: Tiempo Aproximado | H44: =B50+B61 -> 30
G45: Tiene que estar en un rango de 30 a 50 minutos
A46: Actividad 1 (Obligatoria)
A47: Competencia que predomina en la actividad | B47: Analiza el comportamiento de la arquitectura ARM utilizando registros, instrucciones y diagramas de bloques optimizando programas a bajo nivel en microprocesadores
A48: Tipo de Actividad | B48: actividades
A49: Ponderación | B49: 2
A50: Tiempo Aproximado | B50: 30
...

Sheet S.10
B2: Diseño de la Sesión de Laboratorio
B4: Curso | C4: ='Diseño'!C4 -> 778 - Arquitectura de Computadoras y Ensambladores 1
B5: Semana | C5: 10
B6: Tiempo | C6: =H10+H21+H44+H68 -> 115
B7: Ponderación | C7: =B49+B60 -> 2
B8: Validación de Tiempo | C8: =IF(H44<=0, "❌ ERROR: La Actividad 1 debe tener un tiempo mayor a 0.", IF(H21>60, "❌ ERROR: El 'Área de Conocimiento' no puede exceder los 60 min.", IF((H10+H21+H44)<100, "❌ ERROR: El tiempo total debe ser de al menos 100 min.", "✅ VALIDACIÓN CORRECTA"))) -> ✅ VALIDACIÓN CORRECTA
A10: 1. Área Actitudinal (Saber Ser) | G10: Tiempo Aproximado | H10: =B13 -> 10
G11: Tiene que estar en un rango de 3 a 5 minutos
A12: Nombre del Valor | B12: Adaptabilidad
A13: Tiempo Aproximado | B13: 10
A14: Descripcion
A15: Adaptarse a diferentes entornos permitiendole una maleabilidad pensativa, que abarca diferentes areas de forma holistica
A17: Como se relaciona con los conocimientos de la sesion y se aplicaria
A18: Conocer las diferentes herramientas que tenemos a disposicion para un conocimiento profundo del lenguaje ensamblador, lo que a su vez nos permite adaptarnos a diferentes ambientes de desarrollo
A21: 2. Área Conocimiento (Saber) | G21: Tiempo Aproximado | H21: =D39+D40+D41+D42 -> 60
G22: No puede exceder los 60 minutos
A23: Competencia a desarrollar | B23: Crea crea soluciones innovadoras desarrollando algoritmos mediantes aritmetica, logica y control del flujo que permitan resolver problemas computacionales orientado al analisis de datos de sistemas embebidos
A24: Competencia a desarrollar
A26: 2.1 Contenido
A27: No. | B27: Unidad | D27: Tema | F27: Sub Tema
A28: 1 | B28: =IFERROR(__xludf.DUMMYFUNCTION("FILTER('Diseño'!D:D,'Diseño'!H:H=$C$5)"),"Programacion Hibrida ARM-64 bits") -> Programacion Hibrida ARM-64 bits | D28: =IFERROR(__xludf.DUMMYFUNCTION("FILTER('Diseño'!E:E,'Diseño'!H:H=$C$5)"),"Herramientas ARM") -> Herramientas ARM | F28: =IFERROR(__xludf.DUMMYFUNCTION("FILTER('Diseño'!F:F,'Diseño'!H:H=$C$5)"),"Usando El Depurador De ARM (GDB)") -> Usando El Depurador De ARM (GDB)
A29: 2 | B29: =IFERROR(__xludf.DUMMYFUNCTION("""COMPUTED_VALUE"""),"Programacion Hibrida ARM-64 bits") -> Programacion Hibrida ARM-64 bits | D29: =IFERROR(__xludf.DUMMYFUNCTION("""COMPUTED_VALUE"""),"Herramientas ARM") -> Herramientas ARM | F29: =IFERROR(__xludf.DUMMYFUNCTION("""COMPUTED_VALUE"""),"Creacion De Funciones") -> Creacion De Funciones
A30: 3 | B30: =IFERROR(__xludf.DUMMYFUNCTION("""COMPUTED_VALUE"""),"Programacion Hibrida ARM-64 bits") -> Programacion Hibrida ARM-64 bits | D30: =IFERROR(__xludf.DUMMYFUNCTION("""COMPUTED_VALUE"""),"STACK de ARM") -> STACK de ARM | F30: =IFERROR(__xludf.DUMMYFUNCTION("""COMPUTED_VALUE"""),"El Stack Del Procesador") -> El Stack Del Procesador
A31: 4 | B31: =IFERROR(__xludf.DUMMYFUNCTION("""COMPUTED_VALUE"""),"Programacion Hibrida ARM-64 bits") -> Programacion Hibrida ARM-64 bits | D31: =IFERROR(__xludf.DUMMYFUNCTION("""COMPUTED_VALUE"""),"STACK de ARM") -> STACK de ARM | F31: =IFERROR(__xludf.DUMMYFUNCTION("""COMPUTED_VALUE"""),"Manejo Del Stack A Nivel De Codigo") -> Manejo Del Stack A Nivel De Codigo
A32: 5
A33: 6
A34: 7
A36: 2.2 Recursos Educativos
A38: Tipo de Recurso a utilizar | B38: Tipo | C38: Rango Aproximando | D38: Tiempo Aproximado
A39: Presentacion | B39: Obligatorio | D39: 40
A40: Video | B40: Obligatorio | C40: 3 a 6 minutos | D40: 5
A41: Lectura | B41: Optativo | D41: 5
A42: Ejercicio Demostrativo | B42: Obligatorio | D42: 10
A44: 3. Área de Habilidades (Saber Hacer) | G44: Tiempo Aproximado | H44: =B50+B61 -> 30
G45: Tiene que estar en un rango de 30 a 50 minutos
A46: Actividad 1 (Obligatoria)
A47: Competencia que predomina en la actividad | B47: Crea crea soluciones innovadoras desarrollando algoritmos mediantes aritmetica, logica y control del flujo que permitan resolver problemas computacionales orientado al analisis de datos de sistemas embebidos
A48: Tipo de Actividad | B48: actividades
A49: Ponderación | B49: 2
A50: Tiempo Aproximado | B50: 30
...

Sheet S.11
B2: Diseño de la Sesión de Laboratorio
B4: Curso | C4: ='Diseño'!C4 -> 778 - Arquitectura de Computadoras y Ensambladores 1
B5: Semana | C5: 11
B6: Tiempo | C6: =H10+H21+H44+H68 -> 115
B7: Ponderación | C7: =B49+B60 -> 2
B8: Validación de Tiempo | C8: =IF(H44<=0, "❌ ERROR: La Actividad 1 debe tener un tiempo mayor a 0.", IF(H21>60, "❌ ERROR: El 'Área de Conocimiento' no puede exceder los 60 min.", IF((H10+H21+H44)<100, "❌ ERROR: El tiempo total debe ser de al menos 100 min.", "✅ VALIDACIÓN CORRECTA"))) -> ✅ VALIDACIÓN CORRECTA
A10: 1. Área Actitudinal (Saber Ser) | G10: Tiempo Aproximado | H10: =B13 -> 10
G11: Tiene que estar en un rango de 3 a 5 minutos
A12: Nombre del Valor | B12: Innovacion
A13: Tiempo Aproximado | B13: 10
A14: Descripcion
A15: Diseñar y construir herramientas modernas, desarrollar el sentimiento de curiosidad para poder entrar mas a fondo en diferentes temas del area profesional
A17: Como se relaciona con los conocimientos de la sesion y se aplicaria
A18: Conocer la integracon del lenguaje ensamblador con otros lenguajes de programacion como C o Python permiten que el estudiante en su afan de crecimiento profesional quiera indagar mas sobre posibles aplicaciones del lenguaje ensamblador en el mundo actual.
A21: 2. Área Conocimiento (Saber) | G21: Tiempo Aproximado | H21: =D39+D40+D41+D42 -> 55
G22: No puede exceder los 60 minutos
A23: Competencia a desarrollar | B23: Evalua diferentes soluciones a bajo nivel en base a los recursos disponibles y encontrando la eficiencia determinando la alternativa mas optima segun el entorno en donde se este desarrollando
A24: Competencia a desarrollar
A26: 2.1 Contenido
A27: No. | B27: Unidad | D27: Tema | F27: Sub Tema
A28: 1 | B28: =IFERROR(__xludf.DUMMYFUNCTION("FILTER('Diseño'!D:D,'Diseño'!H:H=$C$5)"),"Programacion Hibrida ARM-64 bits") -> Programacion Hibrida ARM-64 bits | D28: =IFERROR(__xludf.DUMMYFUNCTION("FILTER('Diseño'!E:E,'Diseño'!H:H=$C$5)"),"STACK de ARM") -> STACK de ARM | F28: =IFERROR(__xludf.DUMMYFUNCTION("FILTER('Diseño'!F:F,'Diseño'!H:H=$C$5)"),"Casos De Uso Del Stack") -> Casos De Uso Del Stack
A29: 2 | B29: =IFERROR(__xludf.DUMMYFUNCTION("""COMPUTED_VALUE"""),"Programacion Hibrida ARM-64 bits") -> Programacion Hibrida ARM-64 bits | D29: =IFERROR(__xludf.DUMMYFUNCTION("""COMPUTED_VALUE"""),"Compatibilidad de ARM Con C") -> Compatibilidad de ARM Con C | F29: =IFERROR(__xludf.DUMMYFUNCTION("""COMPUTED_VALUE"""),"Desarrollando Bloques En ARM") -> Desarrollando Bloques En ARM
A30: 3 | B30: =IFERROR(__xludf.DUMMYFUNCTION("""COMPUTED_VALUE"""),"Programacion Hibrida ARM-64 bits") -> Programacion Hibrida ARM-64 bits | D30: =IFERROR(__xludf.DUMMYFUNCTION("""COMPUTED_VALUE"""),"Compatibilidad de ARM Con C") -> Compatibilidad de ARM Con C | F30: =IFERROR(__xludf.DUMMYFUNCTION("""COMPUTED_VALUE"""),"Integracion De Bloques ARM En C") -> Integracion De Bloques ARM En C
A31: 4 | B31: =IFERROR(__xludf.DUMMYFUNCTION("""COMPUTED_VALUE"""),"Programacion Hibrida ARM-64 bits") -> Programacion Hibrida ARM-64 bits | D31: =IFERROR(__xludf.DUMMYFUNCTION("""COMPUTED_VALUE"""),"Compatibilidad de ARM Con C") -> Compatibilidad de ARM Con C | F31: =IFERROR(__xludf.DUMMYFUNCTION("""COMPUTED_VALUE"""),"Integracion De Librerias De C En ARM") -> Integracion De Librerias De C En ARM
A32: 5
A33: 6
A34: 7
A36: 2.2 Recursos Educativos
A38: Tipo de Recurso a utilizar | B38: Tipo | C38: Rango Aproximando | D38: Tiempo Aproximado
A39: Presentacion | B39: Obligatorio | D39: 30
A40: Video | B40: Obligatorio | C40: 3 a 6 minutos | D40: 5
A41: Lectura | B41: Optativo | D41: 5
A42: Ejercicio Demostrativo | B42: Obligatorio | D42: 15
A44: 3. Área de Habilidades (Saber Hacer) | G44: Tiempo Aproximado | H44: =B50+B61 -> 35
G45: Tiene que estar en un rango de 30 a 50 minutos
A46: Actividad 1 (Obligatoria)
A47: Competencia que predomina en la actividad | B47: Evalua diferentes soluciones a bajo nivel en base a los recursos disponibles y encontrando la eficiencia determinando la alternativa mas optima segun el entorno en donde se este desarrollando
A48: Tipo de Actividad | B48: Ejercicio practico
A49: Ponderación | B49: 2
A50: Tiempo Aproximado | B50: 35
...

Sheet Proyectos
B2: Proyectos
B4: Curso | C4: ='Diseño'!C4 -> 778 - Arquitectura de Computadoras y Ensambladores 1
B5: Tiempo | C5: =H9+H26+H43 -> 80
B6: Ponderación | C6: =F9+F26+F43 -> 60
B7: La sumatoria de los puntos de los proyectos debe superar el 70% del total de la nota, no puede ser un 100%
A9: 1. Primer Proyecto | E9: Ponderación | F9: 30 | G9: Horas para realizarlo | H9: 30
A10: Obligatorio
A11: Competencia a desarrollar | B11: Recuerda diferentes dispositivos de electronica digital que le permitan dar soluciones a sistemas IoT analizando documentacion tecnica, catalogos de hardware que aporten un valor agregado a la solucion de sistemas embebidos y su interaccion con el entorno
A12: Competencia a desarrollar | B12: Aplica conceptos de electronica para la construccion de prototipos IoT orientados a casos de uso del mundo real mediante placas de desarrollo como raspberry pi, sensores digitales y diseño de sistemas para la automatizacion de procesos logrando mayor eficiencia
A13: Competencia a desarrollar
A14: Titulo | B14: Estación de Control de la Nave Espacial (Star Wars)
A15: Qué tecnologías, lenguajes de programación, plataformas, hardware o software se utilizaran
A16: Raspberry Pi, Raspberry Pi OS, Python, MQTT, Actuadores, Sensores, Protocolos de Comunicación, Node.js, React, MongoDB
A19: Descripción de lo que se realizara
A20: Los estudiantes crean una estación de monitoreo de una nave espacial ficticia. La estación mide temperatura, humedad ambiental y humedad del suelo (simulando “zonas verdes o de cultivo dentro de la nave”). Los LED RGB funcionan como un haz de luz o espada láser que cambia de color según el estado del sistema o según la elección del usuario en el dashboard. Los servomotores y LCD se usan para efectos físicos y visualización de datos. Todo está conectado mediante Raspberry Pi, MQTT, una API REST y almacenamiento en MongoDB para gráficas y estadísticas.
A26: 2. Segundo Proyecto | E26: Ponderación | F26: 30 | G26: Horas para realizarlo | H26: 50
A27: Obligatorio
A28: Competencia a desarrollar | B28: Analiza el comportamiento de la arquitectura ARM utilizando registros, instrucciones y diagramas de bloques optimizando programas a bajo nivel en microprocesadores
A29: Competencia a desarrollar | B29: Crea crea soluciones innovadoras desarrollando algoritmos mediantes aritmetica, logica y control del flujo que permitan resolver problemas computacionales orientado al analisis de datos de sistemas embebidos
